File: Thermal Chamber for UTM/LSR Room temp..csv
Force (N),Position (mm),Stress (MPa),Strain (%),Time (min)
0.00,0.00,0.00,0.00,0.00252
0.00,0.0529,0.00,0.353,0.0323
0.00,0.112,0.00,0.747,0.0620
0.00,0.172,0.00,1.14,0.0917
0.00,0.231,0.00,1.54,0.121
0.00,0.290,0.00,1.94,0.151
0.00,0.350,0.00,2.33,0.181
0.167,0.409,0.0286,2.73,0.211
0.167,0.469,0.0286,3.13,0.240
0.167,0.528,0.0286,3.52,0.270
0.167,0.588,0.0286,3.92,0.300
0.167,0.648,0.0286,4.32,0.330
0.167,0.707,0.0286,4.71,0.359
0.167,0.767,0.0286,5.11,0.389
0.333,0.826,0.0573,5.51,0.419
0.333,0.886,0.0573,5.91,0.449
0.167,0.945,0.0286,6.30,0.478
0.333,1.00,0.0573,6.69,0.508
0.167,1.06,0.0286,7.09,0.538
0.333,1.12,0.0573,7.49,0.568
0.333,1.18,0.0573,7.89,0.597
0.333,1.24,0.0573,8.28,0.627
0.333,1.30,0.0573,8.68,0.657
0.333,1.36,0.0573,9.07,0.687
0.333,1.42,0.0573,9.47,0.716
0.333,1.48,0.0573,9.87,0.746
0.500,1.54,0.0859,10.3,0.776
0.333,1.60,0.0573,10.7,0.805
0.396,1.66,0.0680,11.1,0.835
0.333,1.72,0.0573,11.5,0.865
0.333,1.78,0.0573,11.8,0.895
0.500,1.84,0.0859,12.2,0.924
0.500,1.90,0.0859,12.6,0.954
0.500,1.96,0.0859,13.0,0.984
0.500,2.02,0.0859,13.4,1.01
0.500,2.08,0.0859,13.8,1.04
0.500,2.13,0.0859,14.2,1.07
0.500,2.19,0.0859,14.6,1.10
0.500,2.25,0.0859,15.0,1.13
0.500,2.31,0.0859,15.4,1.16
0.664,2.37,0.114,15.8,1.19
0.500,2.43,0.0859,16.2,1.22
0.541,2.49,0.0930,16.6,1.25
0.667,2.55,0.115,17.0,1.28
0.667,2.61,0.115,17.4,1.31
0.651,2.67,0.112,17.8,1.34
0.667,2.73,0.115,18.2,1.37
0.667,2.79,0.115,18.6,1.40
0.667,2.85,0.115,19.0,1.43
0.667,2.91,0.115,19.4,1.46
0.667,2.97,0.115,19.8,1.49
0.667,3.03,0.115,20.2,1.52
0.667,3.09,0.115,20.6,1.55
0.833,3.15,0.143,21.0,1.58
0.667,3.21,0.115,21.4,1.61
0.667,3.26,0.115,21.8,1.64
0.667,3.32,0.115,22.2,1.67
0.833,3.38,0.143,22.6,1.70
0.833,3.44,0.143,23.0,1.73
0.785,3.50,0.135,23.3,1.76
0.721,3.56,0.124,23.7,1.79
0.833,3.62,0.143,24.1,1.82
0.833,3.68,0.143,24.5,1.85
0.833,3.74,0.143,24.9,1.88
0.833,3.80,0.143,25.3,1.91
0.833,3.86,0.143,25.7,1.94
0.833,3.92,0.143,26.1,1.97
0.833,3.98,0.143,26.5,2.00
0.833,4.04,0.143,26.9,2.02
0.833,4.10,0.143,27.3,2.05
1.00,4.16,0.172,27.7,2.08
0.983,4.22,0.169,28.1,2.11
1.00,4.28,0.172,28.5,2.14
1.00,4.34,0.172,28.9,2.17
1.00,4.39,0.172,29.3,2.20
1.00,4.45,0.172,29.7,2.23
1.00,4.51,0.172,30.1,2.26
1.00,4.57,0.172,30.5,2.29
1.00,4.63,0.172,30.9,2.32
1.00,4.69,0.172,31.3,2.35
1.00,4.75,0.172,31.7,2.38
1.00,4.81,0.172,32.1,2.41
1.00,4.87,0.172,32.5,2.44
1.10,4.93,0.190,32.9,2.47
1.00,4.99,0.172,33.3,2.50
1.17,5.05,0.200,33.7,2.53
1.17,5.11,0.200,34.1,2.56
1.16,5.17,0.199,34.5,2.59
1.17,5.23,0.200,34.8,2.62
1.17,5.29,0.200,35.2,2.65
1.17,5.35,0.200,35.6,2.68
1.17,5.41,0.200,36.0,2.71
1.17,5.47,0.200,36.4,2.74
1.17,5.52,0.200,36.8,2.77
1.17,5.58,0.200,37.2,2.80
1.17,5.64,0.200,37.6,2.83
1.17,5.70,0.200,38.0,2.86
1.17,5.76,0.200,38.4,2.89
1.17,5.82,0.200,38.8,2.92
1.17,5.88,0.200,39.2,2.95
1.33,5.94,0.229,39.6,2.98
1.17,6.00,0.200,40.0,3.01
1.33,6.06,0.229,40.4,3.04
1.33,6.12,0.229,40.8,3.07
1.33,6.18,0.229,41.2,3.10
1.33,6.24,0.229,41.6,3.13
1.33,6.30,0.229,42.0,3.15
1.33,6.36,0.229,42.4,3.18
1.33,6.42,0.229,42.8,3.21
1.33,6.48,0.229,43.2,3.24
1.33,6.54,0.229,43.6,3.27
1.41,6.60,0.242,44.0,3.30
1.44,6.65,0.248,44.4,3.33
1.34,6.71,0.230,44.8,3.36
1.50,6.77,0.258,45.2,3.39
1.50,6.83,0.258,45.6,3.42
1.33,6.89,0.229,46.0,3.45
1.50,6.95,0.258,46.3,3.48
1.34,7.01,0.230,46.7,3.51
1.50,7.07,0.258,47.1,3.54
1.50,7.13,0.258,47.5,3.57
1.50,7.19,0.258,47.9,3.60
1.50,7.25,0.258,48.3,3.63
1.50,7.31,0.258,48.7,3.66
1.50,7.37,0.258,49.1,3.69
1.50,7.43,0.258,49.5,3.72
1.50,7.49,0.258,49.9,3.75
1.50,7.55,0.258,50.3,3.78
1.50,7.61,0.258,50.7,3.81
1.50,7.67,0.258,51.1,3.84
1.50,7.73,0.258,51.5,3.87
1.50,7.79,0.258,51.9,3.90
1.50,7.84,0.258,52.3,3.93
1.50,7.90,0.258,52.7,3.96
1.50,7.96,0.258,53.1,3.99
1.50,8.02,0.258,53.5,4.02
1.50,8.08,0.258,53.9,4.05
1.50,8.14,0.258,54.3,4.08
1.50,8.20,0.258,54.7,4.11
1.50,8.26,0.258,55.1,4.14
1.50,8.32,0.258,55.5,4.17
1.67,8.38,0.286,55.9,4.20
1.50,8.44,0.258,56.3,4.23
1.50,8.50,0.258,56.7,4.26
1.67,8.56,0.286,57.1,4.29
1.67,8.62,0.286,57.5,4.31
1.67,8.68,0.286,57.8,4.34
1.67,8.74,0.286,58.2,4.37
1.67,8.80,0.286,58.6,4.40
1.67,8.86,0.286,59.0,4.43
1.67,8.91,0.286,59.4,4.46
1.67,8.97,0.286,59.8,4.49
1.67,9.03,0.286,60.2,4.52
1.67,9.09,0.286,60.6,4.55
1.67,9.15,0.286,61.0,4.58
1.67,9.21,0.286,61.4,4.61
1.67,9.27,0.286,61.8,4.64
1.67,9.33,0.286,62.2,4.67
1.67,9.39,0.286,62.6,4.70
1.67,9.45,0.286,63.0,4.73
1.67,9.51,0.286,63.4,4.76
1.83,9.57,0.315,63.8,4.79
1.83,9.63,0.315,64.2,4.82
1.83,9.69,0.315,64.6,4.85
1.83,9.75,0.315,65.0,4.88
1.83,9.81,0.315,65.4,4.91
1.83,9.87,0.315,65.8,4.94
1.83,9.93,0.315,66.2,4.97
1.83,9.99,0.315,66.6,5.00
1.91,10.0,0.329,67.0,5.03
1.83,10.1,0.315,67.4,5.06
1.83,10.2,0.315,67.8,5.09
1.83,10.2,0.315,68.2,5.12
1.83,10.3,0.315,68.6,5.15
1.83,10.3,0.315,68.9,5.18
2.00,10.4,0.344,69.3,5.21
1.83,10.5,0.315,69.7,5.24
2.00,10.5,0.344,70.1,5.27
1.83,10.6,0.315,70.5,5.30
2.00,10.6,0.344,70.9,5.33
1.96,10.7,0.336,71.3,5.36
2.00,10.8,0.344,71.7,5.39
2.00,10.8,0.344,72.1,5.42
2.00,10.9,0.344,72.5,5.44
2.00,10.9,0.344,72.9,5.47
2.00,11.0,0.344,73.3,5.50
2.00,11.1,0.344,73.7,5.53
2.00,11.1,0.344,74.1,5.56
2.00,11.2,0.344,74.5,5.59
2.00,11.2,0.344,74.9,5.62
2.00,11.3,0.344,75.3,5.65
2.00,11.4,0.344,75.7,5.68
2.17,11.4,0.372,76.1,5.71
2.00,11.5,0.344,76.5,5.74
2.17,11.5,0.372,76.9,5.77
2.17,11.6,0.372,77.3,5.80
2.17,11.7,0.372,77.7,5.83
2.17,11.7,0.372,78.1,5.86
2.17,11.8,0.372,78.5,5.89
2.17,11.8,0.372,78.9,5.92
2.17,11.9,0.372,79.3,5.95
2.17,11.9,0.372,79.7,5.98
2.17,12.0,0.372,80.1,6.01
2.17,12.1,0.372,80.5,6.04
2.17,12.1,0.372,80.8,6.07
2.17,12.2,0.372,81.2,6.10
2.17,12.2,0.372,81.6,6.13
2.17,12.3,0.372,82.0,6.16
2.17,12.4,0.372,82.4,6.19
2.33,12.4,0.401,82.8,6.22
2.33,12.5,0.401,83.2,6.25
2.33,12.5,0.401,83.6,6.28
2.33,12.6,0.401,84.0,6.31
2.33,12.7,0.401,84.4,6.34
2.33,12.7,0.401,84.8,6.37
2.33,12.8,0.401,85.2,6.40
2.33,12.8,0.401,85.6,6.43
2.33,12.9,0.401,86.0,6.46
2.33,13.0,0.401,86.4,6.49
2.33,13.0,0.401,86.8,6.52
2.50,13.1,0.430,87.2,6.55
2.33,13.1,0.401,87.6,6.57
2.50,13.2,0.430,88.0,6.60
2.33,13.3,0.401,88.4,6.63
2.50,13.3,0.430,88.8,6.66
2.50,13.4,0.430,89.2,6.69
2.50,13.4,0.430,89.6,6.72
2.50,13.5,0.430,90.0,6.75
2.50,13.6,0.430,90.4,6.78
2.50,13.6,0.430,90.8,6.81
2.50,13.7,0.430,91.2,6.84
2.50,13.7,0.430,91.6,6.87
2.55,13.8,0.438,91.9,6.90
2.50,13.9,0.430,92.3,6.93
2.67,13.9,0.458,92.7,6.96
2.67,14.0,0.458,93.1,6.99
2.67,14.0,0.458,93.5,7.02
2.50,14.1,0.430,93.9,7.05
2.67,14.1,0.458,94.3,7.08
2.67,14.2,0.458,94.7,7.11
2.67,14.3,0.458,95.1,7.14
2.67,14.3,0.458,95.5,7.17
2.67,14.4,0.458,95.9,7.20
2.67,14.4,0.458,96.3,7.23
2.67,14.5,0.458,96.7,7.26
2.67,14.6,0.458,97.1,7.29
2.68,14.6,0.460,97.5,7.32
2.67,14.7,0.458,97.9,7.35
2.83,14.7,0.487,98.3,7.38
2.67,14.8,0.458,98.7,7.41
2.67,14.9,0.458,99.1,7.44
2.83,14.9,0.487,99.5,7.47
2.83,15.0,0.487,99.9,7.50
2.83,15.0,0.487,100,7.53
2.83,15.1,0.487,101,7.56
2.83,15.2,0.487,101,7.59
2.83,15.2,0.487,101,7.62
2.83,15.3,0.487,102,7.65
2.83,15.3,0.487,102,7.68
2.83,15.4,0.487,103,7.71
2.83,15.5,0.487,103,7.73
2.83,15.5,0.487,103,7.76
2.83,15.6,0.487,104,7.79
3.00,15.6,0.515,104,7.82
3.00,15.7,0.515,105,7.85
3.00,15.8,0.515,105,7.88
3.00,15.8,0.515,105,7.91
3.00,15.9,0.515,106,7.94
3.00,15.9,0.515,106,7.97
3.00,16.0,0.515,107,8.00
3.00,16.1,0.515,107,8.03
3.00,16.1,0.515,107,8.06
3.00,16.2,0.515,108,8.09
3.00,16.2,0.515,108,8.12
3.05,16.3,0.524,109,8.15
3.00,16.4,0.515,109,8.18
3.17,16.4,0.544,109,8.21
3.17,16.5,0.544,110,8.24
3.17,16.5,0.544,110,8.27
3.17,16.6,0.544,111,8.30
3.00,16.6,0.515,111,8.33
3.17,16.7,0.544,111,8.36
3.17,16.8,0.544,112,8.39
3.17,16.8,0.544,112,8.42
3.17,16.9,0.544,113,8.45
3.17,16.9,0.544,113,8.48
3.17,17.0,0.544,113,8.51
3.17,17.1,0.544,114,8.54
3.17,17.1,0.544,114,8.57
3.33,17.2,0.573,115,8.60
3.33,17.2,0.573,115,8.63
3.33,17.3,0.573,115,8.66
3.33,17.4,0.573,116,8.69
3.33,17.4,0.573,116,8.72
3.33,17.5,0.573,117,8.75
3.33,17.5,0.573,117,8.78
3.33,17.6,0.573,117,8.81
3.33,17.7,0.573,118,8.84
3.33,17.7,0.573,118,8.86
3.33,17.8,0.573,119,8.89
3.33,17.8,0.573,119,8.92
3.33,17.9,0.573,119,8.95
3.33,18.0,0.573,120,8.98
3.33,18.0,0.573,120,9.01
3.50,18.1,0.601,121,9.04
3.50,18.1,0.601,121,9.07
3.33,18.2,0.573,121,9.10
3.50,18.3,0.601,122,9.13
3.50,18.3,0.601,122,9.16
3.50,18.4,0.601,122,9.19
3.50,18.4,0.601,123,9.22
3.50,18.5,0.601,123,9.25
3.50,18.6,0.601,124,9.28
3.50,18.6,0.601,124,9.31
3.50,18.7,0.601,124,9.34
3.50,18.7,0.601,125,9.37
3.50,18.8,0.601,125,9.40
3.50,18.8,0.601,126,9.43
3.50,18.9,0.601,126,9.46
3.67,19.0,0.630,126,9.49
3.50,19.0,0.601,127,9.52
3.67,19.1,0.630,127,9.55
3.67,19.1,0.630,128,9.58
3.67,19.2,0.630,128,9.61
3.67,19.3,0.630,128,9.64
3.67,19.3,0.630,129,9.67
3.67,19.4,0.630,129,9.70
3.67,19.4,0.630,130,9.73
3.73,19.5,0.641,130,9.76
3.83,19.6,0.659,130,9.79
3.73,19.6,0.641,131,9.82
3.83,19.7,0.659,131,9.85
3.83,19.7,0.659,132,9.88
3.83,19.8,0.659,132,9.91
3.83,19.9,0.659,132,9.94
3.83,19.9,0.659,133,9.97
3.83,20.0,0.659,133,10.0
3.99,20.0,0.685,134,10.0
4.00,20.1,0.687,134,10.1
3.83,20.2,0.659,134,10.1
4.00,20.2,0.687,135,10.1
4.00,20.3,0.687,135,10.1
4.00,20.3,0.687,136,10.2
4.00,20.4,0.687,136,10.2
4.00,20.5,0.687,136,10.2
4.00,20.5,0.687,137,10.3
4.00,20.6,0.687,137,10.3
4.00,20.6,0.687,138,10.3
4.00,20.7,0.687,138,10.4
4.00,20.8,0.687,138,10.4
4.00,20.8,0.687,139,10.4
4.17,20.9,0.716,139,10.4
4.17,20.9,0.716,140,10.5
4.17,21.0,0.716,140,10.5
4.17,21.0,0.716,140,10.5
4.17,21.1,0.716,141,10.6
4.17,21.2,0.716,141,10.6
4.17,21.2,0.716,142,10.6
4.17,21.3,0.716,142,10.6
4.17,21.3,0.716,142,10.7
4.17,21.4,0.716,143,10.7
4.17,21.5,0.716,143,10.7
4.17,21.5,0.716,143,10.8
4.33,21.6,0.745,144,10.8
4.17,21.6,0.716,144,10.8
4.33,21.7,0.745,145,10.9
4.33,21.8,0.745,145,10.9
4.33,21.8,0.745,145,10.9
4.33,21.9,0.745,146,10.9
4.33,21.9,0.745,146,11.0
4.33,22.0,0.745,147,11.0
4.33,22.1,0.745,147,11.0
4.33,22.1,0.745,147,11.1
4.33,22.2,0.745,148,11.1
4.33,22.2,0.745,148,11.1
4.33,22.3,0.745,149,11.2
4.33,22.4,0.745,149,11.2
4.50,22.4,0.773,149,11.2
4.33,22.5,0.745,150,11.2
4.33,22.5,0.745,150,11.3
4.33,22.6,0.745,151,11.3
4.33,22.7,0.745,151,11.3
4.50,22.7,0.773,151,11.4
4.50,22.8,0.773,152,11.4
4.50,22.8,0.773,152,11.4
4.50,22.9,0.773,153,11.5
4.50,23.0,0.773,153,11.5
4.50,23.0,0.773,153,11.5
4.50,23.1,0.773,154,11.5
4.50,23.1,0.773,154,11.6
4.67,23.2,0.802,155,11.6
4.64,23.2,0.797,155,11.6
4.50,23.3,0.773,155,11.7
4.67,23.4,0.802,156,11.7
4.67,23.4,0.802,156,11.7
4.67,23.5,0.802,157,11.7
4.67,23.5,0.802,157,11.8
4.67,23.6,0.802,157,11.8
4.67,23.7,0.802,158,11.8
4.67,23.7,0.802,158,11.9
4.67,23.8,0.802,159,11.9
4.83,23.8,0.830,159,11.9
4.68,23.9,0.804,159,12.0
4.83,24.0,0.830,160,12.0
4.83,24.0,0.830,160,12.0
4.83,24.1,0.830,161,12.0
4.83,24.1,0.830,161,12.1
4.83,24.2,0.830,161,12.1
4.83,24.3,0.830,162,12.1
4.83,24.3,0.830,162,12.2
4.83,24.4,0.830,163,12.2
4.83,24.4,0.830,163,12.2
4.83,24.5,0.830,163,12.3
4.83,24.6,0.830,164,12.3
5.00,24.6,0.859,164,12.3
5.00,24.7,0.859,165,12.3
4.91,24.7,0.843,165,12.4
5.00,24.8,0.859,165,12.4
5.00,24.9,0.859,166,12.4
5.00,24.9,0.859,166,12.5
5.00,25.0,0.859,166,12.5
5.00,25.0,0.859,167,12.5
5.00,25.1,0.859,167,12.6
5.00,25.2,0.859,168,12.6
5.00,25.2,0.859,168,12.6
5.02,25.3,0.862,168,12.6
5.00,25.3,0.859,169,12.7
5.00,25.4,0.859,169,12.7
5.17,25.5,0.888,170,12.7
5.17,25.5,0.888,170,12.8
5.17,25.6,0.888,170,12.8
5.17,25.6,0.888,171,12.8
5.17,25.7,0.888,171,12.9
5.17,25.7,0.888,172,12.9
5.17,25.8,0.888,172,12.9
5.17,25.9,0.888,172,12.9
5.17,25.9,0.888,173,13.0
5.17,26.0,0.888,173,13.0
5.17,26.0,0.888,174,13.0
5.17,26.1,0.888,174,13.1
5.33,26.2,0.916,174,13.1
5.33,26.2,0.916,175,13.1
5.33,26.3,0.916,175,13.1
5.33,26.3,0.916,176,13.2
5.33,26.4,0.916,176,13.2
5.33,26.5,0.916,176,13.2
5.33,26.5,0.916,177,13.3
5.33,26.6,0.916,177,13.3
5.33,26.6,0.916,178,13.3
5.33,26.7,0.916,178,13.4
5.33,26.8,0.916,178,13.4
5.33,26.8,0.916,179,13.4
5.33,26.9,0.916,179,13.4
5.50,26.9,0.945,180,13.5
5.50,27.0,0.945,180,13.5
5.50,27.1,0.945,180,13.5
5.50,27.1,0.945,181,13.6
5.50,27.2,0.945,181,13.6
5.50,27.2,0.945,182,13.6
5.50,27.3,0.945,182,13.7
5.50,27.4,0.945,182,13.7
5.50,27.4,0.945,183,13.7
5.50,27.5,0.945,183,13.7
5.67,27.5,0.974,184,13.8
5.67,27.6,0.974,184,13.8
5.67,27.7,0.974,184,13.8
5.67,27.7,0.974,185,13.9
5.67,27.8,0.974,185,13.9
5.67,27.8,0.974,186,13.9
5.67,27.9,0.974,186,14.0
5.67,27.9,0.974,186,14.0
5.67,28.0,0.974,187,14.0
5.67,28.1,0.974,187,14.0
5.67,28.1,0.974,188,14.1
5.71,28.2,0.981,188,14.1
5.67,28.2,0.974,188,14.1
5.83,28.3,1.00,189,14.2
5.83,28.4,1.00,189,14.2
5.67,28.4,0.974,189,14.2
5.78,28.5,0.992,190,14.2
5.83,28.5,1.00,190,14.3
5.83,28.6,1.00,191,14.3
5.83,28.7,1.00,191,14.3
5.83,28.7,1.00,191,14.4
5.83,28.8,1.00,192,14.4
5.83,28.8,1.00,192,14.4
5.83,28.9,1.00,193,14.5
5.83,29.0,1.00,193,14.5
5.83,29.0,1.00,193,14.5
5.83,29.1,1.00,194,14.5
5.83,29.1,1.00,194,14.6
5.83,29.2,1.00,195,14.6
5.83,29.3,1.00,195,14.6
5.83,29.3,1.00,195,14.7
5.93,29.4,1.02,196,14.7
5.90,29.4,1.01,196,14.7
6.00,29.5,1.03,197,14.8
6.00,29.6,1.03,197,14.8
6.00,29.6,1.03,197,14.8
6.00,29.7,1.03,198,14.8
6.00,29.7,1.03,198,14.9
6.00,29.8,1.03,199,14.9
6.00,29.9,1.03,199,14.9
6.00,29.9,1.03,199,15.0
6.00,30.0,1.03,200,15.0
6.00,30.0,1.03,200,15.0
6.00,30.1,1.03,201,15.1
6.17,30.1,1.06,201,15.1
6.17,30.2,1.06,201,15.1
6.17,30.3,1.06,202,15.1
6.17,30.3,1.06,202,15.2
6.17,30.4,1.06,203,15.2
6.17,30.4,1.06,203,15.2
6.17,30.5,1.06,203,15.3
6.17,30.6,1.06,204,15.3
6.17,30.6,1.06,204,15.3
6.33,30.7,1.09,205,15.3
6.17,30.7,1.06,205,15.4
6.00,30.8,1.03,205,15.4
6.00,30.9,1.03,206,15.4
6.17,30.9,1.06,206,15.5
6.17,31.0,1.06,207,15.5
6.17,31.0,1.06,207,15.5
6.17,31.1,1.06,207,15.6
6.32,31.2,1.09,208,15.6
6.17,31.2,1.06,208,15.6
6.33,31.3,1.09,209,15.6
6.33,31.3,1.09,209,15.7
6.33,31.4,1.09,209,15.7
6.33,31.5,1.09,210,15.7
6.33,31.5,1.09,210,15.8
6.33,31.6,1.09,211,15.8
6.50,31.6,1.12,211,15.8
6.33,31.7,1.09,211,15.9
6.50,31.8,1.12,212,15.9
6.50,31.8,1.12,212,15.9
6.50,31.9,1.12,212,15.9
6.50,31.9,1.12,213,16.0
6.50,32.0,1.12,213,16.0
6.50,32.1,1.12,214,16.0
6.50,32.1,1.12,214,16.1
6.50,32.2,1.12,214,16.1
6.50,32.2,1.12,215,16.1
6.67,32.3,1.15,215,16.2
6.50,32.4,1.12,216,16.2
6.67,32.4,1.15,216,16.2
6.67,32.5,1.15,216,16.2
6.67,32.5,1.15,217,16.3
6.67,32.6,1.15,217,16.3
6.67,32.6,1.15,218,16.3
6.67,32.7,1.15,218,16.4
6.72,32.8,1.15,218,16.4
6.67,32.8,1.15,219,16.4
6.83,32.9,1.17,219,16.4
6.83,32.9,1.17,220,16.5
6.67,33.0,1.15,220,16.5
6.83,33.1,1.17,220,16.5
6.83,33.1,1.17,221,16.6
6.83,33.2,1.17,221,16.6
6.83,33.2,1.17,222,16.6
6.83,33.3,1.17,222,16.7
6.83,33.4,1.17,222,16.7
6.83,33.4,1.17,223,16.7
6.99,33.5,1.20,223,16.7
6.83,33.5,1.17,224,16.8
6.95,33.6,1.19,224,16.8
6.85,33.7,1.18,224,16.8
7.00,33.7,1.20,225,16.9
7.00,33.8,1.20,225,16.9
7.00,33.8,1.20,226,16.9
6.83,33.9,1.17,226,17.0
7.00,34.0,1.20,226,17.0
7.00,34.0,1.20,227,17.0
7.00,34.1,1.20,227,17.0
7.00,34.1,1.20,228,17.1
7.00,34.2,1.20,228,17.1
7.17,34.3,1.23,228,17.1
7.00,34.3,1.20,229,17.2
7.17,34.4,1.23,229,17.2
7.00,34.4,1.20,230,17.2
7.17,34.5,1.23,230,17.3
7.17,34.6,1.23,230,17.3
7.17,34.6,1.23,231,17.3
7.00,34.7,1.20,231,17.3
7.17,34.7,1.23,232,17.4
7.00,34.8,1.20,232,17.4
7.00,34.8,1.20,232,17.4
7.00,34.9,1.20,233,17.5
7.00,35.0,1.20,233,17.5
7.00,35.0,1.20,234,17.5
7.17,35.1,1.23,234,17.5
7.00,35.1,1.20,234,17.6
7.17,35.2,1.23,235,17.6
7.17,35.3,1.23,235,17.6
7.17,35.3,1.23,235,17.7
7.17,35.4,1.23,236,17.7
7.33,35.4,1.26,236,17.7
7.17,35.5,1.23,237,17.8
7.33,35.6,1.26,237,17.8
7.17,35.6,1.23,237,17.8
7.33,35.7,1.26,238,17.8
7.33,35.7,1.26,238,17.9
7.33,35.8,1.26,239,17.9
7.33,35.9,1.26,239,17.9
7.33,35.9,1.26,239,18.0
7.33,36.0,1.26,240,18.0
7.33,36.0,1.26,240,18.0
7.33,36.1,1.26,241,18.1
7.33,36.2,1.26,241,18.1
7.33,36.2,1.26,241,18.1
7.33,36.3,1.26,242,18.1
7.33,36.3,1.26,242,18.2
7.33,36.4,1.26,243,18.2
7.33,36.5,1.26,243,18.2
7.33,36.5,1.26,243,18.3
7.49,36.6,1.29,244,18.3
7.33,36.6,1.26,244,18.3
7.50,36.7,1.29,245,18.4
7.50,36.8,1.29,245,18.4
7.50,36.8,1.29,245,18.4
7.50,36.9,1.29,246,18.4
7.50,36.9,1.29,246,18.5
7.50,37.0,1.29,247,18.5
7.50,37.0,1.29,247,18.5
7.50,37.1,1.29,247,18.6
7.67,37.2,1.32,248,18.6
7.67,37.2,1.32,248,18.6
7.67,37.3,1.32,249,18.6
7.67,37.3,1.32,249,18.7
7.67,37.4,1.32,249,18.7
7.50,37.5,1.29,250,18.7
7.50,37.5,1.29,250,18.8
7.67,37.6,1.32,251,18.8
7.50,37.6,1.29,251,18.8
7.63,37.7,1.31,251,18.9
7.67,37.8,1.32,252,18.9
7.67,37.8,1.32,252,18.9
7.67,37.9,1.32,253,18.9
7.67,37.9,1.32,253,19.0
7.67,38.0,1.32,253,19.0
7.67,38.1,1.32,254,19.0
7.83,38.1,1.35,254,19.1
7.83,38.2,1.35,255,19.1
7.83,38.2,1.35,255,19.1
7.83,38.3,1.35,255,19.2
7.83,38.4,1.35,256,19.2
7.83,38.4,1.35,256,19.2
7.83,38.5,1.35,257,19.2
7.83,38.5,1.35,257,19.3
7.83,38.6,1.35,257,19.3
7.83,38.7,1.35,258,19.3
7.83,38.7,1.35,258,19.4
8.00,38.8,1.37,258,19.4
8.00,38.8,1.37,259,19.4
8.00,38.9,1.37,259,19.5
8.00,39.0,1.37,260,19.5
8.00,39.0,1.37,260,19.5
8.00,39.1,1.37,260,19.5
8.00,39.1,1.37,261,19.6
8.00,39.2,1.37,261,19.6
8.00,39.2,1.37,262,19.6
8.00,39.3,1.37,262,19.7
8.00,39.4,1.37,262,19.7
8.00,39.4,1.37,263,19.7
8.00,39.5,1.37,263,19.7
8.00,39.5,1.37,264,19.8
8.00,39.6,1.37,264,19.8
8.00,39.7,1.37,264,19.8
8.05,39.7,1.38,265,19.9
8.17,39.8,1.40,265,19.9
8.17,39.8,1.40,266,19.9
8.17,39.9,1.40,266,20.0
8.17,40.0,1.40,266,20.0
8.00,40.0,1.37,267,20.0
7.93,40.1,1.36,267,20.0
7.83,40.1,1.35,268,20.1
8.00,40.2,1.37,268,20.1
8.00,40.3,1.37,268,20.1
8.00,40.3,1.37,269,20.2
8.00,40.4,1.37,269,20.2
8.17,40.4,1.40,270,20.2
8.00,40.5,1.37,270,20.3
8.17,40.6,1.40,270,20.3
8.17,40.6,1.40,271,20.3
8.17,40.7,1.40,271,20.3
8.33,40.7,1.43,272,20.4
8.17,40.8,1.40,272,20.4
8.33,40.9,1.43,272,20.4
8.33,40.9,1.43,273,20.5
8.33,41.0,1.43,273,20.5
8.33,41.0,1.43,274,20.5
8.33,41.1,1.43,274,20.6
8.33,41.2,1.43,274,20.6
8.33,41.2,1.43,275,20.6
8.33,41.3,1.43,275,20.6
8.33,41.3,1.43,276,20.7
8.33,41.4,1.43,276,20.7
8.33,41.5,1.43,276,20.7
8.33,41.5,1.43,277,20.8
8.33,41.6,1.43,277,20.8
8.33,41.6,1.43,278,20.8
8.50,41.7,1.46,278,20.8
8.50,41.7,1.46,278,20.9
8.33,41.8,1.43,279,20.9
8.50,41.9,1.46,279,20.9
8.50,41.9,1.46,280,21.0
8.50,42.0,1.46,280,21.0
8.67,42.0,1.49,280,21.0
8.67,42.1,1.49,281,21.1
8.67,42.2,1.49,281,21.1
8.67,42.2,1.49,281,21.1
8.67,42.3,1.49,282,21.1
8.67,42.3,1.49,282,21.2
8.67,42.4,1.49,283,21.2
8.67,42.5,1.49,283,21.2
8.67,42.5,1.49,283,21.3
8.67,42.6,1.49,284,21.3
8.67,42.6,1.49,284,21.3
8.67,42.7,1.49,285,21.4
8.67,42.8,1.49,285,21.4
8.67,42.8,1.49,285,21.4
8.67,42.9,1.49,286,21.4
8.83,42.9,1.52,286,21.5
8.83,43.0,1.52,287,21.5
8.70,43.1,1.49,287,21.5
8.83,43.1,1.52,287,21.6
8.83,43.2,1.52,288,21.6
8.83,43.2,1.52,288,21.6
8.83,43.3,1.52,289,21.7
8.83,43.4,1.52,289,21.7
9.00,43.4,1.55,289,21.7
9.00,43.5,1.55,290,21.7
8.83,43.5,1.52,290,21.8
9.00,43.6,1.55,291,21.8
9.00,43.7,1.55,291,21.8
9.00,43.7,1.55,291,21.9
9.00,43.8,1.55,292,21.9
9.00,43.8,1.55,292,21.9
9.00,43.9,1.55,293,22.0
9.00,43.9,1.55,293,22.0
9.00,44.0,1.55,293,22.0
9.00,44.1,1.55,294,22.0
9.12,44.1,1.57,294,22.1
9.00,44.2,1.55,295,22.1
8.67,44.2,1.49,295,22.1
8.83,44.3,1.52,295,22.2
8.67,44.4,1.49,296,22.2
8.83,44.4,1.52,296,22.2
8.83,44.5,1.52,297,22.2
9.00,44.5,1.55,297,22.3
9.00,44.6,1.55,297,22.3
9.00,44.7,1.55,298,22.3
9.00,44.7,1.55,298,22.4
9.00,44.8,1.55,299,22.4
9.17,44.8,1.58,299,22.4
9.05,44.9,1.55,299,22.5
9.17,45.0,1.58,300,22.5
9.17,45.0,1.58,300,22.5
9.17,45.1,1.58,301,22.5
9.17,45.1,1.58,301,22.6
9.00,45.2,1.55,301,22.6
9.00,45.3,1.55,302,22.6
9.00,45.3,1.55,302,22.7
9.00,45.4,1.55,303,22.7
9.17,45.4,1.58,303,22.7
9.17,45.5,1.58,303,22.8
9.17,45.6,1.58,304,22.8
9.17,45.6,1.58,304,22.8
9.17,45.7,1.58,304,22.8
9.17,45.7,1.58,305,22.9
9.33,45.8,1.60,305,22.9
9.33,45.9,1.60,306,22.9
9.33,45.9,1.60,306,23.0
9.33,46.0,1.60,306,23.0
9.33,46.0,1.60,307,23.0
9.33,46.1,1.60,307,23.1
9.33,46.1,1.60,308,23.1
9.47,46.2,1.63,308,23.1
9.50,46.3,1.63,308,23.1
9.50,46.3,1.63,309,23.2
9.50,46.4,1.63,309,23.2
9.50,46.4,1.63,310,23.2
9.50,46.5,1.63,310,23.3
9.50,46.6,1.63,310,23.3
9.50,46.6,1.63,311,23.3
9.50,46.7,1.63,311,23.3
9.50,46.7,1.63,312,23.4
9.67,46.8,1.66,312,23.4
9.67,46.9,1.66,312,23.4
9.67,46.9,1.66,313,23.5
9.67,47.0,1.66,313,23.5
9.67,47.0,1.66,314,23.5
9.67,47.1,1.66,314,23.6
9.67,47.2,1.66,314,23.6
9.67,47.2,1.66,315,23.6
9.67,47.3,1.66,315,23.6
9.67,47.3,1.66,316,23.7
9.67,47.4,1.66,316,23.7
9.67,47.5,1.66,316,23.7
9.83,47.5,1.69,317,23.8
9.83,47.6,1.69,317,23.8
9.83,47.6,1.69,318,23.8
9.83,47.7,1.69,318,23.9
9.83,47.8,1.69,318,23.9
9.83,47.8,1.69,319,23.9
9.83,47.9,1.69,319,23.9
9.83,47.9,1.69,320,24.0
9.83,48.0,1.69,320,24.0
10.0,48.1,1.72,320,24.0
10.0,48.1,1.72,321,24.1
10.0,48.2,1.72,321,24.1
10.0,48.2,1.72,322,24.1
10.0,48.3,1.72,322,24.2
10.0,48.4,1.72,322,24.2
10.0,48.4,1.72,323,24.2
9.67,48.5,1.66,323,24.2
9.67,48.5,1.66,324,24.3
9.67,48.6,1.66,324,24.3
9.67,48.6,1.66,324,24.3
9.67,48.7,1.66,325,24.4
9.83,48.8,1.69,325,24.4
9.83,48.8,1.69,326,24.4
9.83,48.9,1.69,326,24.4
9.83,48.9,1.69,326,24.5
10.0,49.0,1.72,327,24.5
9.89,49.1,1.70,327,24.5
10.0,49.1,1.72,327,24.6
10.0,49.2,1.72,328,24.6
10.0,49.2,1.72,328,24.6
10.0,49.3,1.72,329,24.7
10.1,49.4,1.73,329,24.7
10.2,49.4,1.75,329,24.7
10.0,49.5,1.72,330,24.7
9.95,49.5,1.71,330,24.8
10.0,49.6,1.72,331,24.8
10.0,49.7,1.72,331,24.8
9.83,49.7,1.69,331,24.9
10.0,49.8,1.72,332,24.9
10.0,49.8,1.72,332,24.9
10.0,49.9,1.72,333,25.0
10.0,50.0,1.72,333,25.0
10.2,50.0,1.75,333,25.0
10.2,50.1,1.75,334,25.0
10.2,50.1,1.75,334,25.1
10.3,50.2,1.78,335,25.1
10.2,50.3,1.75,335,25.1
10.3,50.3,1.78,335,25.2
10.3,50.4,1.78,336,25.2
10.3,50.4,1.78,336,25.2
10.3,50.5,1.78,337,25.3
10.3,50.6,1.78,337,25.3
10.3,50.6,1.78,337,25.3
10.3,50.7,1.78,338,25.3
10.3,50.7,1.78,338,25.4
10.5,50.8,1.80,339,25.4
10.4,50.8,1.78,339,25.4
10.3,50.9,1.78,339,25.5
10.5,51.0,1.80,340,25.5
10.5,51.0,1.80,340,25.5
10.5,51.1,1.80,341,25.5
10.5,51.1,1.80,341,25.6
10.5,51.2,1.80,341,25.6
10.5,51.3,1.80,342,25.6
10.5,51.3,1.80,342,25.7
10.5,51.4,1.80,343,25.7
10.7,51.4,1.83,343,25.7
10.5,51.5,1.80,343,25.8
10.7,51.6,1.83,344,25.8
10.7,51.6,1.83,344,25.8
10.7,51.7,1.83,345,25.8
10.7,51.7,1.83,345,25.9
10.7,51.8,1.83,345,25.9
10.7,51.9,1.83,346,25.9
10.7,51.9,1.83,346,26.0
10.7,52.0,1.83,347,26.0
10.7,52.0,1.83,347,26.0
10.7,52.1,1.83,347,26.1
10.7,52.2,1.83,348,26.1
10.7,52.2,1.83,348,26.1
10.7,52.3,1.83,349,26.1
10.7,52.3,1.83,349,26.2
10.7,52.4,1.83,349,26.2
10.7,52.5,1.83,350,26.2
10.8,52.5,1.86,350,26.3
10.8,52.6,1.86,350,26.3
10.8,52.6,1.86,351,26.3
10.8,52.7,1.86,351,26.4
10.8,52.8,1.86,352,26.4
10.8,52.8,1.86,352,26.4
11.0,52.9,1.89,352,26.4
10.9,52.9,1.87,353,26.5
10.8,53.0,1.86,353,26.5
11.0,53.0,1.89,354,26.5
11.0,53.1,1.89,354,26.6
11.0,53.2,1.89,354,26.6
11.0,53.2,1.89,355,26.6
11.0,53.3,1.89,355,26.6
11.0,53.3,1.89,356,26.7
11.0,53.4,1.89,356,26.7
11.0,53.5,1.89,356,26.7
11.0,53.5,1.89,357,26.8
11.0,53.6,1.89,357,26.8
11.2,53.6,1.92,358,26.8
11.2,53.7,1.92,358,26.9
11.2,53.8,1.92,358,26.9
11.2,53.8,1.92,359,26.9
11.2,53.9,1.92,359,26.9
11.2,53.9,1.92,360,27.0
11.3,54.0,1.95,360,27.0
11.2,54.1,1.92,360,27.0
11.2,54.1,1.92,361,27.1
11.3,54.2,1.95,361,27.1
11.2,54.2,1.92,362,27.1
11.3,54.3,1.95,362,27.2
11.3,54.4,1.95,362,27.2
11.3,54.4,1.95,363,27.2
11.3,54.5,1.95,363,27.2
11.3,54.5,1.95,364,27.3
11.5,54.6,1.98,364,27.3
11.3,54.7,1.95,364,27.3
11.5,54.7,1.98,365,27.4
11.5,54.8,1.98,365,27.4
11.5,54.8,1.98,366,27.4
11.5,54.9,1.98,366,27.5
11.5,55.0,1.98,366,27.5
11.5,55.0,1.98,367,27.5
11.7,55.1,2.00,367,27.5
11.5,55.1,1.98,368,27.6
11.7,55.2,2.00,368,27.6
11.7,55.2,2.00,368,27.6
11.7,55.3,2.00,369,27.7
11.7,55.4,2.00,369,27.7
11.5,55.4,1.98,370,27.7
11.5,55.5,1.98,370,27.7
11.5,55.5,1.98,370,27.8
11.7,55.6,2.00,371,27.8
11.7,55.7,2.00,371,27.8
11.5,55.7,1.98,372,27.9
11.7,55.8,2.00,372,27.9
11.7,55.8,2.00,372,27.9
11.7,55.9,2.00,373,28.0
11.7,56.0,2.00,373,28.0
11.7,56.0,2.00,373,28.0
11.7,56.1,2.00,374,28.0
11.7,56.1,2.02,374,28.1
11.8,56.2,2.03,375,28.1
11.7,56.3,2.00,375,28.1
11.8,56.3,2.03,375,28.2
11.8,56.4,2.03,376,28.2
11.8,56.4,2.03,376,28.2
12.0,56.5,2.06,377,28.3
12.0,56.6,2.06,377,28.3
11.8,56.6,2.03,377,28.3
11.8,56.7,2.03,378,28.3
11.3,56.7,1.95,378,28.4
11.3,56.8,1.95,379,28.4
11.5,56.9,1.98,379,28.4
11.5,56.9,1.98,379,28.5
11.5,57.0,1.98,380,28.5
11.6,57.0,2.00,380,28.5
11.7,57.1,2.00,381,28.6
11.7,57.2,2.00,381,28.6
11.8,57.2,2.02,381,28.6
11.8,57.3,2.03,382,28.6
11.8,57.3,2.03,382,28.7
11.8,57.4,2.03,383,28.7
12.0,57.5,2.06,383,28.7
12.0,57.5,2.06,383,28.8
12.0,57.6,2.06,384,28.8
12.0,57.6,2.06,384,28.8
12.0,57.7,2.06,385,28.8
12.2,57.7,2.09,385,28.9
12.0,57.8,2.06,385,28.9
12.2,57.9,2.09,386,28.9
12.2,57.9,2.09,386,29.0
12.2,58.0,2.09,387,29.0
12.2,58.0,2.09,387,29.0
12.2,58.1,2.09,387,29.1
12.2,58.2,2.09,388,29.1
12.2,58.2,2.09,388,29.1
12.3,58.3,2.11,389,29.1
12.3,58.3,2.12,389,29.2
12.3,58.4,2.12,389,29.2
12.3,58.5,2.12,390,29.2
12.3,58.5,2.12,390,29.3
12.3,58.6,2.12,391,29.3
12.3,58.6,2.12,391,29.3
12.5,58.7,2.15,391,29.4
12.5,58.8,2.15,392,29.4
12.5,58.8,2.15,392,29.4
12.5,58.9,2.15,393,29.4
12.5,58.9,2.15,393,29.5
12.5,59.0,2.15,393,29.5
12.5,59.1,2.15,394,29.5
12.3,59.1,2.12,394,29.6
12.3,59.2,2.12,394,29.6
12.3,59.2,2.12,395,29.6
12.5,59.3,2.15,395,29.7
12.3,59.4,2.12,396,29.7
12.5,59.4,2.15,396,29.7
12.5,59.5,2.15,396,29.7
12.5,59.5,2.15,397,29.8
12.5,59.6,2.15,397,29.8
12.7,59.7,2.18,398,29.8
12.7,59.7,2.18,398,29.9
12.7,59.8,2.18,398,29.9
12.7,59.8,2.18,399,29.9
12.7,59.9,2.18,399,30.0
12.7,59.9,2.18,400,30.0
12.7,60.0,2.18,400,30.0
12.7,60.1,2.18,400,30.0
12.7,60.1,2.18,401,30.1
12.7,60.2,2.18,401,30.1
12.8,60.2,2.21,402,30.1
12.7,60.3,2.18,402,30.2
12.8,60.4,2.21,402,30.2
12.7,60.4,2.18,403,30.2
12.8,60.5,2.21,403,30.2
12.8,60.5,2.21,404,30.3
12.5,60.6,2.15,404,30.3
12.5,60.7,2.15,404,30.3
12.5,60.7,2.15,405,30.4
12.5,60.8,2.15,405,30.4
12.5,60.8,2.15,406,30.4
12.5,60.9,2.15,406,30.5
12.5,61.0,2.15,406,30.5
12.7,61.0,2.18,407,30.5
12.7,61.1,2.18,407,30.5
12.7,61.1,2.18,408,30.6
12.5,61.2,2.15,408,30.6
12.6,61.3,2.16,408,30.6
12.7,61.3,2.18,409,30.7
12.7,61.4,2.18,409,30.7
12.7,61.4,2.18,410,30.7
12.7,61.5,2.18,410,30.8
12.7,61.6,2.18,410,30.8
12.7,61.6,2.18,411,30.8
12.8,61.7,2.21,411,30.8
12.8,61.7,2.21,412,30.9
12.8,61.8,2.21,412,30.9
12.8,61.9,2.21,412,30.9
12.8,61.9,2.21,413,31.0
13.0,62.0,2.23,413,31.0
13.0,62.0,2.23,414,31.0
13.0,62.1,2.23,414,31.1
13.0,62.1,2.23,414,31.1
13.0,62.2,2.23,415,31.1
13.2,62.3,2.26,415,31.1
13.1,62.3,2.24,416,31.2
13.2,62.4,2.26,416,31.2
13.2,62.4,2.26,416,31.2
13.2,62.5,2.26,417,31.3
13.2,62.6,2.26,417,31.3
13.3,62.6,2.29,417,31.3
13.3,62.7,2.29,418,31.3
13.3,62.7,2.29,418,31.4
13.3,62.8,2.29,419,31.4
13.4,62.9,2.30,419,31.4
13.4,62.9,2.30,419,31.5
13.5,63.0,2.32,420,31.5
13.5,63.0,2.32,420,31.5
13.5,63.1,2.32,421,31.6
13.5,63.2,2.32,421,31.6
13.5,63.2,2.32,421,31.6
13.5,63.3,2.32,422,31.6
13.5,63.3,2.32,422,31.7
13.7,63.4,2.35,423,31.7
13.7,63.5,2.35,423,31.7
13.7,63.5,2.35,423,31.8
13.7,63.6,2.35,424,31.8
13.7,63.6,2.35,424,31.8
13.7,63.7,2.35,425,31.9
13.7,63.8,2.35,425,31.9
13.7,63.8,2.35,425,31.9
13.7,63.9,2.35,426,31.9
13.8,63.9,2.38,426,32.0
13.8,64.0,2.38,427,32.0
13.8,64.1,2.38,427,32.0
13.8,64.1,2.38,427,32.1
13.8,64.2,2.38,428,32.1
13.8,64.2,2.38,428,32.1
13.8,64.3,2.38,429,32.2
13.9,64.3,2.39,429,32.2
13.8,64.4,2.38,429,32.2
13.8,64.5,2.38,430,32.2
14.0,64.5,2.41,430,32.3
14.0,64.6,2.41,431,32.3
14.0,64.6,2.41,431,32.3
14.0,64.7,2.41,431,32.4
14.0,64.8,2.41,432,32.4
14.0,64.8,2.41,432,32.4
14.0,64.9,2.41,433,32.4
14.0,64.9,2.41,433,32.5
14.0,65.0,2.41,433,32.5
14.0,65.1,2.41,434,32.5
14.2,65.1,2.43,434,32.6
14.2,65.2,2.43,435,32.6
14.2,65.2,2.43,435,32.6
14.2,65.3,2.43,435,32.7
14.2,65.4,2.43,436,32.7
14.2,65.4,2.43,436,32.7
14.2,65.5,2.43,437,32.7
14.2,65.5,2.44,437,32.8
14.3,65.6,2.46,437,32.8
14.3,65.7,2.46,438,32.8
14.3,65.7,2.46,438,32.9
14.3,65.8,2.46,439,32.9
14.3,65.8,2.46,439,32.9
14.3,65.9,2.46,439,33.0
14.5,66.0,2.49,440,33.0
14.3,66.0,2.46,440,33.0
14.3,66.1,2.46,440,33.0
14.5,66.1,2.49,441,33.1
14.5,66.2,2.49,441,33.1
14.5,66.3,2.49,442,33.1
14.5,66.3,2.49,442,33.2
14.5,66.4,2.49,442,33.2
14.5,66.4,2.49,443,33.2
14.5,66.5,2.49,443,33.3
14.5,66.6,2.49,444,33.3
14.5,66.6,2.49,444,33.3
14.5,66.7,2.49,444,33.3
14.7,66.7,2.52,445,33.4
14.7,66.8,2.52,445,33.4
14.7,66.8,2.52,446,33.4
14.7,66.9,2.52,446,33.5
14.7,67.0,2.52,446,33.5
14.7,67.0,2.52,447,33.5
14.7,67.1,2.52,447,33.5
14.7,67.1,2.52,448,33.6
14.7,67.2,2.52,448,33.6
14.8,67.3,2.55,448,33.6
14.8,67.3,2.55,449,33.7
14.8,67.4,2.55,449,33.7
14.8,67.4,2.55,450,33.7
14.8,67.5,2.55,450,33.8
15.0,67.6,2.57,450,33.8
14.8,67.6,2.55,451,33.8
15.0,67.7,2.58,451,33.8
14.9,67.7,2.56,452,33.9
15.0,67.8,2.58,452,33.9
15.0,67.9,2.58,452,33.9
15.0,67.9,2.58,453,34.0
15.0,68.0,2.58,453,34.0
15.0,68.0,2.58,454,34.0
15.0,68.1,2.58,454,34.1
15.0,68.2,2.58,454,34.1
15.0,68.2,2.58,455,34.1
15.0,68.3,2.58,455,34.1
15.0,68.3,2.58,456,34.2
15.2,68.4,2.61,456,34.2
15.2,68.5,2.61,456,34.2
15.2,68.5,2.61,457,34.3
15.2,68.6,2.61,457,34.3
15.2,68.6,2.61,458,34.3
15.2,68.7,2.61,458,34.4
15.2,68.8,2.61,458,34.4
15.2,68.8,2.61,459,34.4
15.3,68.9,2.63,459,34.4
15.3,68.9,2.63,460,34.5
15.3,69.0,2.63,460,34.5
15.3,69.0,2.63,460,34.5
15.3,69.1,2.63,461,34.6
15.3,69.2,2.63,461,34.6
15.3,69.2,2.63,462,34.6
15.3,69.3,2.63,462,34.6
15.5,69.3,2.66,462,34.7
15.5,69.4,2.66,463,34.7
15.5,69.5,2.66,463,34.7
15.5,69.5,2.66,463,34.8
15.5,69.6,2.66,464,34.8
15.5,69.6,2.66,464,34.8
15.5,69.7,2.66,465,34.9
15.5,69.8,2.66,465,34.9
15.5,69.8,2.66,465,34.9
15.5,69.9,2.66,466,34.9
15.7,69.9,2.69,466,35.0
15.5,70.0,2.66,467,35.0
15.7,70.1,2.69,467,35.0
15.7,70.1,2.69,467,35.1
15.7,70.2,2.69,468,35.1
15.7,70.2,2.69,468,35.1
15.7,70.3,2.69,469,35.2
15.7,70.4,2.69,469,35.2
15.7,70.4,2.69,469,35.2
15.7,70.5,2.69,470,35.2
15.7,70.5,2.70,470,35.3
15.7,70.6,2.69,471,35.3
15.8,70.7,2.72,471,35.3
15.8,70.7,2.72,471,35.4
15.8,70.8,2.72,472,35.4
15.8,70.8,2.72,472,35.4
15.8,70.9,2.72,473,35.5
15.8,71.0,2.72,473,35.5
15.8,71.0,2.72,473,35.5
15.8,71.1,2.72,474,35.5
15.8,71.1,2.72,474,35.6
15.8,71.2,2.72,475,35.6
15.8,71.2,2.72,475,35.6
15.8,71.3,2.72,475,35.7
15.8,71.4,2.72,476,35.7
16.0,71.4,2.75,476,35.7
15.8,71.5,2.72,477,35.7
15.9,71.5,2.73,477,35.8
15.8,71.6,2.72,477,35.8
16.0,71.7,2.75,478,35.8
16.0,71.7,2.75,478,35.9
16.0,71.8,2.75,479,35.9
16.0,71.8,2.75,479,35.9
16.0,71.9,2.75,479,36.0
16.0,72.0,2.75,480,36.0
16.0,72.0,2.75,480,36.0
16.0,72.1,2.75,481,36.0
16.0,72.1,2.75,481,36.1
16.0,72.2,2.75,481,36.1
16.0,72.3,2.75,482,36.1
16.0,72.3,2.75,482,36.2
16.0,72.4,2.75,483,36.2
16.0,72.4,2.75,483,36.2
16.0,72.5,2.75,483,36.3
16.0,72.6,2.75,484,36.3
16.0,72.6,2.75,484,36.3
16.0,72.7,2.75,485,36.3
16.0,72.7,2.75,485,36.4
16.0,72.8,2.75,485,36.4
16.0,72.9,2.75,486,36.4
16.0,72.9,2.75,486,36.5
16.0,73.0,2.75,486,36.5
16.0,73.0,2.75,487,36.5
15.8,73.1,2.72,487,36.6
15.7,73.2,2.69,488,36.6
15.7,73.2,2.69,488,36.6
15.7,73.3,2.69,488,36.6
15.5,73.3,2.66,489,36.7
15.5,73.4,2.66,489,36.7
15.5,73.5,2.66,490,36.7
15.5,73.5,2.66,490,36.8
15.5,73.6,2.66,490,36.8
15.5,73.6,2.66,491,36.8
15.5,73.7,2.66,491,36.8
15.3,73.7,2.63,492,36.9
15.3,73.8,2.63,492,36.9
15.3,73.9,2.63,492,36.9
15.3,73.9,2.63,493,37.0
15.3,74.0,2.63,493,37.0
15.3,74.0,2.63,494,37.0
15.2,74.1,2.61,494,37.1
15.3,74.2,2.63,494,37.1
15.2,74.2,2.61,495,37.1
15.2,74.3,2.61,495,37.1
-0.167,74.3,-0.0286,496,37.2