File: Thermal Chamber for UTM/LSR 50%.csv
Force (N),Position (mm),Stress (MPa),Strain (%),Time (min)
-0.167,0.00,-0.0159,0.00,0.00549
0.00,0.0353,0.00,0.235,0.00936
0.00,0.0743,0.00,0.495,0.0132
0.00,0.113,0.00,0.754,0.0171
0.00,0.152,0.00,1.01,0.0210
0.00,0.190,0.00,1.27,0.0248
0.00,0.229,0.00,1.53,0.0287
0.00,0.267,0.00,1.78,0.0326
0.00,0.306,0.00,2.04,0.0364
0.00,0.345,0.00,2.30,0.0403
0.00,0.383,0.00,2.56,0.0441
0.00,0.422,0.00,2.82,0.0480
0.00,0.460,0.00,3.07,0.0519
0.00,0.500,0.00,3.33,0.0557
0.00,0.538,0.00,3.59,0.0596
0.00,0.578,0.00,3.85,0.0635
0.00,0.616,0.00,4.10,0.0673
0.00,0.654,0.00,4.36,0.0712
0.00,0.693,0.00,4.62,0.0751
0.00,0.732,0.00,4.88,0.0789
0.00,0.771,0.00,5.14,0.0828
0.167,0.808,0.0159,5.39,0.0867
0.00,0.848,0.00,5.65,0.0905
0.167,0.887,0.0159,5.91,0.0944
0.0452,0.925,0.00430,6.17,0.0983
0.167,0.963,0.0159,6.42,0.102
0.167,1.00,0.0159,6.68,0.106
0.167,1.04,0.0159,6.93,0.110
0.167,1.08,0.0159,7.19,0.114
0.167,1.12,0.0159,7.45,0.118
0.167,1.16,0.0159,7.71,0.121
0.167,1.19,0.0159,7.97,0.125
0.167,1.23,0.0159,8.22,0.129
0.167,1.27,0.0159,8.48,0.133
0.167,1.31,0.0159,8.74,0.137
0.167,1.35,0.0159,9.00,0.141
0.333,1.39,0.0317,9.26,0.145
0.167,1.43,0.0159,9.51,0.149
0.193,1.47,0.0183,9.78,0.152
0.333,1.50,0.0317,10.0,0.156
0.167,1.54,0.0159,10.3,0.160
0.167,1.58,0.0159,10.5,0.164
0.167,1.62,0.0159,10.8,0.168
0.333,1.66,0.0317,11.1,0.172
0.333,1.70,0.0317,11.3,0.176
0.333,1.74,0.0317,11.6,0.179
0.333,1.78,0.0317,11.8,0.183
0.333,1.81,0.0317,12.1,0.187
0.333,1.85,0.0317,12.4,0.191
0.333,1.89,0.0317,12.6,0.195
0.333,1.93,0.0317,12.9,0.199
0.333,1.97,0.0317,13.1,0.203
0.333,2.01,0.0317,13.4,0.206
0.333,2.05,0.0317,13.6,0.210
0.333,2.08,0.0317,13.9,0.214
0.500,2.12,0.0476,14.2,0.218
0.333,2.16,0.0317,14.4,0.222
0.333,2.20,0.0317,14.7,0.226
0.333,2.24,0.0317,14.9,0.230
0.333,2.28,0.0317,15.2,0.234
0.333,2.32,0.0317,15.4,0.237
0.333,2.35,0.0317,15.7,0.241
0.333,2.39,0.0317,16.0,0.245
0.333,2.43,0.0317,16.2,0.249
0.500,2.47,0.0476,16.5,0.253
0.333,2.51,0.0317,16.7,0.257
0.333,2.55,0.0317,17.0,0.261
0.500,2.59,0.0476,17.2,0.264
0.333,2.63,0.0317,17.5,0.268
0.333,2.66,0.0317,17.8,0.272
0.500,2.70,0.0476,18.0,0.276
0.333,2.74,0.0317,18.3,0.280
0.333,2.78,0.0317,18.5,0.284
0.500,2.82,0.0476,18.8,0.288
0.500,2.86,0.0476,19.0,0.292
0.333,2.90,0.0317,19.3,0.295
0.500,2.93,0.0476,19.6,0.299
0.500,2.97,0.0476,19.8,0.303
0.500,3.01,0.0476,20.1,0.307
0.500,3.05,0.0476,20.3,0.311
0.500,3.09,0.0476,20.6,0.315
0.500,3.13,0.0476,20.9,0.319
0.500,3.17,0.0476,21.1,0.322
0.500,3.20,0.0476,21.4,0.326
0.500,3.24,0.0476,21.6,0.330
0.500,3.28,0.0476,21.9,0.334
0.500,3.32,0.0476,22.1,0.338
0.500,3.36,0.0476,22.4,0.342
0.500,3.40,0.0476,22.7,0.346
0.500,3.44,0.0476,22.9,0.350
0.500,3.48,0.0476,23.2,0.353
0.500,3.51,0.0476,23.4,0.357
0.500,3.55,0.0476,23.7,0.361
0.500,3.59,0.0476,23.9,0.365
0.500,3.63,0.0476,24.2,0.369
0.500,3.67,0.0476,24.5,0.373
0.500,3.71,0.0476,24.7,0.377
0.500,3.75,0.0476,25.0,0.380
0.500,3.78,0.0476,25.2,0.384
0.500,3.82,0.0476,25.5,0.388
0.500,3.86,0.0476,25.7,0.392
0.667,3.90,0.0635,26.0,0.396
0.500,3.94,0.0476,26.3,0.400
0.667,3.98,0.0635,26.5,0.404
0.667,4.02,0.0635,26.8,0.408
0.500,4.06,0.0476,27.0,0.411
0.667,4.09,0.0635,27.3,0.415
0.667,4.13,0.0635,27.6,0.419
0.667,4.17,0.0635,27.8,0.423
0.667,4.21,0.0635,28.1,0.427
0.667,4.25,0.0635,28.3,0.431
0.667,4.29,0.0635,28.6,0.435
0.667,4.33,0.0635,28.8,0.438
0.629,4.36,0.0599,29.1,0.442
0.667,4.40,0.0635,29.4,0.446
0.667,4.44,0.0635,29.6,0.450
0.667,4.48,0.0635,29.9,0.454
0.667,4.52,0.0635,30.1,0.458
0.667,4.56,0.0635,30.4,0.462
0.667,4.60,0.0635,30.6,0.465
0.667,4.64,0.0635,30.9,0.469
0.667,4.67,0.0635,31.2,0.473
0.667,4.71,0.0635,31.4,0.477
0.667,4.75,0.0635,31.7,0.481
0.667,4.79,0.0635,31.9,0.485
0.667,4.83,0.0635,32.2,0.489
0.667,4.87,0.0635,32.5,0.493
0.667,4.91,0.0635,32.7,0.496
0.667,4.94,0.0635,33.0,0.500
0.667,4.98,0.0635,33.2,0.504
0.753,5.02,0.0717,33.5,0.508
0.833,5.06,0.0794,33.7,0.512
0.667,5.10,0.0635,34.0,0.516
0.667,5.14,0.0635,34.2,0.520
0.667,5.18,0.0635,34.5,0.523
0.833,5.22,0.0794,34.8,0.527
0.713,5.25,0.0679,35.0,0.531
0.833,5.29,0.0794,35.3,0.535
0.833,5.33,0.0794,35.5,0.539
0.667,5.37,0.0635,35.8,0.543
0.833,5.41,0.0794,36.1,0.547
0.833,5.45,0.0794,36.3,0.551
0.833,5.49,0.0794,36.6,0.554
0.833,5.52,0.0794,36.8,0.558
0.833,5.56,0.0794,37.1,0.562
0.833,5.60,0.0794,37.3,0.566
0.833,5.64,0.0794,37.6,0.570
0.833,5.68,0.0794,37.9,0.574
0.833,5.72,0.0794,38.1,0.578
0.833,5.76,0.0794,38.4,0.581
0.833,5.80,0.0794,38.6,0.585
0.833,5.83,0.0794,38.9,0.589
0.833,5.87,0.0794,39.1,0.593
0.833,5.91,0.0794,39.4,0.597
0.833,5.95,0.0794,39.7,0.601
1.00,5.99,0.0952,39.9,0.605
0.833,6.03,0.0794,40.2,0.609
0.833,6.06,0.0794,40.4,0.612
0.833,6.10,0.0794,40.7,0.616
0.833,6.14,0.0794,41.0,0.620
0.833,6.18,0.0794,41.2,0.624
0.833,6.22,0.0794,41.5,0.628
0.833,6.26,0.0794,41.7,0.632
0.857,6.30,0.0816,42.0,0.636
1.00,6.34,0.0952,42.2,0.639
1.00,6.37,0.0952,42.5,0.643
1.00,6.41,0.0952,42.8,0.647
1.00,6.45,0.0952,43.0,0.651
1.00,6.49,0.0952,43.3,0.655
0.833,6.53,0.0794,43.5,0.659
1.00,6.57,0.0952,43.8,0.663
1.00,6.61,0.0952,44.0,0.666
1.00,6.64,0.0952,44.3,0.670
1.00,6.68,0.0952,44.6,0.674
1.00,6.72,0.0952,44.8,0.678
1.00,6.76,0.0952,45.1,0.682
1.00,6.80,0.0952,45.3,0.686
1.00,6.84,0.0952,45.6,0.690
1.00,6.88,0.0952,45.9,0.694
1.00,6.92,0.0952,46.1,0.697
1.00,6.95,0.0952,46.4,0.701
1.00,6.99,0.0952,46.6,0.705
1.06,7.03,0.101,46.9,0.709
1.08,7.07,0.103,47.1,0.713
1.17,7.11,0.111,47.4,0.717
1.17,7.15,0.111,47.7,0.721
1.17,7.19,0.111,47.9,0.724
1.17,7.23,0.111,48.2,0.728
1.17,7.26,0.111,48.4,0.732
1.17,7.30,0.111,48.7,0.736
1.17,7.34,0.111,48.9,0.740
1.17,7.38,0.111,49.2,0.744
1.17,7.42,0.111,49.5,0.748
1.17,7.46,0.111,49.7,0.752
1.17,7.50,0.111,50.0,0.755
1.00,7.53,0.0952,50.2,0.759
1.17,7.57,0.111,50.5,0.763
1.17,7.61,0.111,50.7,0.767
1.17,7.65,0.111,51.0,0.771
1.17,7.69,0.111,51.3,0.775
1.17,7.73,0.111,51.5,0.779
1.17,7.77,0.111,51.8,0.782
1.17,7.81,0.111,52.0,0.786
1.17,7.84,0.111,52.3,0.790
1.17,7.88,0.111,52.5,0.794
1.17,7.92,0.111,52.8,0.798
1.17,7.96,0.111,53.1,0.802
1.33,8.00,0.127,53.3,0.806
1.17,8.04,0.111,53.6,0.810
1.33,8.08,0.127,53.8,0.813
1.17,8.11,0.111,54.1,0.817
1.33,8.15,0.127,54.4,0.821
1.17,8.19,0.111,54.6,0.825
1.33,8.23,0.127,54.9,0.829
1.33,8.27,0.127,55.1,0.833
1.33,8.31,0.127,55.4,0.837
1.33,8.35,0.127,55.6,0.840
1.33,8.38,0.127,55.9,0.844
1.33,8.42,0.127,56.2,0.848
1.33,8.46,0.127,56.4,0.852
1.33,8.50,0.127,56.7,0.856
1.33,8.54,0.127,56.9,0.860
1.33,8.58,0.127,57.2,0.864
1.33,8.62,0.127,57.4,0.867
1.33,8.66,0.127,57.7,0.871
1.33,8.69,0.127,58.0,0.875
1.33,8.73,0.127,58.2,0.879
1.33,8.77,0.127,58.5,0.883
1.33,8.81,0.127,58.7,0.887
1.33,8.85,0.127,59.0,0.891
1.33,8.89,0.127,59.2,0.895
1.50,8.93,0.143,59.5,0.898
1.50,8.96,0.143,59.8,0.902
1.50,9.00,0.143,60.0,0.906
1.33,9.04,0.127,60.3,0.910
1.50,9.08,0.143,60.5,0.914
1.33,9.12,0.127,60.8,0.918
1.33,9.16,0.127,61.1,0.922
1.33,9.20,0.127,61.3,0.925
1.33,9.24,0.127,61.6,0.929
1.33,9.27,0.127,61.8,0.933
1.33,9.31,0.127,62.1,0.937
1.50,9.35,0.143,62.3,0.941
1.33,9.39,0.127,62.6,0.945
1.50,9.43,0.143,62.9,0.949
1.50,9.47,0.143,63.1,0.953
1.50,9.51,0.143,63.4,0.956
1.50,9.54,0.143,63.6,0.960
1.50,9.58,0.143,63.9,0.964
1.50,9.62,0.143,64.1,0.968
1.50,9.66,0.143,64.4,0.972
1.50,9.70,0.143,64.7,0.976
1.50,9.74,0.143,64.9,0.980
1.50,9.78,0.143,65.2,0.983
1.50,9.81,0.143,65.4,0.987
1.50,9.85,0.143,65.7,0.991
1.50,9.89,0.143,66.0,0.995
1.50,9.93,0.143,66.2,0.999
1.50,9.97,0.143,66.5,1.00
1.50,10.0,0.143,66.7,1.01
1.50,10.0,0.143,67.0,1.01
1.50,10.1,0.143,67.2,1.01
1.50,10.1,0.143,67.5,1.02
1.67,10.2,0.159,67.8,1.02
1.67,10.2,0.159,68.0,1.03
1.67,10.2,0.159,68.3,1.03
1.67,10.3,0.159,68.5,1.03
1.67,10.3,0.159,68.8,1.04
1.67,10.4,0.159,69.0,1.04
1.67,10.4,0.159,69.3,1.05
1.67,10.4,0.159,69.6,1.05
1.67,10.5,0.159,69.8,1.05
1.67,10.5,0.159,70.1,1.06
1.67,10.5,0.159,70.3,1.06
1.67,10.6,0.159,70.6,1.06
1.67,10.6,0.159,70.8,1.07
1.67,10.7,0.159,71.1,1.07
1.67,10.7,0.159,71.4,1.08
1.67,10.7,0.159,71.6,1.08
1.67,10.8,0.159,71.9,1.08
1.67,10.8,0.159,72.1,1.09
1.67,10.9,0.159,72.4,1.09
1.67,10.9,0.159,72.7,1.10
1.67,10.9,0.159,72.9,1.10
1.67,11.0,0.159,73.2,1.10
1.67,11.0,0.159,73.4,1.11
1.67,11.1,0.159,73.7,1.11
1.67,11.1,0.159,73.9,1.11
1.67,11.1,0.159,74.2,1.12
1.67,11.2,0.159,74.5,1.12
1.67,11.2,0.159,74.7,1.13
1.67,11.2,0.159,75.0,1.13
1.67,11.3,0.159,75.2,1.13
1.67,11.3,0.159,75.5,1.14
1.83,11.4,0.175,75.7,1.14
1.83,11.4,0.175,76.0,1.15
1.83,11.4,0.175,76.3,1.15
1.83,11.5,0.175,76.5,1.15
1.70,11.5,0.162,76.8,1.16
1.83,11.6,0.175,77.0,1.16
1.83,11.6,0.175,77.3,1.17
1.83,11.6,0.175,77.5,1.17
1.83,11.7,0.175,77.8,1.17
1.83,11.7,0.175,78.1,1.18
1.83,11.7,0.175,78.3,1.18
1.83,11.8,0.175,78.6,1.18
1.83,11.8,0.175,78.8,1.19
1.83,11.9,0.175,79.1,1.19
1.83,11.9,0.175,79.4,1.20
2.00,11.9,0.190,79.6,1.20
1.83,12.0,0.175,79.9,1.20
1.83,12.0,0.175,80.1,1.21
1.83,12.1,0.175,80.4,1.21
1.83,12.1,0.175,80.6,1.22
1.83,12.1,0.175,80.9,1.22
1.83,12.2,0.175,81.2,1.22
1.90,12.2,0.181,81.4,1.23
1.83,12.3,0.175,81.7,1.23
1.83,12.3,0.175,81.9,1.23
2.00,12.3,0.190,82.2,1.24
1.88,12.4,0.179,82.4,1.24
1.83,12.4,0.175,82.7,1.25
2.00,12.4,0.190,83.0,1.25
2.00,12.5,0.190,83.2,1.25
2.00,12.5,0.190,83.5,1.26
2.00,12.6,0.190,83.7,1.26
2.00,12.6,0.190,84.0,1.27
2.00,12.6,0.190,84.2,1.27
2.00,12.7,0.190,84.5,1.27
2.17,12.7,0.206,84.8,1.28
2.00,12.8,0.190,85.0,1.28
2.00,12.8,0.190,85.3,1.28
2.00,12.8,0.190,85.5,1.29
2.17,12.9,0.206,85.8,1.29
2.10,12.9,0.200,86.0,1.30
2.00,12.9,0.190,86.3,1.30
2.00,13.0,0.190,86.6,1.30
2.00,13.0,0.190,86.8,1.31
2.00,13.1,0.190,87.1,1.31
2.04,13.1,0.194,87.3,1.32
2.17,13.1,0.206,87.6,1.32
2.17,13.2,0.206,87.9,1.32
2.00,13.2,0.190,88.1,1.33
2.17,13.3,0.206,88.4,1.33
2.17,13.3,0.206,88.6,1.34
2.17,13.3,0.206,88.9,1.34
2.17,13.4,0.206,89.1,1.34
2.17,13.4,0.206,89.4,1.35
2.17,13.4,0.206,89.7,1.35
2.07,13.5,0.197,89.9,1.35
2.00,13.5,0.190,90.2,1.36
2.17,13.6,0.206,90.4,1.36
2.17,13.6,0.206,90.7,1.37
2.17,13.6,0.206,90.9,1.37
2.17,13.7,0.206,91.2,1.37
2.17,13.7,0.206,91.5,1.38
2.17,13.8,0.206,91.7,1.38
2.17,13.8,0.206,92.0,1.39
2.17,13.8,0.206,92.2,1.39
2.17,13.9,0.206,92.5,1.39
2.17,13.9,0.206,92.8,1.40
2.17,14.0,0.206,93.0,1.40
2.17,14.0,0.206,93.3,1.40
2.17,14.0,0.206,93.5,1.41
2.17,14.1,0.206,93.8,1.41
2.17,14.1,0.206,94.0,1.42
2.17,14.1,0.206,94.3,1.42
2.17,14.2,0.206,94.6,1.42
2.17,14.2,0.206,94.8,1.43
2.17,14.3,0.206,95.1,1.43
2.17,14.3,0.206,95.3,1.44
2.17,14.3,0.206,95.6,1.44
2.33,14.4,0.222,95.8,1.44
2.17,14.4,0.206,96.1,1.45
2.17,14.5,0.206,96.4,1.45
2.17,14.5,0.206,96.6,1.46
2.33,14.5,0.222,96.9,1.46
2.17,14.6,0.206,97.1,1.46
2.33,14.6,0.222,97.4,1.47
2.33,14.6,0.222,97.6,1.47
2.33,14.7,0.222,97.9,1.47
2.33,14.7,0.222,98.2,1.48
2.33,14.8,0.222,98.4,1.48
2.17,14.8,0.206,98.7,1.49
2.33,14.8,0.222,98.9,1.49
2.17,14.9,0.206,99.2,1.49
2.33,14.9,0.222,99.5,1.50
2.33,15.0,0.222,99.7,1.50
2.33,15.0,0.222,100,1.51
2.33,15.0,0.222,100,1.51
2.33,15.1,0.222,100,1.51
2.33,15.1,0.222,101,1.52
2.33,15.1,0.222,101,1.52
2.33,15.2,0.222,101,1.52
2.33,15.2,0.222,102,1.53
2.33,15.3,0.222,102,1.53
2.33,15.3,0.222,102,1.54
2.33,15.3,0.222,102,1.54
2.33,15.4,0.222,103,1.54
2.33,15.4,0.222,103,1.55
2.33,15.5,0.222,103,1.55
2.33,15.5,0.222,103,1.56
2.33,15.5,0.222,104,1.56
2.33,15.6,0.222,104,1.56
2.33,15.6,0.222,104,1.57
2.33,15.7,0.222,104,1.57
2.50,15.7,0.238,105,1.57
2.33,15.7,0.222,105,1.58
2.50,15.8,0.238,105,1.58
2.50,15.8,0.238,105,1.59
2.50,15.8,0.238,106,1.59
2.50,15.9,0.238,106,1.59
2.50,15.9,0.238,106,1.60
2.50,16.0,0.238,106,1.60
2.50,16.0,0.238,107,1.61
2.50,16.0,0.238,107,1.61
2.50,16.1,0.238,107,1.61
2.50,16.1,0.238,107,1.62
2.50,16.2,0.238,108,1.62
2.50,16.2,0.238,108,1.63
2.67,16.2,0.254,108,1.63
2.50,16.3,0.238,108,1.63
2.67,16.3,0.254,109,1.64
2.67,16.3,0.254,109,1.64
2.67,16.4,0.254,109,1.64
2.67,16.4,0.254,109,1.65
2.50,16.5,0.238,110,1.65
2.67,16.5,0.254,110,1.66
2.50,16.5,0.238,110,1.66
2.67,16.6,0.254,111,1.66
2.67,16.6,0.254,111,1.67
2.67,16.7,0.254,111,1.67
2.67,16.7,0.254,111,1.68
2.67,16.7,0.254,112,1.68
2.67,16.8,0.254,112,1.68
2.67,16.8,0.254,112,1.69
2.67,16.8,0.254,112,1.69
2.67,16.9,0.254,113,1.69
2.67,16.9,0.254,113,1.70
2.67,17.0,0.254,113,1.70
2.67,17.0,0.254,113,1.71
2.67,17.0,0.254,114,1.71
2.65,17.1,0.252,114,1.71
2.67,17.1,0.254,114,1.72
2.67,17.2,0.254,114,1.72
2.67,17.2,0.254,115,1.73
2.67,17.2,0.254,115,1.73
2.67,17.3,0.254,115,1.73
2.67,17.3,0.254,115,1.74
2.67,17.4,0.254,116,1.74
2.67,17.4,0.254,116,1.74
2.67,17.4,0.254,116,1.75
2.67,17.5,0.254,116,1.75
2.83,17.5,0.270,117,1.76
2.75,17.5,0.262,117,1.76
2.83,17.6,0.270,117,1.76
2.83,17.6,0.270,117,1.77
2.83,17.7,0.270,118,1.77
2.83,17.7,0.270,118,1.78
2.83,17.7,0.270,118,1.78
2.83,17.8,0.270,119,1.78
2.83,17.8,0.270,119,1.79
2.83,17.9,0.270,119,1.79
2.83,17.9,0.270,119,1.80
2.83,17.9,0.270,120,1.80
2.83,18.0,0.270,120,1.80
2.83,18.0,0.270,120,1.81
2.83,18.0,0.270,120,1.81
2.83,18.1,0.270,121,1.81
2.83,18.1,0.270,121,1.82
2.83,18.2,0.270,121,1.82
2.83,18.2,0.270,121,1.83
2.83,18.2,0.270,122,1.83
2.84,18.3,0.270,122,1.83
2.83,18.3,0.270,122,1.84
2.95,18.4,0.281,122,1.84
3.00,18.4,0.286,123,1.85
3.00,18.4,0.286,123,1.85
3.00,18.5,0.286,123,1.85
3.00,18.5,0.286,123,1.86
3.00,18.6,0.286,124,1.86
3.00,18.6,0.286,124,1.86
3.00,18.6,0.286,124,1.87
3.00,18.7,0.286,124,1.87
3.17,18.7,0.302,125,1.88
3.00,18.7,0.286,125,1.88
3.00,18.8,0.286,125,1.88
3.00,18.8,0.286,125,1.89
3.17,18.9,0.302,126,1.89
3.00,18.9,0.286,126,1.90
3.00,18.9,0.286,126,1.90
3.00,19.0,0.286,127,1.90
3.09,19.0,0.294,127,1.91
3.00,19.1,0.286,127,1.91
3.00,19.1,0.286,127,1.92
3.00,19.1,0.286,128,1.92
3.00,19.2,0.286,128,1.92
3.00,19.2,0.286,128,1.93
3.00,19.2,0.286,128,1.93
3.00,19.3,0.286,129,1.93
3.17,19.3,0.302,129,1.94
3.17,19.4,0.302,129,1.94
3.17,19.4,0.302,129,1.95
3.17,19.4,0.302,130,1.95
3.17,19.5,0.302,130,1.95
3.17,19.5,0.302,130,1.96
3.17,19.6,0.302,130,1.96
3.17,19.6,0.302,131,1.97
3.17,19.6,0.302,131,1.97
3.17,19.7,0.302,131,1.97
3.17,19.7,0.302,131,1.98
3.17,19.7,0.302,132,1.98
3.17,19.8,0.302,132,1.98
3.17,19.8,0.302,132,1.99
3.33,19.9,0.317,132,1.99
3.17,19.9,0.302,133,2.00
3.17,19.9,0.302,133,2.00
3.33,20.0,0.317,133,2.00
3.17,20.0,0.302,133,2.01
3.33,20.1,0.317,134,2.01
3.33,20.1,0.317,134,2.02
3.33,20.1,0.317,134,2.02
3.17,20.2,0.302,134,2.02
3.33,20.2,0.317,135,2.03
3.33,20.3,0.317,135,2.03
3.50,20.3,0.333,135,2.03
3.33,20.3,0.317,136,2.04
3.33,20.4,0.317,136,2.04
3.33,20.4,0.317,136,2.05
3.33,20.4,0.317,136,2.05
3.33,20.5,0.317,137,2.05
3.33,20.5,0.317,137,2.06
3.33,20.6,0.317,137,2.06
3.50,20.6,0.333,137,2.07
3.50,20.6,0.333,138,2.07
3.33,20.7,0.317,138,2.07
3.33,20.7,0.317,138,2.08
3.33,20.8,0.317,138,2.08
3.33,20.8,0.317,139,2.09
3.33,20.8,0.317,139,2.09
3.33,20.9,0.317,139,2.09
3.33,20.9,0.317,139,2.10
3.33,20.9,0.317,140,2.10
3.33,21.0,0.317,140,2.10
3.50,21.0,0.333,140,2.11
3.50,21.1,0.333,140,2.11
3.50,21.1,0.333,141,2.12
3.50,21.1,0.333,141,2.12
3.50,21.2,0.333,141,2.12
3.50,21.2,0.333,141,2.13
3.50,21.3,0.333,142,2.13
3.50,21.3,0.333,142,2.14
3.50,21.3,0.333,142,2.14
3.50,21.4,0.333,142,2.14
3.67,21.4,0.349,143,2.15
3.67,21.5,0.349,143,2.15
3.67,21.5,0.349,143,2.15
3.67,21.5,0.349,144,2.16
3.50,21.6,0.333,144,2.16
3.57,21.6,0.340,144,2.17
3.67,21.6,0.349,144,2.17
3.50,21.7,0.333,145,2.17
3.67,21.7,0.349,145,2.18
3.67,21.8,0.349,145,2.18
3.67,21.8,0.349,145,2.19
3.67,21.8,0.349,146,2.19
3.67,21.9,0.349,146,2.19
3.67,21.9,0.349,146,2.20
3.67,22.0,0.349,146,2.20
3.67,22.0,0.349,147,2.20
3.67,22.0,0.349,147,2.21
3.67,22.1,0.349,147,2.21
3.67,22.1,0.349,147,2.22
3.83,22.1,0.365,148,2.22
3.67,22.2,0.349,148,2.22
3.67,22.2,0.349,148,2.23
3.67,22.3,0.349,148,2.23
3.67,22.3,0.349,149,2.24
3.83,22.3,0.365,149,2.24
3.83,22.4,0.365,149,2.24
3.67,22.4,0.349,149,2.25
3.78,22.5,0.360,150,2.25
3.83,22.5,0.365,150,2.26
3.83,22.5,0.365,150,2.26
3.83,22.6,0.365,150,2.26
3.83,22.6,0.365,151,2.27
3.83,22.6,0.365,151,2.27
3.83,22.7,0.365,151,2.27
3.83,22.7,0.365,152,2.28
3.83,22.8,0.365,152,2.28
3.83,22.8,0.365,152,2.29
3.83,22.8,0.365,152,2.29
3.83,22.9,0.365,153,2.29
3.83,22.9,0.365,153,2.30
3.83,23.0,0.365,153,2.30
3.83,23.0,0.365,153,2.31
3.83,23.0,0.365,154,2.31
3.83,23.1,0.365,154,2.31
3.83,23.1,0.365,154,2.32
3.83,23.2,0.365,154,2.32
3.83,23.2,0.365,155,2.32
3.83,23.2,0.365,155,2.33
4.00,23.3,0.381,155,2.33
4.00,23.3,0.381,155,2.34
3.94,23.3,0.375,156,2.34
4.00,23.4,0.381,156,2.34
3.83,23.4,0.365,156,2.35
4.00,23.5,0.381,156,2.35
4.00,23.5,0.381,157,2.36
4.00,23.5,0.381,157,2.36
4.00,23.6,0.381,157,2.36
4.00,23.6,0.381,157,2.37
4.00,23.7,0.381,158,2.37
4.00,23.7,0.381,158,2.38
4.00,23.7,0.381,158,2.38
4.00,23.8,0.381,158,2.38
4.17,23.8,0.397,159,2.39
4.17,23.8,0.397,159,2.39
4.17,23.9,0.397,159,2.39
4.17,23.9,0.397,159,2.40
4.17,24.0,0.397,160,2.40
4.17,24.0,0.397,160,2.41
4.17,24.0,0.397,160,2.41
4.17,24.1,0.397,161,2.41
4.17,24.1,0.397,161,2.42
4.17,24.2,0.397,161,2.42
4.17,24.2,0.397,161,2.43
4.17,24.2,0.397,162,2.43
4.17,24.3,0.397,162,2.43
4.17,24.3,0.397,162,2.44
4.17,24.3,0.397,162,2.44
4.17,24.4,0.397,163,2.44
4.32,24.4,0.411,163,2.45
4.33,24.5,0.413,163,2.45
4.33,24.5,0.413,163,2.46
4.17,24.5,0.397,164,2.46
4.17,24.6,0.397,164,2.46
4.21,24.6,0.401,164,2.47
4.33,24.7,0.413,164,2.47
4.17,24.7,0.397,165,2.48
4.33,24.7,0.413,165,2.48
4.33,24.8,0.413,165,2.48
4.33,24.8,0.413,165,2.49
4.33,24.9,0.413,166,2.49
4.33,24.9,0.413,166,2.49
4.33,24.9,0.413,166,2.50
4.33,25.0,0.413,166,2.50
4.50,25.0,0.429,167,2.51
4.50,25.0,0.429,167,2.51
4.50,25.1,0.429,167,2.51
4.33,25.1,0.413,167,2.52
4.33,25.2,0.413,168,2.52
4.50,25.2,0.429,168,2.53
4.48,25.2,0.426,168,2.53
4.50,25.3,0.429,169,2.53
4.50,25.3,0.429,169,2.54
4.50,25.4,0.429,169,2.54
4.50,25.4,0.429,169,2.55
4.50,25.4,0.429,170,2.55
4.50,25.5,0.429,170,2.55
4.50,25.5,0.429,170,2.56
4.50,25.5,0.429,170,2.56
4.50,25.6,0.429,171,2.56
4.50,25.6,0.429,171,2.57
4.50,25.7,0.429,171,2.57
4.50,25.7,0.429,171,2.58
4.50,25.7,0.429,172,2.58
4.50,25.8,0.429,172,2.58
4.50,25.8,0.429,172,2.59
4.50,25.9,0.429,172,2.59
4.50,25.9,0.429,173,2.60
4.50,25.9,0.429,173,2.60
4.50,26.0,0.429,173,2.60
4.50,26.0,0.429,173,2.61
4.50,26.1,0.429,174,2.61
4.50,26.1,0.429,174,2.61
4.50,26.1,0.429,174,2.62
4.50,26.2,0.429,174,2.62
4.50,26.2,0.429,175,2.63
4.50,26.2,0.429,175,2.63
4.50,26.3,0.429,175,2.63
4.50,26.3,0.429,175,2.64
4.50,26.4,0.429,176,2.64
4.50,26.4,0.429,176,2.65
4.50,26.4,0.429,176,2.65
4.50,26.5,0.429,176,2.65
4.50,26.5,0.429,177,2.66
4.50,26.6,0.429,177,2.66
4.50,26.6,0.429,177,2.66
4.50,26.6,0.429,178,2.67
4.50,26.7,0.429,178,2.67
4.50,26.7,0.429,178,2.68
4.67,26.7,0.444,178,2.68
4.67,26.8,0.444,179,2.68
4.67,26.8,0.444,179,2.69
4.67,26.9,0.444,179,2.69
4.67,26.9,0.444,179,2.70
4.67,26.9,0.444,180,2.70
4.67,27.0,0.444,180,2.70
4.67,27.0,0.444,180,2.71
4.67,27.1,0.444,180,2.71
4.67,27.1,0.444,181,2.72
4.67,27.1,0.444,181,2.72
4.75,27.2,0.453,181,2.72
4.67,27.2,0.444,181,2.73
4.79,27.2,0.456,182,2.73
4.81,27.3,0.458,182,2.73
4.83,27.3,0.460,182,2.74
4.83,27.4,0.460,182,2.74
4.67,27.4,0.444,183,2.75
4.67,27.4,0.444,183,2.75
4.67,27.5,0.444,183,2.75
4.83,27.5,0.460,183,2.76
4.83,27.6,0.460,184,2.76
4.83,27.6,0.460,184,2.77
4.83,27.6,0.460,184,2.77
4.83,27.7,0.460,184,2.77
4.83,27.7,0.460,185,2.78
4.83,27.8,0.460,185,2.78
4.83,27.8,0.460,185,2.78
4.83,27.8,0.460,186,2.79
4.83,27.9,0.460,186,2.79
4.83,27.9,0.460,186,2.80
4.83,27.9,0.460,186,2.80
5.00,28.0,0.476,187,2.80
5.00,28.0,0.476,187,2.81
5.00,28.1,0.476,187,2.81
5.00,28.1,0.476,187,2.82
5.00,28.1,0.476,188,2.82
5.00,28.2,0.476,188,2.82
5.00,28.2,0.476,188,2.83
5.00,28.3,0.476,188,2.83
5.00,28.3,0.476,189,2.84
5.00,28.3,0.476,189,2.84
5.00,28.4,0.476,189,2.84
5.17,28.4,0.492,189,2.85
5.02,28.4,0.479,190,2.85
5.17,28.5,0.492,190,2.85
5.17,28.5,0.492,190,2.86
5.17,28.6,0.492,190,2.86
5.17,28.6,0.492,191,2.87
5.17,28.6,0.492,191,2.87
5.17,28.7,0.492,191,2.87
5.17,28.7,0.492,191,2.88
5.17,28.8,0.492,192,2.88
5.17,28.8,0.492,192,2.89
5.17,28.8,0.492,192,2.89
5.17,28.9,0.492,192,2.89
5.24,28.9,0.499,193,2.90
5.33,28.9,0.508,193,2.90
5.33,29.0,0.508,193,2.90
5.33,29.0,0.508,194,2.91
5.33,29.1,0.508,194,2.91
5.33,29.1,0.508,194,2.92
5.33,29.1,0.508,194,2.92
5.33,29.2,0.508,195,2.92
5.33,29.2,0.508,195,2.93
5.33,29.3,0.508,195,2.93
5.33,29.3,0.508,195,2.94
5.33,29.3,0.508,196,2.94
5.33,29.4,0.508,196,2.94
5.33,29.4,0.508,196,2.95
5.33,29.5,0.508,196,2.95
5.50,29.5,0.524,197,2.95
5.50,29.5,0.524,197,2.96
5.50,29.6,0.524,197,2.96
5.50,29.6,0.524,197,2.97
5.50,29.6,0.524,198,2.97
5.50,29.7,0.524,198,2.97
5.50,29.7,0.524,198,2.98
5.50,29.8,0.524,198,2.98
5.50,29.8,0.524,199,2.99
5.50,29.8,0.524,199,2.99
5.50,29.9,0.524,199,2.99
5.50,29.9,0.524,199,3.00
5.50,30.0,0.524,200,3.00
5.50,30.0,0.524,200,3.01
5.50,30.0,0.524,200,3.01
5.67,30.1,0.540,200,3.01
5.50,30.1,0.524,201,3.02
5.67,30.1,0.540,201,3.02
5.67,30.2,0.540,201,3.02
5.67,30.2,0.540,202,3.03
5.67,30.3,0.540,202,3.03
5.67,30.3,0.540,202,3.04
5.50,30.3,0.524,202,3.04
5.50,30.4,0.524,203,3.04
5.50,30.4,0.524,203,3.05
5.67,30.5,0.540,203,3.05
5.67,30.5,0.540,203,3.06
5.67,30.5,0.540,204,3.06
5.67,30.6,0.540,204,3.06
5.50,30.6,0.524,204,3.07
5.67,30.7,0.540,204,3.07
5.67,30.7,0.540,205,3.07
5.67,30.7,0.540,205,3.08
5.67,30.8,0.540,205,3.08
5.67,30.8,0.540,205,3.09
5.67,30.8,0.540,206,3.09
5.83,30.9,0.556,206,3.09
5.67,30.9,0.540,206,3.10
5.67,31.0,0.540,206,3.10
5.83,31.0,0.556,207,3.11
5.67,31.0,0.540,207,3.11
5.67,31.1,0.540,207,3.11
5.83,31.1,0.556,207,3.12
5.83,31.2,0.556,208,3.12
5.83,31.2,0.556,208,3.12
5.83,31.2,0.556,208,3.13
5.83,31.3,0.556,208,3.13
5.83,31.3,0.556,209,3.14
6.00,31.3,0.571,209,3.14
5.83,31.4,0.556,209,3.14
5.83,31.4,0.556,209,3.15
5.83,31.5,0.556,210,3.15
5.89,31.5,0.561,210,3.16
5.83,31.5,0.556,210,3.16
6.00,31.6,0.571,211,3.16
5.95,31.6,0.567,211,3.17
5.98,31.7,0.569,211,3.17
5.83,31.7,0.556,211,3.18
5.85,31.7,0.557,212,3.18
5.83,31.8,0.556,212,3.18
5.83,31.8,0.556,212,3.19
5.92,31.8,0.564,212,3.19
5.83,31.9,0.556,213,3.19
5.83,31.9,0.556,213,3.20
5.83,32.0,0.556,213,3.20
5.83,32.0,0.556,213,3.21
6.00,32.0,0.571,214,3.21
6.00,32.1,0.571,214,3.21
6.00,32.1,0.571,214,3.22
6.00,32.2,0.571,214,3.22
6.00,32.2,0.571,215,3.23
6.00,32.2,0.571,215,3.23
6.00,32.3,0.571,215,3.23
6.17,32.3,0.587,215,3.24
6.00,32.4,0.571,216,3.24
6.10,32.4,0.581,216,3.24
6.00,32.4,0.571,216,3.25
6.17,32.5,0.587,216,3.25
6.04,32.5,0.575,217,3.26
6.17,32.5,0.587,217,3.26
6.17,32.6,0.587,217,3.26
6.17,32.6,0.587,217,3.27
6.17,32.7,0.587,218,3.27
6.17,32.7,0.587,218,3.28
6.17,32.7,0.587,218,3.28
6.17,32.8,0.587,219,3.28
6.17,32.8,0.587,219,3.29
6.17,32.9,0.587,219,3.29
6.17,32.9,0.587,219,3.30
6.33,32.9,0.603,220,3.30
6.17,33.0,0.587,220,3.30
6.17,33.0,0.587,220,3.31
6.17,33.0,0.587,220,3.31
6.33,33.1,0.603,221,3.31
6.17,33.1,0.587,221,3.32
6.33,33.2,0.603,221,3.32
6.17,33.2,0.587,221,3.33
6.33,33.2,0.603,222,3.33
6.33,33.3,0.603,222,3.33
6.33,33.3,0.603,222,3.34
6.33,33.4,0.603,222,3.34
6.33,33.4,0.603,223,3.35
6.33,33.4,0.603,223,3.35
6.33,33.5,0.603,223,3.35
6.33,33.5,0.603,223,3.36
6.50,33.5,0.619,224,3.36
6.33,33.6,0.603,224,3.36
6.50,33.6,0.619,224,3.37
6.50,33.7,0.619,224,3.37
6.50,33.7,0.619,225,3.38
6.50,33.7,0.619,225,3.38
6.50,33.8,0.619,225,3.38
6.50,33.8,0.619,225,3.39
6.50,33.9,0.619,226,3.39
6.50,33.9,0.619,226,3.40
6.33,33.9,0.603,226,3.40
6.33,34.0,0.603,226,3.40
6.50,34.0,0.619,227,3.41
6.50,34.1,0.619,227,3.41
6.50,34.1,0.619,227,3.41
6.67,34.1,0.635,228,3.42
6.50,34.2,0.619,228,3.42
6.67,34.2,0.635,228,3.43
6.67,34.2,0.635,228,3.43
6.67,34.3,0.635,229,3.43
6.67,34.3,0.635,229,3.44
6.67,34.4,0.635,229,3.44
6.67,34.4,0.635,229,3.45
6.67,34.4,0.635,230,3.45
6.67,34.5,0.635,230,3.45
6.67,34.5,0.635,230,3.46
6.67,34.6,0.635,230,3.46
6.67,34.6,0.635,231,3.47
6.82,34.6,0.650,231,3.47
6.67,34.7,0.635,231,3.47
6.83,34.7,0.651,231,3.48
6.83,34.7,0.651,232,3.48
6.83,34.8,0.651,232,3.48
6.83,34.8,0.651,232,3.49
6.83,34.9,0.651,232,3.49
6.83,34.9,0.651,233,3.50
6.83,34.9,0.651,233,3.50
6.83,35.0,0.651,233,3.50
7.00,35.0,0.667,233,3.51
6.83,35.1,0.651,234,3.51
6.83,35.1,0.651,234,3.52
6.83,35.1,0.651,234,3.52
6.85,35.2,0.652,234,3.52
6.83,35.2,0.651,235,3.53
7.00,35.2,0.667,235,3.53
7.00,35.3,0.667,235,3.53
7.00,35.3,0.667,236,3.54
7.00,35.4,0.667,236,3.54
7.00,35.4,0.667,236,3.55
7.00,35.4,0.667,236,3.55
6.83,35.5,0.651,237,3.55
6.98,35.5,0.665,237,3.56
7.17,35.6,0.683,237,3.56
7.00,35.6,0.667,237,3.57
7.00,35.6,0.667,238,3.57
7.00,35.7,0.667,238,3.57
7.17,35.7,0.683,238,3.58
7.02,35.8,0.668,238,3.58
7.17,35.8,0.683,239,3.58
7.03,35.8,0.669,239,3.59
7.00,35.9,0.667,239,3.59
7.17,35.9,0.683,239,3.60
7.17,35.9,0.683,240,3.60
7.17,36.0,0.683,240,3.60
7.17,36.0,0.683,240,3.61
7.17,36.1,0.683,240,3.61
7.17,36.1,0.683,241,3.62
7.33,36.1,0.698,241,3.62
7.17,36.2,0.683,241,3.62
7.17,36.2,0.683,241,3.63
7.33,36.3,0.698,242,3.63
7.33,36.3,0.698,242,3.64
7.33,36.3,0.698,242,3.64
7.33,36.4,0.698,242,3.64
7.33,36.4,0.698,243,3.65
7.33,36.4,0.698,243,3.65
7.33,36.5,0.698,243,3.65
7.33,36.5,0.698,244,3.66
7.33,36.6,0.698,244,3.66
7.33,36.6,0.698,244,3.67
7.33,36.6,0.698,244,3.67
7.33,36.7,0.698,245,3.67
7.47,36.7,0.711,245,3.68
7.33,36.8,0.698,245,3.68
7.33,36.8,0.698,245,3.69
7.33,36.8,0.698,246,3.69
7.33,36.9,0.698,246,3.69
7.33,36.9,0.698,246,3.70
7.33,36.9,0.698,246,3.70
7.33,37.0,0.698,247,3.70
7.33,37.0,0.698,247,3.71
7.43,37.1,0.708,247,3.71
7.33,37.1,0.698,247,3.72
7.50,37.1,0.714,248,3.72
7.33,37.2,0.698,248,3.72
7.50,37.2,0.714,248,3.73
7.50,37.3,0.714,248,3.73
7.50,37.3,0.714,249,3.74
7.50,37.3,0.714,249,3.74
7.50,37.4,0.714,249,3.74
7.50,37.4,0.714,249,3.75
7.67,37.5,0.730,250,3.75
7.67,37.5,0.730,250,3.76
7.67,37.5,0.730,250,3.76
7.52,37.6,0.716,250,3.76
7.67,37.6,0.730,251,3.77
7.67,37.6,0.730,251,3.77
7.50,37.7,0.714,251,3.77
7.50,37.7,0.714,251,3.78
7.50,37.8,0.714,252,3.78
7.67,37.8,0.730,252,3.79
7.67,37.8,0.730,252,3.79
7.67,37.9,0.730,253,3.79
7.67,37.9,0.730,253,3.80
7.67,38.0,0.730,253,3.80
7.67,38.0,0.730,253,3.81
7.67,38.0,0.730,254,3.81
7.67,38.1,0.730,254,3.81
7.83,38.1,0.746,254,3.82
7.81,38.1,0.744,254,3.82
7.71,38.2,0.734,255,3.82
7.83,38.2,0.746,255,3.83
7.83,38.3,0.746,255,3.83
7.83,38.3,0.746,255,3.84
7.83,38.3,0.746,256,3.84
7.67,38.4,0.730,256,3.84
7.67,38.4,0.730,256,3.85
7.83,38.5,0.746,256,3.85
7.83,38.5,0.746,257,3.86
7.83,38.5,0.746,257,3.86
7.83,38.6,0.746,257,3.86
7.83,38.6,0.746,257,3.87
7.83,38.7,0.746,258,3.87
7.83,38.7,0.746,258,3.87
8.00,38.7,0.762,258,3.88
8.00,38.8,0.762,258,3.88
8.00,38.8,0.762,259,3.89
8.00,38.8,0.762,259,3.89
8.00,38.9,0.762,259,3.89
8.00,38.9,0.762,259,3.90
8.00,39.0,0.762,260,3.90
8.00,39.0,0.762,260,3.91
8.17,39.0,0.778,260,3.91
8.17,39.1,0.778,261,3.91
8.17,39.1,0.778,261,3.92
8.17,39.2,0.778,261,3.92
8.00,39.2,0.762,261,3.93
8.17,39.2,0.778,262,3.93
8.17,39.3,0.778,262,3.93
8.17,39.3,0.778,262,3.94
8.00,39.3,0.762,262,3.94
8.00,39.4,0.762,263,3.94
8.00,39.4,0.762,263,3.95
8.17,39.5,0.778,263,3.95
8.17,39.5,0.778,263,3.96
8.17,39.5,0.778,264,3.96
8.17,39.6,0.778,264,3.96
8.17,39.6,0.778,264,3.97
8.17,39.7,0.778,264,3.97
8.33,39.7,0.794,265,3.98
8.26,39.7,0.787,265,3.98
8.33,39.8,0.794,265,3.98
8.17,39.8,0.778,265,3.99
8.33,39.9,0.794,266,3.99
8.33,39.9,0.794,266,3.99
8.33,39.9,0.794,266,4.00
8.33,40.0,0.794,266,4.00
8.41,40.0,0.801,267,4.01
8.33,40.0,0.794,267,4.01
8.33,40.1,0.794,267,4.01
8.50,40.1,0.810,267,4.02
8.50,40.2,0.810,268,4.02
8.33,40.2,0.794,268,4.03
8.33,40.2,0.794,268,4.03
8.50,40.3,0.810,269,4.03
8.50,40.3,0.810,269,4.04
8.50,40.4,0.810,269,4.04
8.50,40.4,0.810,269,4.04
8.50,40.4,0.810,270,4.05
8.33,40.5,0.794,270,4.05
8.50,40.5,0.810,270,4.06
8.45,40.5,0.804,270,4.06
8.33,40.6,0.794,271,4.06
8.33,40.6,0.794,271,4.07
8.33,40.7,0.794,271,4.07
8.50,40.7,0.810,271,4.08
8.33,40.7,0.794,272,4.08
8.33,40.8,0.794,272,4.08
8.33,40.8,0.794,272,4.09
8.50,40.9,0.810,272,4.09
8.50,40.9,0.810,273,4.10
8.50,40.9,0.810,273,4.10
8.50,41.0,0.810,273,4.10
8.50,41.0,0.810,273,4.11
8.50,41.0,0.810,274,4.11
8.50,41.1,0.810,274,4.11
8.50,41.1,0.810,274,4.12
8.50,41.2,0.810,274,4.12
8.50,41.2,0.810,275,4.13
8.67,41.2,0.825,275,4.13
8.67,41.3,0.825,275,4.13
8.67,41.3,0.825,275,4.14
8.83,41.4,0.841,276,4.14
8.83,41.4,0.841,276,4.15
8.83,41.4,0.841,276,4.15
8.82,41.5,0.840,276,4.15
8.83,41.5,0.841,277,4.16
8.83,41.6,0.841,277,4.16
8.83,41.6,0.841,277,4.16
8.83,41.6,0.841,278,4.17
8.83,41.7,0.841,278,4.17
8.83,41.7,0.841,278,4.18
8.83,41.7,0.841,278,4.18
9.00,41.8,0.857,279,4.18
9.00,41.8,0.857,279,4.19
8.83,41.9,0.841,279,4.19
9.00,41.9,0.857,279,4.20
8.83,41.9,0.841,280,4.20
9.00,42.0,0.857,280,4.20
9.00,42.0,0.857,280,4.21
9.00,42.1,0.857,280,4.21
9.00,42.1,0.857,281,4.22
8.83,42.1,0.841,281,4.22
9.00,42.2,0.857,281,4.22
9.00,42.2,0.857,281,4.23
9.00,42.2,0.857,282,4.23
9.00,42.3,0.857,282,4.23
9.10,42.3,0.866,282,4.24
9.00,42.4,0.857,282,4.24
9.00,42.4,0.857,283,4.25
9.00,42.4,0.857,283,4.25
9.01,42.5,0.858,283,4.25
9.17,42.5,0.873,283,4.26
9.00,42.6,0.857,284,4.26
9.00,42.6,0.857,284,4.27
9.00,42.6,0.857,284,4.27
9.00,42.7,0.857,284,4.27
9.17,42.7,0.873,285,4.28
9.17,42.7,0.873,285,4.28
9.17,42.8,0.873,285,4.28
9.00,42.8,0.857,286,4.29
9.17,42.9,0.873,286,4.29
9.17,42.9,0.873,286,4.30
9.17,42.9,0.873,286,4.30
9.17,43.0,0.873,287,4.30
9.17,43.0,0.873,287,4.31
9.17,43.1,0.873,287,4.31
9.17,43.1,0.873,287,4.32
9.20,43.1,0.876,288,4.32
9.17,43.2,0.873,288,4.32
9.17,43.2,0.873,288,4.33
9.33,43.3,0.889,288,4.33
9.33,43.3,0.889,289,4.33
9.33,43.3,0.889,289,4.34
9.33,43.4,0.889,289,4.34
9.33,43.4,0.889,289,4.35
9.26,43.4,0.882,290,4.35
9.33,43.5,0.889,290,4.35
9.33,43.5,0.889,290,4.36
9.33,43.6,0.889,290,4.36
9.33,43.6,0.889,291,4.37
9.33,43.6,0.889,291,4.37
9.33,43.7,0.889,291,4.37
9.33,43.7,0.889,291,4.38
9.33,43.8,0.889,292,4.38
9.33,43.8,0.889,292,4.39
9.33,43.8,0.889,292,4.39
9.33,43.9,0.889,292,4.39
9.33,43.9,0.889,293,4.40
9.33,43.9,0.889,293,4.40
9.33,44.0,0.889,293,4.40
9.33,44.0,0.889,293,4.41
9.33,44.1,0.889,294,4.41
9.50,44.1,0.905,294,4.42
9.50,44.1,0.905,294,4.42
9.50,44.2,0.905,295,4.42
9.50,44.2,0.905,295,4.43
9.50,44.3,0.905,295,4.43
9.50,44.3,0.905,295,4.44
9.50,44.3,0.905,296,4.44
9.50,44.4,0.905,296,4.44
9.50,44.4,0.905,296,4.45
9.67,44.5,0.921,296,4.45
9.67,44.5,0.921,297,4.45
9.67,44.5,0.921,297,4.46
9.67,44.6,0.921,297,4.46
9.54,44.6,0.909,297,4.47
9.67,44.6,0.921,298,4.47
9.67,44.7,0.921,298,4.47
9.67,44.7,0.921,298,4.48
9.67,44.8,0.921,298,4.48
9.67,44.8,0.921,299,4.49
9.67,44.8,0.921,299,4.49
9.67,44.9,0.921,299,4.49
9.67,44.9,0.921,299,4.50
9.67,45.0,0.921,300,4.50
9.83,45.0,0.936,300,4.50
9.67,45.0,0.921,300,4.51
9.67,45.1,0.921,300,4.51
9.83,45.1,0.937,301,4.52
9.83,45.1,0.937,301,4.52
9.83,45.2,0.937,301,4.52
9.83,45.2,0.937,301,4.53
9.83,45.3,0.937,302,4.53
9.83,45.3,0.937,302,4.54
9.87,45.3,0.940,302,4.54
9.83,45.4,0.937,303,4.54
9.83,45.4,0.937,303,4.55
9.83,45.5,0.937,303,4.55
9.67,45.5,0.921,303,4.56
9.67,45.5,0.921,304,4.56
9.83,45.6,0.937,304,4.56
9.83,45.6,0.937,304,4.57
9.83,45.6,0.937,304,4.57
9.83,45.7,0.937,305,4.57
10.0,45.7,0.952,305,4.58
9.83,45.8,0.937,305,4.58
9.94,45.8,0.947,305,4.59
9.83,45.8,0.937,306,4.59
10.0,45.9,0.952,306,4.59
10.0,45.9,0.952,306,4.60
9.83,46.0,0.937,306,4.60
9.83,46.0,0.937,307,4.61
9.86,46.0,0.939,307,4.61
9.88,46.1,0.941,307,4.61
10.0,46.1,0.952,307,4.62
10.0,46.2,0.952,308,4.62
10.0,46.2,0.952,308,4.62
10.0,46.2,0.952,308,4.63
10.0,46.3,0.952,308,4.63
10.0,46.3,0.952,309,4.64
10.0,46.3,0.952,309,4.64
10.0,46.4,0.952,309,4.64
10.0,46.4,0.952,309,4.65
10.0,46.5,0.952,310,4.65
10.0,46.5,0.952,310,4.66
10.2,46.5,0.968,310,4.66
10.0,46.6,0.952,311,4.66
10.0,46.6,0.952,311,4.67
10.2,46.7,0.968,311,4.67
10.2,46.7,0.968,311,4.68
10.2,46.7,0.968,312,4.68
10.2,46.8,0.968,312,4.68
10.2,46.8,0.968,312,4.69
10.2,46.8,0.968,312,4.69
10.2,46.9,0.968,313,4.69
10.2,46.9,0.968,313,4.70
10.2,47.0,0.968,313,4.70
10.3,47.0,0.984,313,4.71
10.2,47.0,0.968,314,4.71
10.2,47.1,0.968,314,4.71
10.2,47.1,0.968,314,4.72
10.3,47.2,0.984,314,4.72
10.3,47.2,0.984,315,4.73
10.3,47.2,0.984,315,4.73
10.3,47.3,0.984,315,4.73
10.3,47.3,0.984,315,4.74
10.3,47.3,0.984,316,4.74
10.3,47.4,0.984,316,4.74
10.3,47.4,0.984,316,4.75
10.3,47.5,0.984,316,4.75
10.3,47.5,0.984,317,4.76
10.3,47.5,0.984,317,4.76
10.3,47.6,0.984,317,4.76
10.3,47.6,0.984,317,4.77
10.3,47.7,0.984,318,4.77
10.3,47.7,0.984,318,4.78
10.3,47.7,0.984,318,4.78
10.3,47.8,0.984,318,4.78
10.3,47.8,0.984,319,4.79
10.3,47.9,0.984,319,4.79
10.3,47.9,0.984,319,4.79
10.3,47.9,0.984,320,4.80
10.1,48.0,0.965,320,4.80
7.76,48.0,0.739,320,4.81
-2.17,48.0,-0.206,320,4.81
-2.17,48.1,-0.206,321,4.81
-2.17,48.1,-0.206,321,4.82
-2.17,48.2,-0.206,321,4.82
-2.17,48.2,-0.206,321,4.83
-2.17,48.2,-0.206,322,4.83
-2.17,48.3,-0.206,322,4.83
-2.17,48.3,-0.206,322,4.84