File: Thermal Chamber for UTM/LSR70%.csv
Force (N),Position (mm),Stress (MPa),Strain (%),Time (min)
0.00,0.00,0.00,0.00,0.00534
0.00,0.0317,0.00,0.211,0.00968
0.00,0.0767,0.00,0.511,0.0140
0.167,0.120,0.0159,0.797,0.0184
0.167,0.162,0.0159,1.08,0.0227
0.167,0.207,0.0159,1.38,0.0270
0.167,0.250,0.0159,1.67,0.0314
0.167,0.294,0.0159,1.96,0.0357
0.167,0.337,0.0159,2.25,0.0401
0.167,0.381,0.0159,2.54,0.0444
0.167,0.424,0.0159,2.83,0.0487
0.167,0.467,0.0159,3.11,0.0531
0.167,0.511,0.0159,3.41,0.0574
0.167,0.554,0.0159,3.69,0.0618
0.167,0.598,0.0159,3.99,0.0661
0.333,0.641,0.0317,4.27,0.0704
0.272,0.685,0.0259,4.56,0.0748
0.333,0.728,0.0317,4.85,0.0791
0.333,0.771,0.0317,5.14,0.0835
0.333,0.814,0.0317,5.43,0.0878
0.333,0.858,0.0317,5.72,0.0921
0.333,0.901,0.0317,6.01,0.0965
0.333,0.945,0.0317,6.30,0.101
0.333,0.988,0.0317,6.58,0.105
0.333,1.03,0.0317,6.88,0.109
0.333,1.07,0.0317,7.17,0.114
0.333,1.12,0.0317,7.46,0.118
0.500,1.16,0.0476,7.75,0.123
0.500,1.20,0.0476,8.03,0.127
0.500,1.25,0.0476,8.32,0.131
0.500,1.29,0.0476,8.61,0.136
0.500,1.34,0.0476,8.90,0.140
0.500,1.38,0.0476,9.19,0.144
0.666,1.42,0.0634,9.48,0.149
0.667,1.47,0.0635,9.77,0.153
0.667,1.51,0.0635,10.1,0.157
0.500,1.55,0.0476,10.3,0.162
0.500,1.60,0.0476,10.6,0.166
0.667,1.64,0.0635,10.9,0.170
0.667,1.68,0.0635,11.2,0.175
0.667,1.73,0.0635,11.5,0.179
0.667,1.77,0.0635,11.8,0.183
0.667,1.81,0.0635,12.1,0.188
0.667,1.86,0.0635,12.4,0.192
0.667,1.90,0.0635,12.7,0.196
0.667,1.94,0.0635,13.0,0.201
0.667,1.99,0.0635,13.2,0.205
0.667,2.03,0.0635,13.5,0.209
0.667,2.07,0.0635,13.8,0.214
0.667,2.12,0.0635,14.1,0.218
0.667,2.16,0.0635,14.4,0.222
0.833,2.20,0.0794,14.7,0.227
0.833,2.25,0.0794,15.0,0.231
0.833,2.29,0.0794,15.3,0.235
0.833,2.33,0.0794,15.6,0.240
0.833,2.38,0.0794,15.8,0.244
0.833,2.42,0.0794,16.1,0.248
0.833,2.46,0.0794,16.4,0.253
0.833,2.51,0.0794,16.7,0.257
0.833,2.55,0.0794,17.0,0.261
0.833,2.59,0.0794,17.3,0.266
0.833,2.64,0.0794,17.6,0.270
0.833,2.68,0.0794,17.9,0.274
0.833,2.72,0.0794,18.2,0.279
0.833,2.77,0.0794,18.4,0.283
0.833,2.81,0.0794,18.7,0.287
0.833,2.85,0.0794,19.0,0.292
0.833,2.90,0.0794,19.3,0.296
0.833,2.94,0.0794,19.6,0.300
0.833,2.98,0.0794,19.9,0.305
0.833,3.03,0.0794,20.2,0.309
0.833,3.07,0.0794,20.5,0.313
0.833,3.11,0.0794,20.8,0.318
0.833,3.16,0.0794,21.1,0.322
0.833,3.20,0.0794,21.3,0.326
0.835,3.24,0.0795,21.6,0.331
0.866,3.29,0.0824,21.9,0.335
0.833,3.33,0.0794,22.2,0.339
0.833,3.37,0.0794,22.5,0.344
0.833,3.42,0.0794,22.8,0.348
0.833,3.46,0.0794,23.1,0.352
1.00,3.51,0.0952,23.4,0.357
0.833,3.55,0.0794,23.7,0.361
0.918,3.59,0.0874,23.9,0.366
1.00,3.63,0.0952,24.2,0.370
0.833,3.68,0.0794,24.5,0.374
1.00,3.72,0.0952,24.8,0.379
1.00,3.77,0.0952,25.1,0.383
1.00,3.81,0.0952,25.4,0.387
1.00,3.85,0.0952,25.7,0.392
1.00,3.90,0.0952,26.0,0.396
1.00,3.94,0.0952,26.3,0.400
1.00,3.98,0.0952,26.5,0.405
1.00,4.03,0.0952,26.8,0.409
1.15,4.07,0.109,27.1,0.413
1.00,4.11,0.0952,27.4,0.418
1.00,4.16,0.0952,27.7,0.422
1.00,4.20,0.0952,28.0,0.426
1.17,4.24,0.111,28.3,0.431
1.17,4.29,0.111,28.6,0.435
1.00,4.33,0.0952,28.9,0.439
1.17,4.37,0.111,29.2,0.444
1.17,4.42,0.111,29.4,0.448
1.17,4.46,0.111,29.7,0.452
1.00,4.50,0.0952,30.0,0.457
1.17,4.55,0.111,30.3,0.461
1.17,4.59,0.111,30.6,0.465
1.00,4.63,0.0952,30.9,0.470
1.17,4.68,0.111,31.2,0.474
1.17,4.72,0.111,31.5,0.478
1.17,4.76,0.111,31.8,0.483
1.17,4.81,0.111,32.0,0.487
1.09,4.85,0.104,32.3,0.491
1.17,4.89,0.111,32.6,0.496
1.17,4.94,0.111,32.9,0.500
1.17,4.98,0.111,33.2,0.504
1.17,5.02,0.111,33.5,0.509
1.17,5.07,0.111,33.8,0.513
1.17,5.11,0.111,34.1,0.517
1.17,5.15,0.111,34.4,0.522
1.17,5.20,0.111,34.7,0.526
1.17,5.24,0.111,34.9,0.530
1.17,5.28,0.111,35.2,0.535
1.17,5.33,0.111,35.5,0.539
1.17,5.37,0.111,35.8,0.543
1.17,5.41,0.111,36.1,0.548
1.30,5.46,0.124,36.4,0.552
1.31,5.50,0.125,36.7,0.556
1.24,5.54,0.118,37.0,0.561
1.33,5.59,0.127,37.3,0.565
1.33,5.63,0.127,37.5,0.569
1.33,5.67,0.127,37.8,0.574
1.33,5.72,0.127,38.1,0.578
1.33,5.76,0.127,38.4,0.582
1.33,5.80,0.127,38.7,0.587
1.33,5.85,0.127,39.0,0.591
1.33,5.89,0.127,39.3,0.596
1.33,5.93,0.127,39.6,0.600
1.33,5.98,0.127,39.9,0.604
1.33,6.02,0.127,40.1,0.609
1.33,6.06,0.127,40.4,0.613
1.33,6.11,0.127,40.7,0.617
1.46,6.15,0.139,41.0,0.622
1.33,6.20,0.127,41.3,0.626
1.33,6.24,0.127,41.6,0.630
1.33,6.28,0.127,41.9,0.635
1.50,6.33,0.143,42.2,0.639
1.38,6.37,0.132,42.5,0.643
1.50,6.41,0.143,42.8,0.648
1.50,6.46,0.143,43.0,0.652
1.50,6.50,0.143,43.3,0.656
1.50,6.54,0.143,43.6,0.661
1.50,6.59,0.143,43.9,0.665
1.50,6.63,0.143,44.2,0.669
1.50,6.67,0.143,44.5,0.674
1.52,6.72,0.145,44.8,0.678
1.50,6.76,0.143,45.1,0.682
1.50,6.80,0.143,45.3,0.687
1.67,6.85,0.159,45.6,0.691
1.67,6.89,0.159,45.9,0.695
1.56,6.93,0.149,46.2,0.700
1.50,6.98,0.143,46.5,0.704
1.50,7.02,0.143,46.8,0.708
1.67,7.06,0.159,47.1,0.713
1.60,7.11,0.152,47.4,0.717
1.50,7.15,0.143,47.7,0.721
1.50,7.19,0.143,48.0,0.726
1.67,7.24,0.159,48.2,0.730
1.67,7.28,0.159,48.5,0.734
1.67,7.32,0.159,48.8,0.739
1.67,7.37,0.159,49.1,0.743
1.67,7.41,0.159,49.4,0.747
1.67,7.45,0.159,49.7,0.752
1.67,7.50,0.159,50.0,0.756
1.67,7.54,0.159,50.3,0.760
1.67,7.58,0.159,50.6,0.765
1.67,7.63,0.159,50.9,0.769
1.67,7.67,0.159,51.1,0.773
1.67,7.71,0.159,51.4,0.778
1.78,7.76,0.170,51.7,0.782
1.67,7.80,0.159,52.0,0.786
1.67,7.84,0.159,52.3,0.791
1.67,7.89,0.159,52.6,0.795
1.83,7.93,0.175,52.9,0.799
1.83,7.97,0.175,53.2,0.804
1.83,8.02,0.175,53.5,0.808
1.74,8.06,0.165,53.7,0.812
1.83,8.10,0.175,54.0,0.817
1.83,8.15,0.175,54.3,0.821
1.83,8.19,0.175,54.6,0.825
1.83,8.24,0.175,54.9,0.830
1.83,8.28,0.175,55.2,0.834
1.83,8.32,0.175,55.5,0.839
1.83,8.37,0.175,55.8,0.843
1.83,8.41,0.175,56.1,0.847
1.83,8.45,0.175,56.3,0.852
1.67,8.49,0.159,56.6,0.856
1.67,8.54,0.159,56.9,0.860
1.83,8.58,0.175,57.2,0.865
1.67,8.63,0.159,57.5,0.869
1.83,8.67,0.175,57.8,0.873
1.83,8.71,0.175,58.1,0.878
1.83,8.76,0.175,58.4,0.882
1.83,8.80,0.175,58.7,0.886
1.83,8.84,0.175,58.9,0.891
2.00,8.89,0.190,59.2,0.895
2.00,8.93,0.190,59.5,0.899
2.00,8.97,0.190,59.8,0.904
2.00,9.02,0.190,60.1,0.908
2.00,9.06,0.190,60.4,0.912
2.00,9.10,0.190,60.7,0.917
2.00,9.15,0.190,61.0,0.921
2.00,9.19,0.190,61.3,0.925
2.00,9.23,0.190,61.6,0.930
2.00,9.28,0.190,61.8,0.934
2.00,9.32,0.190,62.1,0.938
2.00,9.36,0.190,62.4,0.943
2.00,9.41,0.190,62.7,0.947
2.00,9.45,0.190,63.0,0.951
2.00,9.49,0.190,63.3,0.956
2.00,9.54,0.190,63.6,0.960
2.17,9.58,0.206,63.9,0.964
2.17,9.62,0.206,64.2,0.969
2.17,9.67,0.206,64.4,0.973
2.17,9.71,0.206,64.7,0.977
2.33,9.75,0.222,65.0,0.982
2.33,9.80,0.222,65.3,0.986
2.33,9.84,0.222,65.6,0.990
2.26,9.88,0.215,65.9,0.995
2.33,9.93,0.222,66.2,0.999
2.33,9.97,0.222,66.5,1.00
2.17,10.0,0.206,66.8,1.01
2.33,10.1,0.222,67.1,1.01
2.33,10.1,0.222,67.3,1.02
2.33,10.1,0.222,67.6,1.02
2.33,10.2,0.222,67.9,1.03
2.33,10.2,0.222,68.2,1.03
2.33,10.3,0.222,68.5,1.03
2.33,10.3,0.222,68.8,1.04
2.33,10.4,0.222,69.1,1.04
2.33,10.4,0.222,69.4,1.05
2.33,10.4,0.222,69.7,1.05
2.33,10.5,0.222,69.9,1.06
2.33,10.5,0.222,70.2,1.06
2.33,10.6,0.222,70.5,1.06
2.33,10.6,0.222,70.8,1.07
2.33,10.7,0.222,71.1,1.07
2.33,10.7,0.222,71.4,1.08
2.33,10.8,0.222,71.7,1.08
2.33,10.8,0.222,72.0,1.09
2.33,10.8,0.222,72.3,1.09
2.33,10.9,0.222,72.5,1.09
2.33,10.9,0.222,72.8,1.10
2.33,11.0,0.222,73.1,1.10
2.33,11.0,0.222,73.4,1.11
2.33,11.1,0.222,73.7,1.11
2.48,11.1,0.236,74.0,1.12
2.43,11.1,0.231,74.3,1.12
2.50,11.2,0.238,74.6,1.12
2.33,11.2,0.222,74.9,1.13
2.33,11.3,0.222,75.1,1.13
2.39,11.3,0.227,75.4,1.14
2.33,11.4,0.222,75.7,1.14
2.50,11.4,0.238,76.0,1.15
2.50,11.4,0.238,76.3,1.15
2.50,11.5,0.238,76.6,1.16
2.37,11.5,0.226,76.9,1.16
2.50,11.6,0.238,77.2,1.16
2.50,11.6,0.238,77.5,1.17
2.50,11.7,0.238,77.8,1.17
2.50,11.7,0.238,78.0,1.18
2.50,11.7,0.238,78.3,1.18
2.50,11.8,0.238,78.6,1.19
2.67,11.8,0.254,78.9,1.19
2.62,11.9,0.249,79.2,1.19
2.50,11.9,0.238,79.5,1.20
2.56,12.0,0.243,79.8,1.20
2.50,12.0,0.238,80.1,1.21
2.50,12.1,0.238,80.4,1.21
2.50,12.1,0.238,80.6,1.22
2.67,12.1,0.254,80.9,1.22
2.65,12.2,0.253,81.2,1.22
2.67,12.2,0.254,81.5,1.23
2.58,12.3,0.246,81.8,1.23
2.67,12.3,0.254,82.1,1.24
2.67,12.4,0.254,82.4,1.24
2.67,12.4,0.254,82.7,1.25
2.67,12.4,0.254,83.0,1.25
2.67,12.5,0.254,83.3,1.26
2.67,12.5,0.254,83.5,1.26
2.67,12.6,0.254,83.8,1.26
2.67,12.6,0.254,84.1,1.27
2.67,12.7,0.254,84.4,1.27
2.67,12.7,0.254,84.7,1.28
2.67,12.7,0.254,85.0,1.28
2.67,12.8,0.254,85.3,1.29
2.67,12.8,0.254,85.6,1.29
2.67,12.9,0.254,85.9,1.29
2.67,12.9,0.254,86.1,1.30
2.67,13.0,0.254,86.4,1.30
2.67,13.0,0.254,86.7,1.31
2.67,13.1,0.254,87.0,1.31
2.83,13.1,0.270,87.3,1.32
2.67,13.1,0.254,87.6,1.32
2.83,13.2,0.270,87.9,1.32
2.83,13.2,0.270,88.2,1.33
2.83,13.3,0.270,88.5,1.33
2.83,13.3,0.270,88.7,1.34
2.83,13.4,0.270,89.0,1.34
2.83,13.4,0.270,89.3,1.35
2.83,13.4,0.270,89.6,1.35
2.83,13.5,0.270,89.9,1.35
2.83,13.5,0.270,90.2,1.36
2.83,13.6,0.270,90.5,1.36
2.83,13.6,0.270,90.8,1.37
2.83,13.7,0.270,91.1,1.37
2.83,13.7,0.270,91.3,1.38
2.83,13.7,0.270,91.6,1.38
2.83,13.8,0.270,91.9,1.39
2.83,13.8,0.270,92.2,1.39
2.83,13.9,0.270,92.5,1.39
2.83,13.9,0.270,92.8,1.40
2.83,14.0,0.270,93.1,1.40
3.00,14.0,0.286,93.4,1.41
2.83,14.1,0.270,93.7,1.41
3.00,14.1,0.286,94.0,1.42
2.83,14.1,0.270,94.2,1.42
2.83,14.2,0.270,94.5,1.42
3.00,14.2,0.286,94.8,1.43
2.98,14.3,0.284,95.1,1.43
3.00,14.3,0.286,95.4,1.44
3.00,14.4,0.286,95.7,1.44
3.00,14.4,0.286,96.0,1.45
3.00,14.4,0.286,96.3,1.45
3.00,14.5,0.286,96.6,1.45
3.00,14.5,0.286,96.8,1.46
3.00,14.6,0.286,97.1,1.46
3.00,14.6,0.286,97.4,1.47
3.00,14.7,0.286,97.7,1.47
3.00,14.7,0.286,98.0,1.48
3.00,14.7,0.286,98.3,1.48
3.17,14.8,0.302,98.6,1.49
3.17,14.8,0.302,98.9,1.49
3.17,14.9,0.302,99.2,1.49
3.17,14.9,0.302,99.5,1.50
3.17,15.0,0.302,99.7,1.50
3.01,15.0,0.287,100,1.51
3.17,15.0,0.302,100,1.51
3.17,15.1,0.302,101,1.52
3.17,15.1,0.302,101,1.52
3.17,15.2,0.302,101,1.52
3.17,15.2,0.302,101,1.53
3.17,15.3,0.302,102,1.53
3.17,15.3,0.302,102,1.54
3.17,15.4,0.302,102,1.54
3.17,15.4,0.302,103,1.55
3.17,15.4,0.302,103,1.55
3.17,15.5,0.302,103,1.55
3.17,15.5,0.302,104,1.56
3.17,15.6,0.302,104,1.56
3.17,15.6,0.302,104,1.57
3.17,15.7,0.302,104,1.57
3.17,15.7,0.302,105,1.58
3.33,15.7,0.317,105,1.58
3.33,15.8,0.317,105,1.58
3.32,15.8,0.316,106,1.59
3.33,15.9,0.317,106,1.59
3.33,15.9,0.317,106,1.60
3.33,16.0,0.317,106,1.60
3.33,16.0,0.317,107,1.61
3.33,16.0,0.317,107,1.61
3.33,16.1,0.317,107,1.62
3.33,16.1,0.317,108,1.62
3.33,16.2,0.317,108,1.62
3.33,16.2,0.317,108,1.63
3.50,16.3,0.333,108,1.63
3.33,16.3,0.317,109,1.64
3.33,16.3,0.317,109,1.64
3.33,16.4,0.317,109,1.65
3.33,16.4,0.317,110,1.65
3.33,16.5,0.317,110,1.65
3.33,16.5,0.317,110,1.66
3.33,16.6,0.317,110,1.66
3.33,16.6,0.317,111,1.67
3.33,16.7,0.317,111,1.67
3.33,16.7,0.317,111,1.68
3.33,16.7,0.317,112,1.68
3.50,16.8,0.333,112,1.68
3.33,16.8,0.317,112,1.69
3.33,16.9,0.317,112,1.69
3.33,16.9,0.317,113,1.70
3.33,17.0,0.317,113,1.70
3.50,17.0,0.333,113,1.71
3.50,17.0,0.333,114,1.71
3.50,17.1,0.333,114,1.72
3.50,17.1,0.333,114,1.72
3.50,17.2,0.333,114,1.72
3.67,17.2,0.349,115,1.73
3.67,17.3,0.349,115,1.73
3.67,17.3,0.349,115,1.74
3.67,17.3,0.349,116,1.74
3.67,17.4,0.349,116,1.75
3.67,17.4,0.349,116,1.75
3.83,17.5,0.365,117,1.75
3.83,17.5,0.365,117,1.76
3.67,17.6,0.349,117,1.76
3.83,17.6,0.365,117,1.77
3.83,17.7,0.365,118,1.77
3.67,17.7,0.349,118,1.78
3.83,17.7,0.365,118,1.78
3.83,17.8,0.365,119,1.78
3.83,17.8,0.365,119,1.79
3.83,17.9,0.365,119,1.79
3.83,17.9,0.365,119,1.80
3.83,18.0,0.365,120,1.80
3.83,18.0,0.365,120,1.81
3.83,18.0,0.365,120,1.81
4.00,18.1,0.381,121,1.81
4.00,18.1,0.381,121,1.82
4.00,18.2,0.381,121,1.82
3.83,18.2,0.365,121,1.83
3.83,18.3,0.365,122,1.83
3.94,18.3,0.376,122,1.84
4.00,18.3,0.381,122,1.84
4.00,18.4,0.381,123,1.85
4.00,18.4,0.381,123,1.85
4.00,18.5,0.381,123,1.85
4.00,18.5,0.381,123,1.86
4.00,18.6,0.381,124,1.86
4.00,18.6,0.381,124,1.87
4.00,18.6,0.381,124,1.87
4.00,18.7,0.381,125,1.88
4.00,18.7,0.381,125,1.88
4.00,18.8,0.381,125,1.88
4.17,18.8,0.397,125,1.89
4.17,18.9,0.397,126,1.89
4.17,18.9,0.397,126,1.90
4.00,19.0,0.381,126,1.90
4.00,19.0,0.381,127,1.91
4.17,19.0,0.397,127,1.91
4.17,19.1,0.397,127,1.91
4.17,19.1,0.397,128,1.92
4.17,19.2,0.397,128,1.92
4.17,19.2,0.397,128,1.93
4.17,19.3,0.397,128,1.93
4.17,19.3,0.397,129,1.94
4.17,19.3,0.397,129,1.94
4.17,19.4,0.397,129,1.95
4.17,19.4,0.397,130,1.95
4.17,19.5,0.397,130,1.95
4.17,19.5,0.397,130,1.96
4.17,19.6,0.397,130,1.96
4.17,19.6,0.397,131,1.97
4.17,19.6,0.397,131,1.97
4.33,19.7,0.413,131,1.98
4.33,19.7,0.413,132,1.98
4.17,19.8,0.397,132,1.98
4.33,19.8,0.413,132,1.99
4.33,19.9,0.413,132,1.99
4.33,19.9,0.413,133,2.00
4.33,20.0,0.413,133,2.00
4.33,20.0,0.413,133,2.01
4.50,20.0,0.429,134,2.01
4.33,20.1,0.413,134,2.01
4.33,20.1,0.413,134,2.02
4.33,20.2,0.413,134,2.02
4.33,20.2,0.413,135,2.03
4.50,20.3,0.429,135,2.03
4.33,20.3,0.413,135,2.04
4.33,20.3,0.413,136,2.04
4.33,20.4,0.413,136,2.04
4.33,20.4,0.413,136,2.05
4.33,20.5,0.413,136,2.05
4.33,20.5,0.413,137,2.06
4.50,20.6,0.429,137,2.06
4.50,20.6,0.429,137,2.07
4.50,20.6,0.429,138,2.07
4.50,20.7,0.429,138,2.08
4.50,20.7,0.429,138,2.08
4.50,20.8,0.429,139,2.08
4.50,20.8,0.429,139,2.09
4.50,20.9,0.429,139,2.09
4.67,20.9,0.444,139,2.10
4.67,20.9,0.444,140,2.10
4.50,21.0,0.429,140,2.11
4.67,21.0,0.444,140,2.11
4.67,21.1,0.444,141,2.11
4.67,21.1,0.444,141,2.12
4.67,21.2,0.444,141,2.12
4.67,21.2,0.444,141,2.13
4.67,21.3,0.444,142,2.13
4.67,21.3,0.444,142,2.14
4.67,21.3,0.444,142,2.14
4.67,21.4,0.444,143,2.14
4.67,21.4,0.444,143,2.15
4.67,21.5,0.444,143,2.15
4.83,21.5,0.460,143,2.16
4.67,21.6,0.444,144,2.16
4.67,21.6,0.444,144,2.17
4.67,21.6,0.444,144,2.17
4.83,21.7,0.460,145,2.18
4.67,21.7,0.444,145,2.18
4.67,21.8,0.444,145,2.18
4.83,21.8,0.460,145,2.19
4.83,21.9,0.460,146,2.19
4.83,21.9,0.460,146,2.20
4.83,21.9,0.460,146,2.20
4.83,22.0,0.460,147,2.21
4.83,22.0,0.460,147,2.21
4.83,22.1,0.460,147,2.21
4.83,22.1,0.460,147,2.22
4.83,22.2,0.460,148,2.22
4.83,22.2,0.460,148,2.23
4.88,22.3,0.464,148,2.23
5.00,22.3,0.476,149,2.24
5.00,22.3,0.476,149,2.24
5.00,22.4,0.476,149,2.24
5.00,22.4,0.476,150,2.25
5.00,22.5,0.476,150,2.25
5.00,22.5,0.476,150,2.26
5.02,22.6,0.478,150,2.26
5.00,22.6,0.476,151,2.27
5.00,22.6,0.476,151,2.27
5.00,22.7,0.476,151,2.27
5.00,22.7,0.476,152,2.28
5.17,22.8,0.492,152,2.28
5.17,22.8,0.492,152,2.29
5.17,22.9,0.492,152,2.29
5.17,22.9,0.492,153,2.30
5.17,22.9,0.492,153,2.30
5.17,23.0,0.492,153,2.31
5.17,23.0,0.492,154,2.31
5.06,23.1,0.482,154,2.31
5.17,23.1,0.492,154,2.32
5.17,23.2,0.492,154,2.32
5.17,23.2,0.492,155,2.33
5.17,23.2,0.492,155,2.33
5.17,23.3,0.492,155,2.34
5.17,23.3,0.492,156,2.34
5.17,23.4,0.492,156,2.34
5.17,23.4,0.492,156,2.35
5.17,23.5,0.492,156,2.35
5.17,23.5,0.492,157,2.36
5.17,23.6,0.492,157,2.36
5.17,23.6,0.492,157,2.37
5.17,23.6,0.492,158,2.37
5.33,23.7,0.508,158,2.37
5.17,23.7,0.492,158,2.38
5.17,23.8,0.492,158,2.38
5.33,23.8,0.508,159,2.39
5.33,23.9,0.508,159,2.39
5.17,23.9,0.492,159,2.40
5.33,23.9,0.508,160,2.40
5.33,24.0,0.508,160,2.41
5.33,24.0,0.508,160,2.41
5.17,24.1,0.492,160,2.41
5.17,24.1,0.492,161,2.42
5.17,24.2,0.492,161,2.42
5.33,24.2,0.508,161,2.43
5.33,24.2,0.508,162,2.43
5.33,24.3,0.508,162,2.44
5.33,24.3,0.508,162,2.44
5.33,24.4,0.508,163,2.44
5.33,24.4,0.508,163,2.45
5.33,24.5,0.508,163,2.45
5.33,24.5,0.508,163,2.46
5.33,24.6,0.508,164,2.46
5.33,24.6,0.508,164,2.47
5.33,24.6,0.508,164,2.47
5.49,24.7,0.522,165,2.47
5.50,24.7,0.524,165,2.48
5.50,24.8,0.524,165,2.48
5.50,24.8,0.524,165,2.49
5.50,24.9,0.524,166,2.49
5.50,24.9,0.524,166,2.50
5.50,24.9,0.524,166,2.50
5.50,25.0,0.524,167,2.50
5.50,25.0,0.524,167,2.51
5.50,25.1,0.524,167,2.51
5.50,25.1,0.524,167,2.52
5.50,25.2,0.524,168,2.52
5.50,25.2,0.524,168,2.53
5.50,25.2,0.524,168,2.53
5.67,25.3,0.540,169,2.54
5.67,25.3,0.540,169,2.54
5.67,25.4,0.540,169,2.54
5.67,25.4,0.540,169,2.55
5.61,25.5,0.534,170,2.55
5.50,25.5,0.524,170,2.56
5.67,25.5,0.540,170,2.56
5.67,25.6,0.540,171,2.57
5.67,25.6,0.540,171,2.57
5.67,25.7,0.540,171,2.57
5.67,25.7,0.540,171,2.58
5.67,25.8,0.540,172,2.58
5.83,25.8,0.556,172,2.59
5.67,25.9,0.540,172,2.59
5.67,25.9,0.540,173,2.60
5.83,25.9,0.556,173,2.60
5.67,26.0,0.540,173,2.60
5.83,26.0,0.556,174,2.61
5.83,26.1,0.556,174,2.61
5.83,26.1,0.556,174,2.62
5.83,26.2,0.556,174,2.62
5.83,26.2,0.556,175,2.63
5.83,26.2,0.556,175,2.63
5.83,26.3,0.556,175,2.64
5.83,26.3,0.556,176,2.64
5.83,26.4,0.556,176,2.64
5.83,26.4,0.556,176,2.65
5.83,26.5,0.556,176,2.65
5.83,26.5,0.556,177,2.66
5.83,26.5,0.556,177,2.66
5.83,26.6,0.556,177,2.67
5.83,26.6,0.556,178,2.67
5.83,26.7,0.556,178,2.67
5.83,26.7,0.556,178,2.68
6.00,26.8,0.571,178,2.68
5.83,26.8,0.556,179,2.69
6.00,26.9,0.571,179,2.69
6.00,26.9,0.571,179,2.70
6.00,26.9,0.571,180,2.70
6.00,27.0,0.571,180,2.70
6.00,27.0,0.571,180,2.71
6.00,27.1,0.571,180,2.71
6.00,27.1,0.571,181,2.72
6.00,27.2,0.571,181,2.72
6.00,27.2,0.571,181,2.73
6.00,27.2,0.571,182,2.73
6.00,27.3,0.571,182,2.73
6.00,27.3,0.571,182,2.74
6.17,27.4,0.587,182,2.74
6.00,27.4,0.571,183,2.75
6.17,27.5,0.587,183,2.75
6.17,27.5,0.587,183,2.76
6.17,27.5,0.587,184,2.76
6.17,27.6,0.587,184,2.77
6.17,27.6,0.587,184,2.77
6.17,27.7,0.587,185,2.77
6.33,27.7,0.603,185,2.78
6.17,27.8,0.587,185,2.78
6.27,27.8,0.597,185,2.79
6.17,27.8,0.587,186,2.79
6.33,27.9,0.603,186,2.80
6.33,27.9,0.603,186,2.80
6.33,28.0,0.603,187,2.80
6.33,28.0,0.603,187,2.81
6.33,28.1,0.603,187,2.81
6.33,28.1,0.603,187,2.82
6.33,28.2,0.603,188,2.82
6.33,28.2,0.603,188,2.83
6.33,28.2,0.603,188,2.83
6.50,28.3,0.619,189,2.83
6.33,28.3,0.603,189,2.84
6.50,28.4,0.619,189,2.84
6.50,28.4,0.619,189,2.85
6.50,28.5,0.619,190,2.85
6.50,28.5,0.619,190,2.86
6.50,28.5,0.619,190,2.86
6.50,28.6,0.619,191,2.87
6.50,28.6,0.619,191,2.87
6.67,28.7,0.635,191,2.87
6.67,28.7,0.635,191,2.88
6.67,28.8,0.635,192,2.88
6.67,28.8,0.635,192,2.89
6.83,28.8,0.651,192,2.89
6.83,28.9,0.651,193,2.90
6.83,28.9,0.651,193,2.90
6.83,29.0,0.651,193,2.90
6.83,29.0,0.651,193,2.91
6.83,29.1,0.651,194,2.91
6.87,29.1,0.655,194,2.92
7.00,29.2,0.666,194,2.92
6.83,29.2,0.651,195,2.93
6.83,29.2,0.651,195,2.93
6.67,29.3,0.635,195,2.93
6.83,29.3,0.651,195,2.94
6.83,29.4,0.651,196,2.94
6.83,29.4,0.651,196,2.95
6.83,29.5,0.651,196,2.95
6.83,29.5,0.651,197,2.96
6.83,29.5,0.651,197,2.96
6.83,29.6,0.651,197,2.96
7.00,29.6,0.667,198,2.97
7.00,29.7,0.667,198,2.97
7.00,29.7,0.667,198,2.98
7.00,29.8,0.667,198,2.98
7.00,29.8,0.667,199,2.99
7.00,29.8,0.667,199,2.99
7.00,29.9,0.667,199,3.00
7.00,29.9,0.667,200,3.00
7.00,30.0,0.667,200,3.00
7.14,30.0,0.680,200,3.01
7.17,30.1,0.683,200,3.01
7.17,30.1,0.683,201,3.02
7.17,30.1,0.683,201,3.02
7.17,30.2,0.683,201,3.03
7.17,30.2,0.683,202,3.03
7.33,30.3,0.698,202,3.03
7.17,30.3,0.683,202,3.04
7.17,30.4,0.683,202,3.04
7.17,30.4,0.683,203,3.05
7.33,30.5,0.698,203,3.05
7.17,30.5,0.683,203,3.06
7.17,30.5,0.683,204,3.06
7.20,30.6,0.686,204,3.06
7.17,30.6,0.683,204,3.07
7.17,30.7,0.683,204,3.07
7.31,30.7,0.696,205,3.08
7.17,30.8,0.683,205,3.08
7.33,30.8,0.698,205,3.09
7.33,30.8,0.698,206,3.09
7.33,30.9,0.698,206,3.10
7.50,30.9,0.714,206,3.10
7.33,31.0,0.698,206,3.10
7.33,31.0,0.698,207,3.11
7.33,31.1,0.698,207,3.11
7.33,31.1,0.698,207,3.12
7.50,31.1,0.714,208,3.12
7.50,31.2,0.714,208,3.13
7.50,31.2,0.714,208,3.13
7.50,31.3,0.714,209,3.13
7.50,31.3,0.714,209,3.14
7.50,31.4,0.714,209,3.14
7.67,31.4,0.730,209,3.15
7.67,31.5,0.730,210,3.15
7.67,31.5,0.730,210,3.16
7.67,31.5,0.730,210,3.16
7.67,31.6,0.730,211,3.16
7.83,31.6,0.746,211,3.17
7.83,31.7,0.746,211,3.17
7.67,31.7,0.730,211,3.18
7.83,31.8,0.746,212,3.18
7.83,31.8,0.746,212,3.19
7.83,31.8,0.746,212,3.19
7.83,31.9,0.746,213,3.19
7.83,31.9,0.746,213,3.20
7.83,32.0,0.746,213,3.20
7.92,32.0,0.755,213,3.21
8.00,32.1,0.762,214,3.21
8.00,32.1,0.762,214,3.22
8.00,32.1,0.762,214,3.22
8.00,32.2,0.762,215,3.23
8.00,32.2,0.762,215,3.23
8.00,32.3,0.762,215,3.23
8.00,32.3,0.762,215,3.24
8.00,32.4,0.762,216,3.24
8.00,32.4,0.762,216,3.25
8.17,32.4,0.778,216,3.25
8.17,32.5,0.778,217,3.26
8.17,32.5,0.778,217,3.26
8.17,32.6,0.778,217,3.26
8.17,32.6,0.778,217,3.27
8.17,32.7,0.778,218,3.27
8.17,32.7,0.778,218,3.28
8.17,32.8,0.778,218,3.28
8.33,32.8,0.794,219,3.29
8.33,32.8,0.794,219,3.29
8.29,32.9,0.789,219,3.29
8.33,32.9,0.794,220,3.30
8.33,33.0,0.794,220,3.30
8.33,33.0,0.794,220,3.31
8.33,33.1,0.794,220,3.31
8.33,33.1,0.794,221,3.32
8.33,33.1,0.794,221,3.32
8.33,33.2,0.794,221,3.32
8.33,33.2,0.794,222,3.33
8.33,33.3,0.794,222,3.33
8.50,33.3,0.810,222,3.34
8.50,33.4,0.810,222,3.34
8.50,33.4,0.810,223,3.35
8.67,33.4,0.825,223,3.35
8.67,33.5,0.825,223,3.36
8.67,33.5,0.825,224,3.36
8.67,33.6,0.825,224,3.36
8.67,33.6,0.825,224,3.37
8.67,33.7,0.825,224,3.37
8.67,33.7,0.825,225,3.38
8.83,33.8,0.841,225,3.38
8.83,33.8,0.841,225,3.39
8.83,33.8,0.841,226,3.39
9.00,33.9,0.857,226,3.39
8.83,33.9,0.841,226,3.40
9.00,34.0,0.857,226,3.40
9.00,34.0,0.857,227,3.41
9.00,34.1,0.857,227,3.41
9.00,34.1,0.857,227,3.42
9.00,34.1,0.857,228,3.42
9.00,34.2,0.857,228,3.42
9.00,34.2,0.857,228,3.43
9.00,34.3,0.857,228,3.43
9.00,34.3,0.857,229,3.44
9.00,34.4,0.857,229,3.44
9.17,34.4,0.873,229,3.45
9.17,34.4,0.873,230,3.45
9.17,34.5,0.873,230,3.46
9.17,34.5,0.873,230,3.46
9.12,34.6,0.868,230,3.46
9.17,34.6,0.873,231,3.47
9.17,34.7,0.873,231,3.47
9.17,34.7,0.873,231,3.48
9.17,34.7,0.873,232,3.48
9.17,34.8,0.873,232,3.49
9.33,34.8,0.889,232,3.49
9.33,34.9,0.889,233,3.49
9.33,34.9,0.889,233,3.50
9.33,35.0,0.889,233,3.50
9.33,35.0,0.889,233,3.51
9.35,35.1,0.891,234,3.51
9.50,35.1,0.905,234,3.52
9.50,35.1,0.905,234,3.52
9.50,35.2,0.905,235,3.52
9.50,35.2,0.905,235,3.53
9.67,35.3,0.921,235,3.53
9.67,35.3,0.921,235,3.54
9.67,35.4,0.921,236,3.54
9.67,35.4,0.921,236,3.55
9.67,35.4,0.921,236,3.55
9.67,35.5,0.921,237,3.55
9.67,35.5,0.921,237,3.56
9.67,35.6,0.921,237,3.56
9.67,35.6,0.921,237,3.57
9.67,35.7,0.921,238,3.57
9.67,35.7,0.921,238,3.58
9.67,35.7,0.921,238,3.58
9.67,35.8,0.921,239,3.59
9.67,35.8,0.921,239,3.59
9.67,35.9,0.921,239,3.59
9.67,35.9,0.921,239,3.60
9.67,36.0,0.921,240,3.60
9.83,36.0,0.937,240,3.61
9.83,36.0,0.937,240,3.61
9.83,36.1,0.937,241,3.62
9.83,36.1,0.937,241,3.62
9.83,36.2,0.937,241,3.62
10.0,36.2,0.952,241,3.63
10.0,36.3,0.952,242,3.63
10.0,36.3,0.952,242,3.64
10.0,36.4,0.952,242,3.64
10.0,36.4,0.952,243,3.65
10.0,36.4,0.952,243,3.65
10.0,36.5,0.952,243,3.65
10.0,36.5,0.952,244,3.66
10.0,36.6,0.952,244,3.66
10.0,36.6,0.952,244,3.67
10.0,36.7,0.952,244,3.67
10.0,36.7,0.952,245,3.68
10.0,36.7,0.952,245,3.68
10.0,36.8,0.952,245,3.69
10.2,36.8,0.968,246,3.69
10.2,36.9,0.968,246,3.69
10.2,36.9,0.968,246,3.70
10.2,37.0,0.968,246,3.70
10.2,37.0,0.968,247,3.71
10.3,37.0,0.979,247,3.71
10.3,37.1,0.984,247,3.72
10.3,37.1,0.984,248,3.72
10.4,37.2,0.987,248,3.72
10.3,37.2,0.984,248,3.73
10.5,37.3,1.00,248,3.73
10.5,37.3,0.997,249,3.74
10.3,37.4,0.984,249,3.74
10.3,37.4,0.984,249,3.75
10.5,37.4,1.00,250,3.75
10.5,37.5,1.00,250,3.75
10.3,37.5,0.984,250,3.76
10.5,37.6,1.00,250,3.76
10.5,37.6,1.00,251,3.77
10.5,37.7,1.00,251,3.77
10.5,37.7,1.00,251,3.78
10.5,37.7,1.00,252,3.78
10.7,37.8,1.02,252,3.78
10.7,37.8,1.02,252,3.79
10.5,37.9,1.00,252,3.79
10.7,37.9,1.02,253,3.80
10.7,38.0,1.02,253,3.80
10.7,38.0,1.02,253,3.81
10.7,38.0,1.02,254,3.81
10.7,38.1,1.02,254,3.82
10.7,38.1,1.02,254,3.82
10.8,38.2,1.03,255,3.82
10.8,38.2,1.03,255,3.83
10.8,38.3,1.03,255,3.83
10.7,38.3,1.02,255,3.84
10.8,38.4,1.03,256,3.84
10.8,38.4,1.03,256,3.85
10.8,38.4,1.03,256,3.85
11.0,38.5,1.05,257,3.85
11.0,38.5,1.05,257,3.86
10.8,38.6,1.03,257,3.86
11.0,38.6,1.05,257,3.87
11.0,38.7,1.05,258,3.87
11.1,38.7,1.06,258,3.88
11.1,38.7,1.06,258,3.88
11.0,38.8,1.05,259,3.88
11.0,38.8,1.05,259,3.89
11.0,38.9,1.05,259,3.89
11.2,38.9,1.06,259,3.90
11.2,39.0,1.06,260,3.90
11.2,39.0,1.06,260,3.91
11.2,39.0,1.06,260,3.91
11.2,39.1,1.06,261,3.92
11.3,39.1,1.08,261,3.92
11.2,39.2,1.06,261,3.92
11.3,39.2,1.08,261,3.93
11.3,39.3,1.08,262,3.93
11.3,39.3,1.08,262,3.94
11.3,39.3,1.08,262,3.94
11.3,39.4,1.08,263,3.95
11.3,39.4,1.08,263,3.95
11.3,39.5,1.08,263,3.95
11.3,39.5,1.08,263,3.96
11.3,39.6,1.08,264,3.96
11.5,39.6,1.10,264,3.97
11.5,39.7,1.10,264,3.97
11.5,39.7,1.10,265,3.98
11.5,39.7,1.10,265,3.98
11.5,39.8,1.10,265,3.98
11.5,39.8,1.10,266,3.99
11.5,39.9,1.10,266,3.99
11.7,39.9,1.11,266,4.00
11.5,40.0,1.10,266,4.00
11.7,40.0,1.11,267,4.01
11.7,40.0,1.11,267,4.01
11.7,40.1,1.11,267,4.01
11.7,40.1,1.11,268,4.02
11.7,40.2,1.11,268,4.02
11.7,40.2,1.11,268,4.03
11.7,40.3,1.11,268,4.03
11.7,40.3,1.11,269,4.04
11.7,40.3,1.11,269,4.04
11.8,40.4,1.13,269,4.05
11.8,40.4,1.13,270,4.05
11.8,40.5,1.13,270,4.05
11.8,40.5,1.13,270,4.06
11.8,40.6,1.13,270,4.06
11.8,40.6,1.13,271,4.07
11.8,40.7,1.13,271,4.07
11.8,40.7,1.13,271,4.08
11.8,40.7,1.13,272,4.08
11.8,40.8,1.13,272,4.08
11.8,40.8,1.13,272,4.09
11.9,40.9,1.14,272,4.09
11.8,40.9,1.13,273,4.10
11.8,41.0,1.13,273,4.10
11.8,41.0,1.13,273,4.11
11.8,41.0,1.13,274,4.11
12.0,41.1,1.14,274,4.11
12.0,41.1,1.14,274,4.12
12.0,41.2,1.14,274,4.12
12.0,41.2,1.14,275,4.13
12.0,41.3,1.14,275,4.13
12.0,41.3,1.14,275,4.14
12.2,41.3,1.16,276,4.14
12.2,41.4,1.16,276,4.15
12.2,41.4,1.16,276,4.15
12.2,41.5,1.16,276,4.15
12.2,41.5,1.16,277,4.16
12.2,41.6,1.16,277,4.16
12.2,41.6,1.16,277,4.17
12.2,41.6,1.16,278,4.17
12.2,41.7,1.16,278,4.18
12.3,41.7,1.17,278,4.18
12.3,41.8,1.17,279,4.18
12.2,41.8,1.16,279,4.19
12.3,41.9,1.17,279,4.19
12.3,41.9,1.17,279,4.20
12.3,42.0,1.17,280,4.20
12.3,42.0,1.17,280,4.21
12.3,42.0,1.17,280,4.21
12.5,42.1,1.19,281,4.21
12.3,42.1,1.17,281,4.22
12.3,42.2,1.17,281,4.22
12.3,42.2,1.17,281,4.23
12.3,42.3,1.17,282,4.23
12.3,42.3,1.17,282,4.24
12.3,42.3,1.17,282,4.24
12.4,42.4,1.18,283,4.24
12.5,42.4,1.19,283,4.25
12.5,42.5,1.19,283,4.25
12.5,42.5,1.19,283,4.26
12.5,42.6,1.19,284,4.26
12.7,42.6,1.21,284,4.27
12.7,42.6,1.21,284,4.27
12.7,42.7,1.21,285,4.28
12.7,42.7,1.21,285,4.28
12.7,42.8,1.21,285,4.28
12.8,42.8,1.22,285,4.29
12.8,42.9,1.22,286,4.29
12.8,42.9,1.22,286,4.30
12.8,43.0,1.22,286,4.30
12.8,43.0,1.22,287,4.31
12.8,43.0,1.22,287,4.31
12.8,43.1,1.22,287,4.31
13.0,43.1,1.24,287,4.32
13.0,43.2,1.24,288,4.32
13.0,43.2,1.24,288,4.33
13.0,43.3,1.24,288,4.33
13.0,43.3,1.24,289,4.34
13.0,43.3,1.24,289,4.34
13.0,43.4,1.24,289,4.34
13.2,43.4,1.25,290,4.35
13.2,43.5,1.25,290,4.35
13.2,43.5,1.25,290,4.36
13.2,43.6,1.25,290,4.36
13.2,43.6,1.25,291,4.37
13.2,43.6,1.25,291,4.37
13.2,43.7,1.26,291,4.38
13.2,43.7,1.25,292,4.38
13.2,43.8,1.25,292,4.38
13.2,43.8,1.25,292,4.39
13.3,43.9,1.27,292,4.39
13.3,43.9,1.27,293,4.40
13.3,43.9,1.27,293,4.40
13.3,44.0,1.27,293,4.41
13.3,44.0,1.27,294,4.41
13.3,44.1,1.27,294,4.41
13.3,44.1,1.27,294,4.42
13.3,44.2,1.27,294,4.42
13.3,44.2,1.27,295,4.43
13.3,44.3,1.27,295,4.43
13.5,44.3,1.29,295,4.44
13.3,44.3,1.27,296,4.44
13.5,44.4,1.29,296,4.44
13.5,44.4,1.29,296,4.45
13.5,44.5,1.29,296,4.45
13.5,44.5,1.29,297,4.46
13.5,44.6,1.29,297,4.46
13.5,44.6,1.29,297,4.47
13.5,44.6,1.29,298,4.47
13.7,44.7,1.30,298,4.47
13.7,44.7,1.30,298,4.48
13.5,44.8,1.29,298,4.48
13.7,44.8,1.30,299,4.49
13.7,44.9,1.30,299,4.49
13.5,44.9,1.29,299,4.50
13.6,44.9,1.30,300,4.50
13.7,45.0,1.30,300,4.51
13.5,45.0,1.29,300,4.51
13.7,45.1,1.30,301,4.51
13.7,45.1,1.30,301,4.52
13.7,45.2,1.30,301,4.52
13.7,45.2,1.30,301,4.53
13.7,45.3,1.30,302,4.53
13.7,45.3,1.30,302,4.54
13.7,45.3,1.30,302,4.54
13.7,45.4,1.30,303,4.54
13.8,45.4,1.32,303,4.55
13.7,45.5,1.30,303,4.55
13.8,45.5,1.32,303,4.56
13.8,45.6,1.32,304,4.56
13.8,45.6,1.32,304,4.57
13.8,45.6,1.32,304,4.57
13.8,45.7,1.32,305,4.57
13.8,45.7,1.32,305,4.58
13.8,45.8,1.32,305,4.58
13.8,45.8,1.32,305,4.59
13.8,45.9,1.32,306,4.59
13.8,45.9,1.32,306,4.60
13.8,45.9,1.32,306,4.60
13.8,46.0,1.32,307,4.61
13.8,46.0,1.32,307,4.61
13.8,46.1,1.32,307,4.61
14.0,46.1,1.33,307,4.62
14.0,46.2,1.33,308,4.62
14.0,46.2,1.33,308,4.63
14.0,46.2,1.33,308,4.63
14.0,46.3,1.33,309,4.64
14.0,46.3,1.33,309,4.64
14.2,46.4,1.35,309,4.64
14.2,46.4,1.35,309,4.65
14.2,46.5,1.35,310,4.65
14.2,46.5,1.35,310,4.66
14.2,46.6,1.35,310,4.66
14.2,46.6,1.35,311,4.67
14.3,46.6,1.37,311,4.67
14.3,46.7,1.37,311,4.67
14.3,46.7,1.37,311,4.68
14.3,46.8,1.37,312,4.68
14.3,46.8,1.37,312,4.69
14.3,46.9,1.37,312,4.69
14.3,46.9,1.37,313,4.70
14.3,46.9,1.37,313,4.70
14.3,47.0,1.37,313,4.70
14.3,47.0,1.37,314,4.71
14.3,47.1,1.37,314,4.71
14.3,47.1,1.37,314,4.72
14.3,47.2,1.37,314,4.72
14.3,47.2,1.37,315,4.73
14.3,47.2,1.37,315,4.73
14.3,47.3,1.37,315,4.74
14.3,47.3,1.37,316,4.74
14.5,47.4,1.38,316,4.74
14.5,47.4,1.38,316,4.75
14.5,47.5,1.38,316,4.75
14.5,47.5,1.38,317,4.76
14.5,47.5,1.38,317,4.76
14.5,47.6,1.38,317,4.77
14.5,47.6,1.38,318,4.77
14.5,47.7,1.38,318,4.77
14.5,47.7,1.38,318,4.78
14.7,47.8,1.40,318,4.78
14.7,47.8,1.40,319,4.79
14.5,47.9,1.38,319,4.79
14.7,47.9,1.40,319,4.80
14.7,47.9,1.40,320,4.80
14.7,48.0,1.40,320,4.80
14.7,48.0,1.40,320,4.81
14.7,48.1,1.40,320,4.81
14.7,48.1,1.40,321,4.82
14.8,48.2,1.41,321,4.82
14.8,48.2,1.41,321,4.83
14.8,48.2,1.41,322,4.83
14.8,48.3,1.41,322,4.84
14.8,48.3,1.41,322,4.84
14.8,48.4,1.41,322,4.84
14.8,48.4,1.41,323,4.85
14.8,48.5,1.41,323,4.85
14.8,48.5,1.41,323,4.86
14.8,48.5,1.41,324,4.86
14.8,48.6,1.41,324,4.87
15.0,48.6,1.43,324,4.87
15.0,48.7,1.43,325,4.87
15.0,48.7,1.43,325,4.88
15.0,48.8,1.43,325,4.88
15.0,48.8,1.43,325,4.89
15.0,48.9,1.43,326,4.89
15.0,48.9,1.43,326,4.90
15.0,48.9,1.43,326,4.90
15.0,49.0,1.43,327,4.90
15.2,49.0,1.44,327,4.91
15.0,49.1,1.43,327,4.91
15.0,49.1,1.43,327,4.92
15.0,49.2,1.43,328,4.92
15.0,49.2,1.43,328,4.93
15.0,49.2,1.43,328,4.93
15.2,49.3,1.44,329,4.93
15.2,49.3,1.44,329,4.94
15.2,49.4,1.44,329,4.94
15.2,49.4,1.44,329,4.95
15.2,49.5,1.44,330,4.95
15.2,49.5,1.44,330,4.96
15.2,49.5,1.44,330,4.96
15.2,49.6,1.44,331,4.97
15.2,49.6,1.44,331,4.97
15.2,49.7,1.44,331,4.97
15.2,49.7,1.44,331,4.98
15.2,49.8,1.44,332,4.98
15.2,49.8,1.44,332,4.99
15.2,49.8,1.44,332,4.99
15.2,49.9,1.44,333,5.00
15.2,49.9,1.44,333,5.00
15.2,50.0,1.44,333,5.00
15.2,50.0,1.44,333,5.01
15.3,50.1,1.46,334,5.01
15.3,50.1,1.46,334,5.02
15.3,50.2,1.46,334,5.02
15.2,50.2,1.44,335,5.03
15.2,50.2,1.44,335,5.03
15.2,50.3,1.44,335,5.03
15.3,50.3,1.46,336,5.04
15.2,50.4,1.44,336,5.04
15.2,50.4,1.45,336,5.05
15.3,50.5,1.46,336,5.05
15.2,50.5,1.45,337,5.06
15.2,50.5,1.45,337,5.06
15.3,50.6,1.46,337,5.07
15.3,50.6,1.46,338,5.07
15.3,50.7,1.46,338,5.07
15.3,50.7,1.46,338,5.08
15.3,50.8,1.46,338,5.08
15.3,50.8,1.46,339,5.09
15.3,50.8,1.46,339,5.09
15.3,50.9,1.46,339,5.10
15.2,50.9,1.44,340,5.10
15.3,51.0,1.46,340,5.10
15.2,51.0,1.44,340,5.11
15.2,51.1,1.44,340,5.11
15.2,51.1,1.44,341,5.12
15.2,51.2,1.44,341,5.12
15.3,51.2,1.46,341,5.13
15.0,51.2,1.43,342,5.13
15.2,51.3,1.44,342,5.13
15.2,51.3,1.44,342,5.14
15.2,51.4,1.44,342,5.14
15.2,51.4,1.44,343,5.15
15.2,51.5,1.44,343,5.15
15.1,51.5,1.44,343,5.16
15.2,51.5,1.44,344,5.16
15.0,51.6,1.43,344,5.16
15.2,51.6,1.44,344,5.17
15.2,51.7,1.44,344,5.17
15.0,51.7,1.43,345,5.18
15.2,51.8,1.44,345,5.18
15.0,51.8,1.43,345,5.19
15.0,51.8,1.43,346,5.19
15.0,51.9,1.43,346,5.20
15.0,51.9,1.43,346,5.20
15.0,52.0,1.43,347,5.20
15.0,52.0,1.43,347,5.21
15.0,52.1,1.43,347,5.21
15.0,52.1,1.43,347,5.22
15.0,52.1,1.43,348,5.22
14.8,52.2,1.41,348,5.23
14.8,52.2,1.41,348,5.23
14.8,52.3,1.41,349,5.23
14.8,52.3,1.41,349,5.24
14.8,52.4,1.41,349,5.24
14.7,52.4,1.40,349,5.25
14.7,52.5,1.40,350,5.25
14.5,52.5,1.38,350,5.26
14.5,52.5,1.38,350,5.26
14.7,52.6,1.40,351,5.26
14.5,52.6,1.38,351,5.27
14.5,52.7,1.38,351,5.27
14.7,52.7,1.40,351,5.28
14.5,52.8,1.38,352,5.28
14.5,52.8,1.38,352,5.29
14.5,52.8,1.38,352,5.29
14.5,52.9,1.38,353,5.30
14.5,52.9,1.38,353,5.30
14.5,53.0,1.38,353,5.30
14.5,53.0,1.38,353,5.31
14.5,53.1,1.38,354,5.31
14.5,53.1,1.38,354,5.32
14.5,53.1,1.38,354,5.32
14.5,53.2,1.38,355,5.33
14.5,53.2,1.38,355,5.33
14.5,53.3,1.38,355,5.33
14.3,53.3,1.37,355,5.34
14.5,53.4,1.38,356,5.34
14.3,53.4,1.37,356,5.35
14.0,53.5,1.33,356,5.35
14.0,53.5,1.33,357,5.36
14.0,53.5,1.33,357,5.36
14.0,53.6,1.33,357,5.36
14.0,53.6,1.33,358,5.37
13.8,53.7,1.32,358,5.37
13.5,53.7,1.29,358,5.38
2.40,53.8,0.229,358,5.38
2.50,53.8,0.238,359,5.39
2.50,53.8,0.238,359,5.39
2.50,53.9,0.238,359,5.39
2.50,53.9,0.238,360,5.40
2.50,54.0,0.238,360,5.40
2.50,54.0,0.238,360,5.41
2.67,54.1,0.254,360,5.41
2.67,54.1,0.254,361,5.42
2.50,54.1,0.238,361,5.42
2.67,54.2,0.254,361,5.43
2.67,54.2,0.254,362,5.43