File: Thermal Chamber for UTM/pla room temp..csv
Force (N),Position (mm),Stress (MPa),Strain (%),Time (min)
0.167,0.00,0.00855,0.00,0.00361
0.170,0.00100,0.00873,0.00286,0.00507
1.10,0.00400,0.0564,0.0114,0.00652
2.69,0.00700,0.138,0.0200,0.00797
4.34,0.0100,0.222,0.0286,0.00942
6.04,0.0130,0.310,0.0371,0.0109
7.51,0.0160,0.385,0.0458,0.0123
8.94,0.0188,0.458,0.0538,0.0138
10.2,0.0220,0.523,0.0629,0.0152
11.4,0.0250,0.583,0.0714,0.0167
12.5,0.0280,0.639,0.0800,0.0181
13.5,0.0310,0.692,0.0886,0.0196
14.2,0.0339,0.726,0.0969,0.0210
14.5,0.0370,0.744,0.106,0.0225
14.5,0.0400,0.744,0.114,0.0239
14.5,0.0427,0.744,0.122,0.0254
14.7,0.0452,0.752,0.129,0.0268
14.7,0.0480,0.752,0.137,0.0283
14.7,0.0514,0.752,0.147,0.0297
14.7,0.0540,0.752,0.154,0.0312
14.7,0.0575,0.752,0.164,0.0326
14.7,0.0601,0.752,0.172,0.0341
14.7,0.0627,0.752,0.179,0.0355
14.7,0.0660,0.752,0.189,0.0370
14.5,0.0689,0.744,0.197,0.0384
14.6,0.0720,0.747,0.206,0.0399
14.5,0.0750,0.744,0.214,0.0413
14.5,0.0774,0.744,0.221,0.0428
14.5,0.0802,0.744,0.229,0.0442
14.5,0.0830,0.744,0.237,0.0457
14.7,0.0860,0.752,0.246,0.0471
14.7,0.0890,0.752,0.254,0.0486
14.5,0.0920,0.744,0.263,0.0500
14.5,0.0948,0.744,0.271,0.0515
14.3,0.0976,0.735,0.279,0.0529
14.5,0.101,0.744,0.289,0.0544
14.5,0.104,0.744,0.296,0.0558
14.5,0.106,0.744,0.304,0.0573
14.5,0.109,0.744,0.311,0.0587
14.5,0.112,0.744,0.320,0.0602
14.5,0.115,0.744,0.329,0.0616
14.5,0.118,0.744,0.337,0.0631
14.5,0.121,0.744,0.346,0.0645
14.5,0.124,0.744,0.354,0.0660
14.4,0.126,0.738,0.361,0.0674
14.5,0.129,0.744,0.370,0.0689
14.5,0.133,0.744,0.379,0.0703
14.5,0.135,0.744,0.386,0.0718
14.5,0.138,0.744,0.394,0.0732
14.5,0.141,0.744,0.404,0.0747
14.5,0.144,0.744,0.411,0.0761
14.3,0.147,0.735,0.419,0.0776
14.3,0.150,0.735,0.429,0.0790
14.4,0.153,0.740,0.436,0.0805
14.5,0.155,0.742,0.443,0.0819
14.3,0.159,0.735,0.454,0.0834
14.5,0.161,0.744,0.461,0.0848
14.5,0.164,0.744,0.468,0.0863
14.5,0.167,0.744,0.478,0.0877
14.3,0.170,0.735,0.486,0.0892
14.3,0.174,0.735,0.496,0.0906
14.3,0.176,0.735,0.503,0.0921
14.3,0.179,0.735,0.511,0.0935
14.3,0.181,0.735,0.518,0.0950
14.3,0.185,0.735,0.528,0.0964
14.5,0.187,0.744,0.536,0.0979
14.5,0.191,0.744,0.546,0.0993
14.8,0.194,0.761,0.553,0.101
15.0,0.196,0.769,0.561,0.102
15.1,0.199,0.776,0.569,0.104
15.2,0.202,0.778,0.578,0.105
15.3,0.205,0.786,0.586,0.107
15.3,0.208,0.786,0.594,0.108
15.5,0.211,0.795,0.603,0.109
15.7,0.214,0.803,0.611,0.111
15.8,0.216,0.812,0.618,0.112
16.0,0.219,0.821,0.626,0.114
16.2,0.222,0.829,0.636,0.115
16.2,0.225,0.829,0.643,0.117
16.2,0.228,0.829,0.651,0.118
16.3,0.231,0.838,0.661,0.120
16.3,0.234,0.838,0.669,0.121
16.3,0.237,0.838,0.677,0.123
16.3,0.240,0.838,0.685,0.124
16.4,0.242,0.842,0.693,0.125
16.5,0.245,0.846,0.700,0.127
16.5,0.249,0.846,0.710,0.128
16.5,0.251,0.846,0.718,0.130
16.5,0.254,0.846,0.726,0.131
16.5,0.257,0.846,0.734,0.133
16.5,0.260,0.846,0.743,0.134
16.5,0.263,0.846,0.751,0.136
16.5,0.266,0.845,0.760,0.137
16.4,0.269,0.840,0.768,0.138
16.5,0.271,0.846,0.775,0.140
16.5,0.275,0.846,0.785,0.141
16.5,0.277,0.846,0.793,0.143
16.5,0.281,0.846,0.803,0.144
16.5,0.283,0.846,0.810,0.146
16.5,0.286,0.847,0.818,0.147
16.7,0.289,0.855,0.826,0.149
16.8,0.292,0.863,0.834,0.150
16.8,0.295,0.863,0.843,0.152
16.8,0.298,0.863,0.851,0.153
16.8,0.301,0.863,0.859,0.154
16.8,0.304,0.863,0.867,0.156
16.8,0.307,0.863,0.877,0.157
16.8,0.310,0.863,0.885,0.159
16.8,0.312,0.863,0.892,0.160
17.0,0.315,0.872,0.900,0.162
16.8,0.318,0.863,0.909,0.163
17.0,0.321,0.872,0.917,0.165
17.0,0.324,0.872,0.926,0.166
17.0,0.327,0.872,0.934,0.167
17.1,0.330,0.878,0.942,0.169
17.1,0.332,0.875,0.950,0.170
17.0,0.335,0.872,0.958,0.172
17.0,0.339,0.872,0.967,0.173
17.0,0.341,0.872,0.975,0.175
17.0,0.344,0.872,0.983,0.176
17.0,0.347,0.872,0.991,0.178
17.0,0.350,0.872,0.999,0.179
17.0,0.353,0.872,1.01,0.181
17.0,0.356,0.872,1.02,0.182
17.0,0.359,0.872,1.02,0.183
17.0,0.361,0.872,1.03,0.185
17.0,0.365,0.872,1.04,0.186
17.0,0.367,0.872,1.05,0.188
17.0,0.370,0.872,1.06,0.189
17.0,0.373,0.872,1.07,0.191
17.0,0.376,0.872,1.07,0.192
17.0,0.379,0.872,1.08,0.194
17.0,0.382,0.872,1.09,0.195
17.0,0.385,0.872,1.10,0.196
17.0,0.387,0.872,1.11,0.198
17.0,0.391,0.872,1.12,0.199
17.0,0.393,0.872,1.12,0.201
17.2,0.396,0.880,1.13,0.202
17.2,0.400,0.880,1.14,0.204
17.2,0.402,0.880,1.15,0.205
17.2,0.405,0.880,1.16,0.207
17.2,0.408,0.880,1.17,0.208
17.2,0.411,0.880,1.17,0.210
17.3,0.414,0.889,1.18,0.211
17.3,0.417,0.889,1.19,0.212
17.3,0.420,0.889,1.20,0.214
17.3,0.422,0.889,1.21,0.215
17.2,0.426,0.880,1.22,0.217
17.2,0.428,0.880,1.22,0.218
17.2,0.431,0.880,1.23,0.220
17.2,0.434,0.880,1.24,0.221
17.2,0.437,0.880,1.25,0.223
17.2,0.440,0.880,1.26,0.224
17.2,0.443,0.880,1.27,0.225
17.2,0.446,0.880,1.27,0.227
17.2,0.448,0.880,1.28,0.228
17.3,0.451,0.889,1.29,0.230
17.5,0.455,0.897,1.30,0.231
17.7,0.457,0.906,1.31,0.233
17.8,0.460,0.915,1.31,0.234
18.2,0.463,0.932,1.32,0.236
18.8,0.466,0.965,1.33,0.237
19.7,0.469,1.01,1.34,0.239
20.7,0.472,1.06,1.35,0.240
22.1,0.475,1.13,1.36,0.241
23.4,0.477,1.20,1.36,0.243
25.0,0.481,1.28,1.37,0.244
26.4,0.483,1.35,1.38,0.246
27.8,0.486,1.43,1.39,0.247
29.3,0.489,1.50,1.40,0.249
30.6,0.492,1.57,1.41,0.250
32.3,0.495,1.66,1.41,0.252
33.9,0.498,1.74,1.42,0.253
35.3,0.501,1.81,1.43,0.254
36.8,0.503,1.89,1.44,0.256
38.4,0.507,1.97,1.45,0.257
39.8,0.510,2.04,1.46,0.259
41.2,0.512,2.11,1.46,0.260
42.8,0.515,2.19,1.47,0.262
44.1,0.518,2.26,1.48,0.263
45.7,0.521,2.34,1.49,0.265
47.0,0.524,2.41,1.50,0.266
48.4,0.527,2.48,1.51,0.268
49.8,0.530,2.55,1.51,0.269
51.2,0.533,2.63,1.52,0.270
52.8,0.536,2.71,1.53,0.272
54.1,0.538,2.78,1.54,0.273
55.5,0.541,2.84,1.55,0.275
56.8,0.545,2.91,1.56,0.276
58.2,0.547,2.98,1.56,0.278
59.6,0.550,3.06,1.57,0.279
61.0,0.553,3.13,1.58,0.281
62.3,0.556,3.20,1.59,0.282
63.4,0.559,3.25,1.60,0.284
64.8,0.562,3.32,1.61,0.285
66.2,0.565,3.39,1.61,0.286
67.4,0.568,3.45,1.62,0.288
68.6,0.571,3.52,1.63,0.289
69.9,0.573,3.59,1.64,0.291
71.1,0.576,3.65,1.65,0.292
72.4,0.579,3.71,1.65,0.294
73.5,0.582,3.77,1.66,0.295
74.7,0.585,3.83,1.67,0.297
75.7,0.587,3.88,1.68,0.298
76.8,0.591,3.94,1.69,0.299
77.9,0.593,3.99,1.70,0.301
79.0,0.596,4.05,1.70,0.302
80.1,0.599,4.11,1.71,0.304
81.2,0.602,4.16,1.72,0.305
82.3,0.605,4.22,1.73,0.307
83.2,0.608,4.27,1.74,0.308
84.3,0.611,4.32,1.75,0.310
85.4,0.614,4.38,1.75,0.311
86.5,0.617,4.44,1.76,0.313
87.6,0.620,4.49,1.77,0.314
88.5,0.623,4.54,1.78,0.315
89.5,0.626,4.59,1.79,0.317
90.4,0.628,4.63,1.79,0.318
91.3,0.631,4.68,1.80,0.320
92.2,0.634,4.73,1.81,0.321
93.2,0.637,4.78,1.82,0.323
94.1,0.640,4.83,1.83,0.324
95.0,0.643,4.87,1.84,0.326
95.7,0.646,4.91,1.84,0.327
96.6,0.649,4.95,1.85,0.328
97.5,0.652,5.00,1.86,0.330
98.4,0.654,5.05,1.87,0.331
99.3,0.657,5.09,1.88,0.333
100,0.661,5.14,1.89,0.334
101,0.663,5.18,1.89,0.336
102,0.666,5.23,1.90,0.337
103,0.669,5.29,1.91,0.339
104,0.672,5.33,1.92,0.340
105,0.675,5.39,1.93,0.342
106,0.678,5.44,1.94,0.343
107,0.681,5.49,1.94,0.344
108,0.683,5.54,1.95,0.346
109,0.687,5.60,1.96,0.347
110,0.689,5.66,1.97,0.349
111,0.692,5.72,1.98,0.350
112,0.695,5.76,1.99,0.352
114,0.698,5.82,1.99,0.353
115,0.701,5.88,2.00,0.355
116,0.704,5.93,2.01,0.356
117,0.707,5.98,2.02,0.357
118,0.709,6.04,2.03,0.359
119,0.713,6.09,2.04,0.360
120,0.716,6.15,2.04,0.362
121,0.718,6.21,2.05,0.363
122,0.721,6.26,2.06,0.365
123,0.724,6.31,2.07,0.366
124,0.727,6.37,2.08,0.368
125,0.730,6.42,2.09,0.369
126,0.733,6.47,2.09,0.371
127,0.736,6.53,2.10,0.372
128,0.739,6.58,2.11,0.373
129,0.742,6.63,2.12,0.375
130,0.744,6.69,2.13,0.376
132,0.747,6.75,2.14,0.378
133,0.751,6.80,2.14,0.379
134,0.753,6.85,2.15,0.381
135,0.756,6.90,2.16,0.382
136,0.759,6.95,2.17,0.384
137,0.762,7.01,2.18,0.385
138,0.765,7.05,2.18,0.386
139,0.768,7.11,2.19,0.388
140,0.771,7.16,2.20,0.389
141,0.773,7.22,2.21,0.391
142,0.776,7.27,2.22,0.392
143,0.779,7.32,2.23,0.394
144,0.782,7.37,2.23,0.395
145,0.785,7.42,2.24,0.397
146,0.788,7.48,2.25,0.398
147,0.791,7.53,2.26,0.400
148,0.794,7.57,2.27,0.401
149,0.797,7.62,2.28,0.402
150,0.799,7.67,2.28,0.404
151,0.802,7.73,2.29,0.405
152,0.805,7.77,2.30,0.407
153,0.808,7.83,2.31,0.408
154,0.811,7.88,2.32,0.410
155,0.814,7.93,2.33,0.411
156,0.817,7.98,2.33,0.413
157,0.820,8.03,2.34,0.414
157,0.823,8.08,2.35,0.415
159,0.826,8.13,2.36,0.417
160,0.829,8.19,2.37,0.418
161,0.832,8.23,2.38,0.420
161,0.834,8.28,2.38,0.421
162,0.837,8.33,2.39,0.423
163,0.840,8.38,2.40,0.424
164,0.843,8.43,2.41,0.426
165,0.846,8.48,2.42,0.427
166,0.849,8.53,2.43,0.429
167,0.852,8.57,2.43,0.430
168,0.854,8.62,2.44,0.431
169,0.857,8.67,2.45,0.433
170,0.860,8.72,2.46,0.434
171,0.863,8.77,2.47,0.436
172,0.867,8.81,2.48,0.437
173,0.869,8.86,2.48,0.439
174,0.872,8.91,2.49,0.440
175,0.875,8.97,2.50,0.442
176,0.878,9.02,2.51,0.443
177,0.881,9.06,2.52,0.444
178,0.883,9.10,2.52,0.446
178,0.887,9.15,2.53,0.447
179,0.889,9.20,2.54,0.449
180,0.892,9.25,2.55,0.450
181,0.895,9.29,2.56,0.452
182,0.898,9.34,2.57,0.453
183,0.901,9.39,2.57,0.455
184,0.904,9.44,2.58,0.456
185,0.907,9.48,2.59,0.458
186,0.910,9.53,2.60,0.459
187,0.913,9.57,2.61,0.460
188,0.915,9.62,2.62,0.462
188,0.919,9.66,2.62,0.463
189,0.921,9.71,2.63,0.465
190,0.924,9.75,2.64,0.466
191,0.927,9.79,2.65,0.468
192,0.930,9.83,2.66,0.469
193,0.933,9.88,2.67,0.471
194,0.936,9.92,2.67,0.472
194,0.939,9.97,2.68,0.473
195,0.942,10.0,2.69,0.475
196,0.945,10.1,2.70,0.476
197,0.948,10.1,2.71,0.478
198,0.950,10.1,2.72,0.479
198,0.953,10.2,2.72,0.481
199,0.957,10.2,2.73,0.482
200,0.959,10.3,2.74,0.484
201,0.962,10.3,2.75,0.485
202,0.965,10.3,2.76,0.487
202,0.968,10.4,2.77,0.488
203,0.971,10.4,2.77,0.489
204,0.974,10.5,2.78,0.491
205,0.977,10.5,2.79,0.492
206,0.979,10.5,2.80,0.494
206,0.982,10.6,2.81,0.495
207,0.985,10.6,2.81,0.497
208,0.988,10.7,2.82,0.498
209,0.991,10.7,2.83,0.500
210,0.994,10.8,2.84,0.501
210,0.997,10.8,2.85,0.502
211,1.00,10.8,2.86,0.504
212,1.00,10.9,2.86,0.505
213,1.01,10.9,2.87,0.507
213,1.01,10.9,2.88,0.508
214,1.01,11.0,2.89,0.510
215,1.01,11.0,2.90,0.511
216,1.02,11.1,2.91,0.513
217,1.02,11.1,2.91,0.514
217,1.02,11.1,2.92,0.516
218,1.03,11.2,2.93,0.517
219,1.03,11.2,2.94,0.518
219,1.03,11.2,2.95,0.520
220,1.03,11.3,2.95,0.521
221,1.04,11.3,2.96,0.523
221,1.04,11.3,2.97,0.524
222,1.04,11.4,2.98,0.526
223,1.05,11.4,2.99,0.527
223,1.05,11.5,3.00,0.529
224,1.05,11.5,3.01,0.530
225,1.06,11.5,3.01,0.531
225,1.06,11.5,3.02,0.533
226,1.06,11.6,3.03,0.534
227,1.06,11.6,3.04,0.536
227,1.07,11.7,3.05,0.537
228,1.07,11.7,3.05,0.539
229,1.07,11.7,3.06,0.540
229,1.08,11.8,3.07,0.542
230,1.08,11.8,3.08,0.543
230,1.08,11.8,3.09,0.545
231,1.08,11.8,3.10,0.546
232,1.09,11.9,3.10,0.547
232,1.09,11.9,3.11,0.549
233,1.09,11.9,3.12,0.550
233,1.10,12.0,3.13,0.552
234,1.10,12.0,3.14,0.553
235,1.10,12.0,3.15,0.555
235,1.10,12.1,3.15,0.556
236,1.11,12.1,3.16,0.558
236,1.11,12.1,3.17,0.559
237,1.11,12.1,3.18,0.560
237,1.12,12.2,3.19,0.562
238,1.12,12.2,3.20,0.563
238,1.12,12.2,3.20,0.565
239,1.12,12.3,3.21,0.566
239,1.13,12.3,3.22,0.568
240,1.13,12.3,3.23,0.569
241,1.13,12.3,3.24,0.571
241,1.14,12.4,3.25,0.572
242,1.14,12.4,3.25,0.574
243,1.14,12.4,3.26,0.575
243,1.14,12.5,3.27,0.576
244,1.15,12.5,3.28,0.578
245,1.15,12.6,3.29,0.579
246,1.15,12.6,3.30,0.581
247,1.16,12.6,3.30,0.582
247,1.16,12.7,3.31,0.584
248,1.16,12.7,3.32,0.585
249,1.17,12.8,3.33,0.587
250,1.17,12.8,3.34,0.588
251,1.17,12.9,3.34,0.589
252,1.17,12.9,3.35,0.591
253,1.18,13.0,3.36,0.592
253,1.18,13.0,3.37,0.594
254,1.18,13.0,3.38,0.595
255,1.19,13.1,3.39,0.597
256,1.19,13.1,3.39,0.598
257,1.19,13.2,3.40,0.600
258,1.19,13.2,3.41,0.601
259,1.20,13.3,3.42,0.603
260,1.20,13.3,3.43,0.604
261,1.20,13.4,3.44,0.605
261,1.21,13.4,3.45,0.607
262,1.21,13.4,3.45,0.608
263,1.21,13.5,3.46,0.610
264,1.21,13.5,3.47,0.611
265,1.22,13.6,3.48,0.613
265,1.22,13.6,3.49,0.614
266,1.22,13.7,3.49,0.616
267,1.23,13.7,3.50,0.617
268,1.23,13.7,3.51,0.618
269,1.23,13.8,3.52,0.620
269,1.23,13.8,3.53,0.621
270,1.24,13.9,3.54,0.623
271,1.24,13.9,3.54,0.624
271,1.24,13.9,3.55,0.626
272,1.25,14.0,3.56,0.627
273,1.25,14.0,3.57,0.629
273,1.25,14.0,3.58,0.630
274,1.25,14.1,3.59,0.632
275,1.26,14.1,3.59,0.633
275,1.26,14.1,3.60,0.634
276,1.26,14.1,3.61,0.636
276,1.27,14.2,3.62,0.637
277,1.27,14.2,3.63,0.639
277,1.27,14.2,3.64,0.640
278,1.28,14.2,3.64,0.642
278,1.28,14.3,3.65,0.643
279,1.28,14.3,3.66,0.645
279,1.28,14.3,3.67,0.646
280,1.29,14.3,3.68,0.647
280,1.29,14.4,3.69,0.649
280,1.29,14.4,3.69,0.650
281,1.30,14.4,3.70,0.652
281,1.30,14.4,3.71,0.653
281,1.30,14.4,3.72,0.655
282,1.30,14.5,3.73,0.656
282,1.31,14.5,3.73,0.658
283,1.31,14.5,3.74,0.659
283,1.31,14.5,3.75,0.661
284,1.32,14.6,3.76,0.662
284,1.32,14.6,3.77,0.663
285,1.32,14.6,3.78,0.665
285,1.32,14.6,3.79,0.666
286,1.33,14.7,3.79,0.668
286,1.33,14.7,3.80,0.669
287,1.33,14.7,3.81,0.671
287,1.34,14.7,3.82,0.672
288,1.34,14.8,3.82,0.674
288,1.34,14.8,3.83,0.675
289,1.34,14.8,3.84,0.676
289,1.35,14.8,3.85,0.678
290,1.35,14.9,3.86,0.679
290,1.35,14.9,3.87,0.681
291,1.36,14.9,3.87,0.682
291,1.36,14.9,3.89,0.684
291,1.36,14.9,3.89,0.685
292,1.37,15.0,3.90,0.687
292,1.37,15.0,3.91,0.688
292,1.37,15.0,3.92,0.690
292,1.37,15.0,3.93,0.691
292,1.38,15.0,3.93,0.692
292,1.38,15.0,3.94,0.694
292,1.38,15.0,3.95,0.695
292,1.39,15.0,3.96,0.697
292,1.39,14.9,3.97,0.698
291,1.39,14.9,3.97,0.700
291,1.39,14.9,3.98,0.701
290,1.40,14.9,3.99,0.703
289,1.40,14.8,4.00,0.704
288,1.40,14.8,4.01,0.706
287,1.41,14.7,4.02,0.707
286,1.41,14.7,4.02,0.708
285,1.41,14.6,4.03,0.710
284,1.41,14.6,4.04,0.711
283,1.42,14.5,4.05,0.713
282,1.42,14.5,4.06,0.714
281,1.42,14.4,4.07,0.716
280,1.43,14.4,4.07,0.717
279,1.43,14.3,4.08,0.719
278,1.43,14.3,4.09,0.720
278,1.43,14.2,4.10,0.721
278,1.44,14.2,4.11,0.723
277,1.44,14.2,4.11,0.724
277,1.44,14.2,4.12,0.726
277,1.45,14.2,4.13,0.727
277,1.45,14.2,4.14,0.729
277,1.45,14.2,4.15,0.730
277,1.45,14.2,4.16,0.732
277,1.46,14.2,4.17,0.733
278,1.46,14.2,4.17,0.735
278,1.46,14.2,4.18,0.736
278,1.47,14.3,4.19,0.737
278,1.47,14.3,4.20,0.739
279,1.47,14.3,4.21,0.740
279,1.48,14.3,4.22,0.742
280,1.48,14.3,4.22,0.743
280,1.48,14.4,4.23,0.745
281,1.48,14.4,4.24,0.746
281,1.49,14.4,4.25,0.748
281,1.49,14.4,4.26,0.749
282,1.49,14.5,4.27,0.750
282,1.50,14.5,4.27,0.752
283,1.50,14.5,4.28,0.753
283,1.50,14.5,4.29,0.755
284,1.50,14.5,4.30,0.756
284,1.51,14.6,4.31,0.758
284,1.51,14.6,4.31,0.759
285,1.51,14.6,4.32,0.761
285,1.52,14.6,4.33,0.762
286,1.52,14.6,4.34,0.764
286,1.52,14.7,4.35,0.765
286,1.52,14.7,4.36,0.766
286,1.53,14.7,4.36,0.768
287,1.53,14.7,4.37,0.769
287,1.53,14.7,4.38,0.771
287,1.54,14.7,4.39,0.772
287,1.54,14.7,4.40,0.774
287,1.54,14.7,4.41,0.775
288,1.54,14.7,4.41,0.777
288,1.55,14.8,4.42,0.778
288,1.55,14.8,4.43,0.779
288,1.55,14.8,4.44,0.781
288,1.56,14.8,4.45,0.782
288,1.56,14.8,4.46,0.784
289,1.56,14.8,4.46,0.785
289,1.57,14.8,4.47,0.787
289,1.57,14.8,4.48,0.788
289,1.57,14.8,4.49,0.790
289,1.57,14.8,4.50,0.791
289,1.58,14.8,4.51,0.793
289,1.58,14.8,4.51,0.794
289,1.58,14.8,4.52,0.795
290,1.59,14.8,4.53,0.797
290,1.59,14.8,4.54,0.798
290,1.59,14.8,4.55,0.800
290,1.59,14.8,4.55,0.801
290,1.60,14.8,4.56,0.803
290,1.60,14.8,4.57,0.804
290,1.60,14.8,4.58,0.806
290,1.61,14.8,4.59,0.807
290,1.61,14.8,4.60,0.808
289,1.61,14.8,4.61,0.810
289,1.61,14.8,4.61,0.811
289,1.62,14.8,4.62,0.813
289,1.62,14.8,4.63,0.814
289,1.62,14.8,4.64,0.816
289,1.63,14.8,4.65,0.817
288,1.63,14.8,4.65,0.819
288,1.63,14.8,4.66,0.820
288,1.63,14.8,4.67,0.822
288,1.64,14.7,4.68,0.823
288,1.64,14.7,4.69,0.824
287,1.64,14.7,4.70,0.826
287,1.65,14.7,4.70,0.827
287,1.65,14.7,4.71,0.829
287,1.65,14.7,4.72,0.830
288,1.66,14.7,4.73,0.832
288,1.66,14.8,4.74,0.833
288,1.66,14.8,4.75,0.835
288,1.66,14.8,4.75,0.836
289,1.67,14.8,4.76,0.837
289,1.67,14.8,4.77,0.839
290,1.67,14.8,4.78,0.840
290,1.68,14.9,4.79,0.842
291,1.68,14.9,4.79,0.843
291,1.68,14.9,4.80,0.845
292,1.68,15.0,4.81,0.846
292,1.69,15.0,4.82,0.848
293,1.69,15.0,4.83,0.849
293,1.69,15.0,4.84,0.851
294,1.70,15.1,4.85,0.852
294,1.70,15.1,4.85,0.853
295,1.70,15.1,4.86,0.855
295,1.70,15.1,4.87,0.856
296,1.71,15.2,4.88,0.858
296,1.71,15.2,4.89,0.859
297,1.71,15.2,4.90,0.861
297,1.72,15.2,4.90,0.862
298,1.72,15.3,4.91,0.864
298,1.72,15.3,4.92,0.865
299,1.72,15.3,4.93,0.866
299,1.73,15.3,4.94,0.868
299,1.73,15.4,4.94,0.869
300,1.73,15.4,4.95,0.871
300,1.74,15.4,4.96,0.872
300,1.74,15.4,4.97,0.874
301,1.74,15.4,4.98,0.875
301,1.75,15.4,4.99,0.877
301,1.75,15.4,4.99,0.878
301,1.75,15.4,5.00,0.880
301,1.75,15.4,5.01,0.881
301,1.76,15.4,5.02,0.882
301,1.76,15.4,5.03,0.884
300,1.76,15.4,5.03,0.885
300,1.77,15.4,5.04,0.887
300,1.77,15.4,5.05,0.888
299,1.77,15.3,5.06,0.890
298,1.77,15.3,5.07,0.891
298,1.78,15.3,5.08,0.893
297,1.78,15.2,5.09,0.894
296,1.78,15.2,5.09,0.895
295,1.79,15.1,5.10,0.897
294,1.79,15.1,5.11,0.898
293,1.79,15.0,5.12,0.900
292,1.79,15.0,5.12,0.901
291,1.80,14.9,5.13,0.903
290,1.80,14.9,5.14,0.904
290,1.80,14.9,5.15,0.906
289,1.81,14.8,5.16,0.907
289,1.81,14.8,5.17,0.909
289,1.81,14.8,5.18,0.910
288,1.81,14.8,5.18,0.911
288,1.82,14.8,5.19,0.913
288,1.82,14.8,5.20,0.914
288,1.82,14.8,5.21,0.916
288,1.83,14.8,5.22,0.917
288,1.83,14.8,5.23,0.919
288,1.83,14.8,5.23,0.920
288,1.84,14.8,5.24,0.922
288,1.84,14.8,5.25,0.923
288,1.84,14.8,5.26,0.924
288,1.84,14.8,5.27,0.926
288,1.85,14.8,5.28,0.927
288,1.85,14.8,5.28,0.929
288,1.85,14.8,5.29,0.930
288,1.86,14.8,5.30,0.932
288,1.86,14.8,5.31,0.933
288,1.86,14.8,5.32,0.935
288,1.86,14.8,5.33,0.936
288,1.87,14.8,5.33,0.938
288,1.87,14.8,5.34,0.939
288,1.87,14.8,5.35,0.940
287,1.88,14.7,5.36,0.942
287,1.88,14.7,5.37,0.943
286,1.88,14.7,5.37,0.945
284,1.88,14.6,5.38,0.946
283,1.89,14.5,5.39,0.948
280,1.89,14.4,5.40,0.949
278,1.89,14.3,5.41,0.951
275,1.90,14.1,5.42,0.952
273,1.90,14.0,5.42,0.953
271,1.90,13.9,5.43,0.955
269,1.90,13.8,5.44,0.956
267,1.91,13.7,5.45,0.958
267,1.91,13.7,5.46,0.959
266,1.91,13.6,5.47,0.961
266,1.92,13.6,5.47,0.962
266,1.92,13.6,5.48,0.964
266,1.92,13.7,5.49,0.965
267,1.93,13.7,5.50,0.967
267,1.93,13.7,5.51,0.968
268,1.93,13.7,5.52,0.969
268,1.93,13.8,5.53,0.971
269,1.94,13.8,5.53,0.972
270,1.94,13.8,5.54,0.974
270,1.94,13.8,5.55,0.975
271,1.95,13.9,5.56,0.977
271,1.95,13.9,5.57,0.978
272,1.95,13.9,5.57,0.980
273,1.95,14.0,5.58,0.981
273,1.96,14.0,5.59,0.982
274,1.96,14.0,5.60,0.984
274,1.96,14.1,5.61,0.985
275,1.97,14.1,5.61,0.987
276,1.97,14.1,5.62,0.988
276,1.97,14.2,5.63,0.990
277,1.97,14.2,5.64,0.991
277,1.98,14.2,5.65,0.993
277,1.98,14.2,5.66,0.994
277,1.98,14.2,5.67,0.996
278,1.99,14.2,5.67,0.997
278,1.99,14.2,5.68,0.998
278,1.99,14.2,5.69,1.00
278,1.99,14.2,5.70,1.00
278,2.00,14.2,5.71,1.00
278,2.00,14.2,5.71,1.00
278,2.00,14.2,5.72,1.01
278,2.01,14.2,5.73,1.01
278,2.01,14.2,5.74,1.01
278,2.01,14.2,5.75,1.01
278,2.02,14.2,5.76,1.01
278,2.02,14.2,5.76,1.01
278,2.02,14.2,5.77,1.01
278,2.02,14.2,5.78,1.02
278,2.03,14.2,5.79,1.02
277,2.03,14.2,5.80,1.02
277,2.03,14.2,5.81,1.02
277,2.04,14.2,5.82,1.02
277,2.04,14.2,5.82,1.02
276,2.04,14.1,5.83,1.02
275,2.04,14.1,5.84,1.03
274,2.05,14.1,5.85,1.03
273,2.05,14.0,5.86,1.03
272,2.05,14.0,5.87,1.03
271,2.06,13.9,5.87,1.03
269,2.06,13.8,5.88,1.03
267,2.06,13.7,5.89,1.03
264,2.06,13.5,5.90,1.04
261,2.07,13.4,5.91,1.04
258,2.07,13.2,5.91,1.04
255,2.07,13.1,5.92,1.04
253,2.08,13.0,5.93,1.04
252,2.08,12.9,5.94,1.04
251,2.08,12.9,5.95,1.04
251,2.08,12.9,5.95,1.05
251,2.09,12.9,5.97,1.05
252,2.09,12.9,5.97,1.05
252,2.09,12.9,5.98,1.05
253,2.10,13.0,5.99,1.05
254,2.10,13.0,6.00,1.05
254,2.10,13.0,6.00,1.05
255,2.10,13.1,6.01,1.06
256,2.11,13.1,6.02,1.06
257,2.11,13.2,6.03,1.06
257,2.11,13.2,6.04,1.06
258,2.12,13.2,6.05,1.06
259,2.12,13.3,6.05,1.06
260,2.12,13.3,6.06,1.07
261,2.13,13.4,6.07,1.07
262,2.13,13.4,6.08,1.07
262,2.13,13.5,6.09,1.07
263,2.13,13.5,6.10,1.07
264,2.14,13.5,6.10,1.07
265,2.14,13.6,6.11,1.07
266,2.14,13.6,6.12,1.08
266,2.15,13.7,6.13,1.08
267,2.15,13.7,6.14,1.08
268,2.15,13.7,6.15,1.08
269,2.15,13.8,6.15,1.08
269,2.16,13.8,6.16,1.08
270,2.16,13.8,6.17,1.08
271,2.16,13.9,6.18,1.09
271,2.17,13.9,6.19,1.09
272,2.17,13.9,6.20,1.09
272,2.17,14.0,6.20,1.09
273,2.17,14.0,6.21,1.09
273,2.18,14.0,6.22,1.09
273,2.18,14.0,6.23,1.09
274,2.18,14.0,6.24,1.10
274,2.19,14.1,6.25,1.10
275,2.19,14.1,6.25,1.10
275,2.19,14.1,6.26,1.10
275,2.19,14.1,6.27,1.10
275,2.20,14.1,6.28,1.10
275,2.20,14.1,6.29,1.10
275,2.20,14.1,6.29,1.11
276,2.21,14.1,6.30,1.11
276,2.21,14.1,6.31,1.11
276,2.21,14.1,6.32,1.11
276,2.22,14.1,6.33,1.11
276,2.22,14.1,6.34,1.11
275,2.22,14.1,6.34,1.11
276,2.22,14.1,6.35,1.12
276,2.23,14.1,6.36,1.12
275,2.23,14.1,6.37,1.12
276,2.23,14.1,6.38,1.12
276,2.24,14.1,6.39,1.12
276,2.24,14.1,6.39,1.12
276,2.24,14.1,6.40,1.12
276,2.24,14.1,6.41,1.13
276,2.25,14.2,6.42,1.13
276,2.25,14.2,6.43,1.13
276,2.25,14.2,6.44,1.13
276,2.26,14.2,6.44,1.13
276,2.26,14.1,6.45,1.13
276,2.26,14.1,6.46,1.13
276,2.26,14.1,6.47,1.14
275,2.27,14.1,6.48,1.14
275,2.27,14.1,6.49,1.14
275,2.27,14.1,6.49,1.14
274,2.28,14.1,6.50,1.14
274,2.28,14.0,6.51,1.14
273,2.28,14.0,6.52,1.14
273,2.29,14.0,6.53,1.15
272,2.29,13.9,6.54,1.15
271,2.29,13.9,6.54,1.15
271,2.29,13.9,6.55,1.15
271,2.30,13.9,6.56,1.15
271,2.30,13.9,6.57,1.15
271,2.30,13.9,6.58,1.16
271,2.31,13.9,6.59,1.16
271,2.31,13.9,6.59,1.16
271,2.31,13.9,6.60,1.16
272,2.31,13.9,6.61,1.16
272,2.32,13.9,6.62,1.16
272,2.32,14.0,6.63,1.16
273,2.32,14.0,6.63,1.17
273,2.33,14.0,6.64,1.17
273,2.33,14.0,6.65,1.17
274,2.33,14.0,6.66,1.17
274,2.33,14.1,6.67,1.17
275,2.34,14.1,6.68,1.17
275,2.34,14.1,6.68,1.17
275,2.34,14.1,6.69,1.18
275,2.35,14.1,6.70,1.18
276,2.35,14.1,6.71,1.18
276,2.35,14.1,6.72,1.18
276,2.35,14.1,6.73,1.18
276,2.36,14.2,6.73,1.18
276,2.36,14.2,6.74,1.18
276,2.36,14.1,6.75,1.19
276,2.37,14.1,6.76,1.19
276,2.37,14.1,6.77,1.19
275,2.37,14.1,6.78,1.19
275,2.37,14.1,6.78,1.19
274,2.38,14.1,6.79,1.19
273,2.38,14.0,6.80,1.19
273,2.38,14.0,6.81,1.20
272,2.39,13.9,6.82,1.20
271,2.39,13.9,6.83,1.20
270,2.39,13.9,6.83,1.20
270,2.39,13.8,6.84,1.20
269,2.40,13.8,6.85,1.20
269,2.40,13.8,6.86,1.20
269,2.40,13.8,6.87,1.21
269,2.41,13.8,6.88,1.21
269,2.41,13.8,6.88,1.21
270,2.41,13.8,6.89,1.21
270,2.42,13.9,6.90,1.21
271,2.42,13.9,6.91,1.21
272,2.42,13.9,6.92,1.21
273,2.42,14.0,6.93,1.22
273,2.43,14.0,6.93,1.22
274,2.43,14.1,6.94,1.22
275,2.43,14.1,6.95,1.22
276,2.44,14.2,6.96,1.22
277,2.44,14.2,6.97,1.22
278,2.44,14.2,6.98,1.22
279,2.44,14.3,6.98,1.23
280,2.45,14.3,6.99,1.23
281,2.45,14.4,7.00,1.23
282,2.45,14.4,7.01,1.23
283,2.46,14.5,7.02,1.23
283,2.46,14.5,7.02,1.23
284,2.46,14.6,7.03,1.23
285,2.46,14.6,7.04,1.24
286,2.47,14.7,7.05,1.24
287,2.47,14.7,7.06,1.24
288,2.47,14.8,7.07,1.24
289,2.48,14.8,7.07,1.24
290,2.48,14.9,7.08,1.24
291,2.48,14.9,7.09,1.24
292,2.48,15.0,7.10,1.25
293,2.49,15.0,7.11,1.25
294,2.49,15.1,7.11,1.25
294,2.49,15.1,7.12,1.25
296,2.50,15.2,7.13,1.25
296,2.50,15.2,7.14,1.25
298,2.50,15.3,7.15,1.26
298,2.50,15.3,7.16,1.26
300,2.51,15.4,7.16,1.26
301,2.51,15.4,7.17,1.26
302,2.51,15.5,7.18,1.26
303,2.52,15.5,7.19,1.26
304,2.52,15.6,7.20,1.26
305,2.52,15.6,7.21,1.27
306,2.53,15.7,7.21,1.27
307,2.53,15.7,7.22,1.27
308,2.53,15.8,7.23,1.27
308,2.53,15.8,7.24,1.27
309,2.54,15.9,7.25,1.27
310,2.54,15.9,7.26,1.27
311,2.54,16.0,7.27,1.28
312,2.55,16.0,7.27,1.28
313,2.55,16.1,7.28,1.28
314,2.55,16.1,7.29,1.28
315,2.55,16.2,7.30,1.28
316,2.56,16.2,7.31,1.28
317,2.56,16.3,7.31,1.28
318,2.56,16.3,7.32,1.29
319,2.57,16.4,7.33,1.29
321,2.57,16.4,7.34,1.29
322,2.57,16.5,7.35,1.29
323,2.57,16.6,7.36,1.29
324,2.58,16.6,7.36,1.29
325,2.58,16.7,7.37,1.29
326,2.58,16.7,7.38,1.30
328,2.59,16.8,7.39,1.30
329,2.59,16.9,7.40,1.30
330,2.59,16.9,7.41,1.30
331,2.59,17.0,7.41,1.30
332,2.60,17.0,7.42,1.30
333,2.60,17.1,7.43,1.30
335,2.60,17.2,7.44,1.31
336,2.61,17.2,7.45,1.31
337,2.61,17.3,7.45,1.31
339,2.61,17.4,7.46,1.31
340,2.62,17.4,7.47,1.31
341,2.62,17.5,7.48,1.31
342,2.62,17.5,7.49,1.31
343,2.62,17.6,7.50,1.32
344,2.63,17.6,7.51,1.32
345,2.63,17.7,7.51,1.32
346,2.63,17.8,7.52,1.32
347,2.64,17.8,7.53,1.32
348,2.64,17.9,7.54,1.32
349,2.64,17.9,7.55,1.32
350,2.64,18.0,7.55,1.33
351,2.65,18.0,7.56,1.33
352,2.65,18.1,7.57,1.33
353,2.65,18.1,7.58,1.33
355,2.66,18.2,7.59,1.33
356,2.66,18.2,7.60,1.33
357,2.66,18.3,7.61,1.33
358,2.66,18.4,7.61,1.34
359,2.67,18.4,7.62,1.34
360,2.67,18.5,7.63,1.34
361,2.67,18.5,7.64,1.34
363,2.68,18.6,7.65,1.34
364,2.68,18.7,7.65,1.34
365,2.68,18.7,7.66,1.35
366,2.68,18.8,7.67,1.35
368,2.69,18.8,7.68,1.35
369,2.69,18.9,7.69,1.35
370,2.69,19.0,7.70,1.35
371,2.70,19.0,7.70,1.35
373,2.70,19.1,7.71,1.35
374,2.70,19.2,7.72,1.36
375,2.71,19.2,7.73,1.36
376,2.71,19.3,7.74,1.36
377,2.71,19.4,7.75,1.36
379,2.71,19.4,7.75,1.36
380,2.72,19.5,7.76,1.36
381,2.72,19.5,7.77,1.36
382,2.72,19.6,7.78,1.37
383,2.73,19.7,7.79,1.37
385,2.73,19.7,7.80,1.37
386,2.73,19.8,7.80,1.37
387,2.73,19.9,7.81,1.37
388,2.74,19.9,7.82,1.37
389,2.74,20.0,7.83,1.37
391,2.74,20.0,7.84,1.38
392,2.75,20.1,7.85,1.38
393,2.75,20.1,7.85,1.38
394,2.75,20.2,7.86,1.38
395,2.75,20.3,7.87,1.38
396,2.76,20.3,7.88,1.38
398,2.76,20.4,7.89,1.38
399,2.76,20.5,7.89,1.39
400,2.77,20.5,7.90,1.39
401,2.77,20.6,7.91,1.39
402,2.77,20.6,7.92,1.39
403,2.77,20.7,7.93,1.39
405,2.78,20.7,7.94,1.39
406,2.78,20.8,7.95,1.39
407,2.78,20.9,7.95,1.40
408,2.79,20.9,7.96,1.40
409,2.79,21.0,7.97,1.40
410,2.79,21.0,7.98,1.40
411,2.79,21.1,7.99,1.40
412,2.80,21.1,7.99,1.40
413,2.80,21.2,8.00,1.40
414,2.80,21.3,8.01,1.41
415,2.81,21.3,8.02,1.41
416,2.81,21.4,8.03,1.41
418,2.81,21.4,8.03,1.41
419,2.82,21.5,8.04,1.41
420,2.82,21.5,8.05,1.41
421,2.82,21.6,8.06,1.41
422,2.82,21.6,8.07,1.42
423,2.83,21.7,8.08,1.42
424,2.83,21.7,8.08,1.42
425,2.83,21.8,8.09,1.42
426,2.84,21.8,8.10,1.42
427,2.84,21.9,8.11,1.42
428,2.84,21.9,8.12,1.42
429,2.84,22.0,8.13,1.43
430,2.85,22.1,8.13,1.43
431,2.85,22.1,8.14,1.43
432,2.85,22.2,8.15,1.43
433,2.86,22.2,8.16,1.43
434,2.86,22.3,8.17,1.43
435,2.86,22.3,8.18,1.43
436,2.86,22.4,8.18,1.44
437,2.87,22.4,8.19,1.44
438,2.87,22.4,8.20,1.44
439,2.87,22.5,8.21,1.44
440,2.88,22.5,8.22,1.44
441,2.88,22.6,8.23,1.44
442,2.88,22.6,8.23,1.45
442,2.89,22.7,8.24,1.45
443,2.89,22.7,8.25,1.45
444,2.89,22.8,8.26,1.45
445,2.89,22.8,8.27,1.45
446,2.90,22.9,8.27,1.45
447,2.90,22.9,8.28,1.45
448,2.90,23.0,8.29,1.46
449,2.91,23.0,8.30,1.46
450,2.91,23.1,8.31,1.46
450,2.91,23.1,8.32,1.46
451,2.91,23.1,8.33,1.46
452,2.92,23.2,8.33,1.46
453,2.92,23.2,8.34,1.46
454,2.92,23.3,8.35,1.47
454,2.93,23.3,8.36,1.47
455,2.93,23.3,8.37,1.47
456,2.93,23.4,8.37,1.47
457,2.93,23.4,8.38,1.47
457,2.94,23.5,8.39,1.47
458,2.94,23.5,8.40,1.47
459,2.94,23.5,8.41,1.48
460,2.95,23.6,8.42,1.48
460,2.95,23.6,8.42,1.48
461,2.95,23.6,8.43,1.48
462,2.95,23.7,8.44,1.48
463,2.96,23.7,8.45,1.48
463,2.96,23.8,8.46,1.48
464,2.96,23.8,8.47,1.49
465,2.97,23.8,8.47,1.49
465,2.97,23.9,8.48,1.49
466,2.97,23.9,8.49,1.49
466,2.97,23.9,8.50,1.49
467,2.98,23.9,8.51,1.49
468,2.98,24.0,8.52,1.49
468,2.98,24.0,8.52,1.50
469,2.99,24.0,8.53,1.50
469,2.99,24.1,8.54,1.50
470,2.99,24.1,8.55,1.50
470,3.00,24.1,8.56,1.50
471,3.00,24.1,8.57,1.50
472,3.00,24.2,8.57,1.50
472,3.00,24.2,8.58,1.51
472,3.01,24.2,8.59,1.51
473,3.01,24.3,8.60,1.51
474,3.01,24.3,8.61,1.51
474,3.02,24.3,8.62,1.51
474,3.02,24.3,8.62,1.51
475,3.02,24.3,8.63,1.51
475,3.02,24.4,8.64,1.52
476,3.03,24.4,8.65,1.52
476,3.03,24.4,8.66,1.52
477,3.03,24.4,8.67,1.52
477,3.04,24.5,8.67,1.52
477,3.04,24.5,8.68,1.52
478,3.04,24.5,8.69,1.52
478,3.04,24.5,8.70,1.53
478,3.05,24.5,8.71,1.53
479,3.05,24.5,8.71,1.53
479,3.05,24.6,8.72,1.53
479,3.06,24.6,8.73,1.53
479,3.06,24.6,8.74,1.53
480,3.06,24.6,8.75,1.54
480,3.06,24.6,8.76,1.54
480,3.07,24.6,8.77,1.54
480,3.07,24.6,8.77,1.54
481,3.07,24.6,8.78,1.54
481,3.08,24.7,8.79,1.54
481,3.08,24.7,8.80,1.54
481,3.08,24.7,8.81,1.55
481,3.09,24.7,8.81,1.55
481,3.09,24.7,8.82,1.55
481,3.09,24.7,8.83,1.55
482,3.09,24.7,8.84,1.55
482,3.10,24.7,8.85,1.55
482,3.10,24.7,8.86,1.55
482,3.10,24.7,8.86,1.56
482,3.11,24.7,8.87,1.56
482,3.11,24.7,8.88,1.56
482,3.11,24.7,8.89,1.56
482,3.11,24.7,8.90,1.56
482,3.12,24.7,8.91,1.56
482,3.12,24.7,8.91,1.56
481,3.12,24.7,8.92,1.57
481,3.13,24.7,8.93,1.57
481,3.13,24.7,8.94,1.57
481,3.13,24.6,8.95,1.57
480,3.13,24.6,8.96,1.57
480,3.14,24.6,8.96,1.57
479,3.14,24.6,8.97,1.57
479,3.14,24.5,8.98,1.58
478,3.15,24.5,8.99,1.58
477,3.15,24.5,9.00,1.58
475,3.15,24.4,9.01,1.58
473,3.15,24.3,9.01,1.58
470,3.16,24.1,9.02,1.58
465,3.16,23.8,9.03,1.58
458,3.16,23.5,9.04,1.59
443,3.17,22.7,9.05,1.59
288,3.17,14.8,9.06,1.59
53.1,3.17,2.72,9.06,1.59
-10.3,3.18,-0.530,9.07,1.59
-10.3,3.18,-0.530,9.08,1.59
-10.3,3.18,-0.530,9.09,1.59
-10.3,3.18,-0.530,9.10,1.60
-10.3,3.19,-0.530,9.11,1.60
-10.3,3.19,-0.530,9.11,1.60
-10.3,3.19,-0.530,9.12,1.60
-10.4,3.20,-0.534,9.13,1.60
-10.5,3.20,-0.538,9.14,1.60
-10.3,3.20,-0.530,9.15,1.60
-10.5,3.20,-0.536,9.15,1.61
-10.5,3.21,-0.538,9.16,1.61
-10.5,3.21,-0.538,9.17,1.61
-10.5,3.21,-0.538,9.18,1.61
-10.5,3.22,-0.538,9.19,1.61
-10.5,3.22,-0.538,9.20,1.61
-10.5,3.22,-0.538,9.20,1.61
-10.5,3.22,-0.538,9.21,1.62
-10.5,3.23,-0.538,9.22,1.62
-10.5,3.23,-0.538,9.23,1.62
-10.5,3.23,-0.538,9.24,1.62
-10.5,3.24,-0.538,9.24,1.62
-10.5,3.24,-0.538,9.25,1.62
-10.5,3.24,-0.538,9.26,1.62
-10.4,3.24,-0.536,9.27,1.63
-10.5,3.25,-0.538,9.28,1.63
-10.5,3.25,-0.538,9.29,1.63
-10.5,3.25,-0.538,9.29,1.63
-10.5,3.26,-0.538,9.30,1.63
-10.5,3.26,-0.538,9.31,1.63
-10.5,3.26,-0.538,9.32,1.64
-10.5,3.27,-0.538,9.33,1.64
-10.5,3.27,-0.538,9.34,1.64
-10.5,3.27,-0.538,9.34,1.64
-10.5,3.27,-0.538,9.35,1.64
-10.5,3.28,-0.538,9.36,1.64
-10.5,3.28,-0.538,9.37,1.64
-10.5,3.28,-0.538,9.38,1.65
-10.5,3.29,-0.538,9.39,1.65
-10.5,3.29,-0.538,9.39,1.65
-10.5,3.29,-0.538,9.40,1.65
-10.5,3.29,-0.538,9.41,1.65
-10.5,3.30,-0.538,9.42,1.65
-10.5,3.30,-0.538,9.43,1.65
-10.5,3.30,-0.538,9.44,1.66
-10.5,3.31,-0.538,9.44,1.66
-10.5,3.31,-0.538,9.45,1.66
-10.5,3.31,-0.538,9.46,1.66
-10.5,3.31,-0.538,9.47,1.66
-10.5,3.32,-0.538,9.48,1.66
-10.5,3.32,-0.538,9.49,1.66
-10.5,3.32,-0.538,9.49,1.67
-10.5,3.33,-0.538,9.50,1.67
-10.5,3.33,-0.538,9.51,1.67
-10.5,3.33,-0.538,9.52,1.67
-10.5,3.33,-0.538,9.53,1.67
-10.4,3.34,-0.531,9.53,1.67
-10.5,3.34,-0.538,9.54,1.67
-10.5,3.34,-0.538,9.55,1.68
-10.5,3.35,-0.538,9.56,1.68
-10.5,3.35,-0.538,9.57,1.68
-10.3,3.35,-0.530,9.58,1.68
-10.4,3.35,-0.532,9.58,1.68
-10.5,3.36,-0.538,9.59,1.68
-10.5,3.36,-0.538,9.60,1.68
-10.5,3.36,-0.538,9.61,1.69
-10.5,3.37,-0.538,9.62,1.69
-10.5,3.37,-0.538,9.63,1.69
-10.5,3.37,-0.538,9.63,1.69
-10.5,3.38,-0.538,9.64,1.69
-10.5,3.38,-0.538,9.65,1.69
-10.5,3.38,-0.538,9.66,1.69
-10.5,3.38,-0.538,9.67,1.70
-10.5,3.39,-0.538,9.68,1.70
-10.3,3.39,-0.530,9.69,1.70
-10.3,3.39,-0.530,9.69,1.70
-10.5,3.40,-0.538,9.70,1.70
-10.5,3.40,-0.538,9.71,1.70
-10.3,3.40,-0.530,9.72,1.70
-10.5,3.40,-0.538,9.73,1.71
-10.5,3.41,-0.538,9.73,1.71
-10.5,3.41,-0.538,9.74,1.71
-10.3,3.41,-0.530,9.75,1.71
-10.5,3.42,-0.538,9.76,1.71
-10.5,3.42,-0.538,9.77,1.71
-10.5,3.42,-0.538,9.78,1.71
-10.5,3.42,-0.538,9.78,1.72
-10.3,3.43,-0.530,9.79,1.72
-10.3,3.43,-0.530,9.80,1.72
-10.5,3.43,-0.538,9.81,1.72
-10.5,3.44,-0.538,9.82,1.72
-10.5,3.44,-0.538,9.83,1.72
-10.5,3.44,-0.538,9.83,1.72
-10.3,3.45,-0.530,9.84,1.73
-10.5,3.45,-0.538,9.85,1.73
-10.5,3.45,-0.538,9.86,1.73
-10.5,3.45,-0.538,9.87,1.73
-10.5,3.46,-0.538,9.87,1.73
-10.5,3.46,-0.538,9.88,1.73
-10.5,3.46,-0.538,9.89,1.74
-10.5,3.47,-0.538,9.90,1.74
-10.3,3.47,-0.530,9.91,1.74
-10.5,3.47,-0.538,9.92,1.74
-10.5,3.47,-0.538,9.93,1.74
-10.5,3.48,-0.538,9.93,1.74
-10.5,3.48,-0.538,9.94,1.74
-10.5,3.48,-0.538,9.95,1.75
-10.5,3.49,-0.538,9.96,1.75
-10.5,3.49,-0.538,9.97,1.75
-10.5,3.49,-0.538,9.98,1.75
-10.5,3.49,-0.538,9.98,1.75
-10.5,3.50,-0.538,9.99,1.75
-10.5,3.50,-0.538,10.0,1.75
-10.5,3.50,-0.538,10.0,1.76
-10.5,3.51,-0.538,10.0,1.76
-10.5,3.51,-0.538,10.0,1.76
-10.5,3.51,-0.538,10.0,1.76
-10.5,3.51,-0.538,10.0,1.76
-10.4,3.52,-0.535,10.0,1.76
-10.5,3.52,-0.538,10.1,1.76
-10.5,3.52,-0.538,10.1,1.77
-10.5,3.53,-0.538,10.1,1.77
-10.5,3.53,-0.538,10.1,1.77
-10.3,3.53,-0.530,10.1,1.77
-10.3,3.54,-0.531,10.1,1.77
-10.5,3.54,-0.538,10.1,1.77
-10.5,3.54,-0.538,10.1,1.77
-10.5,3.54,-0.537,10.1,1.78
-10.5,3.55,-0.538,10.1,1.78
-10.3,3.55,-0.530,10.1,1.78
-10.5,3.55,-0.538,10.1,1.78
-10.5,3.56,-0.538,10.2,1.78
-10.5,3.56,-0.538,10.2,1.78
-10.4,3.56,-0.532,10.2,1.78
-10.5,3.56,-0.538,10.2,1.79
-10.4,3.57,-0.535,10.2,1.79
-10.5,3.57,-0.538,10.2,1.79
-10.3,3.57,-0.530,10.2,1.79
-10.3,3.58,-0.530,10.2,1.79
-10.4,3.58,-0.535,10.2,1.79
-10.5,3.58,-0.538,10.2,1.79
-10.5,3.58,-0.538,10.2,1.80
-10.5,3.59,-0.538,10.2,1.80
-10.5,3.59,-0.538,10.3,1.80
-10.5,3.59,-0.538,10.3,1.80
-10.3,3.60,-0.530,10.3,1.80
-10.3,3.60,-0.530,10.3,1.80
-10.3,3.60,-0.530,10.3,1.80
-10.3,3.60,-0.530,10.3,1.81
-10.3,3.61,-0.530,10.3,1.81
-10.3,3.61,-0.530,10.3,1.81
-10.3,3.61,-0.530,10.3,1.81
-10.5,3.62,-0.538,10.3,1.81
-10.5,3.62,-0.538,10.3,1.81
-10.5,3.62,-0.538,10.3,1.81
-10.5,3.63,-0.538,10.4,1.82