File: Thermal Chamber for UTM/pla 50%.csv
Force (N),Position (mm),Stress (MPa),Strain (%),Time (min)
0.00,0.00,0.00,0.00,0.00395
0.167,0.0828,0.00265,0.237,0.0459
0.333,0.167,0.00529,0.477,0.0879
0.500,0.251,0.00794,0.717,0.130
0.667,0.335,0.0106,0.956,0.172
0.667,0.419,0.0106,1.20,0.214
0.667,0.503,0.0106,1.44,0.256
0.833,0.586,0.0132,1.67,0.298
0.773,0.671,0.0123,1.92,0.340
0.833,0.755,0.0132,2.16,0.382
1.00,0.838,0.0159,2.40,0.424
1.00,0.922,0.0159,2.63,0.466
1.12,1.01,0.0178,2.88,0.508
1.17,1.09,0.0185,3.11,0.550
1.33,1.17,0.0212,3.35,0.591
1.33,1.26,0.0212,3.59,0.633
1.35,1.34,0.0214,3.83,0.675
1.67,1.43,0.0265,4.07,0.717
1.67,1.51,0.0265,4.31,0.759
1.83,1.59,0.0291,4.55,0.801
1.83,1.68,0.0291,4.79,0.843
1.83,1.76,0.0291,5.03,0.885
2.00,1.85,0.0317,5.27,0.927
2.17,1.93,0.0344,5.51,0.969
2.17,2.01,0.0344,5.75,1.01
2.17,2.10,0.0344,5.99,1.05
2.17,2.18,0.0344,6.23,1.10
2.33,2.27,0.0370,6.47,1.14
2.33,2.35,0.0370,6.71,1.18
2.33,2.43,0.0370,6.95,1.22
2.33,2.52,0.0370,7.19,1.26
2.33,2.60,0.0370,7.43,1.30
2.50,2.69,0.0397,7.67,1.35
2.50,2.77,0.0397,7.91,1.39
2.67,2.85,0.0423,8.15,1.43
2.67,2.94,0.0423,8.39,1.47
2.67,3.02,0.0423,8.63,1.51
2.83,3.10,0.0450,8.87,1.56
2.83,3.19,0.0450,9.11,1.60
2.83,3.27,0.0450,9.35,1.64
3.00,3.36,0.0476,9.59,1.68
3.00,3.44,0.0476,9.83,1.72
3.00,3.52,0.0476,10.1,1.77
3.00,3.61,0.0476,10.3,1.81
3.00,3.69,0.0476,10.5,1.85
3.00,3.78,0.0476,10.8,1.89
3.00,3.86,0.0476,11.0,1.93
3.00,3.94,0.0476,11.3,1.98
3.00,4.03,0.0476,11.5,2.02
3.17,4.11,0.0503,11.7,2.06
3.17,4.20,0.0503,12.0,2.10
3.28,4.28,0.0521,12.2,2.14
3.33,4.36,0.0529,12.5,2.19
3.33,4.45,0.0529,12.7,2.23
3.33,4.53,0.0529,12.9,2.27
3.33,4.62,0.0529,13.2,2.31
3.44,4.70,0.0546,13.4,2.35
3.50,4.78,0.0556,13.7,2.40
3.50,4.87,0.0556,13.9,2.44
3.50,4.95,0.0556,14.1,2.48
3.67,5.04,0.0582,14.4,2.52
3.67,5.12,0.0582,14.6,2.56
3.67,5.20,0.0582,14.9,2.61
3.83,5.29,0.0608,15.1,2.65
3.67,5.37,0.0582,15.3,2.69
3.83,5.46,0.0608,15.6,2.73
3.83,5.54,0.0608,15.8,2.77
3.83,5.62,0.0608,16.1,2.82
3.83,5.71,0.0608,16.3,2.86
3.83,5.79,0.0608,16.5,2.90
3.83,5.87,0.0608,16.8,2.94
4.00,5.96,0.0635,17.0,2.98
4.00,6.04,0.0635,17.3,3.03
4.00,6.13,0.0635,17.5,3.07
4.00,6.21,0.0635,17.7,3.11
4.00,6.29,0.0635,18.0,3.15
4.00,6.38,0.0635,18.2,3.19
4.17,6.46,0.0661,18.5,3.24
4.33,6.55,0.0688,18.7,3.28
4.33,6.63,0.0688,18.9,3.32
4.50,6.71,0.0714,19.2,3.36
4.67,6.80,0.0741,19.4,3.40
4.67,6.88,0.0741,19.7,3.45
4.83,6.97,0.0767,19.9,3.49
5.00,7.05,0.0794,20.1,3.53
5.17,7.13,0.0820,20.4,3.57
5.17,7.22,0.0820,20.6,3.61
5.33,7.30,0.0847,20.9,3.66
5.33,7.39,0.0847,21.1,3.70
5.50,7.47,0.0873,21.3,3.74
5.50,7.55,0.0873,21.6,3.78
5.67,7.64,0.0899,21.8,3.82
5.67,7.72,0.0899,22.1,3.86
5.83,7.80,0.0926,22.3,3.91
6.00,7.89,0.0952,22.5,3.95
6.00,7.97,0.0952,22.8,3.99
6.17,8.06,0.0979,23.0,4.03
6.33,8.14,0.101,23.3,4.07
6.50,8.22,0.103,23.5,4.12
6.50,8.31,0.103,23.7,4.16
6.67,8.39,0.106,24.0,4.20
6.67,8.48,0.106,24.2,4.24
6.83,8.56,0.108,24.5,4.28
7.00,8.64,0.111,24.7,4.33
7.17,8.73,0.114,24.9,4.37
7.33,8.81,0.116,25.2,4.41
7.67,8.90,0.122,25.4,4.45
7.83,8.98,0.124,25.7,4.49
8.17,9.06,0.130,25.9,4.54
8.33,9.15,0.132,26.1,4.58
8.67,9.23,0.138,26.4,4.62
9.00,9.32,0.143,26.6,4.66
9.17,9.40,0.146,26.9,4.70
9.50,9.48,0.151,27.1,4.75
9.83,9.57,0.156,27.3,4.79
10.2,9.65,0.161,27.6,4.83
10.5,9.74,0.167,27.8,4.87
10.8,9.82,0.172,28.1,4.91
11.3,9.90,0.180,28.3,4.96
11.7,9.99,0.185,28.5,5.00
12.0,10.1,0.191,28.8,5.04
12.5,10.2,0.198,29.0,5.08
13.0,10.2,0.206,29.3,5.12
13.7,10.3,0.217,29.5,5.17
14.0,10.4,0.222,29.7,5.21
14.7,10.5,0.233,30.0,5.25
15.0,10.6,0.239,30.2,5.29
15.8,10.7,0.251,30.5,5.33
16.8,10.7,0.267,30.7,5.38
17.7,10.8,0.280,30.9,5.42
18.5,10.9,0.294,31.2,5.46
19.2,11.0,0.304,31.4,5.50
20.0,11.1,0.317,31.7,5.54
20.8,11.2,0.331,31.9,5.59
21.7,11.2,0.344,32.1,5.63
22.7,11.3,0.360,32.4,5.67
23.7,11.4,0.376,32.6,5.71
24.8,11.5,0.394,32.9,5.75
26.0,11.6,0.413,33.1,5.80
27.2,11.7,0.431,33.3,5.84
28.2,11.7,0.447,33.6,5.88
29.3,11.8,0.466,33.8,5.92
30.5,11.9,0.484,34.1,5.96
31.7,12.0,0.503,34.3,6.01
33.2,12.1,0.526,34.5,6.05
34.3,12.2,0.545,34.8,6.09
35.9,12.3,0.570,35.0,6.13
37.3,12.3,0.593,35.2,6.17
39.2,12.4,0.622,35.5,6.22
41.0,12.5,0.651,35.7,6.26
42.7,12.6,0.677,36.0,6.30
44.5,12.7,0.707,36.2,6.34
46.7,12.8,0.741,36.4,6.38
48.7,12.8,0.772,36.7,6.42
50.7,12.9,0.804,36.9,6.47
52.5,13.0,0.833,37.2,6.51
54.4,13.1,0.864,37.4,6.55
56.3,13.2,0.894,37.6,6.59
58.5,13.3,0.929,37.9,6.63
60.6,13.3,0.962,38.1,6.68
62.8,13.4,0.997,38.4,6.72
64.8,13.5,1.03,38.6,6.76
67.2,13.6,1.07,38.8,6.80
69.3,13.7,1.10,39.1,6.84
71.7,13.8,1.14,39.3,6.89
73.7,13.8,1.17,39.6,6.93
75.8,13.9,1.20,39.8,6.97
77.8,14.0,1.24,40.0,7.01
79.8,14.1,1.27,40.3,7.05
82.2,14.2,1.30,40.5,7.10
84.5,14.3,1.34,40.8,7.14
87.0,14.4,1.38,41.0,7.18
89.7,14.4,1.42,41.2,7.22
92.2,14.5,1.46,41.5,7.26
94.3,14.6,1.50,41.7,7.31
96.5,14.7,1.53,42.0,7.35
98.5,14.8,1.56,42.2,7.39
101,14.9,1.60,42.4,7.43
103,14.9,1.64,42.7,7.47
106,15.0,1.68,42.9,7.52
108,15.1,1.71,43.2,7.56
111,15.2,1.75,43.4,7.60
113,15.3,1.80,43.6,7.64
116,15.4,1.84,43.9,7.68
118,15.4,1.87,44.1,7.73
120,15.5,1.90,44.4,7.77
122,15.6,1.93,44.6,7.81
124,15.7,1.96,44.8,7.85
125,15.8,1.99,45.1,7.89
127,15.9,2.01,45.3,7.94
128,15.9,2.04,45.6,7.98
129,16.0,2.05,45.8,8.02
130,16.1,2.07,46.0,8.06
131,16.2,2.09,46.3,8.10
132,16.3,2.10,46.5,8.15
133,16.4,2.11,46.8,8.19
134,16.5,2.13,47.0,8.23
136,16.5,2.15,47.2,8.27
137,16.6,2.17,47.5,8.31
138,16.7,2.18,47.7,8.36
139,16.8,2.20,48.0,8.40
140,16.9,2.21,48.2,8.44
140,17.0,2.23,48.4,8.48
141,17.0,2.24,48.7,8.52
141,17.1,2.24,48.9,8.57
141,17.2,2.24,49.2,8.61
141,17.3,2.25,49.4,8.65
141,17.4,2.24,49.6,8.69
141,17.5,2.24,49.9,8.73
140,17.5,2.23,50.1,8.78
139,17.6,2.21,50.4,8.82
138,17.7,2.19,50.6,8.86
137,17.8,2.17,50.8,8.90
135,17.9,2.15,51.1,8.94
133,18.0,2.11,51.3,8.98
131,18.0,2.08,51.6,9.03
129,18.1,2.05,51.8,9.07
127,18.2,2.02,52.0,9.11
125,18.3,1.99,52.3,9.15
124,18.4,1.96,52.5,9.19
122,18.5,1.93,52.8,9.24
119,18.5,1.89,53.0,9.28
116,18.6,1.84,53.2,9.32
114,18.7,1.80,53.5,9.36
111,18.8,1.77,53.7,9.40
109,18.9,1.73,54.0,9.45
106,19.0,1.69,54.2,9.49
104,19.1,1.65,54.4,9.53
101,19.1,1.60,54.7,9.57
98.2,19.2,1.56,54.9,9.61
95.3,19.3,1.51,55.2,9.66
92.3,19.4,1.47,55.4,9.70
89.5,19.5,1.42,55.6,9.74
86.5,19.6,1.37,55.9,9.78
84.0,19.6,1.33,56.1,9.82
81.3,19.7,1.29,56.4,9.87
79.1,19.8,1.26,56.6,9.91
76.8,19.9,1.22,56.8,9.95
74.3,20.0,1.18,57.1,9.99
71.8,20.1,1.14,57.3,10.0
69.2,20.1,1.10,57.6,10.1
66.3,20.2,1.05,57.8,10.1
63.7,20.3,1.01,58.0,10.2
61.2,20.4,0.971,58.3,10.2
59.2,20.5,0.939,58.5,10.2
57.0,20.6,0.905,58.8,10.3
54.8,20.6,0.870,59.0,10.3
53.0,20.7,0.841,59.2,10.4
51.3,20.8,0.815,59.5,10.4
49.5,20.9,0.786,59.7,10.5
47.8,21.0,0.759,59.9,10.5
46.2,21.1,0.733,60.2,10.5
44.2,21.2,0.701,60.4,10.6
42.2,21.2,0.669,60.7,10.6
40.5,21.3,0.643,60.9,10.7
38.7,21.4,0.614,61.1,10.7
37.2,21.5,0.590,61.4,10.7
35.7,21.6,0.566,61.6,10.8
34.2,21.7,0.542,61.9,10.8
32.7,21.7,0.519,62.1,10.9
31.5,21.8,0.500,62.3,10.9
30.3,21.9,0.481,62.6,11.0
29.2,22.0,0.463,62.8,11.0
28.5,22.1,0.452,63.1,11.0
27.7,22.2,0.439,63.3,11.1
27.0,22.2,0.429,63.5,11.1
26.3,22.3,0.418,63.8,11.2
25.7,22.4,0.407,64.0,11.2
25.0,22.5,0.397,64.3,11.3
24.5,22.6,0.389,64.5,11.3
23.8,22.7,0.378,64.7,11.3
23.3,22.7,0.370,65.0,11.4
22.8,22.8,0.362,65.2,11.4
22.3,22.9,0.354,65.5,11.5
21.8,23.0,0.347,65.7,11.5
21.3,23.1,0.339,65.9,11.5
21.2,23.2,0.336,66.2,11.6
20.8,23.2,0.331,66.4,11.6
20.7,23.3,0.328,66.7,11.7
20.3,23.4,0.323,66.9,11.7
20.0,23.5,0.317,67.1,11.8
19.8,23.6,0.315,67.4,11.8
19.5,23.7,0.310,67.6,11.8
19.2,23.8,0.304,67.9,11.9
18.9,23.8,0.301,68.1,11.9
18.7,23.9,0.296,68.3,12.0
18.3,24.0,0.291,68.6,12.0
18.2,24.1,0.288,68.8,12.0
17.8,24.2,0.283,69.1,12.1
17.5,24.3,0.278,69.3,12.1
17.3,24.3,0.275,69.5,12.2
17.2,24.4,0.272,69.8,12.2
17.0,24.5,0.270,70.0,12.3
16.7,24.6,0.265,70.3,12.3
16.7,24.7,0.265,70.5,12.3
16.5,24.8,0.262,70.7,12.4
16.3,24.8,0.259,71.0,12.4
16.3,24.9,0.259,71.2,12.5
16.2,25.0,0.257,71.5,12.5
16.0,25.1,0.254,71.7,12.6
15.8,25.2,0.251,71.9,12.6
15.8,25.3,0.251,72.2,12.6
15.7,25.3,0.249,72.4,12.7
15.5,25.4,0.246,72.7,12.7
15.3,25.5,0.243,72.9,12.8
15.2,25.6,0.241,73.1,12.8
15.0,25.7,0.238,73.4,12.8
15.0,25.8,0.238,73.6,12.9
14.8,25.9,0.235,73.9,12.9
14.7,25.9,0.233,74.1,13.0
14.7,26.0,0.233,74.3,13.0
14.5,26.1,0.230,74.6,13.1
14.2,26.2,0.225,74.8,13.1
14.2,26.3,0.225,75.1,13.1
14.2,26.4,0.225,75.3,13.2
14.0,26.4,0.222,75.5,13.2
13.8,26.5,0.220,75.8,13.3
13.7,26.6,0.217,76.0,13.3
13.5,26.7,0.214,76.3,13.3
13.2,26.8,0.209,76.5,13.4
13.2,26.9,0.209,76.7,13.4
13.0,26.9,0.206,77.0,13.5
12.8,27.0,0.204,77.2,13.5
12.7,27.1,0.201,77.5,13.6
12.5,27.2,0.199,77.7,13.6
12.5,27.3,0.198,77.9,13.6
12.3,27.4,0.196,78.2,13.7
12.3,27.4,0.196,78.4,13.7
12.2,27.5,0.193,78.7,13.8
12.2,27.6,0.193,78.9,13.8
12.0,27.7,0.190,79.1,13.9
12.0,27.8,0.190,79.4,13.9
12.0,27.9,0.190,79.6,13.9
11.8,27.9,0.188,79.9,14.0
11.7,28.0,0.185,80.1,14.0
11.7,28.1,0.185,80.3,14.1
11.5,28.2,0.183,80.6,14.1
11.5,28.3,0.183,80.8,14.1
11.3,28.4,0.180,81.1,14.2
11.2,28.5,0.177,81.3,14.2
11.2,28.5,0.177,81.5,14.3
11.2,28.6,0.177,81.8,14.3
11.0,28.7,0.175,82.0,14.4
11.0,28.8,0.175,82.3,14.4
11.0,28.9,0.175,82.5,14.4
10.8,29.0,0.172,82.7,14.5
10.8,29.0,0.172,83.0,14.5
10.7,29.1,0.169,83.2,14.6
10.7,29.2,0.169,83.5,14.6
10.7,29.3,0.169,83.7,14.7
10.7,29.4,0.169,83.9,14.7
10.5,29.5,0.167,84.2,14.7
10.7,29.5,0.169,84.4,14.8
10.5,29.6,0.167,84.7,14.8
10.3,29.7,0.164,84.9,14.9
10.5,29.8,0.167,85.1,14.9
10.3,29.9,0.164,85.4,14.9
10.3,30.0,0.164,85.6,15.0
10.2,30.0,0.161,85.8,15.0
10.2,30.1,0.161,86.1,15.1
10.2,30.2,0.161,86.3,15.1
10.2,30.3,0.161,86.6,15.2
10.2,30.4,0.161,86.8,15.2
10.2,30.5,0.161,87.0,15.2
10.2,30.6,0.161,87.3,15.3
10.2,30.6,0.161,87.5,15.3
10.3,30.7,0.164,87.8,15.4
10.3,30.8,0.164,88.0,15.4
10.3,30.9,0.164,88.2,15.4
10.3,31.0,0.164,88.5,15.5
10.3,31.1,0.164,88.7,15.5
10.5,31.1,0.167,89.0,15.6
10.5,31.2,0.167,89.2,15.6
10.7,31.3,0.169,89.4,15.7
10.7,31.4,0.169,89.7,15.7
10.8,31.5,0.172,89.9,15.7
10.8,31.6,0.172,90.2,15.8
11.0,31.6,0.175,90.4,15.8
11.2,31.7,0.177,90.6,15.9
11.2,31.8,0.177,90.9,15.9
11.3,31.9,0.180,91.1,16.0
11.5,32.0,0.183,91.4,16.0
11.7,32.1,0.185,91.6,16.0
11.8,32.1,0.188,91.8,16.1
12.0,32.2,0.190,92.1,16.1
12.2,32.3,0.193,92.3,16.2
12.3,32.4,0.196,92.6,16.2
12.5,32.5,0.198,92.8,16.2
12.8,32.6,0.204,93.0,16.3
13.0,32.6,0.206,93.3,16.3
13.4,32.7,0.212,93.5,16.4
13.7,32.8,0.217,93.8,16.4
14.0,32.9,0.222,94.0,16.5
14.5,33.0,0.230,94.2,16.5
14.8,33.1,0.235,94.5,16.5
15.2,33.2,0.241,94.7,16.6
15.5,33.2,0.246,95.0,16.6
15.8,33.3,0.251,95.2,16.7
16.5,33.4,0.262,95.4,16.7
16.8,33.5,0.267,95.7,16.7
17.5,33.6,0.278,95.9,16.8
18.0,33.7,0.286,96.2,16.8
18.7,33.7,0.296,96.4,16.9
19.3,33.8,0.307,96.6,16.9
20.0,33.9,0.317,96.9,17.0
20.8,34.0,0.331,97.1,17.0
21.5,34.1,0.341,97.4,17.0
22.3,34.2,0.354,97.6,17.1
23.0,34.2,0.365,97.8,17.1
23.8,34.3,0.378,98.1,17.2
25.0,34.4,0.397,98.3,17.2
25.7,34.5,0.407,98.6,17.3
26.8,34.6,0.426,98.8,17.3
28.2,34.7,0.447,99.0,17.3
29.2,34.7,0.463,99.3,17.4
30.5,34.8,0.484,99.5,17.4
31.8,34.9,0.505,99.8,17.5
33.2,35.0,0.526,100,17.5
34.3,35.1,0.545,100,17.5
35.8,35.2,0.569,100,17.6
37.2,35.3,0.590,101,17.6
39.0,35.3,0.619,101,17.7
40.8,35.4,0.648,101,17.7
42.5,35.5,0.675,101,17.8
44.5,35.6,0.706,102,17.8
46.5,35.7,0.738,102,17.8
48.3,35.8,0.767,102,17.9
50.0,35.8,0.794,102,17.9
51.8,35.9,0.823,103,18.0
53.8,36.0,0.854,103,18.0
55.6,36.1,0.883,103,18.0
57.7,36.2,0.915,103,18.1
59.8,36.3,0.950,104,18.1
62.0,36.3,0.984,104,18.2
64.2,36.4,1.02,104,18.2
66.5,36.5,1.06,104,18.3
69.0,36.6,1.10,105,18.3
71.5,36.7,1.13,105,18.3
73.8,36.8,1.17,105,18.4
76.5,36.8,1.21,105,18.4
79.7,36.9,1.26,106,18.5
82.7,37.0,1.31,106,18.5
85.8,37.1,1.36,106,18.6
89.0,37.2,1.41,106,18.6
91.8,37.3,1.46,106,18.6
94.7,37.3,1.50,107,18.7
97.3,37.4,1.54,107,18.7
99.7,37.5,1.58,107,18.8
102,37.6,1.62,107,18.8
104,37.7,1.65,108,18.8
106,37.8,1.67,108,18.9
107,37.9,1.70,108,18.9
109,37.9,1.72,108,19.0
110,38.0,1.75,109,19.0
112,38.1,1.78,109,19.1
113,38.2,1.80,109,19.1
115,38.3,1.82,109,19.1
116,38.4,1.84,110,19.2
117,38.4,1.85,110,19.2
118,38.5,1.87,110,19.3
119,38.6,1.89,110,19.3
120,38.7,1.91,111,19.4
122,38.8,1.93,111,19.4
123,38.9,1.95,111,19.4
124,38.9,1.97,111,19.5
125,39.0,1.98,112,19.5
125,39.1,1.98,112,19.6
125,39.2,1.99,112,19.6
126,39.3,1.99,112,19.6
125,39.4,1.99,112,19.7
125,39.4,1.99,113,19.7
125,39.5,1.98,113,19.8
124,39.6,1.97,113,19.8
123,39.7,1.96,113,19.9
122,39.8,1.94,114,19.9
121,39.9,1.92,114,19.9
120,40.0,1.90,114,20.0
119,40.0,1.89,114,20.0
118,40.1,1.87,115,20.1
116,40.2,1.84,115,20.1
114,40.3,1.81,115,20.1
113,40.4,1.79,115,20.2
111,40.5,1.76,116,20.2
109,40.5,1.74,116,20.3
108,40.6,1.71,116,20.3
106,40.7,1.68,116,20.4
104,40.8,1.65,117,20.4
102,40.9,1.62,117,20.4
100,41.0,1.59,117,20.5
97.5,41.0,1.55,117,20.5
95.2,41.1,1.51,118,20.6
93.0,41.2,1.48,118,20.6
90.7,41.3,1.44,118,20.7
88.2,41.4,1.40,118,20.7
85.7,41.5,1.36,118,20.7
83.3,41.5,1.32,119,20.8
80.7,41.6,1.28,119,20.8
77.7,41.7,1.23,119,20.9
74.8,41.8,1.19,119,20.9
72.0,41.9,1.14,120,20.9
69.5,42.0,1.10,120,21.0
67.7,42.0,1.07,120,21.0
65.8,42.1,1.04,120,21.1
64.0,42.2,1.02,121,21.1
62.3,42.3,0.989,121,21.2
60.7,42.4,0.963,121,21.2
59.2,42.5,0.939,121,21.2
57.8,42.6,0.918,122,21.3
56.5,42.6,0.897,122,21.3
55.2,42.7,0.876,122,21.4
53.8,42.8,0.854,122,21.4
52.8,42.9,0.839,123,21.4
52.0,43.0,0.825,123,21.5
51.2,43.1,0.812,123,21.5
50.3,43.1,0.799,123,21.6
49.5,43.2,0.786,123,21.6
48.5,43.3,0.770,124,21.7
47.5,43.4,0.754,124,21.7
46.2,43.5,0.733,124,21.7
44.8,43.6,0.712,124,21.8
43.5,43.6,0.690,125,21.8
42.5,43.7,0.674,125,21.9
41.5,43.8,0.659,125,21.9
40.3,43.9,0.640,125,22.0
39.5,44.0,0.627,126,22.0
38.7,44.1,0.614,126,22.0
37.7,44.1,0.598,126,22.1
36.8,44.2,0.585,126,22.1
36.2,44.3,0.574,127,22.2
35.5,44.4,0.563,127,22.2
34.8,44.5,0.553,127,22.2
34.2,44.6,0.542,127,22.3
33.7,44.7,0.534,128,22.3
33.3,44.7,0.529,128,22.4
33.0,44.8,0.524,128,22.4
32.5,44.9,0.516,128,22.5
32.1,45.0,0.509,129,22.5
31.5,45.1,0.500,129,22.5
31.2,45.2,0.495,129,22.6
30.7,45.2,0.487,129,22.6
30.3,45.3,0.481,129,22.7
29.7,45.4,0.471,130,22.7
29.3,45.5,0.466,130,22.7
29.0,45.6,0.460,130,22.8
28.7,45.7,0.455,130,22.8
28.3,45.7,0.450,131,22.9
28.0,45.8,0.444,131,22.9
27.7,45.9,0.439,131,23.0
27.3,46.0,0.434,131,23.0
27.0,46.1,0.429,132,23.0
26.8,46.2,0.426,132,23.1
26.5,46.2,0.421,132,23.1
26.3,46.3,0.418,132,23.2
26.2,46.4,0.415,133,23.2
25.8,46.5,0.410,133,23.3
25.7,46.6,0.407,133,23.3
25.2,46.7,0.399,133,23.3
25.0,46.8,0.397,134,23.4
24.8,46.8,0.393,134,23.4
24.2,46.9,0.384,134,23.5
24.0,47.0,0.381,134,23.5
23.8,47.1,0.378,135,23.5
23.5,47.2,0.373,135,23.6
23.3,47.3,0.370,135,23.6
23.2,47.3,0.368,135,23.7
22.9,47.4,0.363,135,23.7
22.7,47.5,0.360,136,23.8
22.5,47.6,0.357,136,23.8
22.3,47.7,0.354,136,23.8
22.2,47.8,0.352,136,23.9
22.0,47.8,0.349,137,23.9
21.8,47.9,0.347,137,24.0
21.7,48.0,0.344,137,24.0
21.5,48.1,0.341,137,24.1
21.3,48.2,0.339,138,24.1
21.3,48.3,0.339,138,24.1
21.3,48.3,0.339,138,24.2
21.3,48.4,0.338,138,24.2
21.3,48.5,0.339,139,24.3
21.3,48.6,0.339,139,24.3
21.5,48.7,0.341,139,24.3
21.5,48.8,0.341,139,24.4
21.7,48.8,0.344,140,24.4
21.8,48.9,0.347,140,24.5
22.0,49.0,0.349,140,24.5
22.2,49.1,0.352,140,24.6
22.3,49.2,0.355,141,24.6
22.5,49.3,0.357,141,24.6
22.8,49.4,0.362,141,24.7
23.2,49.4,0.368,141,24.7
23.7,49.5,0.376,141,24.8
24.0,49.6,0.381,142,24.8
24.5,49.7,0.389,142,24.8
25.0,49.8,0.397,142,24.9
25.5,49.9,0.405,142,24.9
26.0,49.9,0.413,143,25.0
26.7,50.0,0.423,143,25.0
27.2,50.1,0.431,143,25.1
27.8,50.2,0.442,143,25.1
28.7,50.3,0.455,144,25.1
29.3,50.4,0.466,144,25.2
30.2,50.4,0.479,144,25.2
31.0,50.5,0.492,144,25.3
32.0,50.6,0.508,145,25.3
33.0,50.7,0.524,145,25.4
34.0,50.8,0.540,145,25.4
35.2,50.9,0.558,145,25.4
36.3,50.9,0.577,146,25.5
37.5,51.0,0.595,146,25.5
38.5,51.1,0.611,146,25.6
39.8,51.2,0.632,146,25.6
41.2,51.3,0.654,147,25.6
42.7,51.4,0.677,147,25.7
44.5,51.5,0.706,147,25.7
46.5,51.5,0.738,147,25.8
48.2,51.6,0.765,147,25.8
49.9,51.7,0.792,148,25.9
51.8,51.8,0.823,148,25.9
53.7,51.9,0.852,148,25.9
55.3,52.0,0.878,148,26.0
57.5,52.0,0.913,149,26.0
59.2,52.1,0.939,149,26.1
61.0,52.2,0.968,149,26.1
63.0,52.3,1.00,149,26.1
64.8,52.4,1.03,150,26.2
66.8,52.5,1.06,150,26.2
68.8,52.5,1.09,150,26.3
70.8,52.6,1.12,150,26.3
72.9,52.7,1.16,151,26.4
75.1,52.8,1.19,151,26.4
76.8,52.9,1.22,151,26.4
78.8,53.0,1.25,151,26.5
80.8,53.0,1.28,152,26.5
82.8,53.1,1.31,152,26.6
84.7,53.2,1.34,152,26.6
86.7,53.3,1.38,152,26.7
88.7,53.4,1.41,153,26.7
90.7,53.5,1.44,153,26.7
92.7,53.5,1.47,153,26.8
94.8,53.6,1.51,153,26.8
96.8,53.7,1.54,153,26.9
98.8,53.8,1.57,154,26.9
101,53.9,1.60,154,26.9
103,54.0,1.63,154,27.0
104,54.1,1.65,154,27.0
105,54.1,1.67,155,27.1
106,54.2,1.69,155,27.1
108,54.3,1.71,155,27.2
109,54.4,1.73,155,27.2
110,54.5,1.75,156,27.2
111,54.6,1.76,156,27.3
112,54.6,1.79,156,27.3
114,54.7,1.80,156,27.4
115,54.8,1.82,157,27.4
116,54.9,1.84,157,27.5
117,55.0,1.86,157,27.5
118,55.1,1.88,157,27.5
119,55.1,1.89,158,27.6
120,55.2,1.91,158,27.6
121,55.3,1.93,158,27.7
122,55.4,1.94,158,27.7
123,55.5,1.96,159,27.7
124,55.6,1.97,159,27.8
125,55.6,1.98,159,27.8
125,55.7,1.99,159,27.9
126,55.8,1.99,159,27.9
126,55.9,1.99,160,28.0
125,56.0,1.99,160,28.0
125,56.1,1.98,160,28.0
124,56.2,1.97,160,28.1
123,56.2,1.95,161,28.1
122,56.3,1.93,161,28.2
121,56.4,1.92,161,28.2
119,56.5,1.89,161,28.2
118,56.6,1.87,162,28.3
116,56.7,1.85,162,28.3
115,56.7,1.82,162,28.4
113,56.8,1.79,162,28.4
111,56.9,1.76,163,28.5
109,57.0,1.73,163,28.5
107,57.1,1.70,163,28.5
105,57.2,1.67,163,28.6
103,57.2,1.64,164,28.6
101,57.3,1.61,164,28.7
99.5,57.4,1.58,164,28.7
97.5,57.5,1.55,164,28.8
95.7,57.6,1.52,165,28.8
93.8,57.7,1.49,165,28.8
92.0,57.7,1.46,165,28.9
90.0,57.8,1.43,165,28.9
87.8,57.9,1.39,165,29.0
85.7,58.0,1.36,166,29.0
83.7,58.1,1.33,166,29.0
81.3,58.2,1.29,166,29.1
79.2,58.2,1.26,166,29.1
77.0,58.3,1.22,167,29.2
75.1,58.4,1.19,167,29.2
73.2,58.5,1.16,167,29.3
71.3,58.6,1.13,167,29.3
69.5,58.7,1.10,168,29.3
67.7,58.8,1.07,168,29.4
65.7,58.8,1.04,168,29.4
63.8,58.9,1.01,168,29.5
62.3,59.0,0.989,169,29.5
60.8,59.1,0.966,169,29.5
59.5,59.2,0.944,169,29.6
57.8,59.3,0.918,169,29.6
56.5,59.3,0.897,170,29.7
55.2,59.4,0.876,170,29.7
53.8,59.5,0.854,170,29.8
52.7,59.6,0.836,170,29.8
51.7,59.7,0.820,171,29.8
50.5,59.8,0.802,171,29.9
49.3,59.8,0.783,171,29.9
48.3,59.9,0.767,171,30.0
47.2,60.0,0.749,171,30.0
46.3,60.1,0.735,172,30.1
45.3,60.2,0.720,172,30.1
44.7,60.3,0.709,172,30.1
44.0,60.3,0.698,172,30.2
43.2,60.4,0.685,173,30.2
42.5,60.5,0.675,173,30.3
41.8,60.6,0.664,173,30.3
41.3,60.7,0.656,173,30.3
40.8,60.8,0.648,174,30.4
40.3,60.9,0.640,174,30.4
39.8,60.9,0.632,174,30.5
39.3,61.0,0.624,174,30.5
39.0,61.1,0.619,175,30.6
38.7,61.2,0.614,175,30.6
38.4,61.3,0.610,175,30.6
38.1,61.4,0.605,175,30.7
37.7,61.4,0.598,176,30.7
37.5,61.5,0.595,176,30.8
37.3,61.6,0.593,176,30.8
36.8,61.7,0.585,176,30.8
36.7,61.8,0.582,176,30.9
36.3,61.9,0.577,177,30.9
35.8,61.9,0.569,177,31.0
35.7,62.0,0.566,177,31.0
35.3,62.1,0.561,177,31.1
35.2,62.2,0.558,178,31.1
34.8,62.3,0.553,178,31.1
34.5,62.4,0.548,178,31.2
34.0,62.4,0.540,178,31.2
33.7,62.5,0.534,179,31.3
33.2,62.6,0.526,179,31.3
33.0,62.7,0.524,179,31.4
32.7,62.8,0.519,179,31.4
32.3,62.9,0.513,180,31.4
32.2,62.9,0.511,180,31.5
31.8,63.0,0.505,180,31.5
31.5,63.1,0.500,180,31.6
31.2,63.2,0.495,181,31.6
31.0,63.3,0.492,181,31.6
30.7,63.4,0.487,181,31.7
30.5,63.5,0.484,181,31.7
30.3,63.5,0.481,182,31.8
30.2,63.6,0.479,182,31.8
30.0,63.7,0.476,182,31.9
29.8,63.8,0.474,182,31.9
29.7,63.9,0.471,182,31.9
29.6,64.0,0.469,183,32.0
29.5,64.0,0.468,183,32.0
29.7,64.1,0.471,183,32.1
29.7,64.2,0.471,183,32.1
29.8,64.3,0.474,184,32.2
29.8,64.4,0.474,184,32.2
30.2,64.5,0.479,184,32.2
30.3,64.5,0.481,184,32.3
30.5,64.6,0.484,185,32.3
31.0,64.7,0.492,185,32.4
31.2,64.8,0.495,185,32.4
31.5,64.9,0.500,185,32.4
32.0,65.0,0.508,186,32.5
32.3,65.0,0.513,186,32.5
32.8,65.1,0.521,186,32.6
33.3,65.2,0.529,186,32.6
33.8,65.3,0.537,187,32.7
34.5,65.4,0.548,187,32.7
35.2,65.5,0.558,187,32.7
35.8,65.6,0.569,187,32.8
36.5,65.6,0.579,188,32.8
37.2,65.7,0.590,188,32.9
38.0,65.8,0.603,188,32.9
38.8,65.9,0.616,188,32.9
39.8,66.0,0.632,188,33.0
40.8,66.1,0.648,189,33.0
41.8,66.1,0.664,189,33.1
42.8,66.2,0.680,189,33.1
44.0,66.3,0.698,189,33.2
45.2,66.4,0.717,190,33.2
46.5,66.5,0.738,190,33.2
47.7,66.6,0.758,190,33.3
49.1,66.6,0.779,190,33.3
50.5,66.7,0.802,191,33.4
52.0,66.8,0.825,191,33.4
53.3,66.9,0.847,191,33.5
55.0,67.0,0.873,191,33.5
56.7,67.1,0.899,192,33.5
58.5,67.1,0.929,192,33.6
60.2,67.2,0.955,192,33.6
62.2,67.3,0.987,192,33.7
63.8,67.4,1.01,193,33.7
65.5,67.5,1.04,193,33.7
67.3,67.6,1.07,193,33.8
69.1,67.6,1.10,193,33.8
70.7,67.7,1.12,194,33.9
72.5,67.8,1.15,194,33.9
74.3,67.9,1.18,194,34.0
76.2,68.0,1.21,194,34.0
78.0,68.1,1.24,194,34.0
79.8,68.2,1.27,195,34.1
81.7,68.2,1.30,195,34.1
83.7,68.3,1.33,195,34.2
85.7,68.4,1.36,195,34.2
87.5,68.5,1.39,196,34.2
89.5,68.6,1.42,196,34.3
91.3,68.7,1.45,196,34.3
93.2,68.7,1.48,196,34.4
95.2,68.8,1.51,197,34.4
97.0,68.9,1.54,197,34.5
99.0,69.0,1.57,197,34.5
101,69.1,1.60,197,34.5
103,69.2,1.63,198,34.6
104,69.2,1.65,198,34.6
106,69.3,1.68,198,34.7
107,69.4,1.70,198,34.7
108,69.5,1.71,199,34.8
109,69.6,1.73,199,34.8
109,69.7,1.74,199,34.8
110,69.7,1.74,199,34.9
110,69.8,1.74,200,34.9
110,69.9,1.74,200,35.0
109,70.0,1.73,200,35.0
108,70.1,1.71,200,35.0
107,70.2,1.70,200,35.1
106,70.3,1.68,201,35.1
104,70.3,1.66,201,35.2
103,70.4,1.63,201,35.2
101,70.5,1.60,201,35.3
98.8,70.6,1.57,202,35.3
96.7,70.7,1.53,202,35.3
94.5,70.8,1.50,202,35.4
92.5,70.8,1.47,202,35.4
90.3,70.9,1.43,203,35.5
88.2,71.0,1.40,203,35.5
85.8,71.1,1.36,203,35.5
83.8,71.2,1.33,203,35.6
81.7,71.3,1.30,204,35.6
79.7,71.3,1.26,204,35.7
77.5,71.4,1.23,204,35.7
75.5,71.5,1.20,204,35.8
73.8,71.6,1.17,205,35.8
72.2,71.7,1.15,205,35.8
70.8,71.8,1.12,205,35.9
69.8,71.8,1.11,205,35.9
68.7,71.9,1.09,206,36.0
67.7,72.0,1.07,206,36.0
66.3,72.1,1.05,206,36.1
65.3,72.2,1.04,206,36.1
64.2,72.3,1.02,206,36.1
63.2,72.3,1.00,207,36.2
61.8,72.4,0.981,207,36.2
60.5,72.5,0.960,207,36.3
59.3,72.6,0.942,207,36.3
58.2,72.7,0.923,208,36.3
57.0,72.8,0.905,208,36.4
55.8,72.9,0.886,208,36.4
55.0,72.9,0.873,208,36.5
54.0,73.0,0.857,209,36.5
53.2,73.1,0.844,209,36.6
52.5,73.2,0.833,209,36.6
51.8,73.3,0.823,209,36.6
51.0,73.4,0.810,210,36.7
50.3,73.4,0.799,210,36.7
49.5,73.5,0.786,210,36.8
48.8,73.6,0.775,210,36.8
48.0,73.7,0.762,211,36.9
47.5,73.8,0.754,211,36.9
47.0,73.9,0.746,211,36.9
46.7,73.9,0.741,211,37.0
46.5,74.0,0.738,212,37.0
46.2,74.1,0.733,212,37.1
45.8,74.2,0.728,212,37.1
45.5,74.3,0.722,212,37.1
45.0,74.4,0.714,212,37.2
44.7,74.4,0.709,213,37.2
44.3,74.5,0.704,213,37.3
44.2,74.6,0.701,213,37.3
43.7,74.7,0.693,213,37.4
43.2,74.8,0.685,214,37.4
42.7,74.9,0.677,214,37.4
42.2,75.0,0.669,214,37.5
41.7,75.0,0.661,214,37.5
41.3,75.1,0.656,215,37.6
41.0,75.2,0.651,215,37.6
40.5,75.3,0.643,215,37.6
40.2,75.4,0.638,215,37.7
39.8,75.5,0.632,216,37.7
39.5,75.5,0.627,216,37.8
39.0,75.6,0.619,216,37.8
38.8,75.7,0.616,216,37.9
38.3,75.8,0.608,217,37.9
38.0,75.9,0.603,217,37.9
37.7,76.0,0.598,217,38.0
37.3,76.0,0.593,217,38.0
36.8,76.1,0.585,218,38.1
36.3,76.2,0.577,218,38.1
35.9,76.3,0.570,218,38.2
35.5,76.4,0.563,218,38.2
35.2,76.5,0.558,218,38.2
34.7,76.5,0.550,219,38.3
34.3,76.6,0.545,219,38.3
34.2,76.7,0.542,219,38.4
34.0,76.8,0.540,219,38.4
33.7,76.9,0.534,220,38.4
33.5,77.0,0.532,220,38.5
33.2,77.1,0.526,220,38.5
33.0,77.1,0.524,220,38.6
32.7,77.2,0.519,221,38.6
32.3,77.3,0.513,221,38.7
32.2,77.4,0.511,221,38.7
31.8,77.5,0.505,221,38.7
31.5,77.6,0.500,222,38.8
31.3,77.6,0.497,222,38.8
30.8,77.7,0.489,222,38.9
30.2,77.8,0.479,222,38.9
29.8,77.9,0.474,223,38.9
29.7,78.0,0.471,223,39.0
29.3,78.1,0.466,223,39.0
29.0,78.1,0.460,223,39.1
28.8,78.2,0.458,224,39.1
28.6,78.3,0.454,224,39.2
28.2,78.4,0.447,224,39.2
27.8,78.5,0.442,224,39.2
27.5,78.6,0.437,224,39.3
27.2,78.6,0.431,225,39.3
27.0,78.7,0.429,225,39.4
26.7,78.8,0.423,225,39.4
26.5,78.9,0.421,225,39.5
26.3,79.0,0.418,226,39.5
26.2,79.1,0.415,226,39.5
25.8,79.1,0.410,226,39.6
25.7,79.2,0.407,226,39.6
25.7,79.3,0.407,227,39.7
25.5,79.4,0.405,227,39.7
25.3,79.5,0.402,227,39.7
25.2,79.6,0.399,227,39.8
25.0,79.7,0.397,228,39.8
25.0,79.7,0.397,228,39.9
24.8,79.8,0.394,228,39.9
24.7,79.9,0.392,228,40.0
24.5,80.0,0.389,229,40.0
24.3,80.1,0.386,229,40.0
24.2,80.2,0.384,229,40.1
23.8,80.2,0.378,229,40.1
23.7,80.3,0.376,229,40.2
23.2,80.4,0.368,230,40.2
23.2,80.5,0.368,230,40.3
23.3,80.6,0.370,230,40.3
23.2,80.7,0.368,230,40.3
23.0,80.7,0.365,231,40.4
22.8,80.8,0.362,231,40.4
22.7,80.9,0.360,231,40.5
22.5,81.0,0.357,231,40.5
16.7,81.1,0.265,232,40.5
16.7,81.2,0.265,232,40.6
16.8,81.2,0.267,232,40.6
16.7,81.3,0.265,232,40.7
16.7,81.4,0.265,233,40.7
16.7,81.5,0.265,233,40.8
16.7,81.6,0.265,233,40.8
16.7,81.7,0.265,233,40.8
16.7,81.8,0.265,234,40.9
16.8,81.8,0.267,234,40.9
16.7,81.9,0.265,234,41.0
16.8,82.0,0.267,234,41.0
16.8,82.1,0.267,235,41.0
17.0,82.2,0.270,235,41.1
16.8,82.3,0.267,235,41.1
17.0,82.3,0.270,235,41.2
17.2,82.4,0.272,235,41.2
17.0,82.5,0.270,236,41.3
17.2,82.6,0.272,236,41.3
17.2,82.7,0.272,236,41.3
17.2,82.8,0.272,236,41.4
17.2,82.8,0.272,237,41.4
17.2,82.9,0.272,237,41.5
17.2,83.0,0.272,237,41.5
17.2,83.1,0.272,237,41.6
17.2,83.2,0.272,238,41.6
17.2,83.3,0.272,238,41.6
17.2,83.3,0.272,238,41.7
17.2,83.4,0.272,238,41.7
17.2,83.5,0.272,239,41.8
17.3,83.6,0.275,239,41.8
17.3,83.7,0.275,239,41.8
17.5,83.8,0.278,239,41.9
17.6,83.8,0.279,240,41.9
17.8,83.9,0.283,240,42.0
18.0,84.0,0.286,240,42.0
18.3,84.1,0.290,240,42.1
18.5,84.2,0.294,241,42.1
18.8,84.3,0.299,241,42.1
19.2,84.4,0.304,241,42.2
19.5,84.4,0.310,241,42.2
19.8,84.5,0.315,241,42.3
20.2,84.6,0.320,242,42.3
20.8,84.7,0.331,242,42.3
21.2,84.8,0.336,242,42.4
21.7,84.9,0.344,242,42.4
22.3,84.9,0.354,243,42.5
22.7,85.0,0.360,243,42.5
23.3,85.1,0.370,243,42.6
23.8,85.2,0.378,243,42.6
24.7,85.3,0.392,244,42.6
25.3,85.4,0.402,244,42.7
26.0,85.4,0.413,244,42.7
26.8,85.5,0.426,244,42.8
27.7,85.6,0.439,245,42.8
28.5,85.7,0.452,245,42.9
29.3,85.8,0.466,245,42.9
30.2,85.9,0.479,245,42.9
31.2,85.9,0.495,246,43.0
32.1,86.0,0.510,246,43.0
33.2,86.1,0.526,246,43.1
34.2,86.2,0.542,246,43.1
35.2,86.3,0.558,247,43.1
36.3,86.4,0.576,247,43.2
37.3,86.5,0.593,247,43.2
38.7,86.5,0.614,247,43.3
39.8,86.6,0.632,247,43.3
41.2,86.7,0.653,248,43.4
42.3,86.8,0.672,248,43.4
43.7,86.9,0.693,248,43.4
45.0,87.0,0.714,248,43.5
46.5,87.0,0.738,249,43.5
48.2,87.1,0.765,249,43.6
49.8,87.2,0.791,249,43.6
51.2,87.3,0.812,249,43.6
52.8,87.4,0.839,250,43.7
54.7,87.5,0.868,250,43.7
56.2,87.5,0.892,250,43.8
58.0,87.6,0.921,250,43.8
59.7,87.7,0.947,251,43.9
61.3,87.8,0.973,251,43.9
63.0,87.9,1.00,251,43.9
64.8,88.0,1.03,251,44.0
66.7,88.0,1.06,252,44.0
68.3,88.1,1.08,252,44.1
70.2,88.2,1.11,252,44.1
72.0,88.3,1.14,252,44.2
73.7,88.4,1.17,253,44.2
75.5,88.5,1.20,253,44.2
77.2,88.5,1.22,253,44.3
79.2,88.6,1.26,253,44.3
81.2,88.7,1.29,253,44.4
83.1,88.8,1.32,254,44.4
85.0,88.9,1.35,254,44.4
87.0,89.0,1.38,254,44.5
89.2,89.1,1.42,254,44.5
91.0,89.1,1.44,255,44.6
92.8,89.2,1.47,255,44.6
94.7,89.3,1.50,255,44.7
96.3,89.4,1.53,255,44.7
98.3,89.5,1.56,256,44.7
100,89.6,1.59,256,44.8
102,89.6,1.62,256,44.8
104,89.7,1.65,256,44.9
106,89.8,1.68,257,44.9
108,89.9,1.71,257,45.0
110,90.0,1.74,257,45.0
111,90.1,1.77,257,45.0
113,90.1,1.79,258,45.1
115,90.2,1.82,258,45.1
116,90.3,1.85,258,45.2
118,90.4,1.87,258,45.2
120,90.5,1.90,259,45.2
121,90.6,1.92,259,45.3
122,90.6,1.94,259,45.3
123,90.7,1.96,259,45.4
124,90.8,1.97,259,45.4
125,90.9,1.99,260,45.5
126,91.0,2.00,260,45.5
127,91.1,2.01,260,45.5
128,91.2,2.03,260,45.6
129,91.2,2.04,261,45.6
129,91.3,2.05,261,45.7
130,91.4,2.07,261,45.7
132,91.5,2.09,261,45.7
133,91.6,2.10,262,45.8
134,91.7,2.12,262,45.8
135,91.7,2.14,262,45.9
136,91.8,2.15,262,45.9
137,91.9,2.17,263,46.0
138,92.0,2.19,263,46.0
139,92.1,2.21,263,46.0
140,92.2,2.22,263,46.1
141,92.2,2.24,264,46.1
142,92.3,2.25,264,46.2
142,92.4,2.26,264,46.2
143,92.5,2.26,264,46.3
143,92.6,2.27,265,46.3
144,92.7,2.28,265,46.3
144,92.7,2.28,265,46.4
144,92.8,2.29,265,46.4
145,92.9,2.29,265,46.5
145,93.0,2.30,266,46.5
145,93.1,2.31,266,46.5
146,93.2,2.31,266,46.6
146,93.2,2.32,266,46.6
147,93.3,2.33,267,46.7
147,93.4,2.34,267,46.7
148,93.5,2.35,267,46.8
149,93.6,2.37,267,46.8
150,93.7,2.38,268,46.8
151,93.8,2.39,268,46.9
152,93.8,2.41,268,46.9
153,93.9,2.42,268,47.0
153,94.0,2.43,269,47.0
154,94.1,2.45,269,47.0
155,94.2,2.46,269,47.1
156,94.3,2.47,269,47.1
157,94.3,2.49,270,47.2
157,94.4,2.49,270,47.2
158,94.5,2.51,270,47.3
159,94.6,2.52,270,47.3
159,94.7,2.53,271,47.3
160,94.8,2.54,271,47.4
161,94.8,2.56,271,47.4
162,94.9,2.57,271,47.5
163,95.0,2.58,271,47.5
164,95.1,2.60,272,47.6
164,95.2,2.61,272,47.6
165,95.3,2.62,272,47.6
166,95.3,2.63,272,47.7
166,95.4,2.64,273,47.7
167,95.5,2.65,273,47.8
167,95.6,2.65,273,47.8
167,95.7,2.65,273,47.8
167,95.8,2.66,274,47.9
168,95.9,2.66,274,47.9
168,95.9,2.66,274,48.0
168,96.0,2.67,274,48.0
169,96.1,2.68,275,48.1
169,96.2,2.69,275,48.1
169,96.3,2.69,275,48.1
170,96.4,2.70,275,48.2
170,96.4,2.70,276,48.2
171,96.5,2.71,276,48.3
171,96.6,2.71,276,48.3
171,96.7,2.72,276,48.3
172,96.8,2.72,276,48.4
172,96.9,2.72,277,48.4
172,96.9,2.72,277,48.5
172,97.0,2.72,277,48.5
171,97.1,2.72,277,48.6
171,97.2,2.72,278,48.6
171,97.3,2.71,278,48.6
171,97.4,2.71,278,48.7
170,97.4,2.70,278,48.7
170,97.5,2.69,279,48.8
170,97.6,2.69,279,48.8
169,97.7,2.69,279,48.9
169,97.8,2.69,279,48.9
169,97.9,2.69,280,48.9
170,97.9,2.69,280,49.0
170,98.0,2.69,280,49.0
170,98.1,2.70,280,49.1
170,98.2,2.70,281,49.1
171,98.3,2.71,281,49.1
171,98.4,2.71,281,49.2
171,98.5,2.72,281,49.2
172,98.5,2.72,282,49.3
172,98.6,2.73,282,49.3
172,98.7,2.73,282,49.4
173,98.8,2.74,282,49.4
174,98.9,2.75,282,49.4
174,99.0,2.76,283,49.5
174,99.0,2.77,283,49.5
175,99.1,2.77,283,49.6
175,99.2,2.78,283,49.6
175,99.3,2.78,284,49.7
175,99.4,2.78,284,49.7
175,99.5,2.78,284,49.7
175,99.5,2.78,284,49.8
175,99.6,2.78,285,49.8
175,99.7,2.78,285,49.9
175,99.8,2.78,285,49.9
175,99.9,2.77,285,49.9
174,100,2.77,286,50.0
174,100,2.76,286,50.0
174,100,2.75,286,50.1
173,100,2.75,286,50.1
172,100,2.74,287,50.2
172,100,2.73,287,50.2
171,100,2.72,287,50.2
171,101,2.71,287,50.3
170,101,2.69,288,50.3
169,101,2.68,288,50.4
168,101,2.66,288,50.4
167,101,2.65,288,50.4
166,101,2.63,288,50.5
165,101,2.61,289,50.5
163,101,2.59,289,50.6
162,101,2.57,289,50.6
161,101,2.55,289,50.7
160,101,2.54,290,50.7
159,101,2.52,290,50.7
157,102,2.50,290,50.8
156,102,2.48,290,50.8
155,102,2.46,291,50.9
154,102,2.44,291,50.9
153,102,2.42,291,51.0
151,102,2.40,291,51.0
150,102,2.39,292,51.0
149,102,2.37,292,51.1
148,102,2.35,292,51.1
147,102,2.33,292,51.2
145,102,2.31,293,51.2
145,102,2.31,293,51.2
143,103,2.27,293,51.3
141,103,2.24,293,51.3
140,103,2.22,294,51.4
139,103,2.21,294,51.4
138,103,2.19,294,51.5
137,103,2.17,294,51.5
136,103,2.15,294,51.5
134,103,2.13,295,51.6
134,103,2.12,295,51.6
133,103,2.11,295,51.7
132,103,2.09,295,51.7
131,103,2.08,296,51.7
130,104,2.06,296,51.8
129,104,2.04,296,51.8
128,104,2.03,296,51.9
127,104,2.01,297,51.9
125,104,1.99,297,52.0
124,104,1.97,297,52.0
123,104,1.96,297,52.0
122,104,1.94,298,52.1
121,104,1.92,298,52.1
120,104,1.90,298,52.2
119,104,1.88,298,52.2
118,104,1.87,299,52.3
116,105,1.85,299,52.3
116,105,1.83,299,52.3
115,105,1.82,299,52.4
114,105,1.81,300,52.4
113,105,1.80,300,52.5