File: Thermal Chamber for UTM/room temp pla 2.csv
Force (N),Position (mm),Stress (MPa),Strain (%),Time (min)
-0.167,0.00,-0.00926,0.00,0.00314
-0.167,0.00,-0.00926,0.00,0.00353
-0.167,0.00121,-0.00926,0.00345,0.00393
0.0547,0.00333,0.00304,0.00951,0.00432
0.448,0.00569,0.0249,0.0162,0.00472
1.07,0.00720,0.0592,0.0206,0.00511
1.78,0.00934,0.0989,0.0267,0.00550
2.50,0.0113,0.139,0.0324,0.00590
3.56,0.0137,0.198,0.0391,0.00629
4.76,0.0152,0.264,0.0434,0.00669
5.87,0.0174,0.326,0.0497,0.00708
6.85,0.0194,0.381,0.0556,0.00748
7.87,0.0210,0.437,0.0600,0.00787
8.92,0.0232,0.495,0.0663,0.00826
9.76,0.0252,0.542,0.0720,0.00866
11.0,0.0278,0.611,0.0795,0.00905
11.9,0.0297,0.659,0.0849,0.00945
12.5,0.0311,0.696,0.0888,0.00984
13.8,0.0337,0.765,0.0962,0.0102
14.9,0.0362,0.830,0.103,0.0106
15.8,0.0370,0.877,0.106,0.0110
17.0,0.0394,0.944,0.113,0.0114
18.1,0.0419,1.01,0.120,0.0118
19.0,0.0437,1.06,0.125,0.0122
19.9,0.0449,1.11,0.128,0.0126
21.0,0.0472,1.16,0.135,0.0130
22.1,0.0497,1.23,0.142,0.0134
23.2,0.0516,1.29,0.147,0.0138
23.9,0.0528,1.33,0.151,0.0142
24.9,0.0552,1.38,0.158,0.0146
25.9,0.0577,1.44,0.165,0.0150
26.9,0.0596,1.49,0.170,0.0154
27.8,0.0614,1.54,0.176,0.0158
28.6,0.0634,1.59,0.181,0.0161
29.6,0.0649,1.65,0.186,0.0165
30.4,0.0667,1.69,0.190,0.0169
31.3,0.0687,1.74,0.196,0.0173
32.2,0.0710,1.79,0.203,0.0177
33.2,0.0730,1.84,0.209,0.0181
34.4,0.0755,1.91,0.216,0.0185
35.5,0.0770,1.97,0.220,0.0189
36.6,0.0791,2.03,0.226,0.0193
37.6,0.0812,2.09,0.232,0.0197
38.8,0.0830,2.16,0.237,0.0201
40.0,0.0851,2.22,0.243,0.0205
41.0,0.0872,2.28,0.249,0.0209
42.0,0.0891,2.33,0.255,0.0213
43.2,0.0907,2.40,0.259,0.0217
44.3,0.0932,2.46,0.266,0.0221
45.4,0.0954,2.52,0.272,0.0225
46.3,0.0964,2.57,0.275,0.0228
47.4,0.0987,2.63,0.282,0.0232
48.1,0.100,2.67,0.287,0.0236
49.2,0.103,2.73,0.293,0.0240
50.2,0.104,2.79,0.298,0.0244
51.4,0.107,2.85,0.305,0.0248
52.6,0.109,2.92,0.311,0.0252
53.6,0.110,2.98,0.315,0.0256
54.5,0.112,3.03,0.320,0.0260
55.6,0.115,3.09,0.327,0.0264
56.7,0.116,3.15,0.332,0.0268
57.6,0.118,3.20,0.337,0.0272
58.8,0.120,3.27,0.344,0.0276
60.0,0.123,3.34,0.351,0.0280
61.0,0.124,3.39,0.355,0.0284
61.9,0.126,3.44,0.360,0.0288
63.2,0.128,3.51,0.367,0.0292
64.3,0.131,3.57,0.374,0.0295
65.3,0.132,3.63,0.377,0.0299
66.3,0.134,3.68,0.383,0.0303
67.4,0.136,3.74,0.390,0.0307
68.7,0.138,3.81,0.394,0.0311
69.5,0.140,3.86,0.400,0.0315
70.5,0.142,3.92,0.406,0.0319
71.6,0.145,3.98,0.413,0.0323
72.9,0.146,4.05,0.417,0.0327
73.8,0.148,4.10,0.423,0.0331
74.7,0.150,4.15,0.429,0.0335
75.8,0.152,4.21,0.433,0.0339
76.8,0.154,4.27,0.439,0.0343
77.6,0.156,4.31,0.444,0.0347
78.7,0.158,4.37,0.452,0.0351
79.7,0.160,4.43,0.456,0.0355
80.7,0.161,4.48,0.461,0.0358
81.6,0.164,4.53,0.468,0.0362
82.6,0.166,4.59,0.475,0.0366
83.5,0.168,4.64,0.479,0.0370
84.4,0.169,4.69,0.484,0.0374
85.3,0.172,4.74,0.491,0.0378
86.3,0.174,4.79,0.497,0.0382
87.3,0.176,4.85,0.502,0.0386
88.3,0.178,4.90,0.507,0.0390
89.2,0.180,4.96,0.514,0.0394
90.3,0.181,5.02,0.518,0.0398
91.4,0.184,5.08,0.525,0.0402
92.4,0.186,5.13,0.531,0.0406
93.3,0.187,5.18,0.534,0.0410
94.5,0.189,5.25,0.541,0.0414
95.6,0.192,5.31,0.548,0.0418
96.5,0.193,5.36,0.553,0.0422
97.5,0.195,5.42,0.557,0.0425
98.5,0.197,5.47,0.563,0.0429
99.3,0.199,5.52,0.568,0.0433
100,0.201,5.58,0.574,0.0437
102,0.204,5.64,0.582,0.0441
103,0.205,5.70,0.586,0.0445
104,0.207,5.75,0.592,0.0449
105,0.210,5.82,0.599,0.0453
106,0.211,5.88,0.603,0.0457
107,0.213,5.94,0.609,0.0461
108,0.215,5.99,0.615,0.0465
109,0.218,6.05,0.622,0.0469
110,0.219,6.11,0.626,0.0473
111,0.221,6.17,0.632,0.0477
112,0.223,6.21,0.638,0.0481
113,0.225,6.28,0.642,0.0485
114,0.227,6.34,0.649,0.0489
115,0.229,6.39,0.655,0.0492
116,0.231,6.44,0.661,0.0496
117,0.233,6.50,0.665,0.0500
118,0.235,6.56,0.672,0.0504
119,0.237,6.61,0.677,0.0508
120,0.238,6.66,0.681,0.0512
121,0.241,6.71,0.687,0.0516
122,0.243,6.76,0.693,0.0520
123,0.244,6.81,0.697,0.0524
124,0.246,6.88,0.704,0.0528
125,0.249,6.94,0.711,0.0532
126,0.250,6.98,0.715,0.0536
127,0.252,7.03,0.720,0.0540
128,0.254,7.10,0.727,0.0544
129,0.257,7.15,0.734,0.0548
130,0.258,7.21,0.737,0.0552
131,0.260,7.26,0.743,0.0556
132,0.262,7.32,0.750,0.0559
133,0.264,7.38,0.754,0.0563
134,0.266,7.43,0.760,0.0567
135,0.268,7.47,0.766,0.0571
136,0.270,7.54,0.771,0.0575
137,0.272,7.60,0.777,0.0579
138,0.274,7.65,0.783,0.0583
139,0.276,7.70,0.789,0.0587
140,0.278,7.76,0.793,0.0591
141,0.280,7.82,0.800,0.0595
141,0.282,7.86,0.806,0.0599
142,0.283,7.91,0.810,0.0603
143,0.285,7.96,0.815,0.0607
144,0.287,8.01,0.821,0.0611
145,0.290,8.07,0.828,0.0615
146,0.291,8.10,0.833,0.0619
147,0.294,8.16,0.841,0.0623
148,0.296,8.21,0.844,0.0626
149,0.298,8.27,0.851,0.0630
150,0.300,8.33,0.858,0.0634
151,0.302,8.39,0.862,0.0638
152,0.304,8.44,0.868,0.0642
153,0.306,8.50,0.874,0.0646
154,0.307,8.53,0.878,0.0650
155,0.310,8.59,0.885,0.0654
155,0.312,8.64,0.891,0.0658
156,0.314,8.68,0.897,0.0662
157,0.315,8.75,0.901,0.0666
158,0.318,8.80,0.908,0.0670
159,0.320,8.85,0.914,0.0674
160,0.321,8.90,0.917,0.0678
161,0.323,8.96,0.924,0.0682
162,0.325,9.01,0.930,0.0686
163,0.327,9.05,0.933,0.0690
164,0.329,9.10,0.940,0.0693
165,0.331,9.15,0.946,0.0697
166,0.333,9.20,0.952,0.0701
167,0.335,9.25,0.957,0.0705
168,0.337,9.31,0.963,0.0709
168,0.339,9.35,0.969,0.0713
169,0.341,9.39,0.975,0.0717
170,0.344,9.45,0.982,0.0721
171,0.345,9.51,0.986,0.0725
172,0.347,9.55,0.992,0.0729
173,0.349,9.60,0.998,0.0733
174,0.351,9.65,1.00,0.0737
175,0.353,9.70,1.01,0.0741
175,0.355,9.74,1.01,0.0745
176,0.356,9.79,1.02,0.0749
177,0.359,9.84,1.02,0.0753
178,0.361,9.89,1.03,0.0757
179,0.362,9.94,1.04,0.0760
180,0.364,9.98,1.04,0.0764
181,0.367,10.0,1.05,0.0768
181,0.368,10.1,1.05,0.0772
182,0.370,10.1,1.06,0.0776
183,0.372,10.2,1.06,0.0780
184,0.375,10.2,1.07,0.0784
185,0.377,10.3,1.08,0.0788
186,0.378,10.3,1.08,0.0792
187,0.380,10.4,1.09,0.0796
188,0.383,10.4,1.09,0.0800
189,0.384,10.5,1.10,0.0804
189,0.386,10.5,1.10,0.0808
190,0.388,10.6,1.11,0.0812
191,0.391,10.6,1.12,0.0816
192,0.392,10.7,1.12,0.0820
193,0.394,10.7,1.13,0.0824
194,0.397,10.8,1.13,0.0827
195,0.398,10.8,1.14,0.0831
196,0.400,10.9,1.14,0.0835
196,0.402,10.9,1.15,0.0839
197,0.405,11.0,1.16,0.0843
198,0.406,11.0,1.16,0.0847
199,0.408,11.1,1.17,0.0851
200,0.410,11.1,1.17,0.0855
201,0.411,11.2,1.18,0.0859
201,0.413,11.2,1.18,0.0863
202,0.416,11.2,1.19,0.0867
203,0.418,11.3,1.19,0.0871
204,0.420,11.3,1.20,0.0875
205,0.421,11.4,1.20,0.0879
206,0.424,11.4,1.21,0.0883
207,0.426,11.5,1.22,0.0887
208,0.428,11.5,1.22,0.0891
209,0.430,11.6,1.23,0.0894
210,0.432,11.6,1.23,0.0898
210,0.434,11.7,1.24,0.0902
211,0.436,11.7,1.25,0.0906
212,0.438,11.8,1.25,0.0910
213,0.440,11.8,1.26,0.0914
214,0.442,11.9,1.26,0.0918
215,0.444,11.9,1.27,0.0922
216,0.446,12.0,1.27,0.0926
216,0.448,12.0,1.28,0.0930
217,0.449,12.1,1.28,0.0934
218,0.452,12.1,1.29,0.0938
219,0.453,12.2,1.30,0.0942
220,0.455,12.2,1.30,0.0946
221,0.457,12.3,1.31,0.0950
221,0.459,12.3,1.31,0.0954
222,0.462,12.3,1.32,0.0958
223,0.463,12.4,1.32,0.0961
224,0.465,12.4,1.33,0.0965
225,0.467,12.5,1.33,0.0969
226,0.469,12.5,1.34,0.0973
227,0.471,12.6,1.35,0.0977
228,0.473,12.6,1.35,0.0981
228,0.475,12.7,1.36,0.0985
229,0.477,12.7,1.36,0.0989
230,0.479,12.8,1.37,0.0993
231,0.481,12.8,1.38,0.0997
232,0.482,12.9,1.38,0.100
233,0.485,12.9,1.38,0.100
234,0.487,13.0,1.39,0.101
234,0.489,13.0,1.40,0.101
235,0.491,13.1,1.40,0.102
236,0.493,13.1,1.41,0.102
237,0.495,13.2,1.41,0.102
238,0.496,13.2,1.42,0.103
238,0.498,13.2,1.42,0.103
239,0.501,13.3,1.43,0.104
240,0.503,13.3,1.44,0.104
241,0.505,13.4,1.44,0.104
242,0.506,13.4,1.45,0.105
243,0.509,13.5,1.45,0.105
243,0.511,13.5,1.46,0.106
244,0.512,13.6,1.46,0.106
245,0.514,13.6,1.47,0.106
246,0.517,13.7,1.48,0.107
247,0.518,13.7,1.48,0.107
247,0.520,13.7,1.49,0.108
248,0.523,13.8,1.49,0.108
249,0.525,13.8,1.50,0.108
250,0.526,13.9,1.50,0.109
251,0.528,13.9,1.51,0.109
251,0.531,14.0,1.52,0.110
252,0.532,14.0,1.52,0.110
253,0.534,14.1,1.53,0.110
254,0.536,14.1,1.53,0.111
255,0.539,14.1,1.54,0.111
255,0.540,14.2,1.54,0.112
256,0.542,14.2,1.55,0.112
257,0.544,14.3,1.55,0.112
258,0.546,14.3,1.56,0.113
258,0.547,14.4,1.56,0.113
259,0.550,14.4,1.57,0.113
260,0.552,14.4,1.58,0.114
261,0.554,14.5,1.58,0.114
261,0.556,14.5,1.59,0.115
262,0.558,14.6,1.59,0.115
263,0.560,14.6,1.60,0.115
264,0.562,14.7,1.61,0.116
265,0.564,14.7,1.61,0.116
265,0.566,14.7,1.62,0.117
266,0.568,14.8,1.62,0.117
267,0.570,14.8,1.63,0.117
268,0.571,14.9,1.63,0.118
268,0.574,14.9,1.64,0.118
269,0.576,14.9,1.65,0.119
270,0.578,15.0,1.65,0.119
270,0.579,15.0,1.66,0.119
271,0.582,15.1,1.66,0.120
272,0.584,15.1,1.67,0.120
273,0.585,15.1,1.67,0.121
273,0.588,15.2,1.68,0.121
274,0.590,15.2,1.69,0.121
275,0.592,15.3,1.69,0.122
275,0.593,15.3,1.69,0.122
276,0.596,15.3,1.70,0.123
277,0.597,15.4,1.71,0.123
277,0.599,15.4,1.71,0.123
278,0.601,15.4,1.72,0.124
279,0.603,15.5,1.72,0.124
279,0.605,15.5,1.73,0.125
280,0.607,15.5,1.73,0.125
280,0.609,15.6,1.74,0.125
281,0.611,15.6,1.74,0.126
281,0.612,15.6,1.75,0.126
282,0.615,15.7,1.76,0.126
283,0.616,15.7,1.76,0.127
283,0.618,15.7,1.77,0.127
283,0.621,15.7,1.77,0.128
284,0.623,15.8,1.78,0.128
285,0.624,15.8,1.78,0.128
285,0.627,15.9,1.79,0.129
286,0.629,15.9,1.80,0.129
286,0.630,15.9,1.80,0.130
287,0.632,15.9,1.81,0.130
288,0.635,16.0,1.81,0.130
288,0.636,16.0,1.82,0.131
289,0.638,16.0,1.82,0.131
289,0.640,16.1,1.83,0.132
290,0.643,16.1,1.84,0.132
290,0.645,16.1,1.84,0.132
291,0.646,16.2,1.85,0.133
292,0.649,16.2,1.85,0.133
292,0.651,16.2,1.86,0.134
293,0.653,16.3,1.87,0.134
294,0.654,16.3,1.87,0.134
294,0.657,16.3,1.88,0.135
295,0.659,16.4,1.88,0.135
296,0.661,16.4,1.89,0.136
296,0.662,16.5,1.89,0.136
297,0.665,16.5,1.90,0.136
298,0.666,16.6,1.90,0.137
299,0.668,16.6,1.91,0.137
300,0.670,16.6,1.91,0.138
300,0.672,16.7,1.92,0.138
301,0.674,16.7,1.93,0.138
302,0.676,16.8,1.93,0.139
303,0.678,16.8,1.94,0.139
303,0.681,16.9,1.94,0.139
304,0.682,16.9,1.95,0.140
305,0.684,16.9,1.95,0.140
306,0.686,17.0,1.96,0.141
307,0.688,17.0,1.97,0.141
307,0.690,17.1,1.97,0.141
308,0.692,17.1,1.98,0.142
309,0.693,17.2,1.98,0.142
310,0.695,17.2,1.99,0.143
310,0.697,17.2,1.99,0.143
311,0.700,17.3,2.00,0.143
312,0.702,17.3,2.01,0.144
313,0.704,17.4,2.01,0.144
313,0.705,17.4,2.02,0.145
314,0.708,17.5,2.02,0.145
315,0.710,17.5,2.03,0.145
316,0.712,17.5,2.03,0.146
316,0.713,17.6,2.04,0.146
317,0.716,17.6,2.05,0.147
318,0.718,17.7,2.05,0.147
319,0.719,17.7,2.05,0.147
320,0.722,17.8,2.06,0.148
321,0.724,17.8,2.07,0.148
321,0.725,17.8,2.07,0.149
322,0.727,17.9,2.08,0.149
323,0.730,17.9,2.08,0.149
323,0.731,18.0,2.09,0.150
324,0.733,18.0,2.10,0.150
325,0.735,18.0,2.10,0.151
325,0.737,18.1,2.10,0.151
326,0.739,18.1,2.11,0.151
327,0.742,18.2,2.12,0.152
328,0.743,18.2,2.12,0.152
328,0.745,18.2,2.13,0.152
329,0.747,18.3,2.14,0.153
330,0.750,18.3,2.14,0.153
331,0.751,18.4,2.14,0.154
331,0.753,18.4,2.15,0.154
332,0.755,18.5,2.16,0.154
333,0.757,18.5,2.16,0.155
334,0.758,18.5,2.17,0.155
334,0.761,18.6,2.17,0.156
335,0.763,18.6,2.18,0.156
336,0.764,18.6,2.18,0.156
336,0.766,18.7,2.19,0.157
337,0.769,18.7,2.20,0.157
338,0.771,18.8,2.20,0.158
338,0.772,18.8,2.21,0.158
339,0.775,18.8,2.21,0.158
340,0.777,18.9,2.22,0.159
341,0.778,18.9,2.22,0.159
341,0.780,19.0,2.23,0.160
342,0.783,19.0,2.24,0.160
343,0.784,19.0,2.24,0.160
343,0.786,19.1,2.25,0.161
344,0.788,19.1,2.25,0.161
345,0.790,19.2,2.26,0.162
345,0.792,19.2,2.26,0.162
346,0.794,19.2,2.27,0.162
347,0.796,19.3,2.27,0.163
347,0.797,19.3,2.28,0.163
348,0.799,19.3,2.28,0.164
349,0.802,19.4,2.29,0.164
349,0.804,19.4,2.30,0.164
350,0.807,19.5,2.30,0.165
351,0.808,19.5,2.31,0.165
351,0.810,19.5,2.31,0.166
352,0.812,19.6,2.32,0.166
353,0.815,19.6,2.33,0.166
354,0.816,19.6,2.33,0.167
354,0.818,19.7,2.34,0.167
355,0.820,19.7,2.34,0.167
356,0.822,19.8,2.35,0.168
356,0.824,19.8,2.35,0.168
357,0.826,19.8,2.36,0.169
358,0.827,19.9,2.36,0.169
359,0.830,19.9,2.37,0.169
359,0.832,20.0,2.38,0.170
360,0.833,20.0,2.38,0.170
361,0.836,20.0,2.39,0.171
361,0.838,20.1,2.39,0.171
362,0.839,20.1,2.40,0.171
363,0.841,20.1,2.40,0.172
363,0.843,20.2,2.41,0.172
364,0.845,20.2,2.41,0.173
365,0.848,20.3,2.42,0.173
366,0.849,20.3,2.43,0.173
366,0.851,20.3,2.43,0.174
367,0.853,20.4,2.44,0.174
368,0.856,20.4,2.44,0.175
368,0.858,20.5,2.45,0.175
369,0.859,20.5,2.46,0.175
370,0.861,20.5,2.46,0.176
371,0.864,20.6,2.47,0.176
371,0.865,20.6,2.47,0.177
372,0.868,20.7,2.48,0.177
373,0.869,20.7,2.48,0.177
373,0.871,20.7,2.49,0.178
374,0.873,20.8,2.50,0.178
375,0.876,20.8,2.50,0.179
376,0.877,20.9,2.50,0.179
376,0.879,20.9,2.51,0.179
377,0.881,20.9,2.52,0.180
378,0.883,21.0,2.52,0.180
378,0.884,21.0,2.53,0.180
379,0.887,21.1,2.53,0.181
380,0.889,21.1,2.54,0.181
380,0.891,21.1,2.55,0.182
381,0.892,21.2,2.55,0.182
382,0.895,21.2,2.56,0.182
383,0.897,21.3,2.56,0.183
383,0.898,21.3,2.57,0.183
384,0.901,21.3,2.57,0.184
385,0.903,21.4,2.58,0.184
385,0.905,21.4,2.58,0.184
386,0.906,21.4,2.59,0.185
387,0.909,21.5,2.60,0.185
388,0.911,21.5,2.60,0.186
388,0.913,21.6,2.61,0.186
389,0.914,21.6,2.61,0.186
390,0.917,21.6,2.62,0.187
390,0.918,21.7,2.62,0.187
391,0.920,21.7,2.63,0.188
392,0.922,21.8,2.64,0.188
392,0.924,21.8,2.64,0.188
393,0.926,21.8,2.65,0.189
394,0.928,21.9,2.65,0.189
394,0.930,21.9,2.66,0.190
395,0.933,21.9,2.66,0.190
396,0.934,22.0,2.67,0.190
396,0.936,22.0,2.67,0.191
397,0.938,22.1,2.68,0.191
398,0.941,22.1,2.69,0.192
398,0.942,22.1,2.69,0.192
399,0.944,22.2,2.70,0.192
400,0.946,22.2,2.70,0.193
400,0.949,22.2,2.71,0.193
401,0.950,22.3,2.71,0.193
402,0.952,22.3,2.72,0.194
402,0.954,22.4,2.73,0.194
403,0.956,22.4,2.73,0.195
404,0.958,22.4,2.74,0.195
404,0.960,22.5,2.74,0.195
405,0.962,22.5,2.75,0.196
406,0.964,22.5,2.75,0.196
406,0.966,22.6,2.76,0.197
407,0.968,22.6,2.77,0.197
408,0.969,22.7,2.77,0.197
408,0.971,22.7,2.77,0.198
409,0.974,22.7,2.78,0.198
410,0.976,22.8,2.79,0.199
410,0.977,22.8,2.79,0.199
411,0.979,22.8,2.80,0.199
411,0.982,22.9,2.80,0.200
412,0.983,22.9,2.81,0.200
413,0.985,22.9,2.82,0.201
413,0.987,23.0,2.82,0.201
414,0.989,23.0,2.83,0.201
415,0.991,23.1,2.83,0.202
416,0.994,23.1,2.84,0.202
416,0.995,23.1,2.84,0.203
417,0.997,23.1,2.85,0.203
417,0.999,23.2,2.86,0.203
418,1.00,23.2,2.86,0.204
418,1.00,23.2,2.86,0.204
419,1.00,23.3,2.87,0.205
420,1.01,23.3,2.88,0.205
420,1.01,23.4,2.88,0.205
421,1.01,23.4,2.89,0.206
422,1.01,23.4,2.89,0.206
422,1.01,23.5,2.90,0.206
423,1.02,23.5,2.91,0.207
423,1.02,23.5,2.91,0.207
424,1.02,23.6,2.92,0.208
425,1.02,23.6,2.92,0.208
425,1.02,23.6,2.93,0.208
426,1.03,23.7,2.93,0.209
427,1.03,23.7,2.94,0.209
427,1.03,23.7,2.94,0.210
428,1.03,23.8,2.95,0.210
428,1.03,23.8,2.96,0.210
429,1.04,23.8,2.96,0.211
430,1.04,23.9,2.97,0.211
430,1.04,23.9,2.97,0.212
431,1.04,23.9,2.98,0.212
431,1.04,24.0,2.98,0.212
432,1.05,24.0,2.99,0.213
433,1.05,24.0,3.00,0.213
433,1.05,24.1,3.00,0.214
434,1.05,24.1,3.01,0.214
435,1.05,24.1,3.01,0.214
435,1.06,24.2,3.02,0.215
436,1.06,24.2,3.02,0.215
436,1.06,24.2,3.03,0.216
437,1.06,24.3,3.03,0.216
438,1.06,24.3,3.04,0.216
438,1.07,24.3,3.05,0.217
439,1.07,24.4,3.05,0.217
439,1.07,24.4,3.06,0.218
440,1.07,24.4,3.06,0.218
440,1.07,24.5,3.07,0.218
441,1.08,24.5,3.08,0.219
441,1.08,24.5,3.08,0.219
442,1.08,24.6,3.09,0.219
442,1.08,24.6,3.09,0.220
443,1.08,24.6,3.10,0.220
444,1.09,24.7,3.10,0.221
444,1.09,24.7,3.11,0.221
445,1.09,24.7,3.11,0.221
445,1.09,24.7,3.12,0.222
446,1.09,24.8,3.13,0.222
447,1.10,24.8,3.13,0.223
447,1.10,24.8,3.14,0.223
448,1.10,24.9,3.14,0.223
448,1.10,24.9,3.15,0.224
449,1.10,24.9,3.15,0.224
449,1.11,25.0,3.16,0.225
450,1.11,25.0,3.16,0.225
450,1.11,25.0,3.17,0.225
451,1.11,25.1,3.18,0.226
451,1.11,25.1,3.18,0.226
452,1.12,25.1,3.19,0.227
453,1.12,25.1,3.19,0.227
453,1.12,25.2,3.20,0.227
454,1.12,25.2,3.20,0.228
454,1.12,25.2,3.21,0.228
455,1.13,25.3,3.22,0.229
455,1.13,25.3,3.22,0.229
456,1.13,25.3,3.23,0.229
456,1.13,25.3,3.23,0.230
457,1.13,25.4,3.24,0.230
457,1.13,25.4,3.24,0.231
458,1.14,25.4,3.25,0.231
458,1.14,25.5,3.25,0.231
459,1.14,25.5,3.26,0.232
459,1.14,25.5,3.26,0.232
460,1.14,25.5,3.27,0.232
460,1.15,25.6,3.28,0.233
461,1.15,25.6,3.28,0.233
461,1.15,25.6,3.29,0.234
462,1.15,25.6,3.29,0.234
462,1.16,25.7,3.30,0.234
463,1.16,25.7,3.31,0.235
463,1.16,25.7,3.31,0.235
464,1.16,25.8,3.32,0.236
464,1.16,25.8,3.32,0.236
465,1.17,25.8,3.33,0.236
465,1.17,25.8,3.33,0.237
465,1.17,25.9,3.34,0.237
466,1.17,25.9,3.35,0.238
466,1.17,25.9,3.35,0.238
467,1.17,25.9,3.36,0.238
467,1.18,26.0,3.36,0.239
468,1.18,26.0,3.37,0.239
468,1.18,26.0,3.37,0.240
469,1.18,26.0,3.38,0.240
469,1.18,26.1,3.38,0.240
469,1.19,26.1,3.39,0.241
470,1.19,26.1,3.39,0.241
470,1.19,26.1,3.40,0.242
471,1.19,26.2,3.41,0.242
471,1.19,26.2,3.41,0.242
472,1.20,26.2,3.42,0.243
472,1.20,26.2,3.42,0.243
472,1.20,26.2,3.43,0.244
473,1.20,26.3,3.44,0.244
473,1.20,26.3,3.44,0.244
474,1.21,26.3,3.45,0.245
474,1.21,26.3,3.45,0.245
475,1.21,26.4,3.46,0.246
475,1.21,26.4,3.46,0.246
475,1.21,26.4,3.47,0.246
476,1.22,26.4,3.47,0.247
476,1.22,26.4,3.48,0.247
477,1.22,26.5,3.49,0.247
477,1.22,26.5,3.49,0.248
477,1.22,26.5,3.50,0.248
478,1.23,26.5,3.50,0.249
478,1.23,26.6,3.51,0.249
479,1.23,26.6,3.51,0.249
479,1.23,26.6,3.52,0.250
479,1.23,26.6,3.52,0.250
480,1.24,26.6,3.53,0.251
480,1.24,26.7,3.54,0.251
480,1.24,26.7,3.54,0.251
481,1.24,26.7,3.55,0.252
481,1.24,26.7,3.55,0.252
482,1.25,26.8,3.56,0.253
482,1.25,26.8,3.56,0.253
482,1.25,26.8,3.57,0.253
483,1.25,26.8,3.58,0.254
483,1.25,26.8,3.58,0.254
483,1.26,26.8,3.59,0.255
484,1.26,26.9,3.59,0.255
484,1.26,26.9,3.60,0.255
484,1.26,26.9,3.61,0.256
485,1.26,26.9,3.61,0.256
485,1.26,26.9,3.61,0.257
485,1.27,27.0,3.62,0.257
485,1.27,27.0,3.62,0.257
486,1.27,27.0,3.63,0.258
486,1.27,27.0,3.64,0.258
486,1.27,27.0,3.64,0.259
487,1.28,27.0,3.65,0.259
487,1.28,27.1,3.66,0.259
487,1.28,27.1,3.66,0.260
488,1.28,27.1,3.67,0.260
488,1.28,27.1,3.67,0.260
488,1.29,27.1,3.68,0.261
488,1.29,27.1,3.68,0.261
489,1.29,27.1,3.69,0.262
489,1.29,27.2,3.69,0.262
489,1.29,27.2,3.70,0.262
489,1.30,27.2,3.70,0.263
490,1.30,27.2,3.71,0.263
490,1.30,27.2,3.72,0.264
490,1.30,27.2,3.72,0.264
490,1.30,27.2,3.73,0.264
491,1.31,27.3,3.73,0.265
491,1.31,27.3,3.74,0.265
491,1.31,27.3,3.74,0.266
491,1.31,27.3,3.75,0.266
491,1.31,27.3,3.75,0.266
492,1.32,27.3,3.76,0.267
492,1.32,27.3,3.77,0.267
492,1.32,27.3,3.77,0.268
492,1.32,27.4,3.78,0.268
493,1.32,27.4,3.78,0.268
493,1.33,27.4,3.79,0.269
493,1.33,27.4,3.79,0.269
493,1.33,27.4,3.80,0.270
493,1.33,27.4,3.81,0.270
493,1.33,27.4,3.81,0.270
494,1.34,27.4,3.82,0.271
494,1.34,27.4,3.82,0.271
494,1.34,27.4,3.83,0.272
494,1.34,27.4,3.83,0.272
494,1.34,27.5,3.84,0.272
495,1.35,27.5,3.85,0.273
495,1.35,27.5,3.85,0.273
495,1.35,27.5,3.86,0.273
495,1.35,27.5,3.86,0.274
495,1.35,27.5,3.87,0.274
495,1.36,27.5,3.87,0.275
495,1.36,27.5,3.88,0.275
495,1.36,27.5,3.88,0.275
496,1.36,27.5,3.89,0.276
496,1.36,27.5,3.90,0.276
496,1.37,27.5,3.90,0.277
496,1.37,27.5,3.91,0.277
496,1.37,27.6,3.91,0.277
496,1.37,27.6,3.92,0.278
496,1.37,27.6,3.92,0.278
496,1.38,27.6,3.93,0.279
496,1.38,27.6,3.94,0.279
497,1.38,27.6,3.94,0.279
497,1.38,27.6,3.95,0.280
497,1.38,27.6,3.95,0.280
497,1.39,27.6,3.96,0.281
497,1.39,27.6,3.97,0.281
497,1.39,27.6,3.97,0.281
497,1.39,27.6,3.97,0.282
497,1.39,27.6,3.98,0.282
497,1.40,27.6,3.99,0.283
497,1.40,27.6,3.99,0.283
497,1.40,27.6,4.00,0.283
497,1.40,27.6,4.00,0.284
497,1.40,27.6,4.01,0.284
497,1.41,27.6,4.01,0.285
497,1.41,27.6,4.02,0.285
497,1.41,27.6,4.03,0.285
497,1.41,27.6,4.03,0.286
497,1.41,27.6,4.04,0.286
497,1.42,27.6,4.04,0.286
497,1.42,27.6,4.05,0.287
497,1.42,27.6,4.05,0.287
497,1.42,27.6,4.06,0.288
497,1.42,27.6,4.07,0.288
497,1.43,27.6,4.07,0.288
497,1.43,27.6,4.08,0.289
497,1.43,27.6,4.08,0.289
497,1.43,27.6,4.09,0.290
497,1.43,27.6,4.09,0.290
497,1.43,27.6,4.10,0.290
497,1.44,27.6,4.11,0.291
497,1.44,27.6,4.11,0.291
497,1.44,27.6,4.11,0.292
497,1.44,27.6,4.12,0.292
497,1.44,27.6,4.13,0.292
497,1.45,27.6,4.13,0.293
497,1.45,27.6,4.14,0.293
497,1.45,27.6,4.14,0.294
497,1.45,27.6,4.15,0.294
497,1.45,27.6,4.15,0.294
497,1.46,27.6,4.16,0.295
497,1.46,27.6,4.17,0.295
497,1.46,27.6,4.17,0.296
496,1.46,27.6,4.18,0.296
496,1.46,27.6,4.18,0.296
496,1.47,27.6,4.19,0.297
496,1.47,27.6,4.19,0.297
496,1.47,27.6,4.20,0.298
496,1.47,27.6,4.21,0.298
496,1.47,27.6,4.21,0.298
496,1.48,27.5,4.22,0.299
496,1.48,27.5,4.22,0.299
496,1.48,27.5,4.23,0.299
496,1.48,27.5,4.23,0.300
496,1.48,27.5,4.24,0.300
495,1.49,27.5,4.24,0.301
495,1.49,27.5,4.25,0.301
495,1.49,27.5,4.26,0.301
495,1.49,27.5,4.26,0.302
495,1.49,27.5,4.27,0.302
495,1.50,27.5,4.27,0.303
495,1.50,27.5,4.28,0.303
495,1.50,27.5,4.28,0.303
495,1.50,27.5,4.29,0.304
494,1.50,27.5,4.30,0.304
494,1.51,27.5,4.30,0.305
494,1.51,27.5,4.31,0.305
494,1.51,27.4,4.31,0.305
494,1.51,27.4,4.32,0.306
494,1.51,27.4,4.33,0.306
494,1.52,27.4,4.33,0.307
493,1.52,27.4,4.33,0.307
493,1.52,27.4,4.34,0.307
493,1.52,27.4,4.35,0.308
493,1.52,27.4,4.35,0.308
493,1.53,27.4,4.36,0.309
493,1.53,27.4,4.36,0.309
493,1.53,27.4,4.37,0.309
493,1.53,27.4,4.38,0.310
492,1.53,27.4,4.38,0.310
492,1.54,27.3,4.39,0.311
492,1.54,27.3,4.39,0.311
492,1.54,27.3,4.40,0.311
492,1.54,27.3,4.40,0.312
492,1.54,27.3,4.41,0.312
491,1.55,27.3,4.41,0.312
491,1.55,27.3,4.42,0.313
491,1.55,27.3,4.43,0.313
491,1.55,27.3,4.43,0.314
491,1.55,27.3,4.44,0.314
491,1.55,27.3,4.44,0.314
491,1.56,27.2,4.45,0.315
490,1.56,27.2,4.45,0.315
490,1.56,27.2,4.46,0.316
490,1.56,27.2,4.47,0.316
490,1.56,27.2,4.47,0.316
490,1.57,27.2,4.48,0.317
489,1.57,27.2,4.48,0.317
489,1.57,27.2,4.49,0.318
489,1.57,27.2,4.49,0.318
489,1.57,27.2,4.50,0.318
489,1.58,27.1,4.50,0.319
489,1.58,27.1,4.51,0.319
488,1.58,27.1,4.51,0.320
488,1.58,27.1,4.52,0.320
488,1.58,27.1,4.53,0.320
488,1.59,27.1,4.53,0.321
488,1.59,27.1,4.54,0.321
487,1.59,27.1,4.54,0.322
487,1.59,27.1,4.55,0.322
487,1.60,27.1,4.56,0.322
487,1.60,27.1,4.56,0.323
487,1.60,27.0,4.57,0.323
487,1.60,27.0,4.57,0.324
486,1.60,27.0,4.58,0.324
486,1.60,27.0,4.58,0.324
486,1.61,27.0,4.59,0.325
486,1.61,27.0,4.60,0.325
486,1.61,27.0,4.60,0.326
486,1.61,27.0,4.61,0.326
485,1.61,27.0,4.61,0.326
485,1.62,27.0,4.62,0.327
485,1.62,26.9,4.62,0.327
485,1.62,26.9,4.63,0.327
485,1.62,26.9,4.64,0.328
484,1.62,26.9,4.64,0.328
484,1.63,26.9,4.64,0.329
484,1.63,26.9,4.65,0.329
484,1.63,26.9,4.66,0.329
484,1.63,26.9,4.66,0.330
483,1.63,26.9,4.67,0.330
483,1.64,26.8,4.67,0.331
483,1.64,26.8,4.68,0.331
483,1.64,26.8,4.69,0.331
483,1.64,26.8,4.69,0.332
482,1.64,26.8,4.69,0.332
482,1.65,26.8,4.70,0.333
482,1.65,26.8,4.71,0.333
482,1.65,26.8,4.71,0.333
481,1.65,26.7,4.72,0.334
481,1.65,26.7,4.72,0.334
481,1.66,26.7,4.73,0.335
481,1.66,26.7,4.73,0.335
480,1.66,26.7,4.74,0.335
480,1.66,26.7,4.75,0.336
480,1.66,26.6,4.75,0.336
479,1.67,26.6,4.76,0.337
479,1.67,26.6,4.76,0.337
479,1.67,26.6,4.77,0.337
478,1.67,26.6,4.78,0.338
478,1.67,26.5,4.78,0.338
477,1.68,26.5,4.79,0.339
477,1.68,26.5,4.79,0.339
477,1.68,26.5,4.80,0.339
476,1.68,26.5,4.80,0.340
476,1.68,26.4,4.81,0.340
475,1.68,26.4,4.81,0.340
475,1.69,26.4,4.82,0.341
474,1.69,26.3,4.83,0.341
474,1.69,26.3,4.83,0.342
473,1.69,26.3,4.84,0.342
472,1.69,26.2,4.84,0.342
472,1.70,26.2,4.85,0.343
471,1.70,26.2,4.85,0.343
470,1.70,26.1,4.86,0.344
469,1.70,26.1,4.86,0.344
469,1.70,26.0,4.87,0.344
468,1.71,26.0,4.88,0.345
467,1.71,25.9,4.88,0.345
466,1.71,25.9,4.89,0.346
465,1.71,25.8,4.89,0.346
464,1.71,25.8,4.90,0.346
462,1.72,25.7,4.91,0.347
461,1.72,25.6,4.91,0.347
460,1.72,25.6,4.91,0.348
459,1.72,25.5,4.92,0.348
457,1.73,25.4,4.93,0.348
456,1.73,25.3,4.93,0.349
454,1.73,25.2,4.94,0.349
453,1.73,25.1,4.94,0.350
451,1.73,25.0,4.95,0.350
449,1.73,24.9,4.96,0.350
447,1.74,24.8,4.96,0.351
445,1.74,24.7,4.97,0.351
442,1.74,24.6,4.97,0.352
440,1.74,24.5,4.98,0.352
438,1.74,24.3,4.98,0.352
435,1.75,24.2,4.99,0.353
432,1.75,24.0,5.00,0.353
428,1.75,23.8,5.00,0.353
417,1.75,23.2,5.00,0.354
373,1.75,20.7,5.01,0.354
303,1.76,16.8,5.02,0.355
238,1.76,13.2,5.02,0.355
180,1.76,10.0,5.03,0.355
121,1.76,6.71,5.03,0.356
52.7,1.76,2.93,5.04,0.356
-12.4,1.77,-0.688,5.05,0.357
-16.2,1.77,-0.897,5.05,0.357
-16.3,1.77,-0.907,5.06,0.357
-16.3,1.77,-0.907,5.06,0.358
-16.3,1.77,-0.907,5.07,0.358
-16.3,1.78,-0.907,5.07,0.359
-16.3,1.78,-0.907,5.08,0.359
-16.3,1.78,-0.907,5.08,0.359
-16.3,1.78,-0.907,5.09,0.360
-16.3,1.78,-0.907,5.10,0.360
-16.3,1.78,-0.907,5.10,0.361
-16.3,1.79,-0.907,5.11,0.361
-16.3,1.79,-0.907,5.11,0.361
-16.3,1.79,-0.907,5.12,0.362
-16.3,1.79,-0.907,5.13,0.362
-16.3,1.80,-0.907,5.13,0.363
-16.3,1.80,-0.907,5.14,0.363
-16.3,1.80,-0.907,5.14,0.363
-16.3,1.80,-0.907,5.15,0.364
-16.3,1.80,-0.907,5.15,0.364
-16.3,1.81,-0.907,5.16,0.365
-16.3,1.81,-0.907,5.16,0.365
-16.3,1.81,-0.907,5.17,0.365
-16.3,1.81,-0.907,5.17,0.366
-16.3,1.81,-0.907,5.18,0.366
-16.3,1.81,-0.907,5.18,0.366
-16.3,1.82,-0.907,5.19,0.367
-16.5,1.82,-0.916,5.20,0.367
-16.5,1.82,-0.917,5.20,0.368
-16.3,1.82,-0.908,5.21,0.368
-16.3,1.82,-0.907,5.21,0.368
-16.3,1.83,-0.907,5.22,0.369
-16.3,1.83,-0.907,5.22,0.369
-16.3,1.83,-0.907,5.23,0.370
-16.3,1.83,-0.907,5.24,0.370
-16.3,1.83,-0.907,5.24,0.370
-16.3,1.84,-0.907,5.25,0.371
-16.3,1.84,-0.907,5.25,0.371
-16.3,1.84,-0.907,5.26,0.372
-16.5,1.84,-0.917,5.26,0.372
-16.5,1.84,-0.917,5.27,0.372
-16.5,1.85,-0.917,5.28,0.373
-16.4,1.85,-0.911,5.28,0.373
-16.3,1.85,-0.907,5.29,0.374
-16.3,1.85,-0.907,5.29,0.374
-16.3,1.85,-0.907,5.30,0.374
-16.3,1.86,-0.907,5.30,0.375
-16.3,1.86,-0.907,5.31,0.375
-16.3,1.86,-0.907,5.32,0.376
-16.3,1.86,-0.907,5.32,0.376
-16.3,1.86,-0.907,5.33,0.376
-16.3,1.87,-0.907,5.33,0.377
-16.3,1.87,-0.907,5.34,0.377
-16.3,1.87,-0.907,5.34,0.378
-16.3,1.87,-0.907,5.35,0.378
-16.3,1.87,-0.907,5.36,0.378
-16.3,1.88,-0.907,5.36,0.379
-16.3,1.88,-0.907,5.37,0.379
-16.3,1.88,-0.907,5.37,0.379
-16.3,1.88,-0.907,5.38,0.380
-16.3,1.88,-0.907,5.39,0.380
-16.4,1.89,-0.911,5.39,0.381
-16.5,1.89,-0.917,5.39,0.381
-16.5,1.89,-0.917,5.40,0.381
-16.5,1.89,-0.917,5.41,0.382
-16.5,1.89,-0.917,5.41,0.382
-16.5,1.90,-0.917,5.42,0.383
-16.5,1.90,-0.917,5.42,0.383
-16.5,1.90,-0.916,5.43,0.383
-16.3,1.90,-0.907,5.43,0.384
-16.3,1.90,-0.907,5.44,0.384
-16.3,1.91,-0.907,5.44,0.385
-16.3,1.91,-0.907,5.45,0.385
-16.3,1.91,-0.907,5.46,0.385
-16.3,1.91,-0.907,5.46,0.386
-16.3,1.91,-0.907,5.47,0.386
-16.3,1.92,-0.907,5.47,0.387
-16.3,1.92,-0.907,5.48,0.387
-16.3,1.92,-0.907,5.48,0.387
-16.3,1.92,-0.907,5.49,0.388
-16.3,1.92,-0.907,5.50,0.388
-16.3,1.93,-0.907,5.50,0.389
-16.5,1.93,-0.914,5.51,0.389
-16.3,1.93,-0.907,5.51,0.389
-16.4,1.93,-0.910,5.52,0.390
-16.5,1.93,-0.917,5.52,0.390
-16.5,1.94,-0.917,5.53,0.391
-16.5,1.94,-0.917,5.53,0.391
-16.3,1.94,-0.907,5.54,0.391
-16.3,1.94,-0.907,5.55,0.392
-16.3,1.94,-0.907,5.55,0.392
-16.3,1.94,-0.907,5.56,0.392
-16.3,1.95,-0.907,5.56,0.393
-16.3,1.95,-0.907,5.57,0.393
-16.3,1.95,-0.907,5.57,0.394
-16.3,1.95,-0.907,5.58,0.394
-16.3,1.96,-0.907,5.59,0.394
-16.3,1.96,-0.907,5.59,0.395
-16.3,1.96,-0.907,5.60,0.395
-16.3,1.96,-0.907,5.60,0.396
-16.3,1.96,-0.907,5.61,0.396
-16.3,1.97,-0.907,5.61,0.396
-16.3,1.97,-0.907,5.62,0.397
-16.3,1.97,-0.907,5.62,0.397
-16.3,1.97,-0.907,5.63,0.398
-16.3,1.97,-0.907,5.64,0.398
-16.3,1.97,-0.907,5.64,0.398
-16.3,1.98,-0.907,5.65,0.399
-16.3,1.98,-0.907,5.65,0.399
-16.3,1.98,-0.907,5.66,0.400
-16.3,1.98,-0.907,5.66,0.400
-16.3,1.98,-0.907,5.67,0.400
-16.3,1.99,-0.907,5.68,0.401
-16.3,1.99,-0.907,5.68,0.401
-16.5,1.99,-0.914,5.69,0.402
-16.5,1.99,-0.917,5.69,0.402
-16.5,1.99,-0.917,5.70,0.402
-16.5,2.00,-0.917,5.70,0.403
-16.4,2.00,-0.911,5.71,0.403
-16.3,2.00,-0.907,5.71,0.404
-16.3,2.00,-0.907,5.72,0.404
-16.3,2.00,-0.907,5.72,0.404
-16.3,2.01,-0.907,5.73,0.405
-16.3,2.01,-0.907,5.74,0.405
-16.3,2.01,-0.907,5.74,0.406
-16.3,2.01,-0.907,5.75,0.406
-16.3,2.01,-0.907,5.75,0.406
-16.5,2.02,-0.917,5.76,0.407
-16.5,2.02,-0.917,5.77,0.407
-16.5,2.02,-0.917,5.77,0.407
-16.5,2.02,-0.917,5.78,0.408
-16.3,2.02,-0.907,5.78,0.408
-16.3,2.03,-0.907,5.79,0.409
-16.3,2.03,-0.907,5.79,0.409
-16.3,2.03,-0.907,5.80,0.409
-16.3,2.03,-0.907,5.80,0.410
-16.3,2.03,-0.907,5.81,0.410
-16.3,2.04,-0.907,5.82,0.411
-16.3,2.04,-0.907,5.82,0.411
-16.3,2.04,-0.907,5.83,0.411
-16.3,2.04,-0.907,5.83,0.412
-16.3,2.04,-0.907,5.84,0.412
-16.3,2.05,-0.907,5.84,0.413
-16.3,2.05,-0.907,5.85,0.413
-16.3,2.05,-0.907,5.86,0.413
-16.3,2.05,-0.907,5.86,0.414
-16.3,2.05,-0.907,5.87,0.414
-16.3,2.06,-0.907,5.87,0.415
-16.3,2.06,-0.907,5.88,0.415
-16.3,2.06,-0.907,5.88,0.415
-16.3,2.06,-0.907,5.89,0.416
-16.3,2.06,-0.907,5.90,0.416
-16.3,2.07,-0.907,5.90,0.417
-16.3,2.07,-0.907,5.91,0.417
-16.3,2.07,-0.907,5.91,0.417
-16.3,2.07,-0.907,5.92,0.418
-16.4,2.07,-0.913,5.92,0.418
-16.5,2.07,-0.916,5.93,0.419
-16.5,2.08,-0.917,5.94,0.419
-16.5,2.08,-0.917,5.94,0.419
-16.5,2.08,-0.917,5.95,0.420
-16.5,2.08,-0.917,5.95,0.420
-16.3,2.08,-0.907,5.95,0.420
-16.3,2.09,-0.907,5.96,0.421
-16.3,2.09,-0.907,5.97,0.421
-16.3,2.09,-0.907,5.97,0.422
-16.3,2.09,-0.907,5.98,0.422
-16.3,2.10,-0.907,5.99,0.422
-16.3,2.10,-0.907,5.99,0.423
-16.3,2.10,-0.907,6.00,0.423
-16.3,2.10,-0.907,6.00,0.424
-16.5,2.10,-0.915,6.01,0.424
-16.3,2.10,-0.907,6.01,0.424
-16.4,2.11,-0.909,6.02,0.425
-16.5,2.11,-0.917,6.02,0.425
-16.3,2.11,-0.907,6.03,0.426
-16.3,2.11,-0.907,6.04,0.426
-16.3,2.12,-0.907,6.04,0.426
-16.3,2.12,-0.907,6.05,0.427
-16.3,2.12,-0.907,6.05,0.427
-16.3,2.12,-0.907,6.06,0.428
-16.3,2.12,-0.907,6.06,0.428
-16.3,2.12,-0.907,6.07,0.428
-16.3,2.13,-0.907,6.08,0.429
-16.3,2.13,-0.907,6.08,0.429
-16.3,2.13,-0.907,6.08,0.430
-16.3,2.13,-0.907,6.09,0.430
-16.3,2.13,-0.907,6.10,0.430
-16.3,2.14,-0.907,6.10,0.431
-16.3,2.14,-0.907,6.11,0.431
-16.3,2.14,-0.907,6.11,0.432
-16.3,2.14,-0.907,6.12,0.432
-16.3,2.14,-0.907,6.13,0.432
-16.3,2.15,-0.907,6.13,0.433
-16.3,2.15,-0.907,6.14,0.433
-16.3,2.15,-0.907,6.14,0.433
-16.3,2.15,-0.907,6.15,0.434
-16.3,2.15,-0.907,6.15,0.434
-16.3,2.16,-0.907,6.16,0.435
-16.3,2.16,-0.907,6.16,0.435
-16.3,2.16,-0.907,6.17,0.435
-16.3,2.16,-0.907,6.18,0.436
-16.3,2.16,-0.907,6.18,0.436
-16.3,2.17,-0.907,6.19,0.437
-16.3,2.17,-0.907,6.19,0.437
-16.3,2.17,-0.907,6.20,0.437
-16.4,2.17,-0.912,6.20,0.438
-16.4,2.17,-0.910,6.21,0.438
-16.3,2.18,-0.907,6.22,0.439
-16.3,2.18,-0.907,6.22,0.439
-16.3,2.18,-0.907,6.23,0.439
-16.3,2.18,-0.907,6.23,0.440
-16.3,2.18,-0.907,6.24,0.440
-16.3,2.19,-0.907,6.25,0.441
-16.4,2.19,-0.910,6.25,0.441
-16.5,2.19,-0.917,6.26,0.441
-16.4,2.19,-0.913,6.26,0.442
-16.3,2.19,-0.907,6.27,0.442
-16.3,2.20,-0.907,6.27,0.443
-16.3,2.20,-0.907,6.28,0.443
-16.3,2.20,-0.907,6.28,0.443
-16.3,2.20,-0.907,6.29,0.444
-16.3,2.20,-0.907,6.30,0.444
-16.3,2.20,-0.907,6.30,0.445
-16.3,2.21,-0.907,6.31,0.445
-16.3,2.21,-0.907,6.31,0.445
-16.4,2.21,-0.912,6.32,0.446
-16.5,2.21,-0.917,6.32,0.446
-16.5,2.21,-0.917,6.33,0.446
-16.5,2.22,-0.917,6.33,0.447
-16.5,2.22,-0.917,6.34,0.447
-16.5,2.22,-0.917,6.34,0.448
-16.5,2.22,-0.917,6.35,0.448
-16.5,2.23,-0.917,6.36,0.448
-16.5,2.23,-0.917,6.36,0.449
-16.5,2.23,-0.917,6.37,0.449
-16.4,2.23,-0.911,6.37,0.450
-16.3,2.23,-0.907,6.38,0.450
-16.4,2.23,-0.914,6.38,0.450
-16.5,2.24,-0.917,6.39,0.451
-16.5,2.24,-0.917,6.40,0.451
-16.5,2.24,-0.917,6.40,0.452
-16.5,2.24,-0.917,6.41,0.452
-16.5,2.24,-0.917,6.41,0.452
-16.5,2.25,-0.917,6.42,0.453
-16.3,2.25,-0.907,6.42,0.453
-16.3,2.25,-0.907,6.43,0.454
-16.5,2.25,-0.917,6.44,0.454
-16.5,2.25,-0.917,6.44,0.454
-16.5,2.26,-0.917,6.45,0.455
-16.5,2.26,-0.917,6.45,0.455
-16.5,2.26,-0.917,6.46,0.456
-16.5,2.26,-0.917,6.47,0.456
-16.5,2.26,-0.917,6.47,0.456
-16.5,2.27,-0.917,6.47,0.457
-16.4,2.27,-0.912,6.48,0.457
-16.5,2.27,-0.916,6.49,0.458
-16.5,2.27,-0.917,6.49,0.458
-16.5,2.27,-0.917,6.50,0.458
-16.5,2.28,-0.917,6.50,0.459
-16.5,2.28,-0.917,6.51,0.459
-16.4,2.28,-0.911,6.51,0.459
-16.3,2.28,-0.907,6.52,0.460
-16.3,2.28,-0.907,6.52,0.460
-16.3,2.29,-0.907,6.53,0.461
-16.3,2.29,-0.907,6.54,0.461
-16.3,2.29,-0.907,6.54,0.461
-16.3,2.29,-0.907,6.55,0.462
-16.3,2.29,-0.907,6.55,0.462
-16.3,2.30,-0.907,6.56,0.463
-16.3,2.30,-0.907,6.56,0.463
-16.3,2.30,-0.907,6.57,0.463
-16.3,2.30,-0.907,6.58,0.464
-16.3,2.30,-0.907,6.58,0.464
-16.3,2.31,-0.907,6.59,0.465
-16.3,2.31,-0.907,6.59,0.465
-16.3,2.31,-0.907,6.60,0.465
-16.3,2.31,-0.907,6.61,0.466
-16.3,2.31,-0.907,6.61,0.466
-16.3,2.32,-0.907,6.62,0.467
-16.3,2.32,-0.907,6.62,0.467
-16.3,2.32,-0.907,6.63,0.467
-16.5,2.32,-0.917,6.63,0.468
-16.3,2.32,-0.908,6.64,0.468
-16.3,2.33,-0.907,6.64,0.469
-16.3,2.33,-0.907,6.65,0.469
-16.3,2.33,-0.907,6.66,0.469
-16.3,2.33,-0.907,6.66,0.470
-16.3,2.33,-0.907,6.67,0.470
-16.3,2.33,-0.907,6.67,0.471
-16.3,2.34,-0.907,6.68,0.471
-16.3,2.34,-0.907,6.68,0.471
-16.3,2.34,-0.907,6.69,0.472
-16.3,2.34,-0.907,6.69,0.472
-16.3,2.35,-0.907,6.70,0.472
-16.5,2.35,-0.916,6.70,0.473
-16.3,2.35,-0.907,6.71,0.473
-16.3,2.35,-0.907,6.72,0.474
-16.4,2.35,-0.913,6.72,0.474
-16.5,2.35,-0.915,6.73,0.474
-16.4,2.36,-0.914,6.73,0.475
-16.3,2.36,-0.907,6.74,0.475
-16.3,2.36,-0.907,6.74,0.476
-16.3,2.36,-0.907,6.75,0.476
-16.3,2.36,-0.907,6.76,0.476
-16.3,2.37,-0.907,6.76,0.477
-16.3,2.37,-0.907,6.77,0.477
-16.3,2.37,-0.907,6.77,0.478
-16.3,2.37,-0.907,6.78,0.478
-16.3,2.37,-0.907,6.78,0.478
-16.3,2.38,-0.907,6.79,0.479
-16.3,2.38,-0.907,6.80,0.479
-16.3,2.38,-0.907,6.80,0.480
-16.3,2.38,-0.907,6.81,0.480
-16.3,2.38,-0.907,6.81,0.480
-16.3,2.39,-0.907,6.82,0.481
-16.3,2.39,-0.907,6.83,0.481
-16.3,2.39,-0.907,6.83,0.482
-16.3,2.39,-0.907,6.83,0.482
-16.4,2.39,-0.912,6.84,0.482
-16.3,2.40,-0.907,6.85,0.483
-16.3,2.40,-0.907,6.85,0.483
-16.3,2.40,-0.908,6.86,0.484
-16.5,2.40,-0.917,6.86,0.484
-16.5,2.40,-0.917,6.87,0.484
-16.5,2.41,-0.917,6.87,0.485
-16.5,2.41,-0.917,6.88,0.485
-16.5,2.41,-0.917,6.89,0.485
-16.5,2.41,-0.917,6.89,0.486
-16.5,2.41,-0.917,6.90,0.486
-16.5,2.42,-0.917,6.90,0.487
-16.5,2.42,-0.917,6.91,0.487
-16.3,2.42,-0.907,6.91,0.487
-16.3,2.42,-0.907,6.92,0.488
-16.3,2.42,-0.907,6.92,0.488
-16.3,2.43,-0.907,6.93,0.489
-16.3,2.43,-0.907,6.94,0.489
-16.3,2.43,-0.907,6.94,0.489
-16.3,2.43,-0.907,6.95,0.490
-16.3,2.43,-0.907,6.95,0.490
-16.3,2.44,-0.907,6.96,0.491
-16.3,2.44,-0.907,6.97,0.491
-16.3,2.44,-0.907,6.97,0.491
-16.3,2.44,-0.907,6.98,0.492
-16.3,2.44,-0.907,6.98,0.492
-16.3,2.45,-0.907,6.99,0.493
-16.3,2.45,-0.907,6.99,0.493
-16.3,2.45,-0.907,7.00,0.493
-16.3,2.45,-0.907,7.00,0.494
-16.3,2.45,-0.907,7.01,0.494
-16.3,2.46,-0.907,7.02,0.495
-16.3,2.46,-0.907,7.02,0.495
-16.3,2.46,-0.907,7.03,0.495
-16.3,2.46,-0.907,7.03,0.496