File: Thermal Chamber for UTM/rubber70%.csv
Force (N),Position (mm),Stress (MPa),Strain (%),Time (min)
0.167,0.00,0.0104,0.00,0.00313
0.333,0.0260,0.0208,0.0868,0.00608
0.333,0.0562,0.0208,0.187,0.00904
0.500,0.0851,0.0312,0.284,0.0120
0.500,0.115,0.0312,0.382,0.0149
0.630,0.144,0.0394,0.481,0.0179
0.667,0.174,0.0417,0.579,0.0209
0.667,0.204,0.0417,0.680,0.0238
0.833,0.233,0.0521,0.776,0.0268
0.833,0.264,0.0521,0.878,0.0297
0.833,0.293,0.0521,0.976,0.0327
1.00,0.323,0.0625,1.08,0.0356
1.00,0.351,0.0625,1.17,0.0386
1.17,0.381,0.0729,1.27,0.0415
1.17,0.410,0.0729,1.37,0.0445
1.17,0.441,0.0729,1.47,0.0475
1.17,0.470,0.0729,1.57,0.0504
1.33,0.500,0.0833,1.67,0.0534
1.43,0.529,0.0892,1.76,0.0563
1.33,0.559,0.0833,1.86,0.0593
1.50,0.588,0.0937,1.96,0.0622
1.50,0.618,0.0937,2.06,0.0652
1.67,0.648,0.104,2.16,0.0681
1.67,0.677,0.104,2.26,0.0711
1.67,0.707,0.104,2.36,0.0741
1.83,0.735,0.115,2.45,0.0770
1.83,0.765,0.115,2.55,0.0800
2.00,0.795,0.125,2.65,0.0829
2.00,0.825,0.125,2.75,0.0859
2.00,0.854,0.125,2.85,0.0888
2.00,0.884,0.125,2.95,0.0918
2.17,0.912,0.135,3.04,0.0947
2.17,0.943,0.135,3.14,0.0977
2.32,0.972,0.145,3.24,0.101
2.23,1.00,0.139,3.34,0.104
2.33,1.03,0.146,3.44,0.107
2.33,1.06,0.146,3.54,0.110
2.50,1.09,0.156,3.63,0.112
2.50,1.12,0.156,3.73,0.115
2.50,1.15,0.156,3.83,0.118
2.67,1.18,0.167,3.93,0.121
2.67,1.21,0.167,4.03,0.124
2.83,1.24,0.177,4.13,0.127
2.83,1.27,0.177,4.23,0.130
2.83,1.30,0.177,4.33,0.133
3.00,1.33,0.187,4.42,0.136
3.00,1.36,0.187,4.52,0.139
3.00,1.39,0.187,4.62,0.142
3.00,1.42,0.187,4.72,0.145
3.17,1.44,0.198,4.82,0.148
3.17,1.48,0.198,4.92,0.151
3.17,1.50,0.198,5.02,0.154
3.33,1.53,0.208,5.11,0.157
3.33,1.56,0.208,5.21,0.160
3.33,1.59,0.208,5.31,0.163
3.33,1.62,0.208,5.41,0.166
3.50,1.65,0.219,5.51,0.169
3.50,1.68,0.219,5.60,0.172
3.50,1.71,0.219,5.70,0.175
3.67,1.74,0.229,5.80,0.178
3.67,1.77,0.229,5.90,0.180
3.72,1.80,0.232,6.00,0.183
3.72,1.83,0.233,6.10,0.186
3.83,1.86,0.240,6.19,0.189
3.83,1.89,0.240,6.30,0.192
4.00,1.92,0.250,6.39,0.195
4.00,1.95,0.250,6.49,0.198
4.00,1.98,0.250,6.59,0.201
4.00,2.01,0.250,6.69,0.204
4.17,2.04,0.260,6.79,0.207
4.17,2.07,0.260,6.89,0.210
4.17,2.10,0.260,6.99,0.213
4.33,2.12,0.271,7.08,0.216
4.33,2.15,0.271,7.18,0.219
4.33,2.18,0.271,7.28,0.222
4.50,2.21,0.281,7.38,0.225
4.50,2.24,0.281,7.48,0.228
4.50,2.27,0.281,7.58,0.231
4.67,2.30,0.292,7.68,0.234
4.67,2.33,0.292,7.77,0.237
4.67,2.36,0.292,7.87,0.240
4.67,2.39,0.292,7.97,0.243
4.83,2.42,0.302,8.07,0.245
4.83,2.45,0.302,8.17,0.248
4.83,2.48,0.302,8.27,0.251
5.00,2.51,0.312,8.36,0.254
5.00,2.54,0.312,8.46,0.257
5.00,2.57,0.312,8.56,0.260
5.04,2.60,0.315,8.66,0.263
5.17,2.63,0.323,8.76,0.266
5.17,2.66,0.323,8.86,0.269
5.17,2.69,0.323,8.96,0.272
5.17,2.72,0.323,9.05,0.275
5.33,2.75,0.333,9.15,0.278
5.33,2.78,0.333,9.25,0.281
5.50,2.80,0.344,9.35,0.284
5.50,2.83,0.344,9.45,0.287
5.50,2.86,0.344,9.55,0.290
5.67,2.89,0.354,9.64,0.293
5.67,2.92,0.354,9.74,0.296
5.67,2.95,0.354,9.84,0.299
5.67,2.98,0.354,9.94,0.302
5.77,3.01,0.360,10.0,0.305
5.80,3.04,0.362,10.1,0.308
5.83,3.07,0.365,10.2,0.311
5.83,3.10,0.365,10.3,0.313
5.85,3.13,0.366,10.4,0.316
6.00,3.16,0.375,10.5,0.319
6.00,3.19,0.375,10.6,0.322
6.16,3.22,0.385,10.7,0.325
6.17,3.25,0.385,10.8,0.328
6.17,3.28,0.385,10.9,0.331
6.17,3.31,0.385,11.0,0.334
6.33,3.34,0.396,11.1,0.337
6.33,3.37,0.396,11.2,0.340
6.33,3.39,0.396,11.3,0.343
6.33,3.42,0.396,11.4,0.346
6.50,3.46,0.406,11.5,0.349
6.50,3.48,0.406,11.6,0.352
6.50,3.51,0.406,11.7,0.355
6.67,3.54,0.417,11.8,0.358
6.67,3.57,0.417,11.9,0.361
6.67,3.60,0.417,12.0,0.364
6.67,3.63,0.417,12.1,0.367
6.67,3.66,0.417,12.2,0.370
6.83,3.69,0.427,12.3,0.373
6.83,3.72,0.427,12.4,0.376
6.83,3.75,0.427,12.5,0.378
6.83,3.78,0.427,12.6,0.381
7.00,3.81,0.437,12.7,0.384
7.00,3.84,0.437,12.8,0.387
7.17,3.87,0.448,12.9,0.390
7.17,3.90,0.448,13.0,0.393
7.17,3.93,0.448,13.1,0.396
7.17,3.96,0.448,13.2,0.399
7.33,3.99,0.458,13.3,0.402
7.33,4.02,0.458,13.4,0.405
7.33,4.05,0.458,13.5,0.408
7.33,4.08,0.458,13.6,0.411
7.50,4.11,0.469,13.7,0.414
7.50,4.13,0.469,13.8,0.417
7.50,4.16,0.469,13.9,0.420
7.61,4.19,0.475,14.0,0.423
7.67,4.22,0.479,14.1,0.426
7.67,4.25,0.479,14.2,0.429
7.76,4.28,0.485,14.3,0.432
7.83,4.31,0.490,14.4,0.435
7.83,4.34,0.490,14.5,0.438
7.83,4.37,0.490,14.6,0.441
8.00,4.40,0.500,14.7,0.444
8.00,4.43,0.500,14.8,0.446
8.00,4.46,0.500,14.9,0.449
8.00,4.49,0.500,15.0,0.452
8.17,4.52,0.510,15.1,0.455
8.17,4.55,0.510,15.2,0.458
8.17,4.58,0.510,15.3,0.461
8.25,4.61,0.516,15.4,0.464
8.33,4.64,0.521,15.5,0.467
8.33,4.67,0.521,15.6,0.470
8.50,4.70,0.531,15.7,0.473
8.50,4.73,0.531,15.8,0.476
8.50,4.76,0.531,15.9,0.479
8.50,4.79,0.531,16.0,0.482
8.67,4.81,0.542,16.0,0.485
8.67,4.84,0.542,16.1,0.488
8.67,4.87,0.542,16.2,0.491
8.83,4.90,0.552,16.3,0.494
8.83,4.93,0.552,16.4,0.497
8.83,4.96,0.552,16.5,0.500
8.95,4.99,0.559,16.6,0.503
9.00,5.02,0.562,16.7,0.506
9.00,5.05,0.562,16.8,0.509
9.00,5.08,0.562,16.9,0.511
9.00,5.11,0.562,17.0,0.514
9.17,5.14,0.573,17.1,0.517
9.17,5.17,0.573,17.2,0.520
9.17,5.20,0.573,17.3,0.523
9.17,5.23,0.573,17.4,0.526
9.33,5.26,0.583,17.5,0.529
9.33,5.29,0.583,17.6,0.532
9.33,5.32,0.583,17.7,0.535
9.45,5.35,0.591,17.8,0.538
9.33,5.38,0.583,17.9,0.541
9.50,5.41,0.594,18.0,0.544
9.67,5.43,0.604,18.1,0.547
9.53,5.46,0.596,18.2,0.550
9.67,5.49,0.604,18.3,0.553
9.67,5.52,0.604,18.4,0.556
9.83,5.55,0.615,18.5,0.559
9.83,5.58,0.615,18.6,0.562
9.83,5.61,0.615,18.7,0.565
9.93,5.64,0.621,18.8,0.568
10.0,5.67,0.625,18.9,0.571
10.0,5.70,0.625,19.0,0.574
10.2,5.73,0.635,19.1,0.577
10.0,5.76,0.626,19.2,0.579
10.2,5.79,0.635,19.3,0.582
10.2,5.82,0.635,19.4,0.585
10.2,5.85,0.635,19.5,0.588
10.3,5.88,0.646,19.6,0.591
10.3,5.91,0.646,19.7,0.594
10.3,5.94,0.647,19.8,0.597
10.3,5.97,0.646,19.9,0.600
10.5,6.00,0.656,20.0,0.603
10.5,6.03,0.656,20.1,0.606
10.5,6.06,0.656,20.2,0.609
10.5,6.09,0.656,20.3,0.612
10.7,6.12,0.667,20.4,0.615
10.7,6.14,0.667,20.5,0.618
10.7,6.17,0.667,20.6,0.621
10.8,6.20,0.677,20.7,0.624
10.7,6.23,0.667,20.8,0.627
10.8,6.26,0.677,20.9,0.630
10.8,6.29,0.677,21.0,0.633
10.8,6.32,0.677,21.1,0.636
10.8,6.35,0.677,21.2,0.639
11.0,6.38,0.687,21.3,0.642
11.0,6.41,0.687,21.4,0.644
11.0,6.44,0.687,21.5,0.647
11.2,6.47,0.698,21.6,0.650
11.0,6.50,0.687,21.7,0.653
11.2,6.53,0.698,21.8,0.656
11.3,6.56,0.708,21.9,0.659
11.3,6.59,0.708,22.0,0.662
11.3,6.62,0.708,22.1,0.665
11.3,6.65,0.708,22.2,0.668
11.5,6.68,0.719,22.3,0.671
11.5,6.71,0.719,22.4,0.674
11.5,6.74,0.719,22.5,0.677
11.5,6.77,0.719,22.6,0.680
11.5,6.80,0.719,22.7,0.683
11.7,6.82,0.729,22.7,0.686
11.7,6.85,0.729,22.8,0.689
11.7,6.88,0.729,22.9,0.692
11.7,6.91,0.729,23.0,0.695
11.7,6.94,0.734,23.1,0.698
11.8,6.97,0.740,23.2,0.701
11.8,7.00,0.740,23.3,0.704
11.8,7.03,0.740,23.4,0.707
12.0,7.06,0.750,23.5,0.710
12.0,7.09,0.750,23.6,0.712
12.1,7.12,0.758,23.7,0.715
12.0,7.15,0.750,23.8,0.718
12.0,7.18,0.750,23.9,0.721
12.2,7.21,0.760,24.0,0.724
12.0,7.24,0.753,24.1,0.727
12.2,7.27,0.760,24.2,0.730
12.2,7.30,0.760,24.3,0.733
12.2,7.33,0.760,24.4,0.736
12.3,7.36,0.771,24.5,0.739
12.3,7.39,0.771,24.6,0.742
12.3,7.42,0.771,24.7,0.745
12.5,7.45,0.781,24.8,0.748
12.5,7.47,0.781,24.9,0.751
12.5,7.50,0.781,25.0,0.754
12.5,7.53,0.781,25.1,0.757
12.7,7.56,0.792,25.2,0.760
12.7,7.59,0.792,25.3,0.763
12.7,7.62,0.792,25.4,0.766
12.8,7.65,0.802,25.5,0.769
12.7,7.68,0.792,25.6,0.772
12.8,7.71,0.802,25.7,0.775
12.8,7.74,0.802,25.8,0.777
12.8,7.77,0.802,25.9,0.780
12.8,7.80,0.802,26.0,0.783
13.0,7.83,0.812,26.1,0.786
13.0,7.86,0.812,26.2,0.789
13.0,7.89,0.812,26.3,0.792
13.0,7.92,0.812,26.4,0.795
13.2,7.95,0.823,26.5,0.798
13.2,7.98,0.823,26.6,0.801
13.2,8.01,0.823,26.7,0.804
13.2,8.04,0.823,26.8,0.807
13.2,8.07,0.828,26.9,0.810
13.3,8.09,0.833,27.0,0.813
13.3,8.12,0.833,27.1,0.816
13.3,8.15,0.833,27.2,0.819
13.5,8.18,0.844,27.3,0.822
13.5,8.21,0.844,27.4,0.825
13.5,8.24,0.844,27.5,0.828
13.5,8.27,0.844,27.6,0.831
13.5,8.30,0.844,27.7,0.834
13.5,8.33,0.844,27.8,0.837
13.7,8.36,0.854,27.9,0.840
13.7,8.39,0.854,28.0,0.843
13.7,8.42,0.854,28.1,0.845
13.7,8.45,0.854,28.2,0.848
13.8,8.48,0.865,28.3,0.851
13.8,8.51,0.865,28.4,0.854
13.8,8.54,0.865,28.5,0.857
14.0,8.57,0.873,28.6,0.860
14.0,8.60,0.875,28.7,0.863
14.0,8.63,0.875,28.8,0.866
14.2,8.66,0.885,28.9,0.869
14.2,8.69,0.885,29.0,0.872
14.2,8.72,0.885,29.1,0.875
14.2,8.75,0.885,29.2,0.878
14.2,8.78,0.885,29.3,0.881
14.3,8.80,0.896,29.3,0.884
14.3,8.83,0.896,29.4,0.887
14.3,8.86,0.896,29.5,0.890
14.3,8.89,0.896,29.6,0.893
14.3,8.92,0.896,29.7,0.896
14.4,8.95,0.902,29.8,0.899
14.5,8.98,0.906,29.9,0.902
14.5,9.01,0.906,30.0,0.905
14.5,9.04,0.906,30.1,0.908
14.5,9.07,0.907,30.2,0.911
14.7,9.10,0.917,30.3,0.913
14.7,9.13,0.917,30.4,0.916
14.8,9.16,0.927,30.5,0.919
14.8,9.19,0.927,30.6,0.922
14.8,9.22,0.927,30.7,0.925
15.0,9.25,0.937,30.8,0.928
14.8,9.28,0.927,30.9,0.931
15.0,9.31,0.937,31.0,0.934
15.0,9.34,0.937,31.1,0.937
15.0,9.37,0.937,31.2,0.940
15.0,9.40,0.937,31.3,0.943
15.0,9.43,0.937,31.4,0.946
15.2,9.46,0.948,31.5,0.949
15.2,9.48,0.948,31.6,0.952
15.2,9.51,0.948,31.7,0.955
15.3,9.54,0.958,31.8,0.958
15.3,9.57,0.958,31.9,0.961
15.3,9.60,0.958,32.0,0.964
15.3,9.63,0.958,32.1,0.967
15.5,9.66,0.969,32.2,0.970
15.5,9.69,0.969,32.3,0.973
15.5,9.72,0.969,32.4,0.976
15.5,9.75,0.969,32.5,0.978
15.5,9.78,0.969,32.6,0.981
15.5,9.81,0.971,32.7,0.984
15.7,9.84,0.979,32.8,0.987
15.7,9.87,0.979,32.9,0.990
15.8,9.90,0.990,33.0,0.993
15.8,9.93,0.990,33.1,0.996
15.8,9.96,0.990,33.2,0.999
15.8,9.99,0.990,33.3,1.00
15.8,10.0,0.990,33.4,1.01
16.0,10.0,1.00,33.5,1.01
16.0,10.1,1.00,33.6,1.01
16.0,10.1,1.00,33.7,1.01
16.2,10.1,1.01,33.8,1.02
16.2,10.2,1.01,33.9,1.02
16.2,10.2,1.01,34.0,1.02
16.2,10.2,1.01,34.1,1.03
16.2,10.3,1.01,34.2,1.03
16.2,10.3,1.01,34.3,1.03
16.2,10.3,1.01,34.4,1.03
16.3,10.3,1.02,34.5,1.04
16.3,10.4,1.02,34.6,1.04
16.5,10.4,1.03,34.7,1.04
16.5,10.4,1.03,34.8,1.05
16.5,10.5,1.03,34.9,1.05
16.5,10.5,1.03,35.0,1.05
16.7,10.5,1.04,35.1,1.06
16.7,10.5,1.04,35.2,1.06
16.7,10.6,1.04,35.3,1.06
16.7,10.6,1.04,35.4,1.06
16.7,10.6,1.04,35.5,1.07
16.7,10.7,1.04,35.6,1.07
16.8,10.7,1.05,35.7,1.07
16.8,10.7,1.05,35.8,1.08
16.8,10.8,1.05,35.8,1.08
17.0,10.8,1.06,35.9,1.08
16.8,10.8,1.05,36.0,1.08
17.0,10.8,1.06,36.1,1.09
17.0,10.9,1.06,36.2,1.09
17.0,10.9,1.06,36.3,1.09
17.2,10.9,1.07,36.4,1.10
17.2,11.0,1.07,36.5,1.10
17.3,11.0,1.08,36.6,1.10
17.3,11.0,1.08,36.7,1.11
17.3,11.1,1.08,36.8,1.11
17.3,11.1,1.08,36.9,1.11
17.3,11.1,1.08,37.0,1.11
17.3,11.1,1.08,37.1,1.12
17.5,11.2,1.09,37.2,1.12
17.5,11.2,1.09,37.3,1.12
17.5,11.2,1.09,37.4,1.13
17.5,11.3,1.10,37.5,1.13
17.7,11.3,1.10,37.6,1.13
17.7,11.3,1.10,37.7,1.14
17.7,11.3,1.10,37.8,1.14
17.8,11.4,1.11,37.9,1.14
17.8,11.4,1.11,38.0,1.14
17.8,11.4,1.11,38.1,1.15
17.8,11.5,1.11,38.2,1.15
18.0,11.5,1.12,38.3,1.15
18.0,11.5,1.12,38.4,1.16
18.0,11.6,1.12,38.5,1.16
18.2,11.6,1.14,38.6,1.16
18.2,11.6,1.14,38.7,1.16
18.0,11.6,1.13,38.8,1.17
18.2,11.7,1.14,38.9,1.17
18.2,11.7,1.14,39.0,1.17
18.2,11.7,1.14,39.1,1.18
18.3,11.8,1.15,39.2,1.18
18.3,11.8,1.15,39.3,1.18
18.3,11.8,1.15,39.4,1.19
18.3,11.8,1.15,39.5,1.19
18.3,11.9,1.15,39.6,1.19
18.5,11.9,1.16,39.7,1.19
18.5,11.9,1.16,39.8,1.20
18.5,12.0,1.16,39.9,1.20
18.5,12.0,1.16,40.0,1.20
18.5,12.0,1.16,40.1,1.21
18.7,12.1,1.17,40.2,1.21
18.7,12.1,1.17,40.3,1.21
18.7,12.1,1.17,40.4,1.21
18.7,12.1,1.17,40.5,1.22
18.7,12.2,1.17,40.6,1.22
18.8,12.2,1.18,40.7,1.22
18.8,12.2,1.18,40.8,1.23
18.8,12.3,1.18,40.9,1.23
18.8,12.3,1.18,41.0,1.23
19.0,12.3,1.19,41.1,1.24
19.0,12.4,1.19,41.2,1.24
19.0,12.4,1.19,41.3,1.24
19.2,12.4,1.20,41.4,1.24
19.2,12.4,1.20,41.5,1.25
19.2,12.5,1.20,41.6,1.25
19.2,12.5,1.20,41.7,1.25
19.3,12.5,1.21,41.8,1.26
19.3,12.6,1.21,41.9,1.26
19.3,12.6,1.21,42.0,1.26
19.3,12.6,1.21,42.1,1.27
19.3,12.6,1.21,42.2,1.27
19.5,12.7,1.22,42.3,1.27
19.5,12.7,1.22,42.4,1.27
19.5,12.7,1.22,42.5,1.28
19.5,12.8,1.22,42.6,1.28
19.6,12.8,1.23,42.6,1.28
19.7,12.8,1.23,42.7,1.29
19.7,12.9,1.23,42.8,1.29
19.8,12.9,1.24,42.9,1.29
19.8,12.9,1.24,43.0,1.29
19.7,12.9,1.23,43.1,1.30
19.8,13.0,1.24,43.2,1.30
20.0,13.0,1.25,43.3,1.30
20.0,13.0,1.25,43.4,1.31
20.0,13.1,1.25,43.5,1.31
20.2,13.1,1.26,43.6,1.31
20.0,13.1,1.25,43.7,1.32
20.0,13.2,1.25,43.8,1.32
20.2,13.2,1.26,43.9,1.32
20.2,13.2,1.26,44.0,1.32
20.2,13.2,1.26,44.1,1.33
20.2,13.3,1.26,44.2,1.33
20.3,13.3,1.27,44.3,1.33
20.5,13.3,1.28,44.4,1.34
20.5,13.4,1.28,44.5,1.34
20.5,13.4,1.28,44.6,1.34
20.5,13.4,1.28,44.7,1.34
20.7,13.4,1.29,44.8,1.35
20.7,13.5,1.29,44.9,1.35
20.7,13.5,1.29,45.0,1.35
20.7,13.5,1.29,45.1,1.36
20.7,13.6,1.29,45.2,1.36
20.7,13.6,1.29,45.3,1.36
20.8,13.6,1.30,45.4,1.37
20.8,13.7,1.30,45.5,1.37
20.8,13.7,1.30,45.6,1.37
20.9,13.7,1.30,45.7,1.37
21.0,13.7,1.31,45.8,1.38
21.0,13.8,1.31,45.9,1.38
21.0,13.8,1.31,46.0,1.38
21.0,13.8,1.31,46.1,1.39
21.0,13.9,1.31,46.2,1.39
21.2,13.9,1.32,46.3,1.39
21.2,13.9,1.32,46.4,1.40
21.2,13.9,1.32,46.5,1.40
21.3,14.0,1.33,46.6,1.40
21.3,14.0,1.33,46.7,1.40
21.3,14.0,1.33,46.8,1.41
21.3,14.1,1.33,46.9,1.41
21.4,14.1,1.34,47.0,1.41
21.5,14.1,1.34,47.1,1.42
21.5,14.2,1.34,47.2,1.42
21.6,14.2,1.35,47.3,1.42
21.5,14.2,1.34,47.4,1.42
21.5,14.2,1.34,47.5,1.43
21.7,14.3,1.35,47.6,1.43
21.7,14.3,1.35,47.7,1.43
21.7,14.3,1.35,47.8,1.44
21.7,14.4,1.35,47.9,1.44
21.7,14.4,1.35,48.0,1.44
21.7,14.4,1.35,48.1,1.45
21.8,14.4,1.36,48.2,1.45
21.8,14.5,1.36,48.3,1.45
21.8,14.5,1.36,48.4,1.45
21.8,14.5,1.36,48.5,1.46
22.0,14.6,1.37,48.6,1.46
22.0,14.6,1.37,48.7,1.46
22.0,14.6,1.38,48.8,1.47
22.2,14.7,1.39,48.9,1.47
22.2,14.7,1.39,49.0,1.47
22.2,14.7,1.39,49.1,1.48
22.2,14.7,1.39,49.2,1.48
22.2,14.8,1.39,49.2,1.48
22.3,14.8,1.40,49.3,1.48
22.3,14.8,1.40,49.4,1.49
22.3,14.9,1.40,49.5,1.49
22.3,14.9,1.40,49.6,1.49
22.5,14.9,1.41,49.7,1.50
22.5,15.0,1.41,49.8,1.50
22.5,15.0,1.41,49.9,1.50
22.5,15.0,1.41,50.0,1.50
22.7,15.0,1.42,50.1,1.51
22.7,15.1,1.42,50.2,1.51
22.7,15.1,1.42,50.3,1.51
22.7,15.1,1.42,50.4,1.52
22.7,15.2,1.42,50.5,1.52
22.7,15.2,1.42,50.6,1.52
22.7,15.2,1.42,50.7,1.53
22.8,15.2,1.43,50.8,1.53
22.8,15.3,1.43,50.9,1.53
22.8,15.3,1.43,51.0,1.53
22.8,15.3,1.43,51.1,1.54
23.0,15.4,1.44,51.2,1.54
23.0,15.4,1.44,51.3,1.54
23.0,15.4,1.44,51.4,1.55
23.2,15.5,1.45,51.5,1.55
23.2,15.5,1.45,51.6,1.55
23.2,15.5,1.45,51.7,1.55
23.2,15.5,1.45,51.8,1.56
23.3,15.6,1.46,51.9,1.56
23.3,15.6,1.46,52.0,1.56
23.3,15.6,1.46,52.1,1.57
23.5,15.7,1.47,52.2,1.57
23.5,15.7,1.47,52.3,1.57
23.5,15.7,1.47,52.4,1.58
23.5,15.8,1.47,52.5,1.58
23.5,15.8,1.47,52.6,1.58
23.5,15.8,1.47,52.7,1.58
23.5,15.8,1.47,52.8,1.59
23.5,15.9,1.47,52.9,1.59
23.7,15.9,1.48,53.0,1.59
23.7,15.9,1.48,53.1,1.60
23.7,16.0,1.48,53.2,1.60
23.7,16.0,1.48,53.3,1.60
23.8,16.0,1.49,53.4,1.61
23.8,16.0,1.49,53.5,1.61
23.8,16.1,1.49,53.6,1.61
23.9,16.1,1.49,53.7,1.61
23.8,16.1,1.49,53.8,1.62
24.0,16.2,1.50,53.9,1.62
23.9,16.2,1.49,54.0,1.62
24.0,16.2,1.50,54.1,1.63
24.0,16.3,1.50,54.2,1.63
24.0,16.3,1.50,54.3,1.63
24.0,16.3,1.50,54.4,1.63
24.2,16.3,1.51,54.5,1.64
24.2,16.4,1.51,54.6,1.64
24.2,16.4,1.51,54.7,1.64
24.2,16.4,1.51,54.8,1.65
24.2,16.5,1.51,54.9,1.65
24.2,16.5,1.51,55.0,1.65
24.2,16.5,1.51,55.1,1.66
24.3,16.5,1.52,55.2,1.66
24.3,16.6,1.52,55.3,1.66
24.3,16.6,1.52,55.4,1.66
24.3,16.6,1.52,55.5,1.67
24.3,16.7,1.52,55.6,1.67
24.5,16.7,1.53,55.7,1.67
24.5,16.7,1.53,55.8,1.68
24.5,16.8,1.53,55.9,1.68
24.5,16.8,1.53,55.9,1.68
24.7,16.8,1.54,56.0,1.68
24.7,16.8,1.54,56.1,1.69
24.7,16.9,1.54,56.2,1.69
24.8,16.9,1.55,56.3,1.69
24.8,16.9,1.55,56.4,1.70
24.8,17.0,1.55,56.5,1.70
24.8,17.0,1.55,56.6,1.70
25.0,17.0,1.56,56.7,1.71
25.0,17.1,1.56,56.8,1.71
25.0,17.1,1.56,56.9,1.71
25.2,17.1,1.57,57.0,1.71
25.2,17.1,1.57,57.1,1.72
25.2,17.2,1.57,57.2,1.72
25.2,17.2,1.57,57.3,1.72
25.2,17.2,1.57,57.4,1.73
25.3,17.3,1.58,57.5,1.73
25.3,17.3,1.58,57.6,1.73
25.3,17.3,1.58,57.7,1.74
25.3,17.3,1.58,57.8,1.74
25.5,17.4,1.59,57.9,1.74
25.5,17.4,1.59,58.0,1.74
25.5,17.4,1.59,58.1,1.75
25.6,17.5,1.60,58.2,1.75
25.5,17.5,1.59,58.3,1.75
25.7,17.5,1.60,58.4,1.76
25.7,17.6,1.60,58.5,1.76
25.7,17.6,1.60,58.6,1.76
25.8,17.6,1.61,58.7,1.76
25.8,17.6,1.61,58.8,1.77
25.8,17.7,1.61,58.9,1.77
25.8,17.7,1.61,59.0,1.77
26.0,17.7,1.62,59.1,1.78
26.0,17.8,1.62,59.2,1.78
26.0,17.8,1.62,59.3,1.78
26.0,17.8,1.62,59.4,1.79
26.2,17.8,1.64,59.5,1.79
26.2,17.9,1.64,59.6,1.79
26.2,17.9,1.64,59.7,1.79
26.3,17.9,1.65,59.8,1.80
26.2,18.0,1.64,59.9,1.80
26.3,18.0,1.65,60.0,1.80
26.3,18.0,1.65,60.1,1.81
26.3,18.1,1.65,60.2,1.81
26.5,18.1,1.66,60.3,1.81
26.5,18.1,1.66,60.4,1.81
26.5,18.1,1.66,60.5,1.82
26.5,18.2,1.66,60.6,1.82
26.5,18.2,1.66,60.7,1.82
26.7,18.2,1.67,60.8,1.83
26.7,18.3,1.67,60.9,1.83
26.8,18.3,1.68,61.0,1.83
26.8,18.3,1.68,61.1,1.84
26.8,18.4,1.68,61.2,1.84
26.8,18.4,1.68,61.3,1.84
26.8,18.4,1.68,61.4,1.84
26.8,18.4,1.68,61.5,1.85
27.0,18.5,1.69,61.6,1.85
27.0,18.5,1.69,61.7,1.85
27.2,18.5,1.70,61.8,1.86
27.2,18.6,1.70,61.9,1.86
27.2,18.6,1.70,62.0,1.86
27.3,18.6,1.71,62.1,1.87
27.2,18.6,1.70,62.2,1.87
27.3,18.7,1.71,62.3,1.87
27.3,18.7,1.71,62.4,1.87
27.3,18.7,1.71,62.5,1.88
27.3,18.8,1.71,62.5,1.88
27.3,18.8,1.71,62.6,1.88
27.5,18.8,1.72,62.7,1.89
27.5,18.9,1.72,62.8,1.89
27.5,18.9,1.72,62.9,1.89
27.7,18.9,1.73,63.0,1.89
27.7,18.9,1.73,63.1,1.90
27.8,19.0,1.74,63.2,1.90
27.7,19.0,1.73,63.3,1.90
27.8,19.0,1.74,63.4,1.91
27.8,19.1,1.74,63.5,1.91
27.8,19.1,1.74,63.6,1.91
27.8,19.1,1.74,63.7,1.92
28.0,19.1,1.75,63.8,1.92
28.0,19.2,1.75,63.9,1.92
28.0,19.2,1.75,64.0,1.92
28.0,19.2,1.75,64.1,1.93
28.2,19.3,1.76,64.2,1.93
28.2,19.3,1.76,64.3,1.93
28.2,19.3,1.76,64.4,1.94
28.2,19.4,1.76,64.5,1.94
28.3,19.4,1.77,64.6,1.94
28.3,19.4,1.77,64.7,1.94
28.3,19.4,1.77,64.8,1.95
28.5,19.5,1.78,64.9,1.95
28.5,19.5,1.78,65.0,1.95
28.5,19.5,1.78,65.1,1.96
28.5,19.6,1.78,65.2,1.96
28.7,19.6,1.79,65.3,1.96
28.7,19.6,1.79,65.4,1.97
28.7,19.7,1.79,65.5,1.97
28.7,19.7,1.79,65.6,1.97
28.7,19.7,1.79,65.7,1.97
28.8,19.7,1.80,65.8,1.98
28.8,19.8,1.80,65.9,1.98
28.9,19.8,1.81,66.0,1.98
28.8,19.8,1.80,66.1,1.99
29.0,19.9,1.81,66.2,1.99
29.0,19.9,1.81,66.3,1.99
29.0,19.9,1.81,66.4,2.00
29.0,19.9,1.81,66.5,2.00
29.0,20.0,1.81,66.6,2.00
29.0,20.0,1.81,66.7,2.00
29.2,20.0,1.82,66.8,2.01
29.2,20.1,1.82,66.9,2.01
29.3,20.1,1.83,67.0,2.01
29.3,20.1,1.83,67.1,2.02
29.3,20.2,1.83,67.2,2.02
29.5,20.2,1.84,67.3,2.02
29.5,20.2,1.84,67.4,2.02
29.5,20.2,1.84,67.5,2.03
29.5,20.3,1.84,67.6,2.03
29.5,20.3,1.84,67.7,2.03
29.6,20.3,1.85,67.8,2.04
29.7,20.4,1.85,67.9,2.04
29.7,20.4,1.85,68.0,2.04
29.7,20.4,1.86,68.1,2.05
29.7,20.4,1.85,68.2,2.05
29.7,20.5,1.85,68.3,2.05
29.8,20.5,1.86,68.4,2.05
29.8,20.5,1.86,68.5,2.06
29.8,20.6,1.86,68.6,2.06
30.0,20.6,1.87,68.7,2.06
30.0,20.6,1.87,68.8,2.07
30.0,20.7,1.87,68.9,2.07
30.0,20.7,1.87,69.0,2.07
30.0,20.7,1.87,69.1,2.08
30.2,20.7,1.89,69.2,2.08
30.2,20.8,1.89,69.3,2.08
30.2,20.8,1.89,69.3,2.08
30.3,20.8,1.90,69.4,2.09
30.3,20.9,1.90,69.5,2.09
30.3,20.9,1.90,69.6,2.09
30.3,20.9,1.90,69.7,2.10
30.5,21.0,1.91,69.8,2.10
30.5,21.0,1.91,69.9,2.10
30.5,21.0,1.91,70.0,2.10
30.7,21.0,1.92,70.1,2.11
30.7,21.1,1.92,70.2,2.11
30.7,21.1,1.92,70.3,2.11
30.7,21.1,1.92,70.4,2.12
30.8,21.2,1.93,70.5,2.12
30.8,21.2,1.93,70.6,2.12
30.8,21.2,1.93,70.7,2.13
30.8,21.2,1.93,70.8,2.13
31.0,21.3,1.94,70.9,2.13
31.0,21.3,1.94,71.0,2.13
31.2,21.3,1.95,71.1,2.14
31.2,21.4,1.95,71.2,2.14
31.2,21.4,1.95,71.3,2.14
31.2,21.4,1.95,71.4,2.15
31.2,21.5,1.95,71.5,2.15
31.3,21.5,1.96,71.6,2.15
31.3,21.5,1.96,71.7,2.15
31.4,21.5,1.96,71.8,2.16
31.3,21.6,1.96,71.9,2.16
31.5,21.6,1.97,72.0,2.16
31.5,21.6,1.97,72.1,2.17
31.7,21.7,1.98,72.2,2.17
31.7,21.7,1.98,72.3,2.17
31.7,21.7,1.98,72.4,2.18
31.7,21.8,1.98,72.5,2.18
31.8,21.8,1.99,72.6,2.18
31.8,21.8,1.99,72.7,2.18
32.0,21.8,2.00,72.8,2.19
32.0,21.9,2.00,72.9,2.19
32.0,21.9,2.00,73.0,2.19
32.0,21.9,2.00,73.1,2.20
32.0,22.0,2.00,73.2,2.20
32.2,22.0,2.01,73.3,2.20
32.2,22.0,2.01,73.4,2.21
32.2,22.0,2.01,73.5,2.21
32.2,22.1,2.01,73.6,2.21
32.3,22.1,2.02,73.7,2.21
32.3,22.1,2.02,73.8,2.22
32.3,22.2,2.02,73.9,2.22
32.5,22.2,2.03,74.0,2.22
32.5,22.2,2.03,74.1,2.23
32.5,22.3,2.03,74.2,2.23
32.7,22.3,2.04,74.3,2.23
32.7,22.3,2.04,74.4,2.23
32.7,22.3,2.04,74.5,2.24
32.7,22.4,2.04,74.6,2.24
32.8,22.4,2.05,74.7,2.24
32.8,22.4,2.05,74.8,2.25
32.8,22.5,2.05,74.9,2.25
32.8,22.5,2.05,75.0,2.25
32.8,22.5,2.05,75.1,2.26
33.0,22.5,2.06,75.2,2.26
33.0,22.6,2.06,75.3,2.26
33.0,22.6,2.06,75.4,2.26
33.2,22.6,2.07,75.5,2.27
33.0,22.7,2.06,75.6,2.27
33.2,22.7,2.07,75.7,2.27
33.2,22.7,2.07,75.7,2.28
33.2,22.8,2.07,75.8,2.28
33.2,22.8,2.07,75.9,2.28
33.3,22.8,2.08,76.0,2.28
33.3,22.8,2.08,76.1,2.29
33.3,22.9,2.08,76.2,2.29
33.3,22.9,2.08,76.3,2.29
33.5,22.9,2.09,76.4,2.30
33.5,23.0,2.09,76.5,2.30
33.5,23.0,2.09,76.6,2.30
33.7,23.0,2.10,76.7,2.31
33.7,23.0,2.10,76.8,2.31
33.7,23.1,2.10,76.9,2.31
33.7,23.1,2.10,77.0,2.31
33.8,23.1,2.11,77.1,2.32
33.8,23.2,2.11,77.2,2.32
33.8,23.2,2.11,77.3,2.32
33.8,23.2,2.11,77.4,2.33
34.0,23.3,2.12,77.5,2.33
34.0,23.3,2.12,77.6,2.33
34.0,23.3,2.12,77.7,2.34
34.2,23.3,2.14,77.8,2.34
34.2,23.4,2.14,77.9,2.34
34.2,23.4,2.14,78.0,2.34
34.3,23.4,2.15,78.1,2.35
34.3,23.5,2.15,78.2,2.35
34.3,23.5,2.15,78.3,2.35
34.5,23.5,2.16,78.4,2.36
34.5,23.6,2.16,78.5,2.36
34.5,23.6,2.16,78.6,2.36
34.5,23.6,2.16,78.7,2.36
34.7,23.6,2.17,78.8,2.37
34.7,23.7,2.17,78.9,2.37
34.7,23.7,2.17,79.0,2.37
34.7,23.7,2.17,79.1,2.38
34.8,23.8,2.18,79.2,2.38
34.8,23.8,2.18,79.3,2.38
34.8,23.8,2.18,79.4,2.39
35.0,23.8,2.19,79.5,2.39
35.0,23.9,2.19,79.6,2.39
35.0,23.9,2.19,79.7,2.39
35.2,23.9,2.20,79.8,2.40
35.2,24.0,2.20,79.9,2.40
35.2,24.0,2.20,80.0,2.40
35.2,24.0,2.20,80.1,2.41
35.3,24.1,2.20,80.2,2.41
35.3,24.1,2.21,80.3,2.41
35.3,24.1,2.21,80.4,2.41
35.3,24.1,2.21,80.5,2.42
35.5,24.2,2.22,80.6,2.42
35.5,24.2,2.22,80.7,2.42
35.5,24.2,2.22,80.8,2.43
35.7,24.3,2.23,80.9,2.43
35.7,24.3,2.23,81.0,2.43
35.7,24.3,2.23,81.1,2.44
35.8,24.4,2.24,81.2,2.44
35.8,24.4,2.24,81.3,2.44
35.8,24.4,2.24,81.4,2.44
35.8,24.4,2.24,81.5,2.45
35.8,24.5,2.24,81.6,2.45
36.0,24.5,2.25,81.7,2.45
36.0,24.5,2.25,81.8,2.46
36.2,24.6,2.26,81.9,2.46
36.2,24.6,2.26,82.0,2.46
36.2,24.6,2.26,82.1,2.47
36.2,24.6,2.26,82.2,2.47
36.3,24.7,2.27,82.3,2.47
36.3,24.7,2.27,82.4,2.47
36.3,24.7,2.27,82.4,2.48
36.5,24.8,2.28,82.5,2.48
36.5,24.8,2.28,82.6,2.48
36.5,24.8,2.28,82.7,2.49
36.6,24.9,2.29,82.8,2.49
36.7,24.9,2.29,82.9,2.49
36.7,24.9,2.29,83.0,2.49
36.7,24.9,2.29,83.1,2.50
36.8,25.0,2.30,83.2,2.50
36.8,25.0,2.30,83.3,2.50
36.8,25.0,2.30,83.4,2.51
37.0,25.1,2.31,83.5,2.51
37.0,25.1,2.31,83.6,2.51
37.0,25.1,2.31,83.7,2.52
37.0,25.1,2.31,83.8,2.52
37.0,25.2,2.31,83.9,2.52
37.2,25.2,2.32,84.0,2.52
37.2,25.2,2.32,84.1,2.53
37.2,25.3,2.32,84.2,2.53
37.3,25.3,2.33,84.3,2.53
37.2,25.3,2.32,84.4,2.54
37.3,25.4,2.33,84.5,2.54
37.3,25.4,2.33,84.6,2.54
37.4,25.4,2.34,84.7,2.54
37.5,25.4,2.34,84.8,2.55
37.5,25.5,2.34,84.9,2.55
37.5,25.5,2.34,85.0,2.55
37.5,25.5,2.34,85.1,2.56
37.7,25.6,2.35,85.2,2.56
37.7,25.6,2.35,85.3,2.56
37.7,25.6,2.35,85.4,2.57
37.7,25.7,2.35,85.5,2.57
37.8,25.7,2.36,85.6,2.57
38.0,25.7,2.37,85.7,2.57
37.8,25.7,2.36,85.8,2.58
38.0,25.8,2.37,85.9,2.58
38.0,25.8,2.37,86.0,2.58
38.0,25.8,2.37,86.1,2.59
38.2,25.9,2.39,86.2,2.59
38.2,25.9,2.39,86.3,2.59
38.2,25.9,2.39,86.4,2.60
38.2,25.9,2.39,86.5,2.60
38.2,26.0,2.39,86.6,2.60
38.3,26.0,2.40,86.7,2.60
38.3,26.0,2.40,86.8,2.61
38.3,26.1,2.40,86.9,2.61
38.5,26.1,2.41,87.0,2.61
38.3,26.1,2.40,87.1,2.62
38.5,26.2,2.41,87.2,2.62
38.7,26.2,2.42,87.3,2.62
38.7,26.2,2.42,87.4,2.62
38.7,26.2,2.42,87.5,2.63
38.7,26.3,2.42,87.6,2.63
38.7,26.3,2.42,87.7,2.63
38.8,26.3,2.43,87.8,2.64
38.8,26.4,2.43,87.9,2.64
38.8,26.4,2.43,88.0,2.64
38.8,26.4,2.43,88.1,2.65
38.8,26.4,2.43,88.2,2.65
39.0,26.5,2.44,88.3,2.65
39.0,26.5,2.44,88.4,2.65
39.0,26.5,2.44,88.5,2.66
39.2,26.6,2.45,88.6,2.66
39.2,26.6,2.45,88.7,2.66
39.3,26.6,2.46,88.8,2.67
39.3,26.7,2.46,88.9,2.67
39.3,26.7,2.46,89.0,2.67
39.3,26.7,2.46,89.0,2.68
39.3,26.7,2.46,89.2,2.68
39.5,26.8,2.47,89.2,2.68
39.5,26.8,2.47,89.3,2.68
39.5,26.8,2.47,89.4,2.69
39.5,26.9,2.47,89.5,2.69
39.7,26.9,2.48,89.6,2.69
39.7,26.9,2.48,89.7,2.70
39.7,27.0,2.48,89.8,2.70
39.8,27.0,2.49,89.9,2.70
39.8,27.0,2.49,90.0,2.70
39.8,27.0,2.49,90.1,2.71
40.0,27.1,2.50,90.2,2.71
40.0,27.1,2.50,90.3,2.71
40.0,27.1,2.50,90.4,2.72
40.0,27.2,2.50,90.5,2.72
40.0,27.2,2.50,90.6,2.72
40.2,27.2,2.51,90.7,2.73
40.2,27.2,2.51,90.8,2.73
40.2,27.3,2.51,90.9,2.73
40.2,27.3,2.51,91.0,2.73
40.2,27.3,2.51,91.1,2.74
40.3,27.4,2.52,91.2,2.74
40.3,27.4,2.52,91.3,2.74
40.3,27.4,2.52,91.4,2.75
40.3,27.5,2.52,91.5,2.75
40.5,27.5,2.53,91.6,2.75
40.5,27.5,2.53,91.7,2.75
40.5,27.5,2.53,91.8,2.76
40.5,27.6,2.53,91.9,2.76
40.7,27.6,2.54,92.0,2.76
40.5,27.6,2.53,92.1,2.77
40.7,27.7,2.54,92.2,2.77
40.7,27.7,2.54,92.3,2.77
40.7,27.7,2.54,92.4,2.78
40.8,27.8,2.55,92.5,2.78
40.8,27.8,2.55,92.6,2.78
40.8,27.8,2.55,92.7,2.78
41.0,27.8,2.56,92.8,2.79
41.0,27.9,2.56,92.9,2.79
41.0,27.9,2.56,93.0,2.79
41.0,27.9,2.56,93.1,2.80
41.2,28.0,2.57,93.2,2.80
41.2,28.0,2.57,93.3,2.80
41.3,28.0,2.58,93.4,2.81
41.3,28.0,2.58,93.5,2.81
41.3,28.1,2.58,93.6,2.81
41.3,28.1,2.58,93.7,2.81
41.5,28.1,2.59,93.8,2.82
41.5,28.2,2.59,93.9,2.82
41.5,28.2,2.59,94.0,2.82
41.5,28.2,2.59,94.1,2.83
41.5,28.3,2.59,94.2,2.83
41.7,28.3,2.60,94.3,2.83
41.8,28.3,2.61,94.4,2.83
41.8,28.3,2.61,94.5,2.84
41.8,28.4,2.61,94.6,2.84
41.8,28.4,2.61,94.7,2.84
42.0,28.4,2.62,94.8,2.85
42.0,28.5,2.62,94.9,2.85
42.0,28.5,2.62,95.0,2.85
42.2,28.5,2.64,95.1,2.86
42.0,28.5,2.62,95.2,2.86
42.2,28.6,2.64,95.3,2.86
42.2,28.6,2.64,95.4,2.86
42.2,28.6,2.64,95.5,2.87
42.2,28.7,2.64,95.6,2.87
42.2,28.7,2.64,95.7,2.87
42.2,28.7,2.64,95.8,2.88
42.3,28.8,2.65,95.9,2.88
42.3,28.8,2.65,95.9,2.88
42.5,28.8,2.66,96.0,2.88
42.5,28.8,2.66,96.1,2.89
42.4,28.9,2.65,96.2,2.89
42.3,28.9,2.65,96.3,2.89
42.3,28.9,2.65,96.4,2.90
42.3,29.0,2.65,96.5,2.90
42.5,29.0,2.66,96.6,2.90
42.5,29.0,2.66,96.7,2.91
42.7,29.1,2.67,96.8,2.91
42.7,29.1,2.67,96.9,2.91
42.7,29.1,2.67,97.0,2.91
42.7,29.1,2.67,97.1,2.92
42.7,29.2,2.67,97.2,2.92
42.8,29.2,2.68,97.3,2.92
43.2,29.2,2.70,97.4,2.93
43.0,29.3,2.69,97.5,2.93
42.8,29.3,2.68,97.6,2.93
42.8,29.3,2.68,97.7,2.94
43.0,29.3,2.69,97.8,2.94
43.0,29.4,2.69,97.9,2.94
43.2,29.4,2.70,98.0,2.94
43.2,29.4,2.70,98.1,2.95
43.2,29.5,2.70,98.2,2.95
43.3,29.5,2.71,98.3,2.95
43.3,29.5,2.71,98.4,2.96
43.3,29.6,2.71,98.5,2.96
43.5,29.6,2.72,98.6,2.96
43.5,29.6,2.72,98.7,2.96
43.7,29.6,2.73,98.8,2.97
43.7,29.7,2.73,98.9,2.97
43.7,29.7,2.73,99.0,2.97
43.8,29.7,2.74,99.1,2.98
43.8,29.8,2.74,99.2,2.98
43.8,29.8,2.74,99.3,2.98
44.0,29.8,2.75,99.4,2.99
44.0,29.8,2.75,99.5,2.99
44.0,29.9,2.75,99.6,2.99
44.2,29.9,2.76,99.7,2.99
44.2,29.9,2.76,99.8,3.00
44.2,30.0,2.76,99.9,3.00
44.3,30.0,2.77,100,3.00
44.3,30.0,2.77,100,3.01
44.3,30.1,2.77,100,3.01
44.5,30.1,2.78,100,3.01
44.5,30.1,2.78,100,3.01
44.7,30.1,2.79,100,3.02
44.7,30.2,2.79,101,3.02
44.7,30.2,2.79,101,3.02
44.7,30.2,2.79,101,3.03
44.8,30.3,2.80,101,3.03
44.8,30.3,2.80,101,3.03
44.8,30.3,2.80,101,3.04
45.0,30.4,2.81,101,3.04
45.0,30.4,2.81,101,3.04
45.2,30.4,2.82,101,3.04
45.2,30.4,2.82,101,3.05
45.2,30.5,2.82,102,3.05
45.3,30.5,2.83,102,3.05
45.3,30.5,2.83,102,3.06
45.3,30.6,2.83,102,3.06
45.3,30.6,2.83,102,3.06
45.3,30.6,2.83,102,3.07
45.1,30.6,2.82,102,3.07
45.2,30.7,2.82,102,3.07
45.3,30.7,2.83,102,3.07
45.2,30.7,2.82,102,3.08
45.3,30.8,2.83,103,3.08
45.3,30.8,2.83,103,3.08
45.5,30.8,2.84,103,3.09
45.5,30.9,2.84,103,3.09
45.5,30.9,2.84,103,3.09
45.7,30.9,2.85,103,3.09
45.7,30.9,2.85,103,3.10
45.7,31.0,2.85,103,3.10
45.8,31.0,2.86,103,3.10
45.8,31.0,2.86,103,3.11
45.8,31.1,2.86,104,3.11
46.0,31.1,2.87,104,3.11
46.0,31.1,2.87,104,3.12
46.0,31.1,2.87,104,3.12
46.2,31.2,2.89,104,3.12
46.1,31.2,2.88,104,3.12
46.2,31.2,2.89,104,3.13
46.2,31.3,2.89,104,3.13
46.3,31.3,2.89,104,3.13
46.3,31.3,2.90,104,3.14
46.3,31.4,2.90,105,3.14
46.5,31.4,2.91,105,3.14
46.3,31.4,2.90,105,3.14
46.5,31.4,2.91,105,3.15
46.5,31.5,2.91,105,3.15
46.7,31.5,2.92,105,3.15
46.7,31.5,2.92,105,3.16
46.7,31.6,2.92,105,3.16
46.7,31.6,2.92,105,3.16
46.8,31.6,2.93,105,3.17
46.8,31.7,2.93,106,3.17
46.8,31.7,2.93,106,3.17
47.0,31.7,2.94,106,3.17
47.0,31.7,2.94,106,3.18
47.2,31.8,2.95,106,3.18
47.2,31.8,2.95,106,3.18
47.2,31.8,2.95,106,3.19
47.2,31.9,2.95,106,3.19
47.3,31.9,2.96,106,3.19
47.3,31.9,2.96,106,3.20
47.5,31.9,2.97,106,3.20
47.5,32.0,2.97,107,3.20
47.7,32.0,2.98,107,3.20
47.7,32.0,2.98,107,3.21
47.7,32.1,2.98,107,3.21
47.7,32.1,2.98,107,3.21
47.8,32.1,2.99,107,3.22
47.8,32.2,2.99,107,3.22
48.0,32.2,3.00,107,3.22
48.0,32.2,3.00,107,3.22
48.0,32.2,3.00,107,3.23
48.2,32.3,3.01,108,3.23
48.2,32.3,3.01,108,3.23
48.3,32.3,3.02,108,3.24
48.3,32.4,3.02,108,3.24
48.5,32.4,3.03,108,3.24
48.5,32.4,3.03,108,3.25
48.5,32.5,3.03,108,3.25
48.5,32.5,3.03,108,3.25
48.5,32.5,3.03,108,3.25
48.7,32.5,3.04,108,3.26
48.7,32.6,3.04,109,3.26
48.7,32.6,3.04,109,3.26
48.7,32.6,3.04,109,3.27
48.8,32.7,3.05,109,3.27
48.8,32.7,3.05,109,3.27
48.8,32.7,3.05,109,3.27
48.8,32.7,3.05,109,3.28
48.8,32.8,3.05,109,3.28
49.0,32.8,3.06,109,3.28
49.0,32.8,3.06,109,3.29
49.0,32.9,3.06,110,3.29
49.0,32.9,3.06,110,3.29
49.1,32.9,3.07,110,3.30
49.3,33.0,3.08,110,3.30
49.0,33.0,3.06,110,3.30
49.0,33.0,3.06,110,3.30
49.0,33.0,3.06,110,3.31
49.0,33.1,3.06,110,3.31
48.8,33.1,3.05,110,3.31
48.8,33.1,3.05,110,3.32
48.8,33.2,3.05,111,3.32
49.0,33.2,3.06,111,3.32
49.2,33.2,3.07,111,3.33
49.3,33.2,3.08,111,3.33
50.0,33.3,3.12,111,3.33
49.6,33.3,3.10,111,3.33
49.2,33.3,3.07,111,3.34
49.2,33.4,3.07,111,3.34
49.2,33.4,3.07,111,3.34
49.2,33.4,3.07,111,3.35
49.3,33.5,3.08,112,3.35
49.3,33.5,3.08,112,3.35
49.3,33.5,3.08,112,3.35
49.5,33.5,3.09,112,3.36
49.5,33.6,3.09,112,3.36
49.5,33.6,3.09,112,3.36
49.7,33.6,3.10,112,3.37
49.7,33.7,3.10,112,3.37
49.8,33.7,3.11,112,3.37
49.8,33.7,3.11,112,3.38
49.8,33.8,3.11,113,3.38
50.0,33.8,3.12,113,3.38
50.0,33.8,3.12,113,3.38
50.1,33.8,3.13,113,3.39
50.2,33.9,3.14,113,3.39
50.2,33.9,3.14,113,3.39
50.2,33.9,3.14,113,3.40
50.2,34.0,3.14,113,3.40
50.3,34.0,3.15,113,3.40
50.3,34.0,3.15,113,3.41
50.5,34.0,3.16,113,3.41
50.3,34.1,3.15,114,3.41
50.5,34.1,3.16,114,3.41
50.5,34.1,3.16,114,3.42
50.7,34.2,3.17,114,3.42
50.7,34.2,3.17,114,3.42
50.7,34.2,3.17,114,3.43
50.7,34.3,3.17,114,3.43
50.7,34.3,3.17,114,3.43
50.7,34.3,3.17,114,3.43
50.8,34.3,3.18,114,3.44
50.8,34.4,3.18,115,3.44
50.8,34.4,3.18,115,3.44
50.8,34.4,3.18,115,3.45
51.0,34.5,3.19,115,3.45
51.0,34.5,3.19,115,3.45
51.0,34.5,3.19,115,3.46
51.0,34.5,3.19,115,3.46
51.0,34.6,3.19,115,3.46
51.0,34.6,3.19,115,3.46
51.0,34.6,3.19,115,3.47
51.0,34.7,3.19,116,3.47
51.0,34.7,3.19,116,3.47
51.0,34.7,3.19,116,3.48
51.0,34.8,3.19,116,3.48
51.2,34.8,3.20,116,3.48
51.0,34.8,3.19,116,3.48
51.0,34.8,3.19,116,3.49
51.0,34.9,3.19,116,3.49
51.0,34.9,3.19,116,3.49
51.0,34.9,3.19,116,3.50
51.0,35.0,3.19,117,3.50
50.8,35.0,3.18,117,3.50
21.4,35.0,1.34,117,3.51
0.167,35.1,0.0104,117,3.51
0.196,35.1,0.0123,117,3.51
0.167,35.1,0.0104,117,3.51
0.167,35.1,0.0104,117,3.52
0.178,35.2,0.0111,117,3.52
0.167,35.2,0.0104,117,3.52
0.167,35.2,0.0104,117,3.53
0.167,35.3,0.0104,118,3.53
0.167,35.3,0.0104,118,3.53
0.167,35.3,0.0104,118,3.54
0.167,35.3,0.0104,118,3.54
0.167,35.4,0.0104,118,3.54
0.167,35.4,0.0104,118,3.54
0.167,35.4,0.0104,118,3.55
0.232,35.5,0.0145,118,3.55
0.167,35.5,0.0104,118,3.55
0.333,35.5,0.0208,118,3.56
0.333,35.6,0.0208,119,3.56
0.333,35.6,0.0208,119,3.56
0.333,35.6,0.0208,119,3.56
0.167,35.6,0.0104,119,3.57
0.167,35.7,0.0104,119,3.57
0.333,35.7,0.0208,119,3.57
0.333,35.7,0.0208,119,3.58
0.333,35.8,0.0208,119,3.58
0.333,35.8,0.0208,119,3.58
0.333,35.8,0.0208,119,3.59
0.333,35.8,0.0208,119,3.59
0.333,35.9,0.0208,120,3.59
0.333,35.9,0.0208,120,3.59
0.167,35.9,0.0104,120,3.60
0.167,36.0,0.0104,120,3.60
0.167,36.0,0.0104,120,3.60
0.251,36.0,0.0157,120,3.61
0.333,36.1,0.0208,120,3.61
0.278,36.1,0.0174,120,3.61
0.167,36.1,0.0104,120,3.61
0.167,36.1,0.0104,120,3.62
0.167,36.2,0.0104,121,3.62
0.167,36.2,0.0104,121,3.62
0.196,36.2,0.0123,121,3.63
0.308,36.3,0.0192,121,3.63
0.167,36.3,0.0104,121,3.63
0.167,36.3,0.0104,121,3.64
0.167,36.4,0.0104,121,3.64
0.167,36.4,0.0104,121,3.64
0.167,36.4,0.0104,121,3.64
0.167,36.4,0.0104,121,3.65
0.167,36.5,0.0104,122,3.65
0.333,36.5,0.0208,122,3.65
0.333,36.5,0.0208,122,3.66
0.333,36.6,0.0208,122,3.66
0.167,36.6,0.0104,122,3.66
0.167,36.6,0.0104,122,3.67
0.167,36.6,0.0104,122,3.67
0.217,36.7,0.0136,122,3.67
0.167,36.7,0.0104,122,3.67
0.167,36.7,0.0104,122,3.68
0.167,36.8,0.0104,123,3.68
0.167,36.8,0.0104,123,3.68
0.167,36.8,0.0104,123,3.69
0.167,36.9,0.0104,123,3.69
0.167,36.9,0.0104,123,3.69
0.167,36.9,0.0104,123,3.69
0.167,36.9,0.0104,123,3.70