File: Thermal Chamber for UTM/rubber 50%.csv
Force (N),Position (mm),Stress (MPa),Strain (%),Time (min)
0.00,0.00,0.00,0.00,0.00568
0.00,0.0191,0.00,0.0637,0.00796
0.00,0.0409,0.00,0.136,0.0102
0.00,0.0652,0.00,0.217,0.0125
0.167,0.0881,0.0104,0.294,0.0148
0.167,0.110,0.0104,0.367,0.0170
0.333,0.132,0.0208,0.441,0.0193
0.333,0.155,0.0208,0.518,0.0216
0.333,0.178,0.0208,0.595,0.0239
0.500,0.202,0.0312,0.673,0.0261
0.364,0.225,0.0228,0.751,0.0284
0.500,0.247,0.0312,0.824,0.0307
0.500,0.269,0.0312,0.896,0.0330
0.500,0.292,0.0312,0.974,0.0352
0.667,0.316,0.0417,1.05,0.0375
0.667,0.338,0.0417,1.13,0.0398
0.667,0.360,0.0417,1.20,0.0421
0.800,0.383,0.0500,1.28,0.0443
0.833,0.406,0.0521,1.35,0.0466
0.833,0.429,0.0521,1.43,0.0489
0.833,0.452,0.0521,1.51,0.0511
1.00,0.474,0.0625,1.58,0.0534
1.00,0.497,0.0625,1.66,0.0557
1.00,0.520,0.0625,1.73,0.0580
1.11,0.543,0.0696,1.81,0.0602
1.00,0.565,0.0625,1.88,0.0625
1.17,0.588,0.0729,1.96,0.0648
1.17,0.611,0.0729,2.04,0.0671
1.17,0.633,0.0729,2.11,0.0693
1.17,0.657,0.0729,2.19,0.0716
1.33,0.679,0.0833,2.26,0.0739
1.33,0.702,0.0833,2.34,0.0762
1.33,0.724,0.0833,2.41,0.0784
1.33,0.747,0.0833,2.49,0.0807
1.33,0.770,0.0833,2.57,0.0830
1.33,0.792,0.0833,2.64,0.0852
1.43,0.815,0.0892,2.72,0.0875
1.48,0.839,0.0928,2.80,0.0898
1.50,0.861,0.0937,2.87,0.0921
1.50,0.883,0.0937,2.94,0.0943
1.50,0.905,0.0937,3.02,0.0966
1.50,0.928,0.0937,3.09,0.0989
1.67,0.952,0.104,3.17,0.101
1.67,0.974,0.104,3.25,0.103
1.67,0.997,0.104,3.32,0.106
1.78,1.02,0.111,3.40,0.108
1.83,1.04,0.115,3.47,0.110
1.67,1.07,0.104,3.55,0.113
1.83,1.09,0.115,3.63,0.115
1.83,1.11,0.115,3.70,0.117
1.83,1.13,0.115,3.78,0.119
1.83,1.16,0.115,3.86,0.122
1.86,1.18,0.116,3.93,0.124
2.00,1.20,0.125,4.00,0.126
2.00,1.22,0.125,4.08,0.128
2.00,1.25,0.125,4.15,0.131
2.00,1.27,0.125,4.23,0.133
2.11,1.29,0.132,4.31,0.135
2.17,1.32,0.135,4.38,0.138
2.17,1.34,0.135,4.46,0.140
2.17,1.36,0.135,4.54,0.142
2.17,1.38,0.135,4.61,0.144
2.17,1.41,0.135,4.69,0.147
2.33,1.43,0.146,4.76,0.149
2.33,1.45,0.146,4.84,0.151
2.33,1.47,0.146,4.92,0.153
2.33,1.50,0.146,4.99,0.156
2.50,1.52,0.156,5.06,0.158
2.50,1.54,0.156,5.14,0.160
2.50,1.57,0.156,5.22,0.163
2.67,1.59,0.167,5.29,0.165
2.67,1.61,0.167,5.37,0.167
2.67,1.63,0.167,5.44,0.169
2.67,1.66,0.167,5.52,0.172
2.83,1.68,0.177,5.60,0.174
2.76,1.70,0.172,5.67,0.176
2.83,1.72,0.177,5.75,0.178
2.83,1.75,0.177,5.82,0.181
2.83,1.77,0.177,5.90,0.183
3.00,1.79,0.187,5.98,0.185
3.00,1.82,0.187,6.05,0.188
3.00,1.84,0.187,6.13,0.190
3.00,1.86,0.187,6.20,0.192
3.00,1.88,0.187,6.28,0.194
3.00,1.91,0.187,6.35,0.197
3.17,1.93,0.198,6.43,0.199
3.17,1.95,0.198,6.50,0.201
3.17,1.98,0.198,6.58,0.203
3.33,2.00,0.208,6.66,0.206
3.33,2.02,0.208,6.73,0.208
3.33,2.04,0.208,6.81,0.210
3.33,2.07,0.208,6.89,0.213
3.33,2.09,0.208,6.96,0.215
3.50,2.11,0.219,7.04,0.217
3.50,2.13,0.219,7.11,0.219
3.50,2.16,0.219,7.19,0.222
3.50,2.18,0.219,7.27,0.224
3.67,2.20,0.229,7.34,0.226
3.67,2.22,0.229,7.41,0.228
3.67,2.25,0.229,7.49,0.231
3.67,2.27,0.229,7.57,0.233
3.78,2.29,0.237,7.64,0.235
3.83,2.32,0.240,7.72,0.238
3.83,2.34,0.240,7.80,0.240
3.83,2.36,0.240,7.87,0.242
3.83,2.38,0.240,7.94,0.244
4.00,2.41,0.250,8.02,0.247
4.00,2.43,0.250,8.10,0.249
4.00,2.45,0.250,8.17,0.251
4.00,2.47,0.250,8.25,0.253
4.00,2.50,0.250,8.32,0.256
4.00,2.52,0.250,8.40,0.258
4.17,2.54,0.260,8.48,0.260
4.17,2.57,0.260,8.55,0.263
4.17,2.59,0.260,8.63,0.265
4.17,2.61,0.260,8.70,0.267
4.17,2.63,0.260,8.78,0.269
4.33,2.66,0.271,8.86,0.272
4.33,2.68,0.271,8.93,0.274
4.33,2.70,0.271,9.01,0.276
4.50,2.73,0.281,9.08,0.278
4.46,2.75,0.279,9.16,0.281
4.50,2.77,0.281,9.23,0.283
4.50,2.79,0.281,9.31,0.285
4.50,2.82,0.281,9.39,0.288
4.50,2.84,0.281,9.46,0.290
4.67,2.86,0.292,9.54,0.292
4.67,2.88,0.292,9.61,0.294
4.67,2.91,0.292,9.69,0.297
4.67,2.93,0.292,9.76,0.299
4.67,2.95,0.292,9.84,0.301
4.83,2.97,0.302,9.91,0.303
4.83,3.00,0.302,9.99,0.306
4.83,3.02,0.302,10.1,0.308
4.83,3.04,0.302,10.1,0.310
4.83,3.07,0.302,10.2,0.313
4.83,3.09,0.302,10.3,0.315
5.00,3.11,0.312,10.4,0.317
5.00,3.13,0.312,10.4,0.319
5.00,3.16,0.312,10.5,0.322
5.00,3.18,0.312,10.6,0.324
5.17,3.20,0.323,10.7,0.326
5.17,3.22,0.323,10.7,0.328
5.17,3.25,0.323,10.8,0.331
5.33,3.27,0.333,10.9,0.333
5.33,3.29,0.333,11.0,0.335
5.33,3.32,0.333,11.1,0.338
5.33,3.34,0.333,11.1,0.340
5.33,3.36,0.333,11.2,0.342
5.33,3.38,0.333,11.3,0.344
5.38,3.41,0.336,11.4,0.347
5.50,3.43,0.344,11.4,0.349
5.50,3.45,0.344,11.5,0.351
5.50,3.47,0.344,11.6,0.353
5.50,3.50,0.344,11.7,0.356
5.67,3.52,0.354,11.7,0.358
5.67,3.54,0.354,11.8,0.360
5.67,3.57,0.354,11.9,0.363
5.67,3.59,0.354,12.0,0.365
5.67,3.61,0.354,12.0,0.367
5.67,3.63,0.354,12.1,0.369
5.72,3.66,0.357,12.2,0.372
5.83,3.68,0.365,12.3,0.374
5.83,3.70,0.365,12.3,0.376
6.00,3.72,0.375,12.4,0.378
6.00,3.75,0.375,12.5,0.381
6.00,3.77,0.375,12.6,0.383
6.00,3.79,0.375,12.6,0.385
6.00,3.82,0.375,12.7,0.388
6.00,3.84,0.375,12.8,0.390
6.00,3.86,0.375,12.9,0.392
6.17,3.88,0.385,12.9,0.394
6.17,3.91,0.385,13.0,0.397
6.17,3.93,0.385,13.1,0.399
6.33,3.95,0.396,13.2,0.401
6.33,3.97,0.396,13.2,0.403
6.33,4.00,0.396,13.3,0.406
6.33,4.02,0.396,13.4,0.408
6.45,4.04,0.403,13.5,0.410
6.50,4.07,0.406,13.6,0.413
6.50,4.09,0.406,13.6,0.415
6.55,4.11,0.409,13.7,0.417
6.67,4.13,0.417,13.8,0.419
6.67,4.16,0.417,13.9,0.422
6.67,4.18,0.417,13.9,0.424
6.83,4.20,0.427,14.0,0.426
6.83,4.22,0.427,14.1,0.428
6.83,4.25,0.427,14.2,0.431
6.83,4.27,0.427,14.2,0.433
6.83,4.29,0.427,14.3,0.435
7.00,4.32,0.437,14.4,0.438
7.00,4.34,0.437,14.5,0.440
7.00,4.36,0.437,14.5,0.442
7.00,4.38,0.437,14.6,0.444
7.00,4.41,0.437,14.7,0.447
7.00,4.43,0.437,14.8,0.449
7.17,4.45,0.448,14.8,0.451
7.17,4.48,0.448,14.9,0.454
7.17,4.50,0.448,15.0,0.456
7.17,4.52,0.448,15.1,0.458
7.17,4.54,0.448,15.1,0.460
7.17,4.57,0.448,15.2,0.463
7.17,4.59,0.448,15.3,0.465
7.17,4.61,0.448,15.4,0.467
7.17,4.63,0.448,15.4,0.469
7.17,4.66,0.448,15.5,0.472
7.17,4.68,0.448,15.6,0.474
7.17,4.70,0.448,15.7,0.476
7.17,4.73,0.448,15.8,0.479
7.17,4.75,0.448,15.8,0.481
7.33,4.77,0.458,15.9,0.483
7.33,4.79,0.458,16.0,0.485
7.33,4.82,0.458,16.1,0.488
7.33,4.84,0.458,16.1,0.490
7.33,4.86,0.458,16.2,0.492
7.50,4.88,0.469,16.3,0.494
7.50,4.91,0.469,16.4,0.497
7.50,4.93,0.469,16.4,0.499
7.50,4.95,0.469,16.5,0.501
7.67,4.98,0.479,16.6,0.504
7.67,5.00,0.479,16.7,0.506
7.67,5.02,0.479,16.7,0.508
7.67,5.04,0.479,16.8,0.510
7.67,5.07,0.479,16.9,0.513
7.67,5.09,0.479,17.0,0.515
7.67,5.11,0.479,17.0,0.517
7.67,5.13,0.479,17.1,0.519
7.67,5.16,0.479,17.2,0.522
7.67,5.18,0.479,17.3,0.524
7.83,5.20,0.490,17.3,0.526
7.83,5.23,0.490,17.4,0.529
7.83,5.25,0.490,17.5,0.531
7.83,5.27,0.490,17.6,0.533
8.00,5.29,0.500,17.6,0.535
8.00,5.32,0.500,17.7,0.538
8.00,5.34,0.500,17.8,0.540
8.09,5.36,0.506,17.9,0.542
8.17,5.38,0.510,17.9,0.544
8.17,5.41,0.510,18.0,0.547
8.17,5.43,0.510,18.1,0.549
8.17,5.45,0.510,18.2,0.551
8.33,5.48,0.521,18.3,0.554
8.33,5.50,0.521,18.3,0.556
8.33,5.52,0.521,18.4,0.558
8.46,5.54,0.528,18.5,0.560
8.50,5.57,0.531,18.6,0.563
8.50,5.59,0.531,18.6,0.565
8.50,5.61,0.531,18.7,0.567
8.50,5.63,0.531,18.8,0.569
8.50,5.66,0.531,18.9,0.572
8.50,5.68,0.531,18.9,0.574
8.50,5.70,0.531,19.0,0.576
8.67,5.72,0.542,19.1,0.579
8.67,5.75,0.542,19.2,0.581
8.67,5.77,0.542,19.2,0.583
8.67,5.79,0.542,19.3,0.585
8.74,5.82,0.547,19.4,0.588
8.71,5.84,0.545,19.5,0.590
8.83,5.86,0.552,19.5,0.592
8.83,5.88,0.552,19.6,0.594
8.83,5.91,0.552,19.7,0.597
8.83,5.93,0.552,19.8,0.599
8.83,5.95,0.552,19.8,0.601
9.00,5.98,0.562,19.9,0.604
9.00,6.00,0.562,20.0,0.606
9.00,6.02,0.562,20.1,0.608
9.00,6.04,0.562,20.1,0.610
9.17,6.07,0.573,20.2,0.613
9.17,6.09,0.573,20.3,0.615
9.17,6.11,0.573,20.4,0.617
9.17,6.13,0.573,20.4,0.619
9.17,6.16,0.573,20.5,0.622
9.17,6.18,0.573,20.6,0.624
9.33,6.20,0.583,20.7,0.626
9.33,6.23,0.583,20.8,0.629
9.33,6.25,0.583,20.8,0.631
9.33,6.27,0.583,20.9,0.633
9.33,6.29,0.583,21.0,0.635
9.33,6.32,0.583,21.1,0.638
9.50,6.34,0.594,21.1,0.640
9.50,6.36,0.594,21.2,0.642
9.50,6.38,0.594,21.3,0.644
9.67,6.41,0.604,21.4,0.647
9.67,6.43,0.604,21.4,0.649
9.67,6.45,0.604,21.5,0.651
9.67,6.48,0.604,21.6,0.654
9.67,6.50,0.604,21.7,0.656
9.83,6.52,0.615,21.7,0.658
9.83,6.54,0.615,21.8,0.660
9.83,6.57,0.615,21.9,0.663
9.97,6.59,0.623,22.0,0.665
10.0,6.61,0.625,22.0,0.667
10.0,6.63,0.625,22.1,0.669
10.0,6.66,0.625,22.2,0.672
10.0,6.68,0.625,22.3,0.674
10.0,6.70,0.625,22.3,0.676
10.2,6.73,0.635,22.4,0.679
10.2,6.75,0.635,22.5,0.681
10.2,6.77,0.635,22.6,0.683
10.2,6.79,0.635,22.6,0.685
10.2,6.82,0.635,22.7,0.688
10.3,6.84,0.646,22.8,0.690
10.3,6.86,0.646,22.9,0.692
10.3,6.89,0.646,23.0,0.694
10.3,6.91,0.646,23.0,0.697
10.4,6.93,0.651,23.1,0.699
10.5,6.95,0.656,23.2,0.701
10.5,6.98,0.656,23.3,0.704
10.5,7.00,0.656,23.3,0.706
10.5,7.02,0.656,23.4,0.708
10.7,7.04,0.667,23.5,0.710
10.7,7.07,0.667,23.6,0.713
10.7,7.09,0.667,23.6,0.715
10.7,7.11,0.667,23.7,0.717
10.7,7.13,0.667,23.8,0.719
10.8,7.16,0.677,23.9,0.722
10.8,7.18,0.677,23.9,0.724
10.8,7.20,0.677,24.0,0.726
10.8,7.23,0.677,24.1,0.729
11.0,7.25,0.687,24.2,0.731
11.0,7.27,0.687,24.2,0.733
11.0,7.29,0.687,24.3,0.735
11.0,7.32,0.687,24.4,0.738
11.0,7.34,0.687,24.5,0.740
11.2,7.36,0.698,24.5,0.742
11.2,7.39,0.698,24.6,0.744
11.2,7.41,0.698,24.7,0.747
11.3,7.43,0.708,24.8,0.749
11.3,7.45,0.708,24.8,0.751
11.3,7.48,0.708,24.9,0.754
11.3,7.50,0.708,25.0,0.756
11.3,7.52,0.708,25.1,0.758
11.5,7.54,0.719,25.1,0.760
11.5,7.57,0.719,25.2,0.763
11.5,7.59,0.719,25.3,0.765
11.5,7.61,0.719,25.4,0.767
11.5,7.64,0.719,25.5,0.769
11.5,7.66,0.719,25.5,0.772
11.7,7.68,0.729,25.6,0.774
11.7,7.70,0.729,25.7,0.776
11.7,7.73,0.729,25.8,0.779
11.7,7.75,0.729,25.8,0.781
11.7,7.77,0.729,25.9,0.783
11.8,7.79,0.740,26.0,0.785
11.8,7.82,0.740,26.1,0.788
11.8,7.84,0.740,26.1,0.790
11.8,7.86,0.740,26.2,0.792
12.0,7.89,0.749,26.3,0.794
12.0,7.91,0.750,26.4,0.797
12.0,7.93,0.750,26.4,0.799
12.0,7.95,0.750,26.5,0.801
12.0,7.98,0.750,26.6,0.804
12.2,8.00,0.759,26.7,0.806
12.2,8.02,0.760,26.7,0.808
12.2,8.04,0.760,26.8,0.810
12.3,8.07,0.771,26.9,0.813
12.3,8.09,0.771,27.0,0.815
12.3,8.11,0.771,27.0,0.817
12.3,8.14,0.771,27.1,0.819
12.3,8.16,0.771,27.2,0.822
12.3,8.18,0.771,27.3,0.824
12.5,8.20,0.781,27.3,0.826
12.5,8.23,0.781,27.4,0.829
12.5,8.25,0.781,27.5,0.831
12.6,8.27,0.788,27.6,0.833
12.7,8.29,0.792,27.6,0.835
12.7,8.32,0.792,27.7,0.838
12.7,8.34,0.792,27.8,0.840
12.8,8.36,0.802,27.9,0.842
12.8,8.38,0.802,27.9,0.844
12.8,8.41,0.802,28.0,0.847
12.8,8.43,0.802,28.1,0.849
12.8,8.45,0.802,28.2,0.851
12.8,8.48,0.802,28.3,0.854
13.0,8.50,0.812,28.3,0.856
13.0,8.52,0.812,28.4,0.858
13.0,8.54,0.812,28.5,0.860
13.0,8.57,0.812,28.6,0.863
13.2,8.59,0.823,28.6,0.865
13.2,8.61,0.823,28.7,0.867
13.2,8.64,0.823,28.8,0.869
13.3,8.66,0.832,28.9,0.872
13.3,8.68,0.833,28.9,0.874
13.3,8.70,0.833,29.0,0.876
13.3,8.73,0.833,29.1,0.879
13.3,8.75,0.833,29.2,0.881
13.5,8.77,0.844,29.2,0.883
13.5,8.79,0.844,29.3,0.885
13.5,8.82,0.844,29.4,0.888
13.5,8.84,0.844,29.5,0.890
13.5,8.86,0.844,29.5,0.892
13.7,8.88,0.854,29.6,0.895
13.7,8.91,0.854,29.7,0.897
13.7,8.93,0.854,29.8,0.899
13.7,8.95,0.854,29.8,0.901
13.8,8.98,0.860,29.9,0.904
13.8,9.00,0.865,30.0,0.906
13.8,9.02,0.865,30.1,0.908
13.8,9.04,0.865,30.1,0.910
14.0,9.07,0.875,30.2,0.913
14.0,9.09,0.875,30.3,0.915
14.0,9.11,0.878,30.4,0.917
14.2,9.14,0.885,30.5,0.920
14.2,9.16,0.885,30.5,0.922
14.2,9.18,0.885,30.6,0.924
14.2,9.20,0.885,30.7,0.926
14.3,9.23,0.896,30.8,0.929
14.3,9.25,0.896,30.8,0.931
14.3,9.27,0.896,30.9,0.933
14.3,9.29,0.896,31.0,0.935
14.3,9.32,0.896,31.1,0.938
14.5,9.34,0.906,31.1,0.940
14.5,9.36,0.906,31.2,0.942
14.5,9.38,0.906,31.3,0.945
14.5,9.41,0.906,31.4,0.947
14.5,9.43,0.906,31.4,0.949
14.5,9.45,0.906,31.5,0.951
14.7,9.48,0.917,31.6,0.954
14.7,9.50,0.917,31.7,0.956
14.7,9.52,0.917,31.7,0.958
14.7,9.54,0.917,31.8,0.960
14.7,9.57,0.917,31.9,0.963
14.8,9.59,0.927,32.0,0.965
14.8,9.61,0.927,32.0,0.967
14.8,9.64,0.927,32.1,0.970
14.8,9.66,0.927,32.2,0.972
14.8,9.68,0.927,32.3,0.974
15.0,9.70,0.937,32.3,0.976
15.0,9.73,0.937,32.4,0.979
15.0,9.75,0.937,32.5,0.981
15.1,9.77,0.943,32.6,0.983
15.2,9.79,0.948,32.6,0.985
15.2,9.82,0.948,32.7,0.988
15.2,9.84,0.948,32.8,0.990
15.2,9.86,0.948,32.9,0.992
15.2,9.89,0.948,33.0,0.995
15.3,9.91,0.958,33.0,0.997
15.3,9.93,0.958,33.1,0.999
15.4,9.95,0.960,33.2,1.00
15.5,9.98,0.969,33.3,1.00
15.6,10.0,0.978,33.3,1.01
15.7,10.0,0.979,33.4,1.01
15.7,10.0,0.979,33.5,1.01
15.7,10.1,0.979,33.6,1.01
15.7,10.1,0.979,33.6,1.01
15.8,10.1,0.990,33.7,1.02
15.8,10.1,0.990,33.8,1.02
15.8,10.2,0.990,33.9,1.02
15.8,10.2,0.990,33.9,1.02
15.9,10.2,0.991,34.0,1.03
16.0,10.2,1.00,34.1,1.03
16.0,10.2,1.00,34.2,1.03
16.0,10.3,1.00,34.2,1.03
16.0,10.3,1.00,34.3,1.04
16.0,10.3,1.00,34.4,1.04
16.0,10.3,1.00,34.5,1.04
16.0,10.4,1.00,34.5,1.04
16.2,10.4,1.01,34.6,1.04
16.2,10.4,1.01,34.7,1.05
16.2,10.4,1.01,34.8,1.05
16.2,10.5,1.01,34.8,1.05
16.2,10.5,1.01,34.9,1.05
16.3,10.5,1.02,35.0,1.06
16.3,10.5,1.02,35.1,1.06
16.3,10.5,1.02,35.1,1.06
16.4,10.6,1.03,35.2,1.06
16.5,10.6,1.03,35.3,1.06
16.5,10.6,1.03,35.4,1.07
16.5,10.6,1.03,35.5,1.07
16.7,10.7,1.04,35.5,1.07
16.7,10.7,1.04,35.6,1.07
16.7,10.7,1.04,35.7,1.08
16.7,10.7,1.04,35.8,1.08
16.8,10.7,1.05,35.8,1.08
16.8,10.8,1.05,35.9,1.08
16.8,10.8,1.05,36.0,1.09
16.8,10.8,1.05,36.1,1.09
16.8,10.8,1.05,36.1,1.09
17.0,10.9,1.06,36.2,1.09
17.0,10.9,1.06,36.3,1.09
17.0,10.9,1.06,36.4,1.10
17.0,10.9,1.06,36.4,1.10
17.0,11.0,1.07,36.5,1.10
17.2,11.0,1.07,36.6,1.10
17.2,11.0,1.07,36.7,1.11
17.3,11.0,1.08,36.7,1.11
17.3,11.0,1.08,36.8,1.11
17.3,11.1,1.08,36.9,1.11
17.3,11.1,1.08,37.0,1.12
17.3,11.1,1.08,37.0,1.12
17.5,11.1,1.09,37.1,1.12
17.5,11.2,1.09,37.2,1.12
17.5,11.2,1.09,37.3,1.12
17.5,11.2,1.09,37.3,1.13
17.5,11.2,1.09,37.4,1.13
17.7,11.2,1.10,37.5,1.13
17.7,11.3,1.11,37.6,1.13
17.8,11.3,1.11,37.6,1.14
17.8,11.3,1.11,37.7,1.14
17.8,11.3,1.11,37.8,1.14
18.0,11.4,1.12,37.9,1.14
18.0,11.4,1.12,38.0,1.14
18.0,11.4,1.12,38.0,1.15
18.0,11.4,1.12,38.1,1.15
18.2,11.5,1.14,38.2,1.15
18.2,11.5,1.14,38.3,1.15
18.2,11.5,1.14,38.3,1.16
18.2,11.5,1.14,38.4,1.16
18.2,11.5,1.14,38.5,1.16
18.2,11.6,1.14,38.6,1.16
18.2,11.6,1.14,38.6,1.17
18.3,11.6,1.15,38.7,1.17
18.3,11.6,1.15,38.8,1.17
18.3,11.7,1.15,38.9,1.17
18.5,11.7,1.16,38.9,1.17
18.5,11.7,1.16,39.0,1.18
18.5,11.7,1.16,39.1,1.18
18.5,11.7,1.16,39.2,1.18
18.5,11.8,1.16,39.2,1.18
18.5,11.8,1.16,39.3,1.19
18.7,11.8,1.17,39.4,1.19
18.7,11.8,1.17,39.5,1.19
18.8,11.9,1.18,39.5,1.19
18.8,11.9,1.18,39.6,1.19
18.8,11.9,1.18,39.7,1.20
18.8,11.9,1.18,39.8,1.20
18.8,12.0,1.18,39.8,1.20
19.0,12.0,1.19,39.9,1.20
19.0,12.0,1.19,40.0,1.21
19.0,12.0,1.19,40.1,1.21
19.0,12.0,1.19,40.1,1.21
19.2,12.1,1.20,40.2,1.21
19.2,12.1,1.20,40.3,1.22
19.2,12.1,1.20,40.4,1.22
19.2,12.1,1.20,40.5,1.22
19.3,12.2,1.21,40.5,1.22
19.2,12.2,1.20,40.6,1.22
19.3,12.2,1.21,40.7,1.23
19.3,12.2,1.21,40.8,1.23
19.3,12.2,1.21,40.8,1.23
19.4,12.3,1.21,40.9,1.23
19.5,12.3,1.22,41.0,1.24
19.5,12.3,1.22,41.1,1.24
19.5,12.3,1.22,41.1,1.24
19.5,12.4,1.22,41.2,1.24
19.5,12.4,1.22,41.3,1.24
19.7,12.4,1.23,41.4,1.25
19.7,12.4,1.23,41.4,1.25
19.7,12.5,1.23,41.5,1.25
19.8,12.5,1.24,41.6,1.25
19.8,12.5,1.24,41.7,1.26
19.8,12.5,1.24,41.7,1.26
19.8,12.5,1.24,41.8,1.26
19.8,12.6,1.24,41.9,1.26
20.0,12.6,1.25,42.0,1.27
20.0,12.6,1.25,42.0,1.27
20.0,12.6,1.25,42.1,1.27
20.0,12.7,1.25,42.2,1.27
20.0,12.7,1.25,42.3,1.27
20.0,12.7,1.25,42.3,1.28
20.2,12.7,1.26,42.4,1.28
20.2,12.7,1.26,42.5,1.28
20.3,12.8,1.27,42.6,1.28
20.3,12.8,1.27,42.6,1.29
20.3,12.8,1.27,42.7,1.29
20.3,12.8,1.27,42.8,1.29
20.5,12.9,1.28,42.9,1.29
20.5,12.9,1.28,43.0,1.29
20.5,12.9,1.28,43.0,1.30
20.5,12.9,1.28,43.1,1.30
20.7,13.0,1.29,43.2,1.30
20.7,13.0,1.29,43.3,1.30
20.7,13.0,1.29,43.3,1.31
20.8,13.0,1.30,43.4,1.31
20.8,13.0,1.30,43.5,1.31
20.8,13.1,1.30,43.6,1.31
20.8,13.1,1.30,43.6,1.32
20.8,13.1,1.30,43.7,1.32
21.0,13.1,1.31,43.8,1.32
21.0,13.2,1.31,43.9,1.32
21.0,13.2,1.31,43.9,1.32
21.0,13.2,1.31,44.0,1.33
21.0,13.2,1.31,44.1,1.33
21.2,13.2,1.32,44.2,1.33
21.2,13.3,1.32,44.2,1.33
21.2,13.3,1.32,44.3,1.34
21.3,13.3,1.33,44.4,1.34
21.3,13.3,1.33,44.5,1.34
21.3,13.4,1.33,44.5,1.34
21.3,13.4,1.33,44.6,1.34
21.3,13.4,1.33,44.7,1.35
21.4,13.4,1.34,44.8,1.35
21.5,13.5,1.34,44.8,1.35
21.5,13.5,1.34,44.9,1.35
21.5,13.5,1.34,45.0,1.36
21.7,13.5,1.35,45.1,1.36
21.7,13.5,1.35,45.1,1.36
21.7,13.6,1.35,45.2,1.36
21.7,13.6,1.35,45.3,1.37
21.8,13.6,1.36,45.4,1.37
21.8,13.6,1.36,45.5,1.37
21.8,13.7,1.36,45.5,1.37
21.8,13.7,1.36,45.6,1.37
21.8,13.7,1.36,45.7,1.38
21.8,13.7,1.36,45.8,1.38
22.0,13.7,1.37,45.8,1.38
22.0,13.8,1.37,45.9,1.38
22.0,13.8,1.37,46.0,1.39
22.2,13.8,1.39,46.1,1.39
22.2,13.8,1.39,46.1,1.39
22.2,13.9,1.39,46.2,1.39
22.2,13.9,1.39,46.3,1.39
22.3,13.9,1.39,46.4,1.40
22.3,13.9,1.40,46.4,1.40
22.3,14.0,1.40,46.5,1.40
22.3,14.0,1.40,46.6,1.40
22.3,14.0,1.40,46.7,1.41
22.3,14.0,1.40,46.7,1.41
22.5,14.0,1.41,46.8,1.41
22.5,14.1,1.41,46.9,1.41
22.5,14.1,1.41,47.0,1.42
22.6,14.1,1.41,47.0,1.42
22.7,14.1,1.42,47.1,1.42
22.8,14.2,1.43,47.2,1.42
22.8,14.2,1.43,47.3,1.42
22.8,14.2,1.43,47.3,1.43
22.8,14.2,1.43,47.4,1.43
22.8,14.3,1.43,47.5,1.43
22.8,14.3,1.43,47.6,1.43
23.0,14.3,1.44,47.7,1.44
23.0,14.3,1.44,47.7,1.44
23.0,14.3,1.44,47.8,1.44
23.2,14.4,1.45,47.9,1.44
23.2,14.4,1.45,48.0,1.44
23.2,14.4,1.45,48.0,1.45
23.2,14.4,1.45,48.1,1.45
23.3,14.5,1.46,48.2,1.45
23.3,14.5,1.46,48.3,1.45
23.3,14.5,1.46,48.3,1.46
23.5,14.5,1.47,48.4,1.46
23.5,14.5,1.47,48.5,1.46
23.7,14.6,1.48,48.6,1.46
23.7,14.6,1.48,48.6,1.47
23.7,14.6,1.48,48.7,1.47
23.5,14.6,1.47,48.8,1.47
23.7,14.7,1.48,48.9,1.47
23.7,14.7,1.48,48.9,1.47
23.7,14.7,1.48,49.0,1.48
23.8,14.7,1.49,49.1,1.48
23.8,14.7,1.49,49.2,1.48
23.8,14.8,1.49,49.2,1.48
23.8,14.8,1.49,49.3,1.49
23.8,14.8,1.49,49.4,1.49
24.0,14.8,1.50,49.5,1.49
24.0,14.9,1.50,49.5,1.49
24.0,14.9,1.50,49.6,1.49
24.0,14.9,1.50,49.7,1.50
24.1,14.9,1.50,49.8,1.50
24.0,15.0,1.50,49.9,1.50
24.2,15.0,1.51,49.9,1.50
24.2,15.0,1.51,50.0,1.51
24.3,15.0,1.52,50.1,1.51
24.3,15.0,1.52,50.2,1.51
24.3,15.1,1.52,50.2,1.51
24.3,15.1,1.52,50.3,1.52
24.4,15.1,1.52,50.4,1.52
24.5,15.1,1.53,50.5,1.52
24.5,15.2,1.53,50.5,1.52
24.5,15.2,1.53,50.6,1.52
24.7,15.2,1.54,50.7,1.53
24.7,15.2,1.54,50.8,1.53
24.7,15.3,1.54,50.8,1.53
24.7,15.3,1.54,50.9,1.53
24.7,15.3,1.54,51.0,1.54
24.8,15.3,1.55,51.1,1.54
24.8,15.3,1.55,51.1,1.54
24.8,15.4,1.55,51.2,1.54
24.8,15.4,1.55,51.3,1.54
24.8,15.4,1.55,51.4,1.55
25.0,15.4,1.56,51.4,1.55
25.0,15.5,1.56,51.5,1.55
25.0,15.5,1.56,51.6,1.55
25.2,15.5,1.57,51.7,1.56
25.2,15.5,1.57,51.7,1.56
25.2,15.5,1.57,51.8,1.56
25.2,15.6,1.57,51.9,1.56
25.3,15.6,1.58,52.0,1.57
25.3,15.6,1.58,52.0,1.57
25.3,15.6,1.58,52.1,1.57
25.3,15.7,1.58,52.2,1.57
25.5,15.7,1.59,52.3,1.57
25.5,15.7,1.59,52.3,1.58
25.5,15.7,1.59,52.4,1.58
25.5,15.8,1.59,52.5,1.58
25.7,15.8,1.60,52.6,1.58
25.7,15.8,1.60,52.7,1.59
25.7,15.8,1.60,52.7,1.59
25.7,15.8,1.60,52.8,1.59
25.8,15.9,1.61,52.9,1.59
25.8,15.9,1.61,53.0,1.59
25.8,15.9,1.61,53.0,1.60
25.8,15.9,1.61,53.1,1.60
25.8,16.0,1.61,53.2,1.60
26.0,16.0,1.62,53.3,1.60
26.0,16.0,1.62,53.3,1.61
26.0,16.0,1.62,53.4,1.61
26.0,16.0,1.62,53.5,1.61
26.2,16.1,1.64,53.6,1.61
26.2,16.1,1.64,53.6,1.62
26.2,16.1,1.64,53.7,1.62
26.3,16.1,1.65,53.8,1.62
26.3,16.2,1.65,53.9,1.62
26.3,16.2,1.65,53.9,1.62
26.3,16.2,1.65,54.0,1.63
26.3,16.2,1.65,54.1,1.63
26.5,16.3,1.66,54.2,1.63
26.5,16.3,1.66,54.2,1.63
26.5,16.3,1.66,54.3,1.64
26.7,16.3,1.67,54.4,1.64
26.7,16.3,1.67,54.5,1.64
26.7,16.4,1.67,54.5,1.64
26.8,16.4,1.68,54.6,1.64
26.8,16.4,1.68,54.7,1.65
26.8,16.4,1.68,54.8,1.65
26.8,16.5,1.68,54.9,1.65
27.0,16.5,1.69,54.9,1.65
27.0,16.5,1.69,55.0,1.66
27.0,16.5,1.69,55.1,1.66
27.0,16.5,1.69,55.2,1.66
27.0,16.6,1.69,55.2,1.66
27.2,16.6,1.70,55.3,1.67
27.2,16.6,1.70,55.4,1.67
27.2,16.6,1.70,55.5,1.67
27.2,16.7,1.70,55.5,1.67
27.3,16.7,1.71,55.6,1.67
27.3,16.7,1.71,55.7,1.68
27.3,16.7,1.71,55.8,1.68
27.3,16.7,1.71,55.8,1.68
27.5,16.8,1.72,55.9,1.68
27.5,16.8,1.72,56.0,1.69
27.5,16.8,1.72,56.1,1.69
27.7,16.8,1.73,56.1,1.69
27.7,16.9,1.73,56.2,1.69
27.7,16.9,1.73,56.3,1.69
27.7,16.9,1.73,56.4,1.70
27.7,16.9,1.73,56.4,1.70
27.7,17.0,1.73,56.5,1.70
27.8,17.0,1.74,56.6,1.70
28.0,17.0,1.75,56.7,1.71
28.0,17.0,1.75,56.7,1.71
28.0,17.0,1.75,56.8,1.71
28.0,17.1,1.75,56.9,1.71
28.2,17.1,1.76,57.0,1.72
28.0,17.1,1.75,57.0,1.72
28.2,17.1,1.76,57.1,1.72
28.3,17.2,1.77,57.2,1.72
28.3,17.2,1.77,57.3,1.72
28.3,17.2,1.77,57.4,1.73
28.3,17.2,1.77,57.4,1.73
28.3,17.2,1.77,57.5,1.73
28.5,17.3,1.78,57.6,1.73
28.5,17.3,1.78,57.7,1.74
28.5,17.3,1.78,57.7,1.74
28.7,17.3,1.79,57.8,1.74
28.7,17.4,1.79,57.9,1.74
28.7,17.4,1.79,58.0,1.74
28.7,17.4,1.79,58.0,1.75
28.7,17.4,1.79,58.1,1.75
28.8,17.5,1.80,58.2,1.75
28.8,17.5,1.80,58.3,1.75
28.8,17.5,1.80,58.3,1.76
29.0,17.5,1.81,58.4,1.76
29.0,17.5,1.81,58.5,1.76
29.0,17.6,1.81,58.6,1.76
29.2,17.6,1.82,58.6,1.77
29.2,17.6,1.82,58.7,1.77
29.2,17.6,1.82,58.8,1.77
29.3,17.7,1.83,58.9,1.77
29.3,17.7,1.83,58.9,1.77
29.3,17.7,1.83,59.0,1.78
29.3,17.7,1.83,59.1,1.78
29.3,17.8,1.83,59.2,1.78
29.5,17.8,1.84,59.2,1.78
29.5,17.8,1.84,59.3,1.79
29.5,17.8,1.84,59.4,1.79
29.7,17.8,1.85,59.5,1.79
29.7,17.9,1.85,59.5,1.79
29.7,17.9,1.85,59.6,1.79
29.7,17.9,1.85,59.7,1.80
29.8,17.9,1.86,59.8,1.80
29.8,18.0,1.86,59.9,1.80
29.8,18.0,1.86,59.9,1.80
30.0,18.0,1.87,60.0,1.81
30.0,18.0,1.87,60.1,1.81
30.0,18.0,1.87,60.2,1.81
30.0,18.1,1.87,60.2,1.81
30.2,18.1,1.89,60.3,1.82
30.2,18.1,1.89,60.4,1.82
30.2,18.1,1.89,60.5,1.82
30.2,18.2,1.89,60.5,1.82
30.2,18.2,1.89,60.6,1.82
30.3,18.2,1.90,60.7,1.83
30.3,18.2,1.90,60.8,1.83
30.3,18.2,1.90,60.8,1.83
30.3,18.3,1.90,60.9,1.83
30.3,18.3,1.90,61.0,1.84
30.5,18.3,1.91,61.1,1.84
30.5,18.3,1.91,61.1,1.84
30.5,18.4,1.91,61.2,1.84
30.5,18.4,1.91,61.3,1.84
30.7,18.4,1.92,61.4,1.85
30.7,18.4,1.92,61.4,1.85
30.7,18.5,1.92,61.5,1.85
30.8,18.5,1.93,61.6,1.85
30.8,18.5,1.93,61.7,1.86
30.8,18.5,1.93,61.7,1.86
30.8,18.5,1.93,61.8,1.86
30.8,18.6,1.93,61.9,1.86
31.0,18.6,1.94,62.0,1.87
31.2,18.6,1.95,62.0,1.87
31.2,18.6,1.95,62.1,1.87
31.3,18.7,1.96,62.2,1.87
31.3,18.7,1.96,62.3,1.87
31.3,18.7,1.96,62.4,1.88
31.3,18.7,1.96,62.4,1.88
31.3,18.7,1.96,62.5,1.88
31.3,18.8,1.96,62.6,1.88
31.5,18.8,1.97,62.7,1.89
31.5,18.8,1.97,62.7,1.89
31.5,18.8,1.97,62.8,1.89
31.5,18.9,1.97,62.9,1.89
31.5,18.9,1.97,63.0,1.89
31.7,18.9,1.98,63.0,1.90
31.7,18.9,1.98,63.1,1.90
31.7,19.0,1.98,63.2,1.90
31.8,19.0,1.99,63.3,1.90
31.8,19.0,1.99,63.3,1.91
31.8,19.0,1.99,63.4,1.91
31.8,19.0,1.99,63.5,1.91
32.0,19.1,2.00,63.6,1.91
32.0,19.1,2.00,63.6,1.92
32.0,19.1,2.00,63.7,1.92
32.0,19.1,2.00,63.8,1.92
32.0,19.2,2.00,63.9,1.92
32.2,19.2,2.01,63.9,1.92
32.2,19.2,2.01,64.0,1.93
32.2,19.2,2.01,64.1,1.93
32.3,19.3,2.02,64.2,1.93
32.2,19.3,2.01,64.2,1.93
32.3,19.3,2.02,64.3,1.94
32.3,19.3,2.02,64.4,1.94
32.5,19.3,2.03,64.5,1.94
32.5,19.4,2.03,64.5,1.94
32.5,19.4,2.03,64.6,1.94
32.5,19.4,2.03,64.7,1.95
32.7,19.4,2.04,64.8,1.95
32.7,19.5,2.04,64.8,1.95
32.7,19.5,2.04,64.9,1.95
32.7,19.5,2.04,65.0,1.96
32.7,19.5,2.04,65.1,1.96
32.7,19.5,2.04,65.2,1.96
32.8,19.6,2.05,65.2,1.96
32.8,19.6,2.05,65.3,1.97
32.8,19.6,2.05,65.4,1.97
32.8,19.6,2.05,65.5,1.97
33.0,19.7,2.06,65.5,1.97
33.0,19.7,2.06,65.6,1.97
33.0,19.7,2.06,65.7,1.98
33.2,19.7,2.07,65.8,1.98
33.2,19.7,2.07,65.8,1.98
33.2,19.8,2.07,65.9,1.98
33.2,19.8,2.07,66.0,1.99
33.3,19.8,2.08,66.1,1.99
33.3,19.8,2.08,66.1,1.99
33.3,19.9,2.08,66.2,1.99
33.3,19.9,2.08,66.3,1.99
33.5,19.9,2.09,66.4,2.00
33.5,19.9,2.09,66.4,2.00
33.6,20.0,2.10,66.5,2.00
33.7,20.0,2.10,66.6,2.00
33.7,20.0,2.10,66.7,2.01
33.7,20.0,2.10,66.7,2.01
33.7,20.0,2.11,66.8,2.01
33.8,20.1,2.11,66.9,2.01
33.8,20.1,2.11,67.0,2.02
33.8,20.1,2.11,67.0,2.02
34.0,20.1,2.12,67.1,2.02
34.0,20.2,2.12,67.2,2.02
34.0,20.2,2.12,67.3,2.02
34.0,20.2,2.12,67.4,2.03
34.2,20.2,2.14,67.4,2.03
34.2,20.3,2.14,67.5,2.03
34.2,20.3,2.14,67.6,2.03
34.3,20.3,2.15,67.7,2.04
34.3,20.3,2.15,67.7,2.04
34.3,20.3,2.15,67.8,2.04
34.3,20.4,2.15,67.9,2.04
34.5,20.4,2.16,68.0,2.04
34.5,20.4,2.16,68.0,2.05
34.5,20.4,2.16,68.1,2.05
34.5,20.5,2.16,68.2,2.05
34.5,20.5,2.16,68.3,2.05
34.7,20.5,2.17,68.3,2.06
34.7,20.5,2.17,68.4,2.06
34.8,20.5,2.18,68.5,2.06
34.8,20.6,2.18,68.6,2.06
35.0,20.6,2.19,68.6,2.07
35.0,20.6,2.19,68.7,2.07
35.0,20.6,2.19,68.8,2.07
35.0,20.7,2.19,68.9,2.07
35.2,20.7,2.20,68.9,2.07
35.2,20.7,2.20,69.0,2.08
35.2,20.7,2.20,69.1,2.08
35.2,20.8,2.20,69.2,2.08
35.2,20.8,2.20,69.2,2.08
35.3,20.8,2.21,69.3,2.09
35.3,20.8,2.21,69.4,2.09
35.3,20.8,2.21,69.5,2.09
35.3,20.9,2.21,69.5,2.09
35.3,20.9,2.21,69.6,2.09
35.5,20.9,2.22,69.7,2.10
35.5,20.9,2.22,69.8,2.10
35.5,21.0,2.22,69.9,2.10
35.5,21.0,2.22,69.9,2.10
35.7,21.0,2.23,70.0,2.11
35.7,21.0,2.23,70.1,2.11
35.7,21.0,2.23,70.2,2.11
35.8,21.1,2.24,70.2,2.11
35.8,21.1,2.24,70.3,2.12
35.8,21.1,2.24,70.4,2.12
35.8,21.1,2.24,70.5,2.12
35.8,21.2,2.24,70.5,2.12
35.8,21.2,2.24,70.6,2.12
36.0,21.2,2.25,70.7,2.13
36.0,21.2,2.25,70.8,2.13
36.0,21.3,2.25,70.8,2.13
36.2,21.3,2.26,70.9,2.13
36.2,21.3,2.26,71.0,2.14
36.2,21.3,2.26,71.1,2.14
36.3,21.3,2.27,71.1,2.14
36.3,21.4,2.27,71.2,2.14
36.4,21.4,2.27,71.3,2.14
36.5,21.4,2.28,71.4,2.15
36.5,21.4,2.28,71.4,2.15
36.6,21.5,2.29,71.5,2.15
36.7,21.5,2.29,71.6,2.15
36.7,21.5,2.29,71.7,2.16
36.7,21.5,2.29,71.7,2.16
36.8,21.5,2.30,71.8,2.16
36.8,21.6,2.30,71.9,2.16
36.8,21.6,2.30,72.0,2.17
37.0,21.6,2.31,72.0,2.17
37.0,21.6,2.31,72.1,2.17
37.0,21.7,2.31,72.2,2.17
37.2,21.7,2.32,72.3,2.17
37.2,21.7,2.32,72.4,2.18
37.2,21.7,2.32,72.4,2.18
37.2,21.8,2.32,72.5,2.18
37.2,21.8,2.32,72.6,2.18
37.3,21.8,2.33,72.7,2.19
37.3,21.8,2.33,72.7,2.19
37.3,21.8,2.33,72.8,2.19
37.3,21.9,2.33,72.9,2.19
37.3,21.9,2.33,73.0,2.19
37.5,21.9,2.34,73.0,2.20
37.5,21.9,2.34,73.1,2.20
37.5,22.0,2.34,73.2,2.20
37.5,22.0,2.34,73.3,2.20
37.7,22.0,2.35,73.3,2.21
37.7,22.0,2.35,73.4,2.21
37.7,22.0,2.35,73.5,2.21
37.7,22.1,2.35,73.6,2.21
37.8,22.1,2.36,73.6,2.22
37.8,22.1,2.36,73.7,2.22
37.8,22.1,2.36,73.8,2.22
37.8,22.2,2.36,73.9,2.22
37.8,22.2,2.36,73.9,2.22
37.8,22.2,2.36,74.0,2.23
37.8,22.2,2.36,74.1,2.23
38.0,22.3,2.37,74.2,2.23
38.0,22.3,2.37,74.2,2.23
38.2,22.3,2.39,74.3,2.24
38.2,22.3,2.39,74.4,2.24
38.2,22.3,2.39,74.5,2.24
38.2,22.4,2.39,74.5,2.24
38.3,22.4,2.40,74.6,2.24
38.3,22.4,2.40,74.7,2.25
38.3,22.4,2.40,74.8,2.25
38.3,22.5,2.40,74.9,2.25
38.3,22.5,2.40,74.9,2.25
38.5,22.5,2.41,75.0,2.26
38.7,22.5,2.42,75.1,2.26
38.7,22.5,2.42,75.2,2.26
38.7,22.6,2.42,75.2,2.26
38.7,22.6,2.42,75.3,2.27
38.8,22.6,2.43,75.4,2.27
38.8,22.6,2.43,75.5,2.27
39.0,22.7,2.44,75.5,2.27
39.0,22.7,2.44,75.6,2.27
39.0,22.7,2.44,75.7,2.28
39.0,22.7,2.44,75.8,2.28
39.0,22.8,2.44,75.8,2.28
39.2,22.8,2.45,75.9,2.28
39.2,22.8,2.45,76.0,2.29
39.2,22.8,2.45,76.1,2.29
39.2,22.8,2.45,76.1,2.29
39.3,22.9,2.46,76.2,2.29
39.3,22.9,2.46,76.3,2.29
39.3,22.9,2.46,76.4,2.30
39.3,22.9,2.46,76.4,2.30
39.3,23.0,2.46,76.5,2.30
39.5,23.0,2.47,76.6,2.30
39.5,23.0,2.47,76.7,2.31
39.5,23.0,2.47,76.7,2.31
39.7,23.0,2.48,76.8,2.31
39.7,23.1,2.48,76.9,2.31
39.7,23.1,2.48,77.0,2.32
39.7,23.1,2.48,77.0,2.32
39.8,23.1,2.49,77.1,2.32
39.8,23.2,2.49,77.2,2.32
40.0,23.2,2.50,77.3,2.32
40.0,23.2,2.50,77.4,2.33
40.0,23.2,2.50,77.4,2.33
40.0,23.3,2.50,77.5,2.33
40.0,23.3,2.50,77.6,2.33
40.0,23.3,2.50,77.7,2.34
40.2,23.3,2.51,77.7,2.34
40.2,23.3,2.51,77.8,2.34
40.2,23.4,2.51,77.9,2.34
40.2,23.4,2.51,78.0,2.34
40.2,23.4,2.51,78.0,2.35
40.3,23.4,2.52,78.1,2.35
40.3,23.5,2.52,78.2,2.35
40.3,23.5,2.52,78.3,2.35
40.5,23.5,2.53,78.3,2.36
40.5,23.5,2.53,78.4,2.36
40.5,23.5,2.53,78.5,2.36
40.5,23.6,2.53,78.6,2.36
40.5,23.6,2.53,78.6,2.37
40.5,23.6,2.53,78.7,2.37
40.5,23.6,2.53,78.8,2.37
40.7,23.7,2.54,78.9,2.37
40.7,23.7,2.54,78.9,2.37
40.7,23.7,2.54,79.0,2.38
40.8,23.7,2.55,79.1,2.38
40.8,23.8,2.55,79.2,2.38
40.8,23.8,2.55,79.2,2.38
40.8,23.8,2.55,79.3,2.39
40.9,23.8,2.55,79.4,2.39
41.0,23.8,2.56,79.5,2.39
41.0,23.9,2.56,79.5,2.39
41.2,23.9,2.57,79.6,2.39
41.2,23.9,2.57,79.7,2.40
41.2,23.9,2.57,79.8,2.40
41.3,24.0,2.58,79.9,2.40
41.3,24.0,2.58,79.9,2.40
41.3,24.0,2.58,80.0,2.41
41.3,24.0,2.58,80.1,2.41
41.4,24.0,2.59,80.2,2.41
41.5,24.1,2.59,80.2,2.41
41.5,24.1,2.59,80.3,2.42
41.5,24.1,2.59,80.4,2.42
41.5,24.1,2.59,80.5,2.42
41.5,24.2,2.59,80.5,2.42
41.7,24.2,2.60,80.6,2.42
41.7,24.2,2.60,80.7,2.43
41.7,24.2,2.60,80.8,2.43
41.8,24.3,2.61,80.8,2.43
41.8,24.3,2.61,80.9,2.43
41.8,24.3,2.61,81.0,2.44
41.8,24.3,2.61,81.1,2.44
41.8,24.3,2.61,81.1,2.44
42.0,24.4,2.62,81.2,2.44
42.0,24.4,2.62,81.3,2.44
42.0,24.4,2.62,81.4,2.45
42.2,24.4,2.64,81.4,2.45
42.2,24.5,2.64,81.5,2.45
42.2,24.5,2.64,81.6,2.45
42.2,24.5,2.64,81.7,2.46
42.3,24.5,2.65,81.7,2.46
42.3,24.5,2.65,81.8,2.46
42.3,24.6,2.65,81.9,2.46
42.3,24.6,2.65,82.0,2.47
42.3,24.6,2.65,82.1,2.47
42.5,24.6,2.66,82.1,2.47
42.5,24.7,2.66,82.2,2.47
42.5,24.7,2.66,82.3,2.47
42.5,24.7,2.66,82.4,2.48
42.7,24.7,2.67,82.4,2.48
42.7,24.8,2.67,82.5,2.48
42.7,24.8,2.67,82.6,2.48
42.8,24.8,2.68,82.7,2.49
42.8,24.8,2.68,82.7,2.49
42.8,24.8,2.68,82.8,2.49
42.8,24.9,2.68,82.9,2.49
42.8,24.9,2.68,83.0,2.49
43.0,24.9,2.69,83.0,2.50
43.0,24.9,2.69,83.1,2.50
43.0,25.0,2.69,83.2,2.50
43.0,25.0,2.69,83.3,2.50
43.0,25.0,2.69,83.3,2.51
43.2,25.0,2.70,83.4,2.51
43.2,25.0,2.70,83.5,2.51
43.3,25.1,2.71,83.6,2.51
43.3,25.1,2.71,83.6,2.52
43.3,25.1,2.71,83.7,2.52
43.3,25.1,2.71,83.8,2.52
43.5,25.2,2.72,83.9,2.52
43.5,25.2,2.72,83.9,2.52
43.5,25.2,2.72,84.0,2.53
43.5,25.2,2.72,84.1,2.53
43.6,25.3,2.73,84.2,2.53
43.6,25.3,2.72,84.2,2.53
43.5,25.3,2.72,84.3,2.54
43.5,25.3,2.72,84.4,2.54
43.7,25.3,2.73,84.5,2.54
43.7,25.4,2.73,84.6,2.54
43.7,25.4,2.73,84.6,2.54
43.7,25.4,2.73,84.7,2.55
43.7,25.4,2.73,84.8,2.55
43.7,25.5,2.73,84.9,2.55
43.7,25.5,2.73,84.9,2.55
43.7,25.5,2.73,85.0,2.56
43.8,25.5,2.74,85.1,2.56
43.8,25.5,2.74,85.2,2.56
43.8,25.6,2.74,85.2,2.56
43.8,25.6,2.74,85.3,2.57
43.9,25.6,2.75,85.4,2.57
44.0,25.6,2.75,85.5,2.57
44.0,25.7,2.75,85.5,2.57
44.0,25.7,2.75,85.6,2.57
44.1,25.7,2.76,85.7,2.58
44.2,25.7,2.76,85.8,2.58
44.3,25.8,2.77,85.8,2.58
44.3,25.8,2.77,85.9,2.58
44.3,25.8,2.77,86.0,2.59
44.3,25.8,2.77,86.1,2.59
44.3,25.8,2.77,86.1,2.59
44.3,25.9,2.77,86.2,2.59
44.5,25.9,2.78,86.3,2.59
44.5,25.9,2.78,86.4,2.60
44.5,25.9,2.78,86.4,2.60
44.5,26.0,2.78,86.5,2.60
44.7,26.0,2.79,86.6,2.60
44.7,26.0,2.79,86.7,2.61
44.7,26.0,2.79,86.7,2.61
44.7,26.0,2.79,86.8,2.61
44.8,26.1,2.80,86.9,2.61
44.8,26.1,2.80,87.0,2.62
44.8,26.1,2.80,87.1,2.62
44.8,26.1,2.80,87.1,2.62
44.8,26.2,2.80,87.2,2.62
45.0,26.2,2.81,87.3,2.62
45.0,26.2,2.81,87.4,2.63
45.0,26.2,2.81,87.4,2.63
45.2,26.3,2.82,87.5,2.63
45.1,26.3,2.82,87.6,2.63
45.2,26.3,2.82,87.7,2.64
45.2,26.3,2.82,87.7,2.64
45.2,26.3,2.82,87.8,2.64
45.2,26.4,2.82,87.9,2.64
45.3,26.4,2.83,88.0,2.64
45.3,26.4,2.83,88.0,2.65
45.3,26.4,2.83,88.1,2.65
45.3,26.5,2.83,88.2,2.65
45.3,26.5,2.83,88.3,2.65
45.3,26.5,2.83,88.3,2.66
45.4,26.5,2.84,88.4,2.66
45.5,26.5,2.84,88.5,2.66
45.5,26.6,2.84,88.6,2.66
45.5,26.6,2.84,88.6,2.67
45.5,26.6,2.85,88.7,2.67
45.7,26.6,2.85,88.8,2.67
45.7,26.7,2.85,88.9,2.67
45.7,26.7,2.85,88.9,2.67
45.8,26.7,2.86,89.0,2.68
45.8,26.7,2.86,89.1,2.68
45.8,26.8,2.86,89.2,2.68
45.8,26.8,2.86,89.2,2.68
46.0,26.8,2.87,89.3,2.69
46.0,26.8,2.87,89.4,2.69
46.0,26.8,2.87,89.5,2.69
46.0,26.9,2.87,89.6,2.69
46.0,26.9,2.87,89.6,2.69
46.0,26.9,2.87,89.7,2.70
46.0,26.9,2.87,89.8,2.70
46.1,27.0,2.88,89.9,2.70
46.1,27.0,2.88,89.9,2.70
46.0,27.0,2.87,90.0,2.71
46.2,27.0,2.89,90.1,2.71
46.2,27.0,2.89,90.2,2.71
46.2,27.1,2.89,90.2,2.71
46.2,27.1,2.89,90.3,2.72
46.2,27.1,2.89,90.4,2.72
46.2,27.1,2.89,90.5,2.72
46.3,27.2,2.90,90.5,2.72
46.2,27.2,2.89,90.6,2.72
46.2,27.2,2.89,90.7,2.73
46.2,27.2,2.89,90.8,2.73
46.2,27.3,2.89,90.8,2.73
46.0,27.3,2.88,90.9,2.73
46.0,27.3,2.87,91.0,2.74
46.0,27.3,2.87,91.1,2.74
28.4,27.3,1.78,91.1,2.74
-7.47,27.4,-0.467,91.2,2.74
-7.50,27.4,-0.469,91.3,2.74
-7.50,27.4,-0.469,91.4,2.75
-7.50,27.4,-0.469,91.5,2.75
-7.50,27.5,-0.469,91.5,2.75
-7.50,27.5,-0.469,91.6,2.75
-7.50,27.5,-0.469,91.7,2.76
-7.50,27.5,-0.469,91.8,2.76
-7.50,27.5,-0.469,91.8,2.76
-7.50,27.6,-0.469,91.9,2.76
-7.50,27.6,-0.469,92.0,2.77
-7.50,27.6,-0.469,92.1,2.77
-7.50,27.6,-0.469,92.1,2.77
-7.50,27.7,-0.469,92.2,2.77
-7.50,27.7,-0.469,92.3,2.77
-7.50,27.7,-0.469,92.4,2.78
-7.50,27.7,-0.469,92.4,2.78
-7.50,27.8,-0.469,92.5,2.78
-7.50,27.8,-0.469,92.6,2.78
-7.50,27.8,-0.469,92.7,2.79
-7.50,27.8,-0.469,92.7,2.79
-7.33,27.8,-0.458,92.8,2.79
-7.33,27.9,-0.458,92.9,2.79
-7.33,27.9,-0.458,93.0,2.79
-7.33,27.9,-0.458,93.0,2.80
-7.33,27.9,-0.458,93.1,2.80
-7.50,28.0,-0.469,93.2,2.80
-7.50,28.0,-0.469,93.3,2.80
-7.50,28.0,-0.469,93.3,2.81
-7.50,28.0,-0.469,93.4,2.81
-7.50,28.0,-0.469,93.5,2.81
-7.33,28.1,-0.458,93.6,2.81
-7.33,28.1,-0.458,93.6,2.82
-7.50,28.1,-0.469,93.7,2.82
-7.49,28.1,-0.468,93.8,2.82
-7.33,28.2,-0.458,93.9,2.82
-7.50,28.2,-0.469,93.9,2.82
-7.50,28.2,-0.469,94.0,2.83
-7.50,28.2,-0.469,94.1,2.83
-7.50,28.3,-0.469,94.2,2.83
-7.50,28.3,-0.469,94.3,2.83
-7.50,28.3,-0.469,94.3,2.84
-7.50,28.3,-0.469,94.4,2.84
-7.33,28.3,-0.458,94.5,2.84
-7.50,28.4,-0.469,94.6,2.84
-7.50,28.4,-0.469,94.6,2.84
-7.33,28.4,-0.458,94.7,2.85